Workbook
Name 印刷用: #REF!

Sheet シート説明
C2: ○ がついている部分は必須入力なので必ず埋めるようにしてください。
B3: 機能タイプ | H3: 記入時期
B4: 帳票プログラム | C4: バッチインプット | D4: インバウンド | E4: アウトバウンド | F4: 拡張プログラム | G4: Dynpro | H4: 要件定義時 | I4: 詳細設計時 | J4: 変更時 | K4: 開発時 | L4: 記入シート | T4: 説明
B5: ○ | C5: ○ | D5: ○ | E5: ○ | F5: ○ | G5: ○ | H5: ○ | L5: 1. | M5: 要件定義書 | T5: 要件定義書のタイトル。要件定義書毎に必ず１つ必要
B6: ○ | C6: ○ | D6: ○ | E6: ○ | F6: ○ | G6: ○ | I6: ○ | L6: 2. | M6: 詳細設計書 | T6: 詳細設計書のタイトル。詳細設計書毎に必ず１つ必要
B7: ○ | C7: ○ | D7: ○ | E7: ○ | F7: ○ | G7: ○ | I7: ○ | L7: 3. | M7: 処理詳細 | T7: 詳細設計書シートの詳細処理を記入
H8: △ | I8: △ | L8: 4. | M8: 特殊要件 | T8: 特殊要件があれば記入
B9: ○ | C9: ○ | D9: ○ | E9: ○ | H9: ○ | I9: ○ | L9: 5. | M9: 選択画面レイアウト | T9: Select-options, Parametersの使用時に必要
B10: ○ | H10: △ | I10: △ | L10: 6. | M10: 入力チェック | T10: 上記シートでエラーチェックに印を付けた場合必要
B11: ○ | I11: △ | L11: 7. | M11: Tableデータ抽出 | T11: DBテーブルの抽出があれば必要
H12: △ | I12: △ | L12: 8. | M12: File定義 | T12: File使用時に必要
C13: ○ | D13: ○ | E13: ○ | H13: ○ | L13: 9. | M13: マッピング定義 | T13: 何らかのOutPutがある場合に必要
E14: ○ | I14: ○ | L14: 10. | M14: 出力ファイル定義 | T14: Outboundプログラム必須：要件定義時はマッピング定義
I15: △ | L15: 11. | M15: 抽出項目 | T15: 抽出がある場合必要
B16: ○ | H16: ○ | I16: ○ | L16: 12. | M16: 帳票機能定義 | T16: Reportプログラム必須
B17: ○ | H17: ○ | I17: ○ | L17: 13. | M17: 帳票項目定義書 | T17: Reportプログラム必須
B18: ○ | H18: ○ | I18: ○ | L18: 14. | M18: 帳票レイアウト | T18: Reportプログラム必須
C19: ○ | D19: ○ | I19: ○ | L19: 15. | M19: バッチイプット項目 | T19: BatchInputプログラム必須：要件定義時はマッピング定義
I20: △ | L20: 16. | M20: Table更新 | T20: Add-Onテーブル更新時必須：要件定義時はマッピング定義
G21: ○ | H21: ○ | I21: ○ | L21: 17. | M21: Dynproレイアウト | T21: Dynproプログラム必須
G22: ○ | I22: ○ | L22: 18. | M22: GUIステータス | T22: Dynproプログラム必須
G23: ○ | H23: ○ | I23: ○ | L23: 19. | M23: Dynpro仕様 | T23: Dynproプログラム必須
G24: ○ | H24: ○ | I24: ○ | L24: 20. | M24: 画面遷移図 | T24: Dynproプログラム必須
B25: ○ | H25: △ | I25: △ | L25: 21. | M25: エラーチェック | T25: エラー処理を行なう場合必須
B26: ○ | C26: ○ | D26: ○ | E26: ○ | F26: ○ | G26: ○ | I26: ○ | L26: 22. | M26: テスト概要 | T26: 必須
B27: ○ | C27: ○ | D27: ○ | E27: ○ | F27: ○ | G27: ○ | I27: ○ | K27: ○ | L27: 23. | M27: テストデータ | T27: 必須
B28: ○ | C28: ○ | D28: ○ | E28: ○ | F28: ○ | G28: ○ | K28: ○ | L28: 24. | M28: テスト詳細 | T28: Project依存
B29: ○ | C29: ○ | D29: ○ | E29: ○ | F29: ○ | G29: ○ | J29: ○ | L29: 25. | M29: 変更履歴 | T29: 必須
B30: ○ | I30: ○ | M30: 帳票項目定義書 | T30: Reportプログラム必須
B31: ○ | I31: ○ | M31: 帳票レイアウト(詳細) | T31: Reportプログラム必須

Sheet Check List
D1: Project： | G1: =IF(詳細設計書!G1="","N/A",詳細設計書!G1) -> 統合会計システム開発 | O1: チェック日： | Z1: レビュー日：
D2: System： | G2: =IF(詳細設計書!G2="","N/A",詳細設計書!G2) -> SAP R/3(レポート) | O2: チェック者： | Z2: レビュー者：
D3: DP ID： | G3: =IF(詳細設計書!G3="","N/A",詳細設計書!G3) -> DP_FI_2014_01 | O3: Program ID： | S3: =IF(詳細設計書!S3="","N/A",詳細設計書!S3) -> ZFIPR_2014_01
A4: Title： | D4: 入力チェック要件書 | Z4: Version： | AC4: =詳細設計書!AC4 -> 1.0
A6: シート（用意する条件）
A7: Check | C7: チェック内容
A8: 1. | B8: 仕様定義書
D9: PFD 名称 | H9: PFD 名称が正しく記入されているか
D10: PGM 名称 | H10: Program 名称が正しく記入されている
A11: ◎ | D11: 機能 | H11: プログラム中に含まれる機能とそれぞれの機能数が正しく記入されている
D12: 特殊要件有無 | H12: 特殊要件が存在する場合、正しく選択されている。セキュリティ要件にチェックされている場合は、それがカスタマイズでは回避できる要件ではない。処理時間に制約がある場合、適切な時間が記述されている。
D13: 運用方法 | H13: 運用方法が正しく選択されている。運用上特に運用される方法が記入されている。また、希望処理時間が記入されている
A14: ◎ | D14: 業務目的 | H14: プログラムの業務目的がわかりやすく記述されている
A15: ◎ | D15: 仕様概要 | H15: プログラムの仕様概要が正しく、わかりやすく記述されている
A16: ◎ | D16: 承認 | H16: 承認者、承認日付が記述されている
A18: 2. | B18: 特殊要件（特殊要件が存在する場合）
A19: ◎ | D19: 全体 | H19: 仕様定義書の特殊要件有無が１つ以上選択されている場合、シートが用意されている
D20: セキュリティ要件 | H20: セキュリティ要件が存在する場合、正しく記述されている
D21: 特殊運用要件 | H21: 特殊運用要件が存在する場合、正しく記述されている
D22: 処理時間制約 | H22: 処理時間に制約がある場合、制約時間と理由が記述されている
D23: 複数言語/通貨 | H23: 複数言語、通貨の対応が必要な場合、必要な言語、通貨及び対応方法が記述されている
A25: 3. | B25: 選択画面（プログラムに選択オプションまたはパラメータが含まれる場合）
A26: ◎ | D26: 全体 | H26: プログラムに選択オプションまたはパラメータが含まれる場合、シートが用意されている。
D27: 入力位置 | H27: 入力項目に位置の指定が必要な場合、｢指定有り｣にチェックがついてある
D28: Select-Options | H28: ID、テキスト、テーブル項目が記入されている。また、デフォルト指定、マッチコード検索機能、必須、エラーチェック等の要件がある場合、それらが正しく記入されている。
D29: Parameters | H29: ID、テキスト、テーブル項目が記入されている。また、デフォルト指定、チェックボタン、ラジオボタン、マッチコード検索機能、必須、エラーチェック等の要件がある場合、それらが正しく記入されている。
A31: 4. | B31: 入力チェック要件書（ReportまたはDynproで入力チェックを行う場合）
A32: ◎ | D32: 全体 | H32: ReportまたはDynproで入力チェックを行う場合、シートが用意されている(Dynproの場合、Dynpro数分のシートが用意されている)
D33: Dynpro No. | H33: Dynproの場合、Dynpro No.が正しく記入されている
A34: ◎ | D34: 入力チェック | H34: ID、項目、チェック内容、エラーメッセージの内容が正しく記述されている。また、エラーメッセージのID、タイプ、番号が決定している場合、それらが正しく記入されている。
A36: 5. | B36: Table データ抽出条件（Tableからのデータ抽出が存在する場合）
A37: ◎ | D37: 全体 | H37: プログラム内に２つ以上のテーブルを組み合わせた抽出が存在する場合、シートが独立した抽出の数分用意されている。
A38: ◎ | D38: 抽出ID | H38: 抽出IDが正しく記入されている
A39: ◎ | D39: 抽出対象Table | H39: 抽出に関わるテーブルの情報が正しく記入されている。推定データ件数に適切な値が記述されている
D40: 抽出の目的 | H40: 抽出の目的がわかりやすく具体的に記述されている
D41: 抽出条件 | H41: テーブル毎の結合条件、絞り込み条件が正しくわかりやすく記述されている
A43: 6. | B43: File データ抽出条件（UnixファイルまたはPCファイルを使用する場合）
A44: ◎ | D44: 全体 | H44: UnixファイルまたはPCファイルを使用する場合、シートは用意されている
D45: File一覧 | H45: プログラム内で使用するすべてのファイルが記入されている。推定データ件数が記述されている
A47: 7. | B47: 抽出項目（すべてのプログラム）
...

Sheet 詳細設計書
D1: Project： | G1: 統合会計システム開発 | O1: 仕様作成日： | S1: 42509 | Z1: 最終変更日： | AD1: 42559
D2: System： | G2: SAP R/3(レポート) | O2: 仕様作成者： | S2: KSC 橋本 | Z2: 最終変更者： | AD2: KSC 橋本
D3: DP ID： | G3: DP_FI_2014_01 | O3: Program ID： | S3: =IF(G3="","N/A","ZFIPR_"&MID(G3,7,7)) -> ZFIPR_2014_01 | Z3: RD ID | AC3: RD_FI_2014
A4: Title： | D4: (電子記録債務)送信データ作成 | Z4: Version： | AC4: 1.0
A6: 承認者： | S6: 承認日付：
A7: 事務局： | S7: 承認日付：
A9: DP 名称： | E9: (電子記録債務)送信データ作成
A10: PGM 名称： | E10: (電子記録債務)送信データ作成
A11: 機能 | O11: 特殊要件有無
I12: x
I13: x | U13: （APロジックでのみ実現可能な要件）
I14: x
I15: x | U15: （極小頻度で発生する大量データ処理など）
I16: x | Y16: 制約処理時間： | AF16: 秒
I17: x | J17: 1 | U17: （遵守しなければ運用が不可能となる制約）
A19: 運用方法
R20: 希望処理時間 ： | Y20: 秒
V21: 支払締時
C22: 業務上特に運用される方法：
C23: 利用部門 ： | K23: 事務グループ
C24: 実行前提条件 ： | K24: 支払プログラム印刷実行済[標準機能]
C25: 利用モジュール ： | K25: FI
A28: 業務目的 （業務要件の要約）
B30: ・ | C30: 電子記録債務送信データの作成
A39: 仕様概要 （処理概要）
B41: ・ | C41: 自動支払プログラムの標準機能である印刷処理実行後、
C42: (電子記録債務)送信データを作成する。
C43: 当プログラムは自動支払プログラム(TR-CD:F110)の支払印刷処理より呼び出される。
B45: ・ | C45: 当機能はファクタリング機能と同じ仕組みで作成するため、ファクタリング機能のPGMをコピー新規で作成している。
C46: そのため、電子記録債務で未使用の設計書の記載やロジックもそのまま残している。
C47: なお、当PGMはDP_FI_2001_01（PGMID：ZFIPR_2001_01）をコピーしている。

Sheet 処理詳細(1)
D1: Project： | G1: =IF(詳細設計書!G1="","N/A",詳細設計書!G1) -> 統合会計システム開発 | O1: 仕様作成日： | S1: =IF(詳細設計書!S1="","N/A",詳細設計書!S1) -> 42509 | Z1: 最終変更日： | AD1: =IF(詳細設計書!AD1="","",詳細設計書!AD1) -> 42559
D2: System： | G2: =IF(詳細設計書!G2="","N/A",詳細設計書!G2) -> SAP R/3(レポート) | O2: 仕様作成者： | S2: =IF(詳細設計書!S2="","N/A",詳細設計書!S2) -> KSC 橋本 | Z2: 最終変更者： | AD2: =IF(詳細設計書!AD2="","",詳細設計書!AD2) -> KSC 橋本
D3: DP ID： | G3: =IF(詳細設計書!G3="","N/A",詳細設計書!G3) -> DP_FI_2014_01 | O3: Program ID： | S3: =IF(詳細設計書!S3="","N/A",詳細設計書!S3) -> ZFIPR_2014_01 | Z3: RD ID | AC3: =詳細設計書!AC3 -> RD_FI_2014
A4: Title： | D4: 処理詳細（１） | Z4: Version： | AC4: =詳細設計書!AC4 -> 1.0
A6: 承認者： | S6: 承認日付：
A7: 事務局： | S7: 承認日付：
A9: ID | D9: 処理内容
B10: 1 | E10: 初期処理
E11: 1.1 | F11: 入力パラメータのチェック
G12: ※ | H12: 詳細は別紙「選択画面レイアウト」を参照して下さい。
F13: パラメータは前処理プログラムからバリアントを通じて引き渡される。
G14: ※引渡しのためダミーのバリアントを登録しておく(内容は問わない)。
E16: 1.2 | F16: プログラム開始メッセージの表示
F17: 「「ZFIPR_2014_01:(電子記録債務)送信データファイル作成【開始】」」
F18: ※下線部は変数 | L18: (ID:ZFI002,TYPE:S,NUMBER:073)
B20: 2 | E20: 電手決済債務明細データの取得
E21: 2.1 | F21: データ取得
F22: 入力パラメータ：実行日、認識名により支払プログラムの決済データ(REGUH)を抽出する。
F23: ＜検索条件・取得情報＞
G24: ※ Tableデータ抽出１を参照
E26: 2.2 | F26: 決済データの合計金額の算出
F27: 2.1で取得した決済データの合計金額を計算する。
G28: 対象となるデータ(実行日＋認識名)をすべて加算する。

Sheet 処理詳細(2)
D1: Project： | G1: =IF(詳細設計書!G1="","N/A",詳細設計書!G1) -> 統合会計システム開発 | O1: 仕様作成日： | S1: =IF(詳細設計書!S1="","N/A",詳細設計書!S1) -> 42509 | Z1: 最終変更日： | AD1: =IF(詳細設計書!AD1="","",詳細設計書!AD1) -> 42559
D2: System： | G2: =IF(詳細設計書!G2="","N/A",詳細設計書!G2) -> SAP R/3(レポート) | O2: 仕様作成者： | S2: =IF(詳細設計書!S2="","N/A",詳細設計書!S2) -> KSC 橋本 | Z2: 最終変更者： | AD2: =IF(詳細設計書!AD2="","",詳細設計書!AD2) -> KSC 橋本
D3: DP ID： | G3: =IF(詳細設計書!G3="","N/A",詳細設計書!G3) -> DP_FI_2014_01 | O3: Program ID： | S3: =IF(詳細設計書!S3="","N/A",詳細設計書!S3) -> ZFIPR_2014_01 | Z3: RD ID | AC3: =詳細設計書!AC3 -> RD_FI_2014
A4: Title： | D4: 処理詳細（２） | Z4: Version： | AC4: =詳細設計書!AC4 -> 1.0
A6: 承認者： | S6: 承認日付：
A7: 事務局： | S7: 承認日付：
A9: ID | D9: 処理内容
B11: 3 | E11: 電手決済債務明細データの送信用ファイル出力準備
E13: 3.1 | F13: 電手決済マスタテーブル(ZFIT020)の読み込み
F14: 2.1で取得した支払会社コード(REGUH-ZBUKR)により、電手決済マスタテーブル(ZFIT020)を抽出する。
F15: ＜検索条件・取得情報＞
G16: ※ Tableデータ抽出２を参照
F17: ＜エラー＞
G18: 「テーブル【ZFIT020】に当該データがありません(Key1=【会社コード】 Key2=& Key3=&)。
G19: 管理者に連絡してください」
G20: ※下線部は変数 | M20: (ID:ZFI002,TYPE:E,NUMBER:028)
E22: 3.2 | F22: 固定値マスターテーブル(ZFIT001)より、ファイル書き出し先Path名の取得
F23: 2.1で取得した支払会社コード(REGUH-ZBUKR)により、固定値マスターテーブル(ZFIT001)を抽出する。
F24: ＜検索条件・取得情報＞
G25: ※ Tableデータ抽出３を参照
F26: ＜エラー＞
G27: 「テーブル【ZFIT001】に当該データがありません(Key1=【会社コード】 Key2=& Key3=&)。
G28: 管理者に連絡してください」
G29: ※下線部は変数 | M29: (ID:ZFI002,TYPE:E,NUMBER:028)
E31: 3.3 | F31: 出力ファイル名(フルパス)のセット
F32: 3.2で取得したPath名と実行日＋認識名により、出力ファイル名(フルパス)を決定する。
F33: (1) | G33: 債務明細データ送信ファイル
G34: データ種別(ZFIT001-DATAID)=021
G35: 連番(ZFIT001-SEQNO)=01のレコードを使用する。
G36: 出力ファイル名１ | L36: = | M36: 内容１(ZFIT001-VALUE1)※1＋内容２(ZFIT001-VALUE2)※1＋
M37: 連番(ZFIT001-SEQNO)＋実行日(入力パラメータ)下6桁＋認識名(入力パラメータ)
H38: 例) | I38: 内容１ | M38: /opt/data/sap/zfipr_20001/ | U38: ┐
I39: 内容２ | M39: test/ | U39: │
I40: 実行日 | M40: 2002/4/20 | Q40: ─ | R40: ─ | S40: ─ | T40: ─ | U40: │ | V40: ─ | W40: ─ | X40: ─ | Y40: ┐
I41: 認識名 | M41: SS001 | U41: ↓ | Y41: ↓
I42: 出力ファイル名 | N42: = | O42: "/opt/data/sap/zfipr_20001/test/01020420SS001"
F44: (2) | G44: DME送信ファイル | M44: （※2016/05/19現在､DMEファイルは作成しない為、パスは取得しない)
G45: 連番(ZFIT001-SEQNO)=02のレコードを使用する。
G46: 出力ファイル名２ | L46: = | M46: 内容１(ZFIT001-VALUE1)※1＋内容２(ZFIT001-VALUE2)※1＋
M47: 連番(ZFIT001-SEQNO)＋実行日(入力パラメータ)下6桁＋認識名(入力パラメータ)
...

Sheet 処理詳細(3)
D1: Project： | G1: =IF(詳細設計書!G1="","N/A",詳細設計書!G1) -> 統合会計システム開発 | O1: 仕様作成日： | S1: =IF(詳細設計書!S1="","N/A",詳細設計書!S1) -> 42509 | Z1: 最終変更日： | AD1: =IF(詳細設計書!AD1="","",詳細設計書!AD1) -> 42559
D2: System： | G2: =IF(詳細設計書!G2="","N/A",詳細設計書!G2) -> SAP R/3(レポート) | O2: 仕様作成者： | S2: =IF(詳細設計書!S2="","N/A",詳細設計書!S2) -> KSC 橋本 | Z2: 最終変更者： | AD2: =IF(詳細設計書!AD2="","",詳細設計書!AD2) -> KSC 橋本
D3: DP ID： | G3: =IF(詳細設計書!G3="","N/A",詳細設計書!G3) -> DP_FI_2014_01 | O3: Program ID： | S3: =IF(詳細設計書!S3="","N/A",詳細設計書!S3) -> ZFIPR_2014_01 | Z3: RD ID | AC3: =詳細設計書!AC3 -> RD_FI_2014
A4: Title： | D4: 処理詳細（３） | Z4: Version： | AC4: =詳細設計書!AC4 -> 1.0
A6: 承認者： | S6: 承認日付：
A7: 事務局： | S7: 承認日付：
A9: ID | D9: 処理内容
B10: 4 | E10: 電手決済債務明細データの送信用ファイル出力
E11: 2.1で取得した対象データを送信ファイルに編集し、ファイルに書き出す。
E12: 4.1 | F12: 電手決済債務明細データの送信用ファイルのOPEN
F13: 3.3(1)で決定した出力ファイル名で出力ファイルをオープンする。
G14: OPEN DATASET 出力ファイル名 FOR OUTPUT IN TEXT MODE. → FOR OUTPUT IN BINARY MODE | AJ14: 変更2016/7/12
F15: ※ファイルがすでに存在する場合は上書きされる。
G16: 以下のメッセージを表示し、処理を続行する。
G17: 「【電手決済送信データ】：【/xxxxxx/yyyyyyy/zzzzzzzzzz/1234567890】」
G18: ※下線部は変数 | M18: (ID:ZFI002,TYPE:S,NUMBER:040)
H19: 第一パラメータ：固定値、第二パラメータ：フルpath
F20: ＜エラー＞
G21: OPENできない時、下記のメッセージを表示し、処理を終了する。
G22: 「ファイルの【OPEN：/xxxxx/yyyyy/zzzzz/aaaaaaaaaaaaa】に失敗しました。管理者に連絡してください。」
G23: ※下線部は変数、パス名とファイル名をCONCATENATEする。 | X23: (ID:ZFI002,TYPE:E,NUMBER:030)
E25: 4.2 | F25: ヘッダーレコードの出力
F26: 3で取得した各種情報を編集し出力する。
F27: ＜詳細＞ | I27: ※TRANSFER 命令を使用
G28: TRANSFER ヘッダーレコード TO 出力ファイル名．
G29: 編集内容はFile定義(1)参照
F30: ＜エラー＞
G31: TRANSFERできない時、下記のメッセージを表示し、処理を終了する。
G32: 「ファイルの【TRANSFER：/xxxxx/yyyyy/zzzzz/aaaaaaaaaaaaa】に失敗しました。管理者に連絡してください。」
G33: ※下線部は変数、パス名とファイル名をCONCATENATEする。 | X33: (ID:ZFI002,TYPE:E,NUMBER:030)
E35: 4.3 | F35: 明細レコードの出力
F36: 2.1で抽出した支払先毎の支払情報を編集し出力する。(全支払先分)
F37: ＜詳細＞ | I37: ※TRANSFER 命令を使用
G38: TRANSFER 明細レコード TO 出力ファイル名．
G39: 編集内容はFile定義(1)参照
F40: ＜エラー＞
G41: TRANSFERできない時、下記のメッセージを表示し、処理を終了する。
G42: 「ファイルの【TRANSFER：/xxxxx/yyyyy/zzzzz/aaaaaaaaaaaaa】に失敗しました。管理者に連絡してください。」
G43: ※下線部は変数、パス名とファイル名をCONCATENATEする。 | X43: (ID:ZFI002,TYPE:E,NUMBER:030)
E45: 4.4 | F45: 支払明細トレーラレコードの出力(レコード区分="8")
...

Sheet 処理詳細(4)
D1: Project： | G1: =IF(詳細設計書!G1="","N/A",詳細設計書!G1) -> 統合会計システム開発 | O1: 仕様作成日： | S1: =IF(詳細設計書!S1="","N/A",詳細設計書!S1) -> 42509 | Z1: 最終変更日： | AD1: =IF(詳細設計書!AD1="","",詳細設計書!AD1) -> 42559
D2: System： | G2: =IF(詳細設計書!G2="","N/A",詳細設計書!G2) -> SAP R/3(レポート) | O2: 仕様作成者： | S2: =IF(詳細設計書!S2="","N/A",詳細設計書!S2) -> KSC 橋本 | Z2: 最終変更者： | AD2: =IF(詳細設計書!AD2="","",詳細設計書!AD2) -> KSC 橋本
D3: DP ID： | G3: =IF(詳細設計書!G3="","N/A",詳細設計書!G3) -> DP_FI_2014_01 | O3: Program ID： | S3: =IF(詳細設計書!S3="","N/A",詳細設計書!S3) -> ZFIPR_2014_01 | Z3: RD ID | AC3: =詳細設計書!AC3 -> RD_FI_2014
A4: Title： | D4: 処理詳細（４） | Z4: Version： | AC4: =詳細設計書!AC4 -> 1.0
A6: 承認者： | S6: 承認日付：
A7: 事務局： | S7: 承認日付：
A9: ID | D9: 処理内容
E11: 4.5 | F11: エンドレコードの出力(レコード区分="9")
F12: データの終了情報を出力する。
F13: ＜詳細＞ | I13: ※TRANSFER 命令を使用
G14: TRANSFER 支払明細トレーラレコード TO 出力ファイル名．
G15: 編集内容はFile定義(1)参照
F16: ＜エラー＞
G17: TRANSFERできない時、下記のメッセージを表示し、処理を終了する。
G18: 「ファイルの【TRANSFER：/xxxxx/yyyyy/zzzzz/aaaaaaaaaaaaa】に失敗しました。管理者に連絡してください。」
G19: ※下線部は変数、パス名とファイル名をCONCATENATEする。 | X19: (ID:ZFI002,TYPE:E,NUMBER:030)
E21: 4.6 | F21: 電手決済債務明細データの送信用ファイルのCLOSE
F22: 3.3(1)で決定した出力ファイル名で出力ファイルをクローズする。
G23: CLOSE DATASET 出力ファイル名.
F24: ＜エラー＞
G25: CLOSEできない時、下記のメッセージを表示し、処理を終了する。
G26: 「ファイルの【CLOSE：/xxxxx/yyyyy/zzzzz/aaaaaaaaaaaaa】に失敗しました。管理者に連絡してください。」
G27: ※下線部は変数、パス名とファイル名をCONCATENATEする。 | X27: (ID:ZFI002,TYPE:E,NUMBER:030)
E29: 4.7 | F29: 処理結果メッセージを表示する
F30: 「【電手決済送信データ】：作成件数【ZZZ,ZZZ,ZZ9】件、内明細件数【ZZZ,ZZZ,ZZ9】件」
F31: ※下線部は変数 | L31: (ID:ZFI002,TYPE:S,NUMBER:041)
G32: 第一パラメータ：固定値、第二パラメータ：ヘッダー～エンドの件数、第三パラメータ：明細件数(内数)
E34: ※ | F34: ファイル書き出しエラー時：
G35: ファイルの書き出し時のエラーはディスクの障害等が考えられるため、処理を停止する（削除などは行わない）。
G36: 途中ファイルが存在しても管理テーブル（ZFIT021)に情報がないためダウンロードが出来ないので問題はない。
B38: 5 | E38: 電手決済_DMEファイルの送信用ファイル出力
B40: 6 | E40: 電手決済ファイル管理テーブルの更新
E41: 6.1 | F41: [電子記録債務ファイルの書き出しに成功した場合、各種情報を管理ﾃｰﾌﾞﾙ(ZFIT021)に書き出す。
F42: ＜詳細＞
G43: 編集内容は「Table更新」参照
B45: ７ | E45: プログラム終了メッセージの表示
F46: 「ZFIPR_2014_01:(電子記録債務)送信データファイル作成【終了】」
F47: ※下線部は変数 | L47: (ID:ZFI002,TYPE:S,NUMBER:073)

Sheet 選択画面レイアウト
D1: Project： | G1: =IF(詳細設計書!G1="","N/A",詳細設計書!G1) -> 統合会計システム開発 | O1: 仕様作成日： | S1: =IF(詳細設計書!S1="","N/A",詳細設計書!S1) -> 42509 | Z1: 最終変更日： | AD1: =IF(詳細設計書!AD1="","N/A",詳細設計書!AD1) -> 42559
D2: System： | G2: =IF(詳細設計書!G2="","N/A",詳細設計書!G2) -> SAP R/3(レポート) | O2: 仕様作成者： | S2: =IF(詳細設計書!S2="","N/A",詳細設計書!S2) -> KSC 橋本 | Z2: 最終変更者： | AD2: =IF(詳細設計書!AD2="","N/A",詳細設計書!AD2) -> KSC 橋本
D3: DP ID： | G3: =IF(詳細設計書!G3="","N/A",詳細設計書!G3) -> DP_FI_2014_01 | O3: Program ID： | S3: =IF(詳細設計書!S3="","N/A",詳細設計書!S3) -> ZFIPR_2014_01
A4: Title： | D4: 選択画面レイアウト | Z4: Version： | AC4: =詳細設計書!AC4 -> 1.0
A6: 画面名称： | E6: (電子記録債務)送信データの作成
A7: レイアウト
E11: ① | F11: 実行日 | O11: ▽
E13: ② | F13: 認識名 | O13: ▽
A31: SELECT-OPTIONS
A32: ID | C32: 選択テキスト | H32: 型 / | M32: デフォルト値 | Q32: デフォルト値 | U32: MC | W32: 入力 | Y32: エラー | AB32: その他
H33: テーブル-項目 | M33: From | Q33: To | U33: ID | W33: 必須 | Y33: チェック
A42: PARAMETERS
A43: ID | C43: 選択テキスト | H43: 型 / | M43: デフォルト値 | Q43: チェック / | U43: MC | W43: 入力 | Y43: エラー | AB43: その他
H44: テーブル項目 | Q44: ラジオボタン | U44: ID | W44: 必須 | Y44: チェック
A45: ① | C45: 実行日 | H45: ZFIT021-LAUFD | M45: － | Q45: － | U45: － | W45: ○ | AB45: 検索ヘルプ有り
A47: ② | C47: 認識名 | H47: ZFIT021-LAUFI | M47: － | Q47: － | U47: － | W47: ○ | AB47: 検索ヘルプ有り

Sheet Tableデータ抽出(1)
D1: Project： | G1: =IF(詳細設計書!G1="","N/A",詳細設計書!G1) -> 統合会計システム開発 | R1: 仕様作成日： | V1: =IF(詳細設計書!S1="","N/A",詳細設計書!S1) -> 42509 | AC1: 最終変更日： | AG1: =IF(詳細設計書!AD1="","N/A",詳細設計書!AD1) -> 42559
D2: System： | G2: =IF(詳細設計書!G2="","N/A",詳細設計書!G2) -> SAP R/3(レポート) | R2: 仕様作成者： | V2: =IF(詳細設計書!S2="","N/A",詳細設計書!S2) -> KSC 橋本 | AC2: 最終変更者： | AG2: =IF(詳細設計書!AD2="","N/A",詳細設計書!AD2) -> KSC 橋本
D3: DP ID： | G3: =IF(詳細設計書!G3="","N/A",詳細設計書!G3) -> DP_FI_2014_01 | R3: Program ID： | V3: =IF(詳細設計書!S3="","N/A",詳細設計書!S3) -> ZFIPR_2014_01
A4: Title： | D4: Table データ抽出 | AC4: Version： | AF4: =詳細設計書!AC4 -> 1.0
A6: 抽出ID： | D6: 1
A8: 抽出対象Table
A9: ＩＤ | C9: タイプ | G9: Table名 | L9: 名称 | T9: 推定データ件数 | Y9: 備考
A10: 1 | C10: R/3標準Table | G10: REGUH | L10: 支払プログラム決済データ | T10: 1000 | X10: 件
X11: 件
X12: 件
X13: 件
X14: 件
A15: 抽出の目的
B17: 支払対象の支払データを仕入先単位に取得する。
A23: Table間の結合条件
A33: Table毎の絞り込み条件
A34: ID | D34: Table | H34: 条件式(説明)
A35: 1 | D35: REGUH | I35: LAUFD：実行日 | Q35: ＝ | S35: 入力パラメータ：実行日
A36: 1 | D36: REGUH | I36: LAUFI：認識名 | Q36: ＝ | S36: 入力パラメータ：認識名
A37: 1 | D37: REGUH | I37: XVORL：フラグ提案実行のみ | Q37: ＝ | S37: スペース
A38: 1 | D38: REGUH | I38: RBETR：国内通貨額 | Q38: <> | S38: 0
A41: 抽出項目
A42: ID | C42: 項目ID | G42: 項目名 | L42: テーブル名 | T42: 備考
A43: 1 | C43: ZBUKR | G43: 支払会社コード | L43: REGUH
A44: 2 | C44: LIFNR | G44: 仕入先コード | L44: REGUH
A45: 3 | C45: WAERS | G45: 通貨コード | L45: REGUH
A46: 4 | C46: WEFAE | G46: 手形満期日 | L46: REGUH
A47: 5 | C47: RBETR | G47: 国内通貨額 | L47: REGUH
A48: 6 | C48: WDATE | G48: 手形振出日 | L48: REGUH

Sheet Tableデータ抽出(2)
D1: Project： | G1: =IF(詳細設計書!G1="","N/A",詳細設計書!G1) -> 統合会計システム開発 | R1: 仕様作成日： | V1: =IF(詳細設計書!S1="","N/A",詳細設計書!S1) -> 42509 | AC1: 最終変更日： | AG1: =IF(詳細設計書!AD1="","N/A",詳細設計書!AD1) -> 42559
D2: System： | G2: =IF(詳細設計書!G2="","N/A",詳細設計書!G2) -> SAP R/3(レポート) | R2: 仕様作成者： | V2: =IF(詳細設計書!S2="","N/A",詳細設計書!S2) -> KSC 橋本 | AC2: 最終変更者： | AG2: =IF(詳細設計書!AD2="","N/A",詳細設計書!AD2) -> KSC 橋本
D3: DP ID： | G3: =IF(詳細設計書!G3="","N/A",詳細設計書!G3) -> DP_FI_2014_01 | R3: Program ID： | V3: =IF(詳細設計書!S3="","N/A",詳細設計書!S3) -> ZFIPR_2014_01
A4: Title： | D4: Table データ抽出 | AC4: Version： | AF4: =詳細設計書!AC4 -> 1.0
A6: 抽出ID： | D6: 2
A8: 抽出対象Table
A9: ＩＤ | C9: タイプ | G9: Table名 | L9: 名称 | T9: 推定データ件数 | Y9: 備考
A10: 1 | C10: Add-on Table | G10: ZFIT020 | L10: 電手決済マスタテーブル | T10: 1 | X10: 件
X11: 件
X12: 件
X13: 件
X14: 件
A15: 抽出の目的
B17: 電手決済債務明細データの送信用ファイルの編集に必要な項目を取得。
A23: Table間の結合条件
B25: なし
A33: Table毎の絞り込み条件
A34: ID | D34: Table | H34: 条件式(説明)
A35: 1 | D35: ZFIT020 | I35: ZBUKR：支払会社コード | Q35: ＝ | S35: 支払会社コード(REGUH-ZBUKR)
A41: 抽出項目
A42: ID | C42: 項目ID | G42: 項目名 | L42: テーブル名 | T42: 備考
A43: 1 | C43: ZBUKR | G43: 支払会社コード | L43: ZFIT020
A44: 2 | C44: JIGYONO | G44: 支店番号 | L44: ZFIT020
A45: 3 | C45: HRITRICD | G45: 口座番号 | L45: ZFIT020
A46: 4 | C46: KASYNM | G46: 会社名 | L46: ZFIT020
A47: 5 | C47: HRINM | G47: 支払先名称 | L47: ZFIT020
A48: 6 | C48: BANBRCD | G48: 銀行/支店コード | L48: ZFIT020
A49: 7 | C49: BANKNM | G49: 銀行名 | L49: ZFIT020
A50: 8 | C50: BRANCHNM | G50: 支店名 | L50: ZFIT020
A51: 9 | C51: ACCNTTYPE | G51: 口座種別 | L51: ZFIT020
A52: 10 | C52: ACCNTNO | G52: 口座番号 | L52: ZFIT020
A53: 11 | C53: COMPCD | G53: FB会社コード | L53: ZFIT020
A54: 12 | C54: COMPNM | G54: FB会社名 | L54: ZFIT020
... A60: 18 | C60: MTACCNTNO | G60: 振込元口座No | L60: ZFIT020

Sheet Tableデータ抽出(3)
D1: Project： | G1: =IF(詳細設計書!G1="","N/A",詳細設計書!G1) -> 統合会計システム開発 | R1: 仕様作成日： | V1: =IF(詳細設計書!S1="","N/A",詳細設計書!S1) -> 42509 | AC1: 最終変更日： | AG1: =IF(詳細設計書!AD1="","N/A",詳細設計書!AD1) -> 42559
D2: System： | G2: =IF(詳細設計書!G2="","N/A",詳細設計書!G2) -> SAP R/3(レポート) | R2: 仕様作成者： | V2: =IF(詳細設計書!S2="","N/A",詳細設計書!S2) -> KSC 橋本 | AC2: 最終変更者： | AG2: =IF(詳細設計書!AD2="","N/A",詳細設計書!AD2) -> KSC 橋本
D3: DP ID： | G3: =IF(詳細設計書!G3="","N/A",詳細設計書!G3) -> DP_FI_2014_01 | R3: Program ID： | V3: =IF(詳細設計書!S3="","N/A",詳細設計書!S3) -> ZFIPR_2014_01
A4: Title： | D4: Table データ抽出 | AC4: Version： | AF4: =詳細設計書!AC4 -> 1.0
A6: 抽出ID： | D6: 3
A8: 抽出対象Table
A9: ＩＤ | C9: タイプ | G9: Table名 | L9: 名称 | T9: 推定データ件数 | Y9: 備考
A10: 1 | C10: Add-on Table | G10: ZFIT001 | L10: 固定値マスタテーブル | T10: 1 | X10: 件
X11: 件
X12: 件
X13: 件
X14: 件
A15: 抽出の目的
B17: 電手決済債務明細データの送信用ファイルの書き出し場所(フルパス名)を決定する為に使用。
B18: 連番(SEQNO)=01(債務明細データ) の1件存在する。
A23: Table間の結合条件
B25: なし
A33: Table毎の絞り込み条件
A34: ID | D34: Table | H34: 条件式(説明)
A35: 1 | D35: ZFIT001 | I35: DATAID：データ種別 | Q35: ＝ | S35: "021"
A36: 1 | D36: ZFIT001 | I36: CATEG：分類 | Q36: ＝ | S36: 支払会社コード(REGUH-ZBUKR)
A41: 抽出項目
A42: ID | C42: 項目ID | G42: 項目名 | L42: テーブル名 | T42: 備考
A43: 1 | C43: SEQNO | G43: 連番 | L43: ZFIT001
A44: 2 | C44: VALUE1 | G44: 内容１ | L44: ZFIT001
A45: 3 | C45: VALUE2 | G45: 内容２ | L45: ZFIT001

Sheet Tableデータ抽出(4)
D1: Project： | G1: =IF(詳細設計書!G1="","N/A",詳細設計書!G1) -> 統合会計システム開発 | R1: 仕様作成日： | V1: =IF(詳細設計書!S1="","N/A",詳細設計書!S1) -> 42509 | AC1: 最終変更日： | AG1: =IF(詳細設計書!AD1="","N/A",詳細設計書!AD1) -> 42559
D2: System： | G2: =IF(詳細設計書!G2="","N/A",詳細設計書!G2) -> SAP R/3(レポート) | R2: 仕様作成者： | V2: =IF(詳細設計書!S2="","N/A",詳細設計書!S2) -> KSC 橋本 | AC2: 最終変更者： | AG2: =IF(詳細設計書!AD2="","N/A",詳細設計書!AD2) -> KSC 橋本
D3: DP ID： | G3: =IF(詳細設計書!G3="","N/A",詳細設計書!G3) -> DP_FI_2014_01 | R3: Program ID： | V3: =IF(詳細設計書!S3="","N/A",詳細設計書!S3) -> ZFIPR_2014_01
A4: Title： | D4: Table データ抽出 | AC4: Version： | AF4: =詳細設計書!AC4 -> 1.0
A6: 抽出ID： | D6: 4
A8: 抽出対象Table
A9: ＩＤ | C9: タイプ | G9: Table名 | L9: 名称 | T9: 推定データ件数 | Y9: 備考
A10: 1 | C10: R/3標準Table | G10: LFBK | L10: 仕入先マスター(銀行) | T10: ｎ | X10: 件 | Y10: 1仕入先について複数存在する可能性あり
X11: 件 | Y11: ※1件目を取得
X12: 件
X13: 件
X14: 件
A15: 抽出の目的
B17: 仕入先に関して振込先銀行情報(1件目)の口座名義人名(半角カタカナ)を取得する。
B18: ＜エラー＞
C19: データが取得できない時、下記のメッセージを表示し、処理を終了する。
C20: 「仕入先コード：【XXXXXXXXXX】の口座名義人名が登録されていません。」
C21: ※下線部は変数、パス名とファイル名をCONCATENATEする。 | T21: (ID:ZFI002,TYPE:E,NUMBER:042)
A23: Table間の結合条件
B25: なし
A33: Table毎の絞り込み条件
A34: ID | D34: Table | H34: 条件式(説明)
A35: 1 | D35: LFBK | I35: LIFNR：仕入先コード | Q35: ＝ | S35: REGUH-LIFNR：仕入先コード
A41: 抽出項目
A42: ID | C42: 項目ID | G42: 項目名 | L42: テーブル名 | T42: 備考
A43: 1 | C43: KOINH | G43: 口座名義人名 | L43: LFBK

Sheet File定義(電手決済債務明細データ)(1-1)
D1: Project： | G1: =IF(詳細設計書!G1="","N/A",詳細設計書!G1) -> 統合会計システム開発 | O1: 仕様作成日： | S1: =IF(詳細設計書!S1="","N/A",詳細設計書!S1) -> 42509 | Z1: 最終変更日： | AD1: =IF(詳細設計書!AD1="","N/A",詳細設計書!AD1) -> 42559
D2: System： | G2: =IF(詳細設計書!G2="","N/A",詳細設計書!G2) -> SAP R/3(レポート) | O2: 仕様作成者： | S2: =IF(詳細設計書!S2="","N/A",詳細設計書!S2) -> KSC 橋本 | Z2: 最終変更者： | AD2: =IF(詳細設計書!AD2="","N/A",詳細設計書!AD2) -> KSC 橋本
D3: DP ID： | G3: =IF(詳細設計書!G3="","N/A",詳細設計書!G3) -> DP_FI_2014_01 | O3: Program ID： | S3: =IF(詳細設計書!S3="","N/A",詳細設計書!S3) -> ZFIPR_2014_01
A4: Title： | D4: File 定義(電手決済債務明細データ) | Z4: Version： | AC4: =詳細設計書!AC4 -> 1.0
A7: ファイルＩＤ： | E7: 2 | K7: ファイル名： | O7: （「実行日」＋「認識名」で自動生成)
A8: 名称： | E8: 電手決済債務明細データ（ＳＥ用：支払会社･･･「0191」）
A9: 属性：
B10: レコード長 | F10: 120 | I10: bytes | K10: 形式 | O10: 入出力場所 | T10: 区切り文字 | X10: モード | AB10: 文字コード | AH10: 変更2016/7/12（●BIN）
B11: レコード数 | F11: 100 | I11: Rec
B12: ゼロ件処理
T14: （ | W14: ) | AB14: （ | AF14: ）
A15: ファイル構成：
B16: NO | D16: 項目名称 | K16: 位置 | M16: SIZE | O16: Type | Q16: 内容説明（数値の場合は、書式を記述）
D17: <HeaderRecord>
B18: 1 | D18: CATEGORY | K18: 1 | M18: 1 | O18: CHAR | Q18: 「1」(ヘッダレコード)固定
B19: 2 | D19: ITEM_CD | K19: 2 | M19: 2 | O19: CHAR | Q19: 「35」(西暦利用)固定
B20: 3 | D20: CODE_TYPE | K20: 4 | M20: 1 | O20: CHAR | Q20: 「0」(JIS/ASCII)固定
B21: 4 | D21: JIGYONO | K21: 5 | M21: 3 | O21: CHAR | Q21: 支払企業CD_支店番号(ZFIT020-JIGYONO)
B22: 5 | D22: HRITRICD | K22: 8 | M22: 7 | O22: CHAR | Q22: 支払企業CD_口座番号(ZFIT020-HRITRICD)
B23: 6 | D23: COMPANY_NAME | K23: 15 | M23: 40 | O23: CHAR | Q23: 支払企業名_会社名(ZFIT020-KASYNM) ※1
B24: 7 | D24: WDATE | K24: 55 | M24: 4 | O24: CHAR | Q24: ブランク
B25: 8 | D25: BANK_CD | K25: 59 | M25: 4 | O25: CHAR | Q25: ブランク → "0005"（固定） | AH25: 変更2016/7/8
B26: 9 | D26: BANK_NAME | K26: 63 | M26: 15 | O26: CHAR | Q26: ブランク
B27: 10 | D27: BRANCH_CD | K27: 78 | M27: 3 | O27: CHAR | Q27: ブランク → "005"（固定） | AH27: 変更2016/7/8
B28: 11 | D28: BRNCH_NAME | K28: 81 | M28: 15 | O28: CHAR | Q28: ブランク
B29: 12 | D29: ACCNT_TYPE | K29: 96 | M29: 1 | O29: CHAR | Q29: ブランク → "2"（固定） | AH29: 変更2016/7/8
B30: 13 | D30: ACCNT_NO | K30: 97 | M30: 7 | O30: CHAR | Q30: ブランク → "0857671"（固定） | AH30: 変更2016/7/8
B31: 14 | D31: PAYMENT_DT | K31: 104 | M31: 6 | O31: CHAR | Q31: 手形振出日(REGUH-WDATE)※２
B32: 15 | D32: VALUE_DT | K32: 110 | M32: 6 | O32: CHAR | Q32: 手形満期日(REGUH-WEFAE)※２
B33: 16 | D33: FILLER | K33: 116 | M33: 5 | O33: CHAR | Q33: ブランク
Q35: ※１…カナ小文字をカナ大文字に変換する【別紙１参照】
Q36: ※２…西暦６桁（20050420→050420）
A48: 備考：
B49: 作成タイミング：
B50: 削除タイミング：
B51: その他：

Sheet File定義(電手決済債務明細データ)(1-2)
D1: Project： | G1: =IF(詳細設計書!G1="","N/A",詳細設計書!G1) -> 統合会計システム開発 | O1: 仕様作成日： | S1: =IF(詳細設計書!S1="","N/A",詳細設計書!S1) -> 42509 | Z1: 最終変更日： | AD1: =IF(詳細設計書!AD1="","N/A",詳細設計書!AD1) -> 42559
D2: System： | G2: =IF(詳細設計書!G2="","N/A",詳細設計書!G2) -> SAP R/3(レポート) | O2: 仕様作成者： | S2: =IF(詳細設計書!S2="","N/A",詳細設計書!S2) -> KSC 橋本 | Z2: 最終変更者： | AD2: =IF(詳細設計書!AD2="","N/A",詳細設計書!AD2) -> KSC 橋本
D3: DP ID： | G3: =IF(詳細設計書!G3="","N/A",詳細設計書!G3) -> DP_FI_2014_01 | O3: Program ID： | S3: =IF(詳細設計書!S3="","N/A",詳細設計書!S3) -> ZFIPR_2014_01
A4: Title： | D4: File 定義(電手決済債務明細データ) | Z4: Version： | AC4: =詳細設計書!AC4 -> 1.0
A7: ファイルＩＤ： | E7: 2 | K7: ファイル名： | O7: （「実行日」＋「認識名」で自動生成)
A8: 名称： | E8: 電手決済債務明細データ（ＳＥ用：支払会社･･･「0191」）
A9: 属性：
B10: レコード長 | F10: 120 | I10: bytes | K10: 形式 | O10: 入出力場所 | T10: 区切り文字 | X10: モード | AB10: 文字コード | AH10: 変更2016/7/12（●BIN）
B11: レコード数 | F11: 100 | I11: Rec
B12: ゼロ件処理
T14: （ | W14: ) | AB14: （ | AF14: ）
A15: ファイル構成：
B16: NO | D16: 項目名称 | K16: 位置 | M16: SIZE | O16: Type | Q16: 内容説明（数値の場合は、書式を記述）
D17: <DataRecord>
B18: 1 | D18: CATEGORY | K18: 1 | M18: 1 | O18: CHAR | Q18: 「2」(データレコード)固定
B19: =B18+1 -> 2 | D19: BANK_CD | K19: 2 | M19: 4 | O19: CHAR | Q19: ブランク
B20: =B19+1 -> 3 | D20: LIFNR2 | K20: 6 | M20: 15 | O20: CHAR | Q20: ブランク
B21: =B20+1 -> 4 | D21: BRANCH_CD | K21: 21 | M21: 3 | O21: CHAR | Q21: ブランク
B22: =B21+1 -> 5 | D22: BRNCH_NAME | K22: 24 | M22: 15 | O22: CHAR | Q22: ブランク
B23: =B22+1 -> 6 | D23: FILLER | K23: 39 | M23: 4 | O23: CHAR | Q23: ブランク
B24: =B23+1 -> 7 | D24: ACCNT_TYPE | K24: 43 | M24: 1 | O24: CHAR | Q24: ブランク
B25: =B24+1 -> 8 | D25: ACCNT_NO | K25: 44 | M25: 7 | O25: CHAR | Q25: ブランク
B26: =B25+1 -> 9 | D26: KOINH | K26: 51 | M26: 30 | O26: CHAR | Q26: 仕入先（銀行）の口座名義人名（LFBK-KOINH）
B27: =B26+1 -> 10 | D27: RBETR | K27: 81 | M27: 10 | O27: CHAR | Q27: 国内通貨額(REGUH-RBETR)の集計金額 (※前0埋め) ※３
B28: =B27+1 -> 11 | D28: FILLER | K28: 91 | M28: 1 | O28: CHAR | Q28: ブランク
B29: =B28+1 -> 12 | D29: LIFNR1 | K29: 92 | M29: 10 | O29: CHAR | Q29: ブランク
B30: =B29+1 -> 13 | D30: LIFNR3 | K30: 102 | M30: 10 | O30: CHAR | Q30: 仕入先コード（REGUH-LIFNR）(※前0埋め) ※前0削除、左詰 | AH30: 変更2016/7/8
B31: =B30+1 -> 14 | D31: PAYDS_CD | K31: 112 | M31: 6 | O31: CHAR | Q31: ブランク
B32: =B31+1 -> 15 | D32: FILLER3 | K32: 118 | M32: 3 | O32: CHAR | Q32: ブランク
D34: <TrailerRecord>
B35: 1 | D35: CATEGORY | K35: 1 | M35: 1 | O35: CHAR | Q35: 「8」(トレーラレコード)固定
B36: =B35+1 -> 2 | D36: KENSU | K36: 2 | M36: 6 | O36: CHAR | Q36: 明細レコードの件数 | X36: ※前0埋め、右詰
B37: =B36+1 -> 3 | D37: KINGAK | K37: 8 | M37: 12 | O37: CHAR | Q37: 合計金額 | X37: ※前0埋め、右詰 | AD37: ※３
B38: 4 | D38: FILLER | K38: 20 | M38: 101 | O38: CHAR | Q38: ブランク
D40: <EndRecord>
B41: 1 | D41: CATEGORY | K41: 1 | M41: 1 | O41: NUMC | Q41: 「9」(エンドレコード)固定
B42: 2 | D42: FILLER | K42: 2 | M42: 119 | O42: CHAR | Q42: ブランク
Q44: ※３…×(-1)して編集する(前0編集)。
A47: 備考：
B48: 作成タイミング：
...

Sheet Table更新
D1: Project： | G1: =IF(詳細設計書!G1="","N/A",詳細設計書!G1) -> 統合会計システム開発 | O1: 仕様作成日： | S1: =IF(詳細設計書!S1="","N/A",詳細設計書!S1) -> 42509 | Z1: 最終変更日： | AD1: =IF(詳細設計書!AD1="","N/A",詳細設計書!AD1) -> 42559
D2: System： | G2: =IF(詳細設計書!G2="","N/A",詳細設計書!G2) -> SAP R/3(レポート) | O2: 仕様作成者： | S2: =IF(詳細設計書!S2="","N/A",詳細設計書!S2) -> KSC 橋本 | Z2: 最終変更者： | AD2: =IF(詳細設計書!AD2="","N/A",詳細設計書!AD2) -> KSC 橋本
D3: DP ID： | G3: =IF(詳細設計書!G3="","N/A",詳細設計書!G3) -> DP_FI_2014_01 | O3: Program ID： | S3: =IF(詳細設計書!S3="","N/A",詳細設計書!S3) -> ZFIPR_2014_01
A4: Title： | D4: Table更新 | Z4: Version： | AC4: =IF(詳細設計書!AC4="","N/A",詳細設計書!AC4) -> 1.0
A6: 独立したTable毎に1シート記入する
A7: Table ID： | D7: ZFIT021 | I7: Table名： | L7: 電手決済ファイル管理テーブル | S7: Table説明： | W7: 支払処理(電子記録債務)の実行結果を保持
A8: 更新内容説明：
B10: 電手決済債務明細データの送信用ファイルの出力後、出力情報を更新する。
B11: 同一キーが存在するとき更新、存在しないとき挿入を行う。
A15: 項目名 | G15: Key | I15: 項目編集／説明
A16: MANDT | G16: ○ | I16: クライアント
A17: LAUFD | G17: ○ | I17: 入力パラメータ：実行日
A18: LAUFI | G18: ○ | I18: 入力パラメータ：認識名
A19: DME | I19: ブランク (DMEファイル用)
A20: FACT | I20: 3．3(1)出力ファイル名 (債務明細データ用)
A21: DMERECS | I21: 「0」固定 (DMEファイル用)
A22: FACTRECS | I22: 債務明細送信データの総件数(ヘッダーレコード～エンドレコード)
A23: MODDATE | I23: システム日付
A24: MODTIME | I24: システム時刻

Sheet エラーチェック
D1: Project： | G1: =IF(詳細設計書!G1="","N/A",詳細設計書!G1) -> 統合会計システム開発 | O1: 仕様作成日： | S1: =IF(詳細設計書!S1="","N/A",詳細設計書!S1) -> 42509 | Z1: 最終変更日： | AE1: =IF(詳細設計書!AD1="","N/A",詳細設計書!AD1) -> 42559
D2: System： | G2: =IF(詳細設計書!G2="","N/A",詳細設計書!G2) -> SAP R/3(レポート) | O2: 仕様作成者： | S2: =IF(詳細設計書!S2="","N/A",詳細設計書!S2) -> KSC 橋本 | Z2: 最終変更者： | AE2: =IF(詳細設計書!AD2="","N/A",詳細設計書!AD2) -> KSC 橋本
D3: DP ID： | G3: =IF(詳細設計書!G3="","N/A",詳細設計書!G3) -> DP_FI_2014_01 | O3: Program ID： | S3: =IF(詳細設計書!S3="","N/A",詳細設計書!S3) -> ZFIPR_2014_01
A4: Title： | D4: エラーチェック | Z4: Version： | AD4: =IF(詳細設計書!AC4="","N/A",詳細設計書!AC4) -> 1.0
A7: ID | C7: エラー要件 | AA7: Message
AA8: ID | AD8: タイプ | AF8: 番号
A10: 1 | D10: ファイルの操作において異常が発生した場合 | AA10: ZFI002 | AD10: E | AF10: 030
A12: 2 | D12: アドオンテーブルからデータが取得できなかったとき | AA12: ZFI002 | AD12: E | AF12: 028
A14: 3 | D14: 仕入先マスタ(銀行)から口座名義人が取得できないとき | AA14: ZFI002 | AD14: E | AF14: 042
A16: 4 | D16: アドオンテーブルの更新ができなかったとき | AA16: ZFI002 | AD16: E | AF16: 009

Sheet テスト概要 
D1: Project： | G1: =IF(詳細設計書!G1="","N/A",詳細設計書!G1) -> 統合会計システム開発 | O1: 仕様作成日： | S1: =IF(詳細設計書!S1="","N/A",詳細設計書!S1) -> 42509 | Z1: 最終変更日： | AD1: =IF(詳細設計書!AD1="","",詳細設計書!AD1) -> 42559
D2: System： | G2: =IF(詳細設計書!G2="","N/A",詳細設計書!G2) -> SAP R/3(レポート) | O2: 仕様作成者： | S2: =IF(詳細設計書!S2="","N/A",詳細設計書!S2) -> KSC 橋本 | Z2: 最終変更者： | AD2: =IF(詳細設計書!AD2="","",詳細設計書!AD2) -> KSC 橋本
D3: DP ID： | G3: =IF(詳細設計書!G3="","N/A",詳細設計書!G3) -> DP_FI_2014_01 | O3: Program ID： | S3: =IF(詳細設計書!S3="","N/A",詳細設計書!S3) -> ZFIPR_2014_01
A4: Title： | D4: テスト概要 | Z4: Version： | AC4: =詳細設計書!AC4 -> 1.0
A6: プロセス | I6: テスト目的 | AC6: 参照資料
A7: 1 | B7: input parameter のチェック | I7: 1.1 | K7: パラメータの属性が設計書と合致していることを確認する
K8: （Type/Length/チェックボックス/ラジオボタン等）
I10: 1.2 | K10: 入力可能値やマッチコード検索が利用できることを確認する
I12: 1.3 | K12: 入力必須項目が正しく作動していることを確認する
I14: 1.4 | K14: テキストエレメントが設計書通りに記述されていることを確認する
I16: 1.5 | K16: 入力可能値以外の時はメッセージを表示する事を確認する。 | AC16: 別紙｢入力チェック｣
A20: 2 | B20: 抽出処理チェック | I20: 2.1 | K20: 処理対象データ数が0件のとき、その旨のメッセージが正しく表示され | AC20: 別紙｢処理詳細（１）｣
K21: 処理が中断されることを確認する＜０件処理＞
I23: 2.2 | K23: テーブルの読み込みエラーのとき、その旨のメッセージが正しく表示 | AC23: 別紙｢処理詳細（１）｣
K24: され処理が中断されることを確認する＜異常処理＞
A26: 3 | B26: 出力ファイル内容チェック | I26: 3.1 | K26: INPUTの件数とOUTPUTの件数の関係が一致している。
A28: 4 | B28: 入力データｴﾗｰ処理 | I28: 4.1 | K28: 入力データが設計書に記述された数値、日付などの属性と異なるとき | AC28: 別紙｢入力チェック｣
K29: その旨のメッセージが表示/印字され、処理が中断する
I32: 4.2 | K32: テーブルに存在しない値がパラメータとして入力された場合、 | AC32: 別紙｢入力チェック｣
K33: その旨のメッセージが表示/印字され、処理が中断する
K34: EX.） 仕入先に ”あああああ” など有り得ないデータが入力された場合
I36: 4.3 | K36: 必須項目を未入力のまま実行した場合、
K37: その旨のメッセージが表示/印字され、処理が中断する

Sheet テストデータ
D1: Project： | G1: =IF(詳細設計書!G1="","N/A",詳細設計書!G1) -> 統合会計システム開発 | O1: 仕様作成日： | S1: =IF(詳細設計書!S1="","N/A",詳細設計書!S1) -> 42509 | Z1: 最終変更日： | AD1: =IF(詳細設計書!AD1="","",詳細設計書!AD1) -> 42559
D2: System： | G2: =IF(詳細設計書!G2="","N/A",詳細設計書!G2) -> SAP R/3(レポート) | O2: 仕様作成者： | S2: =IF(詳細設計書!S2="","N/A",詳細設計書!S2) -> KSC 橋本 | Z2: 最終変更者： | AD2: =IF(詳細設計書!AD2="","",詳細設計書!AD2) -> KSC 橋本
D3: DP ID： | G3: =IF(詳細設計書!G3="","N/A",詳細設計書!G3) -> DP_FI_2014_01 | O3: Program ID： | S3: =IF(詳細設計書!S3="","N/A",詳細設計書!S3) -> ZFIPR_2014_01
A4: Title： | D4: テストデータ | Z4: Version： | AC4: =詳細設計書!AC4 -> 1.0
A6: ID | C6: バリアント名 / Parameter値 | M6: テストデータ目的 | AB6: データ作成者

Sheet テスト詳細
D1: Project： | G1: =IF(詳細設計書!G1="","N/A",詳細設計書!G1) -> 統合会計システム開発 | O1: 仕様作成日： | S1: =IF(詳細設計書!S1="","N/A",詳細設計書!S1) -> 42509 | Z1: 最終変更日： | AD1: =IF(詳細設計書!AD1="","",詳細設計書!AD1) -> 42559
D2: System： | G2: =IF(詳細設計書!G2="","N/A",詳細設計書!G2) -> SAP R/3(レポート) | O2: 仕様作成者： | S2: =IF(詳細設計書!S2="","N/A",詳細設計書!S2) -> KSC 橋本 | Z2: 最終変更者： | AD2: =IF(詳細設計書!AD2="","",詳細設計書!AD2) -> KSC 橋本
D3: DP ID： | G3: =IF(詳細設計書!G3="","N/A",詳細設計書!G3) -> DP_FI_2014_01 | O3: Program ID： | S3: =IF(詳細設計書!S3="","N/A",詳細設計書!S3) -> ZFIPR_2014_01
A4: Title： | D4: テスト詳細 （１） | Z4: Version： | AC4: =詳細設計書!AC4 -> 1.0
A6: No. | C6: テスト内容/目的 | S6: データID | V6: 期待結果

Sheet 別紙1
D1: Project： | G1: =IF(詳細設計書!G1="","N/A",詳細設計書!G1) -> 統合会計システム開発 | O1: 仕様作成日： | S1: =IF(詳細設計書!S1="","N/A",詳細設計書!S1) -> 42509 | Z1: 最終変更日： | AD1: =IF(詳細設計書!AD1="","N/A",詳細設計書!AD1) -> 42559
D2: System： | G2: =IF(詳細設計書!G2="","N/A",詳細設計書!G2) -> SAP R/3(レポート) | O2: 仕様作成者： | S2: =IF(詳細設計書!S2="","N/A",詳細設計書!S2) -> KSC 橋本 | Z2: 最終変更者： | AD2: =IF(詳細設計書!AD2="","N/A",詳細設計書!AD2) -> KSC 橋本
D3: DP ID： | G3: =IF(詳細設計書!G3="","N/A",詳細設計書!G3) -> DP_FI_2014_01 | O3: Program ID： | S3: =IF(詳細設計書!S3="","N/A",詳細設計書!S3) -> ZFIPR_2014_01 | Z3: RD ID | AC3: =IF(詳細設計書!AC3="","N/A",詳細設計書!AC3) -> RD_FI_2014
A4: Title： | D4: 別紙１ カナ小文字をカナ大文字に変換する(KATAKANA) | Z4: Version： | AC4: =詳細設計書!AC4 -> 1.0
A6: 詳細
B8: １． | D8: カナ小文字をカナ大文字に変換
D9: 指定されたカナ名称等(会社名)のカナ小文字をカナ大文字に変換する。
C10: １．１ | F10: 下記パラメータで汎用モジュール'KATAKANA' を呼び出す。
F11: CALL FUNCTION 'KATAKANA'
G12: EXPORTING
H13: I_TEXT | Q13: = | S13: 変換元文字列
H14: I_INPUT_SB | Q14: = | S14: ”X"
G15: IMPORTING
H16: E_TEXT | Q16: = | S16: 変換結果文字列
G17: EXCEPTIONS
H18: NOT_KATAKANA | Q18: = | S18: 1
H19: NO_VALID_TYPE | Q19: = | S19: 2
H20: ALL_SPACE | Q20: = | S20: 3
H21: OTHERS | Q21: = | S21: 4

Sheet 別紙2
D1: Project： | G1: =IF(詳細設計書!G1="","N/A",詳細設計書!G1) -> 統合会計システム開発 | O1: 仕様作成日： | S1: =IF(詳細設計書!S1="","N/A",詳細設計書!S1) -> 42509 | Z1: 最終変更日： | AD1: =IF(詳細設計書!AD1="","N/A",詳細設計書!AD1) -> 42559
D2: System： | G2: =IF(詳細設計書!G2="","N/A",詳細設計書!G2) -> SAP R/3(レポート) | O2: 仕様作成者： | S2: =IF(詳細設計書!S2="","N/A",詳細設計書!S2) -> KSC 橋本 | Z2: 最終変更者： | AD2: =IF(詳細設計書!AD2="","N/A",詳細設計書!AD2) -> KSC 橋本
D3: DP ID： | G3: =IF(詳細設計書!G3="","N/A",詳細設計書!G3) -> DP_FI_2014_01 | O3: Program ID： | S3: =IF(詳細設計書!S3="","N/A",詳細設計書!S3) -> ZFIPR_2014_01 | Z3: RD ID | AC3: =IF(詳細設計書!AC3="","N/A",詳細設計書!AC3) -> RD_FI_2014
A4: Title： | D4: 別紙２ 西暦を和暦に変換する(RP_CONVERT_JAPAN_DATE_OUT) | Z4: Version： | AC4: =詳細設計書!AC4 -> 1.0
A6: 詳細
B8: １． | D8: 西暦を和暦に変換
C10: １．１ | F10: 下記パラメータで汎用モジュール'RP_CONVERT_JAPAN_DATE_OUT' を呼び出す。
F11: CALL FUNCTION 'RP_CONVERT_JAPAN_DATE_OUT'
G12: EXPORTING
H13: SEIREKI | Q13: = | S13: 変換元年月日
G14: IMPORTING
H15: NEN | Q15: = | S15: 変換後年
H16: TSUKI | Q16: = | S16: 変換後月
H17: HI | Q17: = | S17: 変換後日

Sheet 変更履歴
D1: Project： | G1: =IF(詳細設計書!G1="","N/A",詳細設計書!G1) -> 統合会計システム開発 | O1: 仕様作成日： | S1: =IF(詳細設計書!S1="","N/A",詳細設計書!S1) -> 42509 | Z1: 最終変更日： | AD1: =IF(詳細設計書!AD1="","",詳細設計書!AD1) -> 42559
D2: System： | G2: =IF(詳細設計書!G2="","N/A",詳細設計書!G2) -> SAP R/3(レポート) | O2: 仕様作成者： | S2: =IF(詳細設計書!S2="","N/A",詳細設計書!S2) -> KSC 橋本 | Z2: 最終変更者： | AD2: =IF(詳細設計書!AD2="","",詳細設計書!AD2) -> KSC 橋本
D3: DP ID： | G3: =IF(詳細設計書!G3="","N/A",詳細設計書!G3) -> DP_FI_2014_01 | O3: Program ID： | S3: =IF(詳細設計書!S3="","N/A",詳細設計書!S3) -> ZFIPR_2014_01
A4: Title： | D4: 変更履歴 | Z4: Version： | AC4: =詳細設計書!AC4 -> 1.0
A6: 変更日付 | E6: 変更者 | I6: 変更文書 | O6: Version | R6: Workload | U6: 変更内容 | AD6: 承認者
A7: 42509 | E7: KSC 橋本 | I7: 初版 | O7: 1.0 | U7: 新規作成 (COPY: ZFIPR_2001_01)
A8: 42559 | E8: KSC 橋本 | I8: File定義(電手決済債務明細データ)(1-1)、File定義(電手決済債務明細データ)(1-2) | O8: 1.1 | U8: 銀行仕様の改修
A9: 42563 | E9: KSC 橋本 | I9: 処理詳細(3)、File定義(電手決済債務明細データ)(1-1)、File定義(電手決済債務明細データ)(1-2) | O9: 1.2 | U9: サーバーファイル出力時、改行コードなしとする
