Workbook

Sheet 表紙
B4: サンスター株式会社 | Q4: 御中
I10: 会計システム刷新プロジェクト
I14: 移行要件確認書
I22: =CONCATENATE("第",MAX(変更履歴!BC6:BG20),"版") -> 第1版
I24: =変更履歴!AX3 -> 45435
I26: 日本ビジネスシステムズ株式会社

Sheet 変更履歴
A1: システム名 | F1: =表紙!I10 -> 会計システム刷新プロジェクト | V1: タイトル | AX1: 日付 | BC1: 担当
A2: 文書名 | F2: =表紙!I14 -> 移行要件確認書 | V2: =MID(CELL("filename",$A$1),FIND("]",CELL("filename",$A$1))+1,31) -> #VALUE! | AU2: 作成 | AX2: =変更履歴!A6 -> 45348 | BC2: JBS入井
AU3: 更新 | AX3: =変更履歴!A7 -> 45435 | BC3: JBS入井
A5: 更新年月日 | G5: 変更箇所 | R5: 変更理由 | AX5: 更新者 | BC5: 版数
A6: 45348 | G6: 全シート | R6: 新規作成 | AX6: JBS入井 | BC6: 0.1
A7: 45435 | G7: 全シート | R7: (初版確定) | AX7: JBS入井 | BC7: 1

Sheet 目次
A1: システム名 | F1: =表紙!I10 -> 会計システム刷新プロジェクト | V1: タイトル | AM1: 日付 | AR1: 担当
A2: 文書名 | F2: =表紙!I14 -> 移行要件確認書 | V2: =MID(CELL("filename",$A$1),FIND("]",CELL("filename",$A$1))+1,31) -> #VALUE! | AJ2: 作成 | AM2: =変更履歴!A6 -> 45348 | AR2: JBS入井
AJ3: 更新
A5: 項番 | G5: シート | R5: 内容
A6: 1 | G6: 表紙 | R6: 表紙。
A7: 2 | G7: 変更履歴 | R7: 本資料の変更の履歴
A8: 3 | G8: 目次 | R8: 本資料の目次。資料の目的。資料中で使用する用語の説明
A9: 4 | G9: 移行全体方針 | R9: 要件定義フェーズで合意した内容を記述
A10: 5 | G10: 移行方針 | R10: 要件定義フェーズで合意した内容を記述
A11: 6 | G11: 移行スケジュール | R11: 要件定義フェーズで合意した内容を記述
A12: 7 | G12: 移行環境 | R12: データ移行に関する移行環境を記載。
A13: 8 | G13: 移行スコープ | R13: データ移行だけでなく、システム移行も含めた移行全体範囲を記載。
A14: 9 | G14: 移行対象データ | R14: 移行する対象データを記載。
A15: 10 | G15: 体制及び役割 | R15: 移行におけるサンスター及び弊社の体制。
A16: 11 | G16: 移行リハーサル実施概要対比表 | R16: 各移行リハーサル内容を一覧化したもの。
A17: 12 | G17: 移行手順 | R17: 移行作業手順。
... A20: 15 | G20: 移行完了基準 | R20: 何を持って移行が完了できたかを計れる基準。 サンスターにて移行計画タイミングで策定頂く。
A22: 本資料の目的
A23: ・現行システムから新システムへ滞りなく移行（データ移行・システム移行）するための移行全体に関わる移行要件をまとめたものです。
A27: 本資料中の用語
A28: FO | M28: 「Microsoft Dynamics 365 for Finance and Operations」の略称
A29: スコープ | M29: 範囲
A30: DIXF | M30: FO機能にあるエンティティを使ったインポート機能。外部データをFOデータへ取込む機能。
A31: I/F | M31: 外部システムとのデータ連携の略。I/FはInterfaceの略。

Sheet 移行全体方針
A1: システム名 | F1: =表紙!I10 -> 会計システム刷新プロジェクト | V1: タイトル | AM1: 日付 | AR1: 担当
A2: 文書名 | F2: =表紙!I14 -> 移行要件確認書 | V2: =MID(CELL("filename",$A$1),FIND("]",CELL("filename",$A$1))+1,31) -> #VALUE! | AJ2: 作成 | AM2: =変更履歴!A6 -> 45348 | AR2: JBS入井
AJ3: 更新
A5: ・以下に移行要件を記述します。
A7: 前提条件
B8: ・移行対象データは、サンスターにてFOのExcelフォーマットに基づき作成して頂く。
B9: FOを導入することによって新たにFO内でのみ設定しなければならなくなったデータ類（＝現行システム、現行業務では使っていないデータ）はJBSにて準備する。
B10: ・移行対象データは、サンスターにて「SSJ、SEJ、SLJ、SGFの4社」分のデータを作成頂く。("SGF"社の移行については、2024/2/22時点では未確定）
B11: ・サンスターにて作成頂いた移行データは、JBS作業としてFOへ取込む。
B12: ※ExcelデータとFOの登録データの整合性の確認はJBSにて行う。
B13: 一方、FOに登録されたデータと現行システムのデータとの整合性確認はサンスターにて行う。
B14: ・2025年10月～2025年12月は現行システムとFOの並行稼働運用とし、2026年1月よりFOの単独運用とする。
B15: ・2025年12月(切替月前月)の締め処理は旧システムで実施し、BS差分の伝票を期首日付で投入する。
B16: ※10-12月はUATで、本番移行を12月に実施？
A18: 移行リハーサル
B19: 本番移行開始前までに以下3回を実施を想定している。
B21: 移行リハーサル①
D22: ・JBSによる総合テスト前に移行データを取り込んだテスト
D23: ・実施期間：xxxx年xx月xx日～xx月xx日
D24: ・移行リハ1回目で以下を測定
F25: ・Excel作成時間（サンスター）
F26: ・Excel取込時間（JBS)
F27: ※JBS内では必要に応じて、移行作業を二つ以上に分けて実施する場合があります。
D28: ・移行後のデータ検証時間（サンスター、JBS）
F29: →移行時間短縮のために自動化も検討
D30: ・移行元データ性質：現行システムでのxxxx年xx月末断面のデータ
D31: ・移行判定1回目：xx月xx日頃
D32: ・同データを使用して、JBS内での結合テストを実施することで、データ検証を実施する想定。
B34: 移行リハーサル②
D35: ・サンスターとJBSによる実質1回目の移行リハーサル
D36: ・実施期間：xxxx年xx月xx日～xx月xx日
D37: ・移行リハ2回目で以下を確認
F38: ・移行時間計測（且つ1回目の手順見直しは必ずある。その再確認も含む）
D39: ・移行元データ性質：現行システムでのxxxx年xx月末断面のデータ
D40: ・移行判定2回目：xx月xx日頃
D41: ・同データを使用して、サンスター内でのUATを実施することで、データ検証を実施する想定。
B43: 移行リハーサル③
D44: ・サンスターとJBSによる実質2回目の移行リハーサル
D45: ・実施期間：xxxx年xx月xx日～xx月xx日
D46: ・移行リハ3回目で以下を確認
...

Sheet 移行方針
A1: システム名 | H1: =表紙!I10 -> 会計システム刷新プロジェクト | AB1: タイトル | AV1: 日付 | BA1: 担当
A2: 文書名 | H2: =表紙!I14 -> 移行要件確認書 | AB2: =MID(CELL("filename",$A$1),FIND("]",CELL("filename",$A$1))+1,31) -> #VALUE! | AS2: 作成 | AV2: =変更履歴!A6 -> 45348 | BA2: JBS入井
AS3: 更新
A5: 移行方針
E8: 移行対象月月末月断面のものを現行システムからFOへ移行する | W8: ◎並行稼働のメリット：2026年1月以降FOのみでの運用となった場合の運用上の課題が減少する。
E9: 本番稼働月以降はFOのみで業務を実施 | W9: ◎並行稼働のデメリット： 2024年10月から新旧システムを並行で作業実施する形となるので、
E10: 2025年10月～2025年12月度はFOとSAP R/3の並行稼働を想定 | AD10: 業務負荷も高まるし、新旧システム間での金額差異が多発する可能性がある。
B13: 移行対象 | H13: 移行対象 | Z13: 移行方法 | AW13: サンスター様側想定作業
B14: 債権・債務 (販売・仕入関連) | H14: 売上データ・仕入データ(未決済分) | Z14: アドオン開発したI/FプログラムにてFOへデータ送付する。 （FOは受信側なので、移行用のプログラム作成は不要の想定 ⇒R/3からデータ受信するためにR/3側にアドオン開発が必要？） | AW14: ・エラーデータについて、エラー内容を修正し、再度I/Fプログラムで送付しなおす。 ・移行結果確認はサンスターで実施
B15: 債権・債務 (販売・仕入以外) | H15: 売上データ・仕入データ以外の債権・債務データ(未決済分) | Z15: アドオン開発したI/FプログラムにてFOへデータ送付する。 （FOは受信側なので、移行用のプログラム作成は不要の想定 ⇒R/3からデータ受信するためにR/3側にアドオン開発が必要？） | AW15: ・エラーデータについて、エラー内容を修正し、再度I/Fプログラムで送付しなおす。 ・移行結果確認はサンスターで実施
B16: 一般会計 | H16: 一般会計データ(基本は無い) | Z16: FOのDIXF機能を使用して仕訳データ取込を実施(DIXFインポート) | AW16: ・DIXFのフォーマットに合わせてサンスターに対象データのクレンジングシートを作成いただく ・移行結果確認はサンスターで実施
B17: 固定資産 | H17: 現在稼働中（減価償却実施中等）の固定資産償却データ | Z17: FOの固定資産仕訳帳から入力(開発機能「一般仕訳帳へのインポート機能」) | AW17: ・Excel Add-Inのデータコネクトフォーマットに合わせてサンスターに対象固定資産償却データを作成いただく
B18: 資産リース | H18: 現在稼働中（支払実施中等）の資産リース支払・償却データ | Z18: FOの支払スケジュール、負債償却スケジュール、資産減価償却スケジュールから入力 | AW18: ・Excel Add-Inのデータコネクトフォーマットに合わせてサンスターに対象FOの支払スケジュール、負債償却スケジュール、資産減価償却スケジュールデータを作成いただく
B19: 残高移行 (BS/PL) | H19: すべての勘定科目 | Z19: FOの一般仕訳帳から入力 | AW19: ・Excel Add-Inのデータコネクトフォーマットに合わせてサンスターに対象勘定科目残高データを作成いただく
A21: 参考資料
B22: (無し）

Sheet 移行スケジュール
A1: システム名 | H1: =表紙!I10 -> 会計システム刷新プロジェクト | AB1: タイトル | AV1: 日付 | BA1: 担当
A2: 文書名 | H2: =表紙!I14 -> 移行要件確認書 | AB2: =MID(CELL("filename",$A$1),FIND("]",CELL("filename",$A$1))+1,31) -> #VALUE! | AS2: 作成 | AV2: =変更履歴!A6 -> 45348 | BA2: JBS入井
AS3: 更新
A5: 移行スケジュール
B7: 2024/2/22段階での移行スケジュール

Sheet 移行環境
A1: システム名 | F1: =表紙!I10 -> 会計システム刷新プロジェクト | V1: タイトル | AM1: 日付 | AR1: 担当
A2: 文書名 | F2: =表紙!I14 -> 移行要件確認書 | V2: =MID(CELL("filename",$A$1),FIND("]",CELL("filename",$A$1))+1,31) -> #VALUE! | AJ2: 作成 | AM2: =変更履歴!A6 -> 45348 | AR2: JBS入井
AJ3: 更新
A5: ・以下はデータ移行に関する移行環境です。
A7: 移行環境
B9: １．移行テスト環境（開発環境：Devx）環境名：sunstar-migration
D11: ・JBSが移行データ評価及び移行作業検証をするための専用環境。
D12: ・初期構築は、開発環境のゴールデンコンフィグ環境からコピーして構築する。
B15: ２．移行リハーサル環境（本番環境：Sandbox2-3）
D17: ・JBSが、サンスターから提供頂く移行データの投入環境及び投入後の整合性確認環境。
D18: ・移行リハーサル後、サンスターによる並行入力環境。※移行リハーサル２回目後で使用する。
D19: ・移行リハーサル都度、前回リハーサル環境は削除し、今回リハーサル環境で新たに塗り替えられる。
D20: 前回リハーサル環境データはバックアップして退避しておく。
D21: バックアップ作業はJBSが担当する。
D22: ・移行リハーサルが全て完了した後、環境は削除する。
A25: 参考資料
B26: (無し）

Sheet 移行スコープ
A1: システム名 | F1: =表紙!I10 -> 会計システム刷新プロジェクト | V1: タイトル | AM1: 日付 | AR1: 担当
A2: 文書名 | F2: =表紙!I14 -> 移行要件確認書 | V2: =MID(CELL("filename",$A$1),FIND("]",CELL("filename",$A$1))+1,31) -> #VALUE! | AJ2: 作成 | AM2: =変更履歴!A6 -> 45348 | AR2: JBS入井
AJ3: 更新
A5: ・以下はデータ移行だけでなく、システム移行も含めた移行全体範囲を記載しています。
A7: 移行スコープ
B9: １．データ移行
D11: ・シート「移行対象データ」に記載あるデータを移行する。 移行方法は上記シートに記載済。
D12: ・移行手順は、移行リハーサル１回目を終えた後、移行リハーサル２回目前に具体化し、移行リハーサル２回目で立案手順を確認する。
B14: ２．システム移行
D16: １．外部I/F
F17: １．外部I/F(※) 外部システム→FO連携
H18: ・外部システムよりFOへデータ送付する
F19: ※外部システムのI/F要件が固まり次第、I/F別に記述を変更する。
F20: (合計レベルでの移行または明細レベルでの移行も記述する）
B22: 3.業務移行
D24: ・業務移行は、サンスター主体で検討する。
D25: ・業務移行検討の前提となるシステム移行、データ移行の方針検討はJBSが実施する。
A29: 参考資料
B30: (無し）

Sheet 移行対象データ
A1: システム名 | F1: =表紙!I10 -> 会計システム刷新プロジェクト | V1: タイトル | AU1: 日付 | AZ1: 担当
A2: 文書名 | F2: =表紙!I14 -> 移行要件確認書 | V2: =MID(CELL("filename",$A$1),FIND("]",CELL("filename",$A$1))+1,31) -> #VALUE! | AR2: 作成 | AU2: =変更履歴!A6 -> 45348 | AZ2: JBS入井
AR3: 更新
A5: ・移行対象データは以下となります。
A7: 移行対象データ
B9: １．対象
AB10: 対象会社 ●：対象 | BL10: リハーサル時の移行対象 ●：対象 移行リハデータを反映させる環境
B11: No. | C11: 移行対象１ | P11: 移行対象２ | V11: 種別 | AB11: SSJ | AE11: SEJ | AH11: SLJ | AK11: 移行方法 | AS11: 移行元 | AY11: 備考 | BL11: リハ１ | BP11: リハ２ | BT11: リハ３
BL12: ・結合テスト | BP12: ・ユーザーT ・UAT | BT12: (無し)
B13: 1 | C13: ユーザー | V13: マスタ | AB13: ● | AE13: ● | AH13: ● | AK13: インポート | AS13: Excel | AY13: ※azure上にインフラが登録。FOでインポートする。 | BL13: ● | BP13: ● | BT13: ●
B14: 2 | C14: 顧客 | P14: 顧客 | V14: マスタ | AB14: ● | AE14: ● | AH14: ● | AK14: DIXF | AS14: SAP R/3 | BL14: ● | BP14: ● | BT14: ●
B15: 3 | C15: 顧客 | P15: 住所 | V15: マスタ | AB15: ● | AE15: ● | AH15: ● | AK15: DIXF | AS15: SAP R/3 | AY15: 複数ある場合に必要。単一の場合は顧客に設定する。 | BL15: ● | BP15: ● | BT15: ●
B16: 4 | C16: 顧客 | P16: 連絡先情報 | V16: マスタ | AB16: ● | AE16: ● | AH16: ● | AK16: DIXF | AS16: SAP R/3 | AY16: 複数ある場合に必要。単一の場合は顧客に設定する。 ※PARTYNUMBERで紐づけ。 | BL16: ● | BP16: ● | BT16: ●
B17: 5 | C17: 仕入先 | P17: 仕入先 | V17: マスタ | AB17: ● | AE17: ● | AH17: ● | AK17: DIXF | AS17: SAP R/3 | BL17: ● | BP17: ● | BT17: ●
B18: 6 | C18: 仕入先 | P18: 住所 | V18: マスタ | AB18: ● | AE18: ● | AH18: ● | AK18: DIXF | AS18: SAP R/3 | AY18: 複数ある場合に必要。単一の場合は仕入先に設定する。 | BL18: ● | BP18: ● | BT18: ●
B19: 7 | C19: 仕入先 | P19: 銀行口座 | V19: マスタ | AB19: ● | AE19: ● | AH19: ● | AK19: DIXF | AS19: SAP R/3
B20: 8
B21: 9
B22: 10
B23: 11
B24: 12
B25: 13
B26: 14
B27: 15
B28: 16
B29: 17
B30: 18
B31: 19
... B51: 39
B53: ２．特記
C54: １．勘定科目マスタ及び財務分析コードの移行について
E55: 初期設定するため、移行対象データ一覧には記載しない。
C57: ２．FOパラメータについて
E58: 初期設定するため、移行対象データ一覧には記載しない。
E59: 初期設定するパラメータはパラメータ定義書に定義する。
C61: ３．以下のような過去データは移行しない。
E62: ・プロジェクトデータ（本番稼働後に手入力いただく）
E64: 上記、「移行対象データ」に記載無きデータは移行しない。
A66: 参考資料
B67: (無し）

Sheet 体制及び役割
A1: システム名 | F1: =表紙!I10 -> 会計システム刷新プロジェクト | V1: タイトル | AM1: 日付 | AR1: 担当
A2: 文書名 | F2: =表紙!I14 -> 移行要件確認書 | V2: =MID(CELL("filename",$A$1),FIND("]",CELL("filename",$A$1))+1,31) -> #VALUE! | AJ2: 作成 | AM2: =変更履歴!A6 -> 45348 | AR2: JBS入井
AJ3: 更新
A5: ・移行推進のための体制及び役割は以下となります。
A7: 体制（移行）
AK28: 連携
A37: 役割（全体）
V39: ◎：主幹 〇：補佐
B40: 工程・作業名 | P40: サンスター | S40: JBS | V40: 備考
C41: ・移行方針(目的/範囲/期間/対象等)検討 | P41: ○ | S41: ◎ | V41: 移行における目的、範囲、期間、対象データ、リハーサル計画等をサンスターと協議する
C42: ・移行計画書作成 | S42: ◎ | V42: サンスターと協議した結果に基づき、移行計画書を作成する
C43: ・移行計画書承認 | P43: ◎ | S43: ○ | V43: 移行計画書をサンスターとレビューし、サンスターにご承認頂く
C44: ・リハーサル用テンプレート提示(ﾏｽﾀ/残高) | S44: ◎ | V44: 移行リハーサル用のマスタデータ及び残高データのテンプレートを作成し、提示する
C45: ・移行リハーサル準備(環境構築/データ整備) | S45: ◎ | V45: 移行リハーサルを実施する為の環境の構築及び整備を行う
C46: ・リハーサル用マスタ移行データ提供 | P46: ◎ | V46: 移行リハーサル用のマスタ移行データをサンスターからご提供頂く
C47: ・リハーサル用残高移行データ提供 | P47: ◎ | V47: 移行リハーサル用の残高移行データをサンスターからご提供頂く
C48: ・移行リハーサル実施 | S48: ◎ | V48: 移行リハーサルを実施する
C49: ・移行リハーサル結果報告 | S49: ◎ | V49: 移行リハーサル実施結果をサンスターに報告する
C50: ・本番用テンプレート提示(ﾏｽﾀ/残高) | S50: ◎ | V50: 本番移行用のマスタデータ及び残高データのテンプレートを作成し、提示する
C51: ・移行データ評価 | P51: ◎ | V51: 移行リハーサルの評価を行う
C52: ・本番稼働支援方針検討 | P52: ○ | S52: ◎ | V52: 本番稼働後の重点サポートの期間、体制、課題対応ルール等をサンスターと協議する
C53: ・本番稼働支援計画書作成 | S53: ◎ | V53: サンスターと協議した結果に基づき、本番稼働支援計画書を作成する
C54: ・本番稼働支援計画書承認 | P54: ◎ | S54: ○ | V54: 本番稼働支援計画書をサンスターとレビューし、サンスターにご承認頂く
C55: ・本稼働判定書作成 | P55: ◎ | V55: サンスターに本稼働判定基準等を記載した本稼働判定書を作成して頂く
C56: ・本番稼働判定会 | P56: ◎ | S56: ○ | V56: 本番稼働判定に必要な情報を収集し、本稼働判定書に基づき本稼働判定を実施する
A58: 役割（移行選任メンバ－）
B60: ロール | M60: 役割
C61: 移行リーダー | M61: ■各メンバーに対し １．移行計画策定及び両社間の合意調整（最終合意はプロジェクト全体にて合意する） ２．作業タスク立案指示・変更指示 ３．具体作業指示 ・現新データ性質のマッピング仕様確認及び仕様確定作業 ・移行テンプレート（クレンジングシート）作成作業 ・移行手順策定作業 ・移行タイムスケジュール策定作業 ・移行作業 ４．具体レビュー ・現新データ性質のマッピング仕様レビュー ・移行テンプレート（クレンジングシート）レビュー ・移行手順レビュー ・移行タイムスケジュールレビュー ５．作業進捗確認・管理 ６．課題確認・管理 ■両社リーダー及び自社各リーダーに対し １．各メンバーから挙がる課題解決のための打合せ・調整（JBS移行リーダー：NETAGE様移行リーダー） ２．自社各リーダーへの仕様確認・調整依頼 ■マネジメントチーム（プロジェクトマネージャー・プロジェクトリーダー）に対し １．作業タスク立案及び変更の報告 ２．作業進捗報告 ３．課題報告 ４．全体スケジュールへの調整依頼 ５．各合意内容への合意依頼
C62: 移行メンバ－ | M62: ■両社メンバー １．具体作業 ・両社メンバ－との仕様確認及び打合せ、自社チームとの仕様確認 ・現新データ性質のマッピング作業、マッピング仕様確定 ・移行テンプレート（クレンジングシート）作成及びサンスターへの提供（JBS） ・移行データの作成（クレンジングシートへ）及びJBS様への提供（サンスター） ・移行手順策定 ・移行タイムスケジュール策定 ・移行データ投入作業 ・移行データ投入後の整合性確認 ２．課題要件への落とし込み、課題解決案の提案 ■リーダーに対し １．作業タスク立案及び変更の報告 ２．作業進捗報告 ３．課題報告 ４．全体スケジュールへの調整依頼 ５．各合意内容への合意依頼
C63: 移行リーダー補佐 | M63: ■移行リーダーの業務を補佐する
C64: 全体補佐 | M64: ■移行リーダー・移行リーダー補佐・移行メンバーの各実務について、必要に応じて補佐する
A66: 参考資料
B67: (無し）

Sheet 移行リハーサル実施概要対比表
A1: システム名 | F1: =表紙!I10 -> 会計システム刷新プロジェクト | V1: タイトル | AM1: 日付 | AR1: 担当
A2: 文書名 | F2: =表紙!I14 -> 移行要件確認書 | V2: =MID(CELL("filename",$A$1),FIND("]",CELL("filename",$A$1))+1,31) -> #VALUE! | AJ2: 作成 | AM2: =変更履歴!A6 -> 45348 | AR2: JBS入井
AJ3: 更新
A5: ・各移行リハーサルの実施概要を対比したものです。
A7: 移行リハーサル実施概要対比
C9: リハーサル | H9: 実施時期 | M9: 判定時期 | Q9: 実施概要 | AJ9: 移行元データ性質 | AU9: 移行先環境 | BE9: 成功基準 | BZ9: 実施結果(サマリー)
B10: リハ１回目 | G10: xxxx年xx月xx日 ～ xxxx年xx月xx日 | L10: xxxx年xx月xx日 | Q10: ・暫定移行手順を策定する(JBS) ・移行元Excelデータ作成時間を計測する（サンスター） ・Excelデータ取込時間を計測する（JBS) ・各社それぞれの移行結果をまとめる。 ・各社それぞれの移行結果をフィードバックする。 ・移行手順を整理する。 ・結合テストを開始できる必要なデータを移行する。 ・キーユーザートレーニングを開始できる必要なデータを移行する。 ・移行時間短縮のために自動化も検討する。 | AJ10: 現行システムのxxxx年xx月末断面のデータ | AU10: ・結合テスト環境 ・キーユーザートレーニング環境 | BE10: ・暫定移行手順を策定できたこと。 ・移行元データ作成の時間を計測できたこと。 ・データ取込の時間を計測できたこと。 ・結合テストを開始できる必要なデータを移行できたこと。 ・移行時間短縮のために自動化の必要可否を判断できたこと。
B11: リハ２回目 | G11: xxxx年xx月xx日 ～ xxxx年xx月xx日 | L11: xxxx年xx月xx日 | Q11: ・暫定移行手順を具体化する。 ・移行所要時間を確定する。 ・移行手順を確定する。 ・各社それぞれの移行結果をまとめる。 ・各社それぞれの移行結果をフィードバックする。 ・総合テストを開始できる必要なデータを移行する。 ・エンドユーザートレーニングを開始できる必要なデータを移行する。 | AJ11: 現行システムのxxxx年xx月締のデータ | AU11: ・エンドユーザートレーニング環境 ・UAT環境 | BE11: ・移行所要時間を確定できたこと。 ・移行手順を確定できたこと。 ・ユーザートレーニングを開始できる必要なデータを移行できたこと。
B12: リハ３回目 | G12: xxxx年xx月xx日 ～ xxxx年xx月xx日 | L12: xxxx年xx月xx日 ～ xxxx年xx月xx日 | Q12: ・本番同様の一連の移行作業を実施する。 ・移行所要時間の見直し点を確定する。 ・移行手順の見直し点を確定する。 ・各社それぞれの移行結果をまとめる。 ・各社それぞれの移行結果をフィードバックする。 ・UATを開始できる必要なデータを移行する。 | AJ12: 現行システムのxxxx年xx月末締のデータ | AU12: ・UAT環境 | BE12: ・UATを開始できる必要なデータを移行できたこと。 ・一連の移行作業が概ね時間通り、手順通りに完了できたこと。
B13: リハ3回目で不合格 となった場合
A236: 参考資料
B237: なし

Sheet 移行手順
A1: システム名 | F1: =表紙!I10 -> 会計システム刷新プロジェクト | V1: タイトル | AM1: 日付 | AR1: 担当
A2: 文書名 | F2: =表紙!I14 -> 移行要件確認書 | V2: =MID(CELL("filename",$A$1),FIND("]",CELL("filename",$A$1))+1,31) -> #VALUE! | AJ2: 作成 | AM2: =変更履歴!A6 -> 45348 | AR2: JBS入井
AJ3: 更新
A5: ・移行作業手順。
A6: ・現時点では移行手順概要であるが、リハーサル２回目前に手順を具体化する。
A8: 移行手順
B10: 移行手順一式は、「移行リハーサル計画書２回目」に記載があり重複することから、「移行リハーサル２回目」の記載を優先とし、当該計画書では割愛する。
A13: 参考資料
B14: (無し）

Sheet 移行成功条件(数値)
A1: システム名 | F1: =表紙!I10 -> 会計システム刷新プロジェクト | V1: タイトル | AP1: 日付 | AU1: 担当
A2: 文書名 | F2: =表紙!I14 -> 移行要件確認書 | V2: =MID(CELL("filename",$A$1),FIND("]",CELL("filename",$A$1))+1,31) -> #VALUE! | AM2: 作成 | AP2: =変更履歴!A6 -> 45348 | AU2: JBS入井
AM3: 更新
A5: ・移行後、何を持って移行が成功したかがわかる条件。数値に関係する条件を記載。
A7: 移行成功条件(数値)
B9: 以下確認対象を比較し、比較値が移行成功基準を満たせれば移行は成功したとする。
B11: No. | C11: 確認対象 | P11: 移行対象２ | V11: 種別 | AB11: 移行方法 | AJ11: 移行元情報 | AN11: 移行先 | AT11: 比較値 | BA11: 移行成功基準 | BE11: 移行後の比較主幹 | BJ11: 比較元データ | BS11: 比較先データ | CA11: 実施結果(OK or NG)
B12: 1 | C12: ユーザー | V12: マスタ | AB12: インポート | AT12: 件数 | BA12: 合致 | BE12: JBS | BJ12: ユーザー登録シート | BS12: FOのExcelエクスポート結果
B13: 2 | C13: 顧客 | P13: 顧客 | V13: マスタ | AB13: DIXF | AT13: 件数 | BA13: 合致 | BE13: JBS | BJ13: クレンジングシート | BS13: FOのExcelエクスポート結果
B14: 3 | C14: 顧客 | P14: 住所 | V14: マスタ | AB14: DIXF | AT14: 件数 | BA14: 合致 | BE14: JBS | BJ14: クレンジングシート | BS14: FOのExcelエクスポート結果
B15: 4 | C15: 顧客 | P15: 連絡先情報 | V15: マスタ | AB15: DIXF | AT15: 件数 | BA15: 合致 | BE15: JBS | BJ15: クレンジングシート | BS15: FOのExcelエクスポート結果
B16: 5 | C16: 仕入先 | P16: 仕入先 | V16: マスタ | AB16: DIXF | AT16: 件数 | BA16: 合致 | BE16: JBS | BJ16: クレンジングシート | BS16: FOのExcelエクスポート結果
B17: 6 | C17: 仕入先 | P17: 住所 | V17: マスタ | AB17: DIXF | AT17: 件数 | BA17: 合致 | BE17: JBS | BJ17: クレンジングシート | BS17: FOのExcelエクスポート結果
B18: 7 | C18: 仕入先 | P18: 銀行口座 | V18: マスタ | AB18: DIXF | AT18: 件数 | BA18: 合致 | BE18: JBS | BJ18: クレンジングシート | BS18: FOのExcelエクスポート結果
B19: 8 | C19: 仕入先 | P19: 連絡先情報 | V19: マスタ | AB19: DIXF | AT19: 件数 | BA19: 合致 | BE19: JBS | BJ19: クレンジングシート | BS19: FOのExcelエクスポート結果
B20: 9
B21: 10
B22: 11
B23: 12
B24: 13
B25: 14
B26: 15
B27: 16
B28: 17
B29: 18
B30: 19
B31: 20
... B50: 39
A52: 参考資料
B53: (無し）

Sheet 移行成功条件(周辺システム)
A1: システム名 | F1: =表紙!I10 -> 会計システム刷新プロジェクト | V1: タイトル | AM1: 日付 | AR1: 担当
A2: 文書名 | F2: =表紙!I14 -> 移行要件確認書 | V2: =MID(CELL("filename",$A$1),FIND("]",CELL("filename",$A$1))+1,31) -> #VALUE! | AJ2: 作成 | AM2: =変更履歴!A6 -> 45348 | AR2: JBS入井
AJ3: 更新
A5: ・移行後、何を持って移行が成功したかがわかる条件。周辺システムに関係する条件を記載。
A7: 移行成功条件(周辺システム)
B9: 以下確認対象が移行成功基準を満たせば移行は成功したとする。
B11: No. | C11: 確認対象 | P11: 周辺システム | V11: 移行成功基準 | AT11: 実施結果(OK or NG)
B12: 1 | C12: SAP R/3→FO連携 | P12: SAP R/3 | V12: 連携対象データ全種類が１件ずつ問題なく連携できたこと。
B13: 2
B14: 3
B15: 4
B16: 5
A18: 参考資料
B19: (無し）

Sheet 移行完了基準
A1: システム名 | F1: =表紙!I10 -> 会計システム刷新プロジェクト | V1: タイトル | AM1: 日付 | AR1: 担当
A2: 文書名 | F2: =表紙!I14 -> 移行要件確認書 | V2: =MID(CELL("filename",$A$1),FIND("]",CELL("filename",$A$1))+1,31) -> #VALUE! | AJ2: 作成 | AM2: =変更履歴!A6 -> 45348 | AR2: JBS入井
AJ3: 更新
A5: ・何を持って移行が完了できたかを計れる基準。
A6: ・サンスターにて移行計画タイミングで策定頂く。
A8: 移行完了基準
B10: 以下、プロジェクト計画書v2.0より例を転記
B12: ①会計データ移行直後に、FO側で会計転記をサンスター様にて手動で実行頂く。
B13: ②この転記が完了して初めて、本番開始とできる、という条件や完了基準を明確化する。
B14: ③伝票処理がエラーなく行えること。
B15: ④以下締め処理が滞りなく完了できたこと。
C16: ④-1 2025年10月の月次締処理が滞りなく完了、月次処理を終えられたこと。
C17: ④-2 2025年10月の入金処理が滞りなく完了できたこと。
C18: ④-3 2025年月の支払処理が滞りなく完了できたこと。
B19: ⑤2025年12月末の年度末決算が正しく行えること。
B20: 、等。
A22: 参考資料
B23: (無し）
