Workbook
Name カレンダータイプ: [2]マスタ!$I$27:$I$29
Name ステータス: [2]マスタ!$C$27:$C$29
Name チェックボックス: [2]マスタ!$B$10:$B$11
Name はいいいえ: [2]マスタ!$B$5:$B$6
Name レポートタイプ: [2]マスタ!$K$6:$K$8
Name 為替換算タイプ: [2]マスタ!$U$5:$U$8
Name 演算子: [2]マスタ!$R$5:$R$14
Name 開始・終了: [2]マスタ!$C$237:$C$238
Name 勘定タイプ: [2]マスタ!$E$27:$E$32
Name 丸め方法: [2]マスタ!$Y$5:$Y$7
Name 既定の説明: [2]マスタ!$H$237:$H$351
Name 期間タイプ: [2]マスタ!$B$237:$B$244
Name 検証: [2]マスタ!$O$6:$O$9
Name 作成日: DATE(2000,3,21)
Name 仕訳帳タイプ: [2]マスタ!$B$27:$B$72
Name 借方貸方: [2]マスタ!$L$6:$L$7
Name 主勘定タイプ: [2]マスタ!$J$6:$J$15
Name 主勘定タイプ2: [2]マスタ!$AB$5:$AB$11
Name 場所: [2]マスタ!$S$5
Name 新しい伝票: [2]マスタ!$D$27:$D$29
Name 性別1: [2]マスタ!$Z$5:$Z$6
Name 精算表に残高を転送するフィールド: [2]マスタ!$M$6:$M$8
Name 選択可能値: [2]マスタ!$C$37:$C$43
Name 単位: [2]マスタ!$W$5:$W$7
Name 調整単位: [2]マスタ!$D$237:$D$240
Name 転記タイプ: [2]マスタ!$F$237:$F$389
Name 分析コード形式タイプ: [2]マスタ!$BA$5:$BA$8
Name 領域: [2]マスタ!$F$99:$F$164:'[2]マスタ'!$F$120

Sheet 表紙
B3: サンスター株式会社 御中
B10: 会計システム刷新プロジェクト（LIBRA）
B14: FOパラメータ定義書-SEJ_99.マスタ
B22: 第1.0版
B24: 45546
B26: 日本ビジネスシステムズ株式会社
F29: 作成者 | O29: JBS承認者
F30: 45546 | N30: ＜YYYY/MM/DD＞
F31: JBS石岡 | N31: 氏名

Sheet パラメータ設定一覧
A1: パラメータ設定一覧
B3: No | C3: 該当モジュール | D3: 法人共通/個別 | E3: 設定項目 | F3: GC設定担当者 | G3: GC設定完了日 | H3: 説明 | I3: パス
B4: =ROW()-3 -> 1 | C4: 組織管理 | D4: 共通 | E4: 作業単位 | H4: 作業単位の定義となる。 ※管理対象が多い場合移行対象の想定 | I4: 組織管理＞組織＞作業単位 Organization administration > Organizations > Operating units
B5: =ROW()-3 -> 2 | C5: 組織管理 | D5: 共通 | E5: 住所の設定 | F5: JBS石岡 | G5: 45548 | H5: 住所の定義となる。 ※市区町村や郵便番号については移行対象の想定（郵便番号インポート） ※住所、家のグループ、土地区画、アパートのグループはロシアのみで使用 | I5: 組織管理＞住所＞住所の設定 Organization administration > Addresses > Address setup
B6: =ROW()-3 -> 3 | C6: システム管理 | D6: 共通 | E6: ユーザーをロールに割り当てる | H6: ユーザをロールに紐づける。 アクセス権限の設定をするため、アクセス権限の種類ごとにユーザを紐づける。 ※移行対象 | I6: システム管理＞セキュリティ＞ユーザーをロールに割り当てる System administration > Security > Assign users to roles
B7: =ROW()-3 -> 4 | C7: システム管理 | D7: 共通 | E7: セキュリティロール | F7: 権限設計書参照 | G7: 権限設計書参照 | H7: ロールの定義となる。 ロールの数は、アクセス権限の種類分となる。 ※FO権限設計書で定義（設計書側で管理） | I7: システム管理＞セキュリティ＞セキュリティのコンフィギュレーション System administration > Security > Security configuration
B8: =ROW()-3 -> 5 | C8: システム管理 | D8: 共通 | E8: ユーザーIDへの作業者の割当 | H8: ユーザーIDに対して作業者の割当を設定する。 ※移行対象の | I8: システム管理＞ユーザー＞ユーザー System administration > Users > Users
B9: =ROW()-3 -> 6 | C9: システム管理 | D9: 共通 | E9: ユーザーグループ | H9: ユーザをグループごとに設定する。 ※ワークフローの割り当て時にユーザグループ単位で設定可能 ※各ユーザーグループに所属するユーザーについては移行対象とする | I9: システム管理＞ユーザー＞ユーザーグループ System administration > User > User Group
B10: =ROW()-3 -> 7 | C10: 一般会計 | D10: 共通 | E10: 通貨の為替レート | H10: 為替レートの定義を行う。 ※管理対象が多い場合移行対象の想定 | I10: 一般会計＞通貨＞通貨の為替レート General ledger > Currencies > Currency exchange rates
B11: =ROW()-3 -> 8 | C11: 売掛金管理 | D11: 個別 | E11: 顧客 | H11: 顧客の定義となる。 ※移行対象 | I11: 売掛金管理＞顧客＞すべての顧客 Accounts receivable > Customers > All customers
B12: =ROW()-3 -> 9 | C12: 買掛金管理 | D12: 個別 | E12: 仕入先 | H12: 仕入先の定義となる。 ※移行対象 | I12: 買掛金管理＞仕入先＞すべての仕入先 Accounts payable > Vendors > All vendors
B13: =ROW()-3 -> 10 | C13: 人事管理 | D13: 個別 | E13: 従業員 | H13: 新しい従業員の採用の定義となる。 ※移行対象 | I13: 人事管理＞作業者＞従業員 Human resources > Workers > Employees
B14: =ROW()-3 -> 11 | C14: 人事管理 | D14: 共通 | E14: 部門 | H14: 部門の設定が必要。 ※管理対象が多い場合移行対象の想定（作業単位同様 作業単位側で対応していたら対応不要） | I14: 人事管理＞部門＞部門 Human resources > Departments > Departments
B15: =ROW()-3 -> 12 | C15: 人事管理 | D15: 共通 | E15: 職務 | H15: 職務の設定が必要。 ※管理対象が多い場合移行対象の想定 | I15: 人事管理＞職務＞職務 Human resources > Jobs > Jobs
B16: =ROW()-3 -> 13 | C16: 人事管理 | D16: 共通 | E16: 職位 | H16: 職位の設定 １作業者に対して１職位となる。 ※部門と職務の設定が先に必要（WFで使用する場合などはタイトルの設定も必要） ※移行対象 | I16: 人事管理＞職位＞すべての職位 Human resources > Positions > All Positions

Sheet 作業単位
A1: 作業単位
B2: 組織管理＞組織＞作業単位
B3: Organization administration > Organizations > Operating units
A4: パラメータ設定一覧へ
B5: # | C5: タブ | D5: タブ説明 | E5: 項目分類 | F5: 項目 | G5: 項目説明 | H5: 設定可能値 | I5: デフォルト値 | J5: 備考 | K5: 設定値 | L5: 設定基準
B6: =ROW() - 5 -> 1 | C6: 概要 | E6: 作業単位 | F6: 名前 | H6: 文字列 | I6: ー | K6: 「作業単位-タ設定値」を参照
B7: =ROW() - 5 -> 2 | F7: 原価部門 番号 | G7: 原価部門 固有の英数字 ID | H7: 文字列 | I7: ー | J7: ○○←選択した作業単位のタイプ ※番号順序に順ずる形で採番されるが、手動変更が可能 | K7: 「作業単位-タ設定値」を参照
B8: =ROW() - 5 -> 3 | F8: 作業単位のタイプ | H8: ・部門 ・原価部門 ・バリューストリーム ・事業単位 ・すべての作業単位 ・小売チャンネル | I8: ー | K8: 「作業単位-タ設定値」を参照
B9: =ROW() - 5 -> 4 | C9: 一般 | F9: 検索名 | H9: 文字列 | I9: 作業単位＞名前 の値 | K9: 「作業単位-タ設定値」を参照
B10: =ROW() - 5 -> 5 | F10: メモ | G10: 選択した作業単位に関するメモを入力します。 | H10: 文字列 | I10: ー | K10: 「作業単位-タ設定値」を参照
B11: =ROW() - 5 -> 6 | F11: 階層 | G11: 選択したオプションは、選択した作業単位が組織階層に属していることを示します。 | H11: はい/いいえ | I11: はい | K11: 「作業単位-タ設定値」を参照
B12: =ROW() - 5 -> 7 | F12: DUNS番号 | H12: 文字列 | I12: ー | K12: 「作業単位-タ設定値」を参照
B13: =ROW() - 5 -> 8 | F13: マネージャー | G13: データベースのレコードの固有 ID | H13: 文字列（ユーザー定義） | I13: ー | K13: 「作業単位-タ設定値」を参照
B14: =ROW() - 4 -> 10 | C14: 住所 | F14: 名前または説明 | H14: 文字列 | I14: ー | K14: 「作業単位-タ設定値」を参照
B15: =ROW() - 4 -> 11 | F15: 住所 | H15: 文字列 | I15: ー | J15: 詳細オプションより以下を入力することで反映される ・国/地域 ・郵便番号 ・住所 ・市町村 ・都道府県 | K15: 「作業単位-タ設定値」を参照
B16: =ROW() - 4 -> 12 | F16: 目的 | H16: ・業務 ・委託販売 ・配送 ・固定資産 ・本社 ・ホーム ・請求書 ・船荷 ・その他 ・支払 ・実際の場所 ・採用 ・送金先 ・サービス ・安定した組織 ・ステートメント ・SWIFT ・船降 | I16: ー | K16: 「作業単位-タ設定値」を参照
B17: =ROW() - 4 -> 13 | F17: 主要 | H17: はい/いいえ | I17: ー | K17: 「作業単位-タ設定値」を参照
B18: =ROW() - 4 -> 14 | E18: 詳細オプション | F18: 国/地域 | H18: 国/地域（システム定義） | I18: ー | J18: 「詳細オプション＞詳細」より編集可能 | K18: 「作業単位-タ設定値」を参照
B19: =ROW() - 4 -> 15 | F19: 郵便番号 | H19: 数値 | I19: ー | J19: 「詳細オプション＞詳細」より編集可能 | K19: 「作業単位-タ設定値」を参照
B20: =ROW() - 4 -> 16 | F20: 住所 | H20: 文字列 | I20: ー | J20: 「詳細オプション＞詳細」より編集可能 | K20: 「作業単位-タ設定値」を参照
B21: =ROW() - 4 -> 17 | F21: 住所（カナ） | H21: 文字列 | I21: ー | J21: 「詳細オプション＞詳細」より編集可能 | K21: 「作業単位-タ設定値」を参照
B22: =ROW() - 4 -> 18 | F22: 市町村 | H22: 文字列 | I22: ー | J22: 「詳細オプション＞詳細」より編集可能 | K22: 「作業単位-タ設定値」を参照
B23: =ROW() - 4 -> 19 | F23: 市町村（カナ） | H23: 文字列 | I23: ー | J23: 「詳細オプション＞詳細」より編集可能 | K23: 「作業単位-タ設定値」を参照
B24: =ROW() - 4 -> 20 | F24: 都道府県 | H24: 文字列 | I24: ー | J24: 「詳細オプション＞詳細」より編集可能 | K24: 「作業単位-タ設定値」を参照
B25: =ROW() - 4 -> 21 | F25: 市区群 | H25: 文字列 | I25: ー | J25: 「詳細オプション＞詳細」より編集可能 | K25: 「作業単位-タ設定値」を参照
B26: =ROW() - 4 -> 22 | F26: 主要 | H26: はい/いいえ | I26: ー | J26: 「詳細オプション＞詳細」より編集可能 | K26: 「作業単位-タ設定値」を参照
B27: =ROW() - 4 -> 23 | F27: 国/地域に関する基本事項 | H27: はい/いいえ | I27: ー | J27: 「詳細オプション＞詳細」より編集可能 | K27: 「作業単位-タ設定値」を参照
B28: =ROW() - 4 -> 24 | C28: 連絡先情報 | F28: 説明 | H28: 文字列 | I28: ー | K28: 「作業単位-タ設定値」を参照
B29: =ROW() - 4 -> 25 | F29: タイプ | H29: ・電話 ・電子メールアドレス ・URL ・テレックス ・FAX ・Facebook ・Twitter ・LinkedIn | I29: ー | K29: 「作業単位-タ設定値」を参照
B30: =ROW() - 4 -> 26 | F30: 連絡先の電話番号/住所 | H30: 文字列 | I30: ー | K30: 「作業単位-タ設定値」を参照
B31: =ROW() - 4 -> 27 | F31: 内線 | H31: 文字列 | I31: ー | K31: 「作業単位-タ設定値」を参照
B32: =ROW() - 4 -> 28 | F32: 主要 | H32: チェック有/チェック無 | I32: チェック無 | K32: 「作業単位-タ設定値」を参照

Sheet 作業単位-設定値
A1: 作業単位-設定値 ※基本的には移行データを正とする
A2: ■凡例「必須：システム上必須」「必須(*)：システムで必須ではないが、トランザクション上や業務などで必須」
A3: パラメータ設定一覧へ
B4: # | C4: 概要 | F4: 一般 | K4: 住所 | Y4: 連絡先情報
C5: 作業単位 | K5: 追加 | O5: 詳細オプション
C6: 名前 | D6: 原価部門 番号 | E6: 作業単位タイプ | F6: 検索名 | G6: メモ | H6: 階層 | I6: DUNS番号 | J6: マネージャー | K6: 名前または説明 | L6: 住所 | M6: 目的 | N6: 主要 | O6: 国/地域 | P6: 郵便番号 | Q6: 住所 | R6: 住所（カナ） | S6: 市町村 | T6: 市町村（カナ） | U6: 都道府県 | V6: 市区群 | W6: 主要 | X6: 国/地域に関する基本事項 | Y6: 説明 | Z6: タイプ | AA6: 連絡先の電話番号/住所 | AB6: 内線 | AC6: 主要
C7: 文字列 | D7: 文字列 ※番号順序に順ずる形で採番されるが、手動変更が可能 | E7: 部門 原価部門 バリューストリーム 事業単位 すべての作業単位 小売チャンネル | F7: 文字列 | G7: 文字列 | H7: はい/いいえ | I7: 文字列 | J7: 文字列（ユーザー定義） | K7: 文字列 | L7: 文字列 | N7: はい/いいえ | O7: 国/地域（システム定義） | P7: 数値 | Q7: 文字列 | R7: 文字列 | S7: 文字列 | T7: 文字列 | U7: 文字列 | V7: 文字列 | W7: はい/いいえ | X7: はい/いいえ | Y7: 文字列 | AA7: 文字列 | AB7: 文字列 | AC7: チェック有/チェック無
C8: 必須 | D8: 必須 | E8: 必須
B9: 例 | C9: Dynamics部 | D9: D0001 | E9: 部門 | F9: Dynamics部
B10: =ROW() - 9 -> 1
B11: =ROW() - 9 -> 2
B12: =ROW() - 9 -> 3
B13: =ROW() - 9 -> 4
B14: =ROW() - 9 -> 5
B15: =ROW() - 9 -> 6
B16: =ROW() - 9 -> 7
B17: =ROW() - 9 -> 8
B18: =ROW() - 9 -> 9
B19: =ROW() - 9 -> 10
B20: =ROW() - 9 -> 11
B21: =ROW() - 9 -> 12
... B109: =ROW() - 9 -> 100

Sheet 住所の設定
A1: 住所の設定
B2: 組織管理＞グローバルアドレス帳>住所＞住所の設定
B3: Organization administration > Addresses > Address setup
A4: パラメータ設定一覧へ
B5: # | C5: タブ | D5: タブ説明 | E5: 項目分類 | F5: 項目 | G5: 項目説明 | H5: 設定可能値 | I5: デフォルト値 | J5: 備考 | K5: 設定値 | L5: 設定基準
B6: =ROW() - 5 -> 1 | C6: パラメーター | D6: 住所作成時に検証 | F6: 郵便番号 | H6: はい/いいえ | I6: いいえ | K6: いいえ
B7: =ROW() - 5 -> 2 | F7: 地区 | H7: はい/いいえ | I7: いいえ | K7: いいえ
B8: =ROW() - 5 -> 3 | F8: 市町村 | H8: はい/いいえ | I8: いいえ | K8: いいえ
A9: △ | B9: =ROW() - 5 -> 4 | F9: 市区群 | H9: はい/いいえ | I9: はい | K9: はい
B10: =ROW() - 5 -> 5 | F10: ロシア語の住所形式の検証を無効にする | H10: はい/いいえ | I10: いいえ | K10: いいえ
B11: =ROW() - 5 -> 6 | C11: 住所の設定 | D11: 住所の設定に住所の形式情報を入力します | F11: 住所の形式 | H11: 文字列 | I11: - | J11: 最初に設定して保存した後は変更不可 | K11: 「住所の形式-設定値」を参照
B12: =ROW() - 5 -> 7 | F12: 説明 | H12: 文字列 | I12: - | K12: 「住所の形式-設定値」を参照
B13: =ROW() - 5 -> 8 | F13: プレビュー | H13: - | I13: - | J13: 設定値のプレビューが表示される | K13: 「住所の形式-設定値」を参照
B14: =ROW() - 5 -> 9 | E14: 住所コンポーネントのコンフィギュレーション | F14: 住所アプリケーションオブジェクト | H14: ・郵便番号 ・市町村 ・市区群 ・都道府県 ・国/地域 ・住所 ・地域 ・番地 ・建物名（補足） ・郵便受 ・番地 ・Building ・Apartment ・家のグループ ・アパートのグループ ・OKSM別コード ・住所形式 ・土地区画 | I14: 選択した「住所の形式」により初期値は異なる | K14: 「住所の形式-設定値」を参照
B15: =ROW() - 5 -> 10 | F15: 区切り | H15: 文字列 | I15: - | K15: 「住所の形式-設定値」を参照
B16: =ROW() - 5 -> 11 | F16: 新しいライン | H16: チェック有/チェック無 | I16: - | K16: 「住所の形式-設定値」を参照
B17: =ROW() - 5 -> 12 | F17: データ入力専用 | G17: 住所情報を入力した場合にのみ住所コンポーネントを含めるには、このオプションを選択します。このオプションを選択した場合、住所の印刷時に、住所コンポーネントは表示されません。 | H17: チェック有/チェック無 | I17: - | K17: 「住所の形式-設定値」を参照
B18: =ROW() - 5 -> 13 | F18: 無効 | H18: チェック有/チェック無 | I18: - | K18: 「住所の形式-設定値」を参照
B19: =ROW() - 5 -> 14 | F19: 展開 | G19: 住所の印刷時に、国/地域、都道府県、および国の正式名を表示するには、このオプションを選択します。このオプションをオフにすると、住所の印刷時に、国/地域、都道府県、および国のコードのみが表示されます。 | H19: チェック有/チェック無 | I19: - | K19: 「住所の形式-設定値」を参照
B20: =ROW() - 5 -> 15 | F20: 特別 | G20: 現在の住所コンポーネントの区切り記号が前の住所コンポーネントの区切り記号と同じであることを指定するには、このオプションを選択します。 | H20: チェック有/チェック無 | I20: - | K20: 「住所の形式-設定値」を参照
B21: =ROW() - 5 -> 16 | C21: 国/地域 | D21: 住所の設定に国/地域情報を入力します | F21: 国/地域（リスト） | H21: 世界各国の国と地域(350か国以上) | I21: -
B22: =ROW() - 5 -> 17 | F22: 略称（リスト） | H22: 世界各国の国と地域(350か国以上) | I22: -
B23: =ROW() - 5 -> 18 | F23: 国/地域 | H23: 文字列 | I23: -
B24: =ROW() - 5 -> 19 | F24: 略称 | H24: 文字列 | I24: -
B25: =ROW() - 5 -> 20 | F25: タイムゾーン | H25: 世界各国のタイムゾーン | I25: -
B26: =ROW() - 5 -> 21 | F26: 郵便番号＋４桁コードの検証ルールを使用 | H26: はい/いいえ | I26: -
B27: =ROW() - 5 -> 22 | F27: ISO | H27: 住所の形式 | I27: -
B28: =ROW() - 5 -> 23 | F28: IOR融資ID | H28: 文字列 | I28: -
B29: =ROW() - 5 -> 24 | F29: 正式名称 | H29: 文字列 | I29: -
B30: =ROW() - 5 -> 25 | F30: 住所の形式 | H30: 住所の形式 | I30: -
B31: =ROW() - 5 -> 26 | F31: BACEN code | H31: 文字列 | I31: -
B32: =ROW() - 5 -> 27 | F32: Code by OKSM | H32: - | I32: -
B33: =ROW() - 5 -> 28 | F33: Member of Customs Union | H33: はい/いいえ | I33: いいえ
B34: =ROW() - 5 -> 29 | C34: 都道府県 | D34: 住所の設定に都道府県情報を入力します | F34: 都道府県 | H34: ・京都府 ・北海道 ・大阪府 ・東京都 ・福岡県 ・群馬県 ・長崎県 | I34: - | J34: 「国/地域」が「JPN」の場合 | K34: 「都道府県-設定値」を参照
B35: =ROW() - 5 -> 30 | F35: 説明 | H35: - | I35: - | K35: 「都道府県-設定値」を参照
B36: =ROW() - 5 -> 31 | F36: 国/地域 | H36: - | I36: JPN | K36: 「都道府県-設定値」を参照
B37: =ROW() - 5 -> 32 | F37: 都道府県 | H37: - | I37: - | J37: 「都道府県」で選択した都道府県が自動で入力される | K37: 「都道府県-設定値」を参照
B38: =ROW() - 5 -> 33 | F38: 説明 | H38: 文字列 | I38: - | K38: 「都道府県-設定値」を参照
B39: =ROW() - 5 -> 34 | F39: タイムゾーン | H39: 世界各国のタイムゾーン | I39: - | K39: 「都道府県-設定値」を参照
B40: =ROW() - 5 -> 35 | F40: イントラスタットコード | H40: 文字列 | I40: - | K40: 「都道府県-設定値」を参照
...

Sheet 住所の形式-設定値
A1: 住所の形式-設定値 ※既定値以外の形式を使用する場合新規で登録し、それのみを記載
A2: ■凡例「必須：システム上必須」「必須(*)：システムで必須ではないが、トランザクション上や業務などで必須」
A3: パラメータ設定一覧へ
B4: # | C4: 住所の形式 | D4: 説明 | E4: 住所アプリケーションオブジェクト | F4: 区切り | G4: 新しいライン | H4: データ入力専用 | I4: 無効 | J4: 展開 | K4: 特別
C5: 文字列 | D5: 文字列 | E5: ※「住所の設定」参照 | F5: 文字列 | G5: チェック有/チェック無 | H5: チェック有/チェック無 | I5: チェック有/チェック無 | J5: チェック有/チェック無 | K5: チェック有/チェック無
C6: 必須 | E6: 必須（国/地域は必須）
B7: 例 | C7: JBS-TEST | D7: JBS使用住所形式 | E7: 国/地域 | G7: チェック有
E8: 郵便番号 | G8: チェック有
E9: 都道府県 | G9: チェック有
E10: 市町村 | G10: チェック有
E11: 住所 | G11: チェック有
B12: 1 | C12: JPN1 | D12: 日本式1（郵便番号／都道府県／市区町村／住所／ビル名） | E12: 国/地域 | F12: ー | G12: チェック有
E13: 郵便番号 | F13: ー | G13: チェック有
E14: 都道府県 | F14: ー | G14: チェック有
E15: 市町村 | F15: ー | G15: チェック有
E16: 住所 | F16: ー | G16: チェック有
E17: 建物名 (補足) | F17: ー | G17: チェック有

Sheet 都道府県-設定値
A1: 都道府県-設定値 ※基本的には移行データを正とする（日本の郵便番号インポートでは反映されない）
A2: ■凡例「必須：システム上必須」「必須(*)：システムで必須ではないが、トランザクション上や業務などで必須」
A3: パラメータ設定一覧へ
B4: # | C4: 都道府県
C5: 国/地域 | D5: 都道府県 | E5: 説明 | F5: タイムゾーン | G5: イントラスタットコード | H5: IT州コード | I5: 既定の都道府県 | J5: State code | K5: Union territory
C6: （ユーザー定義） | E6: 文字列 | G6: 文字列 | H6: 文字列 | I6: はい/いいえ | J6: 文字列 | K6: はい/いいえ
C7: 必須 | D7: 必須
B8: =ROW() - 7 -> 1 | C8: JPN | D8: 北海道 | E8: ー | F8: ー | G8: ー | H8: ー | I8: ー | J8: ー | K8: いいえ
B9: =ROW() - 7 -> 2 | C9: JPN | D9: 青森県 | E9: ー | F9: ー | G9: ー | H9: ー | I9: ー | J9: ー | K9: いいえ
B10: =ROW() - 7 -> 3 | C10: JPN | D10: 岩手県 | E10: ー | F10: ー | G10: ー | H10: ー | I10: ー | J10: ー | K10: いいえ
B11: =ROW() - 7 -> 4 | C11: JPN | D11: 宮城県 | E11: ー | F11: ー | G11: ー | H11: ー | I11: ー | J11: ー | K11: いいえ
B12: =ROW() - 7 -> 5 | C12: JPN | D12: 秋田県 | E12: ー | F12: ー | G12: ー | H12: ー | I12: ー | J12: ー | K12: いいえ
B13: =ROW() - 7 -> 6 | C13: JPN | D13: 山形県 | E13: ー | F13: ー | G13: ー | H13: ー | I13: ー | J13: ー | K13: いいえ
B14: =ROW() - 7 -> 7 | C14: JPN | D14: 福島県 | E14: ー | F14: ー | G14: ー | H14: ー | I14: ー | J14: ー | K14: いいえ
B15: =ROW() - 7 -> 8 | C15: JPN | D15: 茨城県 | E15: ー | F15: ー | G15: ー | H15: ー | I15: ー | J15: ー | K15: いいえ
B16: =ROW() - 7 -> 9 | C16: JPN | D16: 栃木県 | E16: ー | F16: ー | G16: ー | H16: ー | I16: ー | J16: ー | K16: いいえ
B17: =ROW() - 7 -> 10 | C17: JPN | D17: 群馬県 | E17: ー | F17: ー | G17: ー | H17: ー | I17: ー | J17: ー | K17: いいえ
B18: =ROW() - 7 -> 11 | C18: JPN | D18: 埼玉県 | E18: ー | F18: ー | G18: ー | H18: ー | I18: ー | J18: ー | K18: いいえ
B19: =ROW() - 7 -> 12 | C19: JPN | D19: 千葉県 | E19: ー | F19: ー | G19: ー | H19: ー | I19: ー | J19: ー | K19: いいえ
... B54: =ROW() - 7 -> 47 | C54: JPN | D54: 沖縄県 | E54: ー | F54: ー | G54: ー | H54: ー | I54: ー | J54: ー | K54: いいえ

Sheet 市区郡-設定値
A1: 市区郡-設定値 ※基本的には移行データを正とする（日本の郵便番号インポートでは反映されない）
A2: ■凡例「必須：システム上必須」「必須(*)：システムで必須ではないが、トランザクション上や業務などで必須」
A3: パラメータ設定一覧へ
B4: # | C4: 市区郡
C5: 国/地域 | D5: 都道府県 | E5: 市区郡 | F5: 説明 | G5: IT市区郡コード | H5: ES市区郡コード
C6: （ユーザー定義） | D6: （ユーザー定義） | E6: 文字列 | F6: 文字列 | G6: 文字列 | H6: 文字列
C7: 必須 | D7: 必須 | E7: 必須
B8: =ROW() - 7 -> 1
B9: =ROW() - 7 -> 2
B10: =ROW() - 7 -> 3

Sheet 市町村-設定値
A1: 市町村-設定値 ※基本的には移行データを正とする（郵便番号インポート）
A2: ■凡例「必須：システム上必須」「必須(*)：システムで必須ではないが、トランザクション上や業務などで必須」
A3: パラメータ設定一覧へ
B4: # | C4: 市町村
C5: 国/地域 | D5: 市町村 | E5: 説明 | F5: City code | G5: 都道府県 | H5: 市区郡 | I5: IT自治体コード | J5: 市町村キー
C6: （ユーザー定義） | D6: （ユーザー定義） | E6: 文字列 | F6: 文字列 | G6: （ユーザー定義） | H6: 文字列 | I6: 文字列 | J6: 文字列（国/地域、都道府県、市町村を入れると自動反映される）
C7: 必須 | D7: 必須 | J7: 必須
B8: =ROW() - 7 -> 1
B9: =ROW() - 7 -> 2
B10: =ROW() - 7 -> 3
B11: =ROW() - 7 -> 4
B12: =ROW() - 7 -> 5
B13: =ROW() - 7 -> 6

Sheet 地区-設定値
A1: 地区-設定値 ※基本的には移行データを正とする（日本の郵便番号インポートでは反映されない）
A2: ■凡例「必須：システム上必須」「必須(*)：システムで必須ではないが、トランザクション上や業務などで必須」
A3: パラメータ設定一覧へ
B4: # | C4: 地域
C5: 国/地域 | D5: 都道府県 | E5: 市区郡 | F5: 市町村 | G5: 地区 | H5: 説明
C6: （ユーザー定義） | D6: （ユーザー定義） | E6: （ユーザー定義） | F6: （ユーザー定義） | G6: 文字列 | H6: 文字列
F7: 必須 | G7: 必須
B8: =ROW() - 7 -> 1
B9: =ROW() - 7 -> 2
B10: =ROW() - 7 -> 3
B11: =ROW() - 7 -> 4
B12: =ROW() - 7 -> 5

Sheet 住所-設定値
A1: 住所-設定値 ※基本的には移行データを正とする（ロシアでのみ使用）
A2: ■凡例「必須：システム上必須」「必須(*)：システムで必須ではないが、トランザクション上や業務などで必須」
A3: パラメータ設定一覧へ
B4: # | C4: 住所
C5: 国/地域 | D5: 都道府県 | E5: 市区郡 | F5: 市町村 | G5: 地区 | H5: 番地 | I5: 住所 | J5: 省略形コード | K5: 説明 | L5: 郵便番号 | M5: STI code | N5: IMNS 地域の数 | O5: RCM | P5: オブジェクト ステータス
C6: （ユーザー定義） | D6: （ユーザー定義） | E6: （ユーザー定義） | F6: （ユーザー定義） | G6: 数値 | H6: 数値 | I6: 文字列 | J6: （ユーザー定義） | K6: 文字列 | L6: （ユーザー定義） | M6: 数値 | N6: 数値 | O6: 数値
C7: ※RUS固定 | H7: 必須
B8: =ROW() - 7 -> 1 | C8: RUS
B9: =ROW() - 7 -> 2 | C9: RUS
B10: =ROW() - 7 -> 3 | C10: RUS
B11: =ROW() - 7 -> 4 | C11: RUS
B12: =ROW() - 7 -> 5 | C12: RUS

Sheet 家のグループ-設定値
A1: 家のグループ-設定値 ※基本的には移行データを正とする（ロシアでのみ使用）
A2: ■凡例「必須：システム上必須」「必須(*)：システムで必須ではないが、トランザクション上や業務などで必須」
A3: パラメータ設定一覧へ
B4: # | C4: 家のグループ
C5: 国/地域 | D5: 都道府県 | E5: 市区郡 | F5: 市町村 | G5: 地区 | H5: 番地 | I5: 家のグループコード | J5: 建物の番号 | K5: 建物 | L5: 省略形コード | M5: 説明 | N5: 郵便番号 | O5: STI code | P5: IMNS地域の数 | Q5: RCOAD
C6: （ユーザー定義） | D6: （ユーザー定義） | E6: （ユーザー定義） | F6: （ユーザー定義） | G6: （ユーザー定義） | H6: （ユーザー定義） | I6: 数値 | J6: 数値 | K6: 文字列 | L6: （ユーザー定義） | M6: 文字列 | N6: 郵便番号 | O6: 数値 | P6: 数値 | Q6: 数値
C7: ※RUS固定 | I7: 必須
B8: =ROW() - 7 -> 1 | C8: RUS
B9: =ROW() - 7 -> 2 | C9: RUS
B10: =ROW() - 7 -> 3 | C10: RUS
B11: =ROW() - 7 -> 4 | C11: RUS
B12: =ROW() - 7 -> 5 | C12: RUS

Sheet 土地区画-設定値
A1: 土地区画-設定値 ※基本的には移行データを正とする（ロシアでのみ使用）
A2: ■凡例「必須：システム上必須」「必須(*)：システムで必須ではないが、トランザクション上や業務などで必須」
A3: パラメータ設定一覧へ
B4: # | C4: 土地区画
C5: 国/地域 | D5: 都道府県 | E5: 市区郡 | F5: 市町村 | G5: 地区 | H5: 番地 | I5: 土地区画コード | J5: 土地区画の番地 | K5: 建物 | L5: 省略形コード | M5: 説明 | N5: 郵便番号 | O5: STI code | P5: IMNS地域の数 | Q5: RCM
C6: （ユーザー定義） | D6: （ユーザー定義） | E6: （ユーザー定義） | F6: （ユーザー定義） | G6: （ユーザー定義） | H6: （ユーザー定義） | I6: 文字列 | J6: 数値 | K6: 文字列 | M6: 文字列 | N6: 郵便番号 | O6: 数値 | P6: 数値 | Q6: 数値
C7: ※RUS固定 | I7: 必須
B8: =ROW() - 7 -> 1 | C8: RUS
B9: =ROW() - 7 -> 2 | C9: RUS
B10: =ROW() - 7 -> 3 | C10: RUS
B11: =ROW() - 7 -> 4 | C11: RUS
B12: =ROW() - 7 -> 5 | C12: RUS

Sheet アパートのグループ-設定値
A1: アパートのグループ-設定値 ※基本的には移行データを正とする（ロシアでのみ使用）
A2: ■凡例「必須：システム上必須」「必須(*)：システムで必須ではないが、トランザクション上や業務などで必須」
A3: パラメータ設定一覧へ
B4: # | C4: アパートのグループ
C5: 国/地域 | D5: 都道府県 | E5: 市区郡 | F5: 市町村 | G5: 地区 | H5: 番地 | I5: 家のグループ | J5: アパートグループのコード | K5: アパートのグループ | L5: エントランス番号 | M5: 省略形コード | N5: 説明 | O5: 郵便番号 | P5: STI code | Q5: IMNS地域の数
C6: （ユーザー定義） | D6: （ユーザー定義） | E6: （ユーザー定義） | F6: （ユーザー定義） | G6: （ユーザー定義） | H6: （ユーザー定義） | I6: （ユーザー定義） | J6: 文字列 | K6: 文字列 | L6: 数値 | N6: 文字列 | O6: 郵便番号 | P6: 数値 | Q6: 数値
C7: ※RUS固定 | I7: 必須 | J7: 必須
B8: =ROW() - 7 -> 1 | C8: RUS
B9: =ROW() - 7 -> 2 | C9: RUS
B10: =ROW() - 7 -> 3 | C10: RUS
B11: =ROW() - 7 -> 4 | C11: RUS
B12: =ROW() - 7 -> 5 | C12: RUS

Sheet 郵便番号-設定値
A1: 郵便番号-設定値 ※基本的には移行データを正とする（郵便番号インポート）
A2: ■凡例「必須：システム上必須」「必須(*)：システムで必須ではないが、トランザクション上や業務などで必須」
A3: パラメータ設定一覧へ
B4: # | C4: 郵便番号 | E4: ※都道府県以降、入力しているとトランザクション等の住所選択時に郵便番号を選択するだけで既定値として自動反映される
C5: 国/地域 | D5: 郵便番号 | E5: 都道府県 | F5: 市区郡 | G5: 市町村 | H5: 地区 | I5: 住所 | J5: 開始日 | K5: 終了 | L5: すべて/偶数/奇数 | M5: タイムゾーン
C6: （ユーザー定義） | D6: （ユーザー定義） | E6: （ユーザー定義） | F6: （ユーザー定義） | G6: （ユーザー定義） | H6: （ユーザー定義） | I6: 文字列 | J6: 数値 | K6: 数値
C7: 必須 | D7: 必須
B8: =ROW() - 7 -> 1
B9: =ROW() - 7 -> 2
B10: =ROW() - 7 -> 3

Sheet 単位
A1: 単位
B2: 組織管理＞設定＞単位＞単位
B3: Organization administration > Setup > Units > Units
A4: パラメータ設定一覧へ
B5: # | C5: タブ | D5: タブ説明 | E5: 項目分類 | F5: 項目 | G5: 項目説明 | H5: 設定可能値 | I5: デフォルト値 | J5: 備考 | K5: 設定値 | L5: 設定基準
B6: =ROW() - 5 -> 1 | C6: 概要 | E6: 単位 | F6: 単位 | H6: 文字列 | I6: ー | K6: 「単位-設定値」を参照
B7: =ROW() - 5 -> 2 | F7: 説明 | H7: 文字列 | I7: ー | K7: 「単位-設定値」を参照
B8: =ROW() - 5 -> 3 | C8: 一般 | E8: 割り当て | F8: 固定単位の割り当て | H8: はい/いいえ | I8: いいえ | K8: 「単位-設定値」を参照
B9: =ROW() - 5 -> 4 | F9: 固定単位 | H9: ・個 ・フィート ・インチ ・ヤード ・センチメートル ・メートル ・ミリメートル ･ガロン ･リットル ・オンス ・トロイオンス ・ポンド ・グラム ・キログラム ・ミリ秒 ・秒 ・分 ・時間 ・日数 ・週 ・月数 ・年 ・Metric tons | I9: 個 | J9: [固定単位の割り当て]を[はい]にすることで設定可能 | K9: 「単位-設定値」を参照
B10: =ROW() - 5 -> 5 | E10: 分類 | F10: 単位クラス | H10: ・数量 ・長さ ・面積 ・液体体積 ・乾燥体積 ・質量 ・時刻 ・金銭情報 ・温度 ・情報エントロピー ・輝度 ・速度 ・加速度 ・角度 ・立体角 ・強制適用 ・抑圧または機械的ストレス ・トルク ・エネルギー ・パワー ・角運動量 ・静電容量 ・密度 ・電流 ・磁場 ・磁束 ・電荷 ・双極子 ・電位差 ・電気抵抗 ・インダクタンス ・動粘性係数 ・動粘性率 ・放射能 ・未定義 | I10: 数量 | K10: 「単位-設定値」を参照
B11: =ROW() - 5 -> 6 | F11: 単位系 | H11: ・なし ・メートル法 ・米国の慣例的単位 | I11: なし | K11: 「単位-設定値」を参照
B12: =ROW() - 5 -> 7 | E12: ロール | F12: 基本分類 | H12: はい/いいえ | I12: いいえ | K12: 「単位-設定値」を参照
B13: =ROW() - 5 -> 8 | F13: システム単位 | H13: はい/いいえ | I13: いいえ | K13: 「単位-設定値」を参照
B14: =ROW() - 4 -> 10 | E14: 丸め | F14: 小数点以下の制度 | H14: 数値 | I14: 0 | K14: 「単位-設定値」を参照
B15: =ROW() - 4 -> 11 | E15: RUSSIAN CLASSIFIERS | F15: Code by OKEI | H15: 文字列 | I15: ー | K15: 「単位-設定値」を参照
B16: =ROW() - 4 -> 12 | C16: 電子請求書 | F16: SAT code | G16: External classification code | H16: 文字列（ユーザー定義） | I16: ー | K16: 「単位-設定値」を参照
B17: =ROW() - 4 -> 13 | F17: SAT customs unit of measure | G17: External classification code | H17: 文字列（ユーザー定義） | I17: ー | K17: 「単位-設定値」を参照

Sheet 単位-設定値
A1: 単位-設定値 ※基本的には移行データを正とする
A2: ■凡例「必須：システム上必須」「必須(*)：システムで必須ではないが、トランザクション上や業務などで必須」
A3: パラメータ設定一覧へ | G3: 変更不可
B4: # | C4: 概要 | E4: 一般 | M4: 電子請求書
C5: 単位 | E5: 割り当て | G5: 分類 | I5: ロール | J5: 追加 | K5: 丸め | L5: RUSSIAN CLASSIFIERS
C6: 単位 | D6: 説明 | E6: 固定単位の割り当て | F6: 固定単位 | G6: 単位クラス | H6: 単位系 | I6: 基本単位系 | J6: システム単位 | K6: 小数点以下の精度 | L6: Code by OKEI | M6: SAT code | N6: SAT customs unit of measure
C7: 文字列 | D7: 文字列 | E7: はい/いいえ | I7: はい/いいえ | J7: はい/いいえ | K7: 数値 | L7: 文字列 | M7: 文字列（ユーザー定義） | N7: 文字列（ユーザー定義）
C8: 必須
B9: =ROW() - 8 -> 1
B10: =ROW() - 8 -> 2
B11: =ROW() - 8 -> 3 | C11: ↓自動生成
B12: =ROW() - 8 -> 4 | C12: ㎏ | E12: いいえ | F12: 個 | G12: 質量 | H12: なし | I12: いいえ | J12: いいえ | K12: 0 | L12: ー | M12: ー | N12: ー
B13: =ROW() - 8 -> 5 | C13: m | E13: いいえ | F13: 個 | G13: 長さ | H13: なし | I13: いいえ | J13: いいえ | K13: 0 | L13: ー | M13: ー | N13: ー
B14: =ROW() - 8 -> 6 | C14: ㎡ | E14: いいえ | F14: 個 | G14: 面積 | H14: なし | I14: いいえ | J14: いいえ | K14: 0 | L14: ー | M14: ー | N14: ー
B15: =ROW() - 8 -> 7 | C15: ｾｯﾄ | E15: いいえ | F15: 個 | G15: 数量 | H15: なし | I15: いいえ | J15: いいえ | K15: 0 | L15: ー | M15: ー | N15: ー
B16: =ROW() - 8 -> 8 | C16: 個 | E16: いいえ | F16: 個 | G16: 数量 | H16: なし | I16: いいえ | J16: いいえ | K16: 0 | L16: ー | M16: ー | N16: ー
B17: =ROW() - 8 -> 9 | C17: 冊 | E17: いいえ | F17: 個 | G17: 数量 | H17: なし | I17: いいえ | J17: いいえ | K17: 0 | L17: ー | M17: ー | N17: ー
B18: =ROW() - 8 -> 10 | C18: 台 | E18: いいえ | F18: 個 | G18: 数量 | H18: なし | I18: いいえ | J18: いいえ | K18: 0 | L18: ー | M18: ー | N18: ー
B19: =ROW() - 8 -> 11 | C19: 巻 | E19: いいえ | F19: 個 | G19: 数量 | H19: なし | I19: いいえ | J19: いいえ | K19: 0 | L19: ー | M19: ー | N19: ー
B20: =ROW() - 8 -> 12 | C20: 式 | E20: いいえ | F20: 個 | G20: 数量 | H20: なし | I20: いいえ | J20: いいえ | K20: 0 | L20: ー | M20: ー | N20: ー
B21: =ROW() - 8 -> 13 | C21: 本 | E21: いいえ | F21: 個 | G21: 数量 | H21: なし | I21: いいえ | J21: いいえ | K21: 0 | L21: ー | M21: ー | N21: ー
B22: =ROW() - 8 -> 14 | C22: 枚 | E22: いいえ | F22: 個 | G22: 数量 | H22: なし | I22: いいえ | J22: いいえ | K22: 0 | L22: ー | M22: ー | N22: ー
B23: =ROW() - 8 -> 15 | C23: 箱 | E23: いいえ | F23: 個 | G23: 数量 | H23: なし | I23: いいえ | J23: いいえ | K23: 0 | L23: ー | M23: ー | N23: ー
... B26: =ROW() - 8 -> 18 | C26: 足 | E26: いいえ | F26: 個 | G26: 数量 | H26: なし | I26: いいえ | J26: いいえ | K26: 1 | L26: ー | M26: ー | N26: ー

Sheet 単位換算
A1: 単位換算
B2: 組織管理＞設定＞単位＞単位換算
B3: Organization administration > Setup > Units > Unit conversions
A4: パラメータ設定一覧へ
B5: # | C5: タブ | D5: タブ説明 | E5: 項目分類 | F5: 項目 | G5: 項目説明 | H5: 設定可能値 | I5: デフォルト値 | J5: 備考 | K5: 設定値 | L5: 設定基準
B6: =ROW() - 5 -> 1 | C6: 標準単位換算 | D6: すべての製品に対する標準変換ルールの設定 | F6: 定義 | H6: システム自動入力 | I6: ー | K6: 「標準換算-設定値」を参照
B7: =ROW() - 5 -> 2 | F7: （開始単位の数値） | H7: 数値（必ず1） | I7: 1 | K7: 「標準換算-設定値」を参照
B8: =ROW() - 5 -> 3 | F8: 開始単位 | H8: 単位（ユーザー定義） | I8: ー | K8: 「標準換算-設定値」を参照
F9: （終了単位の数値） | H9: 数値 | I9: 1.0000000000 | J9: 開始単位の数値１に対してどう換算するかを入力する | K9: 「標準換算-設定値」を参照
B10: =ROW() - 5 -> 5 | F10: 終了単位 | H10: 単位（ユーザー定義） | I10: ー | K10: 「標準換算-設定値」を参照
B11: =ROW() - 5 -> 6 | F11: 丸め | H11: ・四捨五入 ・切り上げ ・切り捨て | I11: 四捨五入 | K11: 「標準換算-設定値」を参照
B12: =ROW() - 5 -> 7 | F12: 式のレイアウト | H12: ・簡易 ・詳細 | I12: 簡易 | K12: 「標準換算-設定値」を参照
B13: =ROW() - 5 -> 8 | C13: クラス内換算 | D13: 同一単位クラス内の測定単位に対して製品固有の変換ルールを設定します | F13: 製品 | H13: 製品（ユーザー定義） | I13: ー | K13: 「クラス内換算-設定値」を参照
B14: =ROW() - 5 -> 9 | F14: 定義 | H14: システム自動入力 | I14: ー | K14: 「クラス内換算-設定値」を参照
B15: =ROW() - 5 -> 10 | F15: （開始単位の数値） | H15: 数値（必ず1） | I15: 1 | K15: 「クラス内換算-設定値」を参照
B16: =ROW() - 5 -> 11 | F16: 開始単位 | H16: 単位（ユーザー定義） | I16: ー | K16: 「クラス内換算-設定値」を参照
B17: =ROW() - 5 -> 12 | F17: （終了単位の数値） | H17: 数値 | I17: 1.0000000000 | J17: 開始単位の数値１に対してどう換算するかを入力する | K17: 「クラス内換算-設定値」を参照
B18: =ROW() - 5 -> 13 | F18: 終了単位 | H18: 単位（ユーザー定義） | I18: ー | K18: 「クラス内換算-設定値」を参照
B19: =ROW() - 5 -> 14 | F19: 丸め | H19: ・四捨五入 ・切り上げ ・切り捨て | I19: 四捨五入 | K19: 「クラス内換算-設定値」を参照
B20: =ROW() - 5 -> 15 | F20: 式のレイアウト | H20: ・簡易 ・詳細 | I20: 簡易 | K20: 「クラス内換算-設定値」を参照
B21: =ROW() - 5 -> 16 | C21: クラス間換算 | D21: 単位クラスが含む測定単位に対して製品固有の変換ルールを設定する | F21: 製品 | H21: 製品（ユーザー定義） | I21: ー | K21: 「クラス間換算-設定値」を参照
B22: =ROW() - 5 -> 17 | F22: 定義 | H22: システム自動入力 | I22: ー | K22: 「クラス間換算-設定値」を参照
B23: =ROW() - 5 -> 18 | F23: （開始単位の数値） | H23: 数値（必ず1） | I23: 1 | K23: 「クラス間換算-設定値」を参照
B24: =ROW() - 5 -> 19 | F24: 開始単位 | H24: 単位（ユーザー定義） | I24: ー | K24: 「クラス間換算-設定値」を参照
B25: =ROW() - 5 -> 20 | F25: （終了単位の数値） | H25: 数値 | I25: 1.0000000000 | J25: 開始単位の数値１に対してどう換算するかを入力する | K25: 「クラス間換算-設定値」を参照
B26: =ROW() - 5 -> 21 | F26: 終了単位 | H26: 単位（ユーザー定義） | I26: ー | K26: 「クラス間換算-設定値」を参照
B27: =ROW() - 5 -> 22 | F27: 終了単位 | H27: 単位（ユーザー定義） | I27: ー | K27: 「クラス間換算-設定値」を参照
B28: =ROW() - 5 -> 23 | F28: 式のレイアウト | H28: ・簡易 ・詳細 | I28: 簡易 | K28: 「クラス間換算-設定値」を参照

Sheet 標準換算-設定値
A1: 標準換算-設定値 ※基本的には移行データを正とする
A2: ■凡例「必須：システム上必須」「必須(*)：システムで必須ではないが、トランザクション上や業務などで必須」
A3: パラメータ設定一覧へ
B4: # | C4: 定義 | D4: （終了単位の数値） | E4: 開始単位 | F4: （終了単位の数値） | G4: 終了単位 | H4: 丸め | I4: 式のレイアウト
C5: （システム自動入力） | D5: 数値（必ず1） | E5: 単位（ユーザー定義） | F5: 数値 | G5: 単位（ユーザー定義） | H5: 四捨五入 切り上げ 切り捨て | I5: 簡易 詳細
C6: ※Excel上関数で反映 | D6: 必須 | E6: 必須 | F6: 必須 | G6: 必須 | H6: 必須 | I6: 必須
B7: 例 | C7: =D7&E7&"="&F7&G7 -> 1箱=12個 | D7: 1 | E7: 箱 | F7: 12 | G7: 個 | H7: 四捨五入 | I7: 簡易
B8: =ROW() - 7 -> 1 | C8: =D8&E8&"="&F8&G8 -> 1= | D8: 1
B9: =ROW() - 7 -> 2 | C9: =D9&E9&"="&F9&G9 -> 1= | D9: 1
B10: =ROW() - 7 -> 3 | C10: =D10&E10&"="&F10&G10 -> 1= | D10: 1
B11: =ROW() - 7 -> 4 | C11: =D11&E11&"="&F11&G11 -> 1= | D11: 1
B12: =ROW() - 7 -> 5 | C12: =D12&E12&"="&F12&G12 -> 1= | D12: 1
B13: =ROW() - 7 -> 6 | C13: =D13&E13&"="&F13&G13 -> 1= | D13: 1
B14: =ROW() - 7 -> 7 | C14: =D14&E14&"="&F14&G14 -> 1= | D14: 1
B15: =ROW() - 7 -> 8 | C15: =D15&E15&"="&F15&G15 -> 1= | D15: 1
B16: =ROW() - 7 -> 9 | C16: =D16&E16&"="&F16&G16 -> 1= | D16: 1
B17: =ROW() - 7 -> 10 | C17: =D17&E17&"="&F17&G17 -> 1= | D17: 1
B18: =ROW() - 7 -> 11 | C18: =D18&E18&"="&F18&G18 -> 1= | D18: 1
B19: =ROW() - 7 -> 12 | C19: =D19&E19&"="&F19&G19 -> 1= | D19: 1
... B27: =ROW() - 7 -> 20 | C27: =D27&E27&"="&F27&G27 -> 1= | D27: 1

Sheet クラス内換算-設定値
A1: クラス内換算-設定値 ※基本的には移行データを正とする
A2: ■凡例「必須：システム上必須」「必須(*)：システムで必須ではないが、トランザクション上や業務などで必須」
A3: パラメータ設定一覧へ
B4: # | C4: 製品 | D4: 定義 | E4: （開始単位の数値） | F4: 開始単位 | G4: （終了単位の数値） | H4: 終了単位 | I4: 式のレイアウト | J4: 丸め
C5: 製品（ユーザー定義） ※製品番号が入る | D5: （システム自動入力） | E5: 数値（必ず1） | F5: 単位（ユーザー定義） | G5: 数値 | H5: 単位（ユーザー定義） | I5: 簡易 詳細 | J5: 四捨五入 切り上げ 切り捨て
C6: 必須 | D6: ※Excel上関数で反映 | E6: 必須 | F6: 必須 | G6: 必須 | H6: 必須 | I6: 必須 | J6: 必須
B7: 例 | C7: TEST_Prod-001 | D7: =E7&F7&"="&G7&H7 -> 1箱=12個 | E7: 1 | F7: 箱 | G7: 12 | H7: 個 | I7: 簡易 | J7: 四捨五入
B8: =ROW() - 7 -> 1 | D8: =E8&F8&"="&G8&H8 -> 1= | E8: 1
B9: =ROW() - 7 -> 2 | D9: =E9&F9&"="&G9&H9 -> 1= | E9: 1
B10: =ROW() - 7 -> 3 | D10: =E10&F10&"="&G10&H10 -> 1= | E10: 1
B11: =ROW() - 7 -> 4 | D11: =E11&F11&"="&G11&H11 -> 1= | E11: 1
B12: =ROW() - 7 -> 5 | D12: =E12&F12&"="&G12&H12 -> 1= | E12: 1
B13: =ROW() - 7 -> 6 | D13: =E13&F13&"="&G13&H13 -> 1= | E13: 1
B14: =ROW() - 7 -> 7 | D14: =E14&F14&"="&G14&H14 -> 1= | E14: 1
B15: =ROW() - 7 -> 8 | D15: =E15&F15&"="&G15&H15 -> 1= | E15: 1
B16: =ROW() - 7 -> 9 | D16: =E16&F16&"="&G16&H16 -> 1= | E16: 1
B17: =ROW() - 7 -> 10 | D17: =E17&F17&"="&G17&H17 -> 1= | E17: 1
B18: =ROW() - 7 -> 11 | D18: =E18&F18&"="&G18&H18 -> 1= | E18: 1
B19: =ROW() - 7 -> 12 | D19: =E19&F19&"="&G19&H19 -> 1= | E19: 1
... B27: =ROW() - 7 -> 20 | D27: =E27&F27&"="&G27&H27 -> 1= | E27: 1

Sheet クラス間換算-設定値
A1: クラス間換算-設定値 ※基本的には移行データを正とする
A2: ■凡例「必須：システム上必須」「必須(*)：システムで必須ではないが、トランザクション上や業務などで必須」
A3: パラメータ設定一覧へ
B4: # | C4: 製品 | D4: 定義 | E4: （開始単位の数値） | F4: 開始単位 | G4: （終了単位の数値） | H4: 終了単位 | I4: 式のレイアウト | J4: 丸め
C5: 製品（ユーザー定義） ※製品番号が入る | D5: （システム自動入力） | E5: 数値（必ず1） | F5: 単位（ユーザー定義） | G5: 数値 | H5: 単位（ユーザー定義） | I5: 簡易 詳細 | J5: 四捨五入 切り上げ 切り捨て
C6: 必須 | D6: ※Excel上関数で反映 | E6: 必須 | F6: 必須 | G6: 必須 | H6: 必須 | I6: 必須 | J6: 必須
B7: 例 | C7: TEST_Prod-001 | D7: =E7&F7&"="&G7&H7 -> 1箱=12個 | E7: 1 | F7: 箱 | G7: 12 | H7: 個 | I7: 簡易 | J7: 四捨五入
B8: =ROW() - 7 -> 1 | D8: =E8&F8&"="&G8&H8 -> 1= | E8: 1
B9: =ROW() - 7 -> 2 | D9: =E9&F9&"="&G9&H9 -> 1= | E9: 1
B10: =ROW() - 7 -> 3 | D10: =E10&F10&"="&G10&H10 -> 1= | E10: 1
B11: =ROW() - 7 -> 4 | D11: =E11&F11&"="&G11&H11 -> 1= | E11: 1
B12: =ROW() - 7 -> 5 | D12: =E12&F12&"="&G12&H12 -> 1= | E12: 1
B13: =ROW() - 7 -> 6 | D13: =E13&F13&"="&G13&H13 -> 1= | E13: 1
B14: =ROW() - 7 -> 7 | D14: =E14&F14&"="&G14&H14 -> 1= | E14: 1
B15: =ROW() - 7 -> 8 | D15: =E15&F15&"="&G15&H15 -> 1= | E15: 1
B16: =ROW() - 7 -> 9 | D16: =E16&F16&"="&G16&H16 -> 1= | E16: 1
B17: =ROW() - 7 -> 10 | D17: =E17&F17&"="&G17&H17 -> 1= | E17: 1
B18: =ROW() - 7 -> 11 | D18: =E18&F18&"="&G18&H18 -> 1= | E18: 1
B19: =ROW() - 7 -> 12 | D19: =E19&F19&"="&G19&H19 -> 1= | E19: 1
... B27: =ROW() - 7 -> 20 | D27: =E27&F27&"="&G27&H27 -> 1= | E27: 1

Sheet ユーザーをロールに割り当てる
A1: ユーザーをロールに割り当てる
B2: システム管理＞セキュリティ＞ユーザーをロールに割り当てる
B3: System administration > Security > Assign users to roles
A4: パラメータ設定一覧へ
B5: # | C5: タブ | D5: タブ説明 | E5: 項目分類 | F5: 項目 | G5: 項目説明 | H5: 設定可能値 | I5: デフォルト値 | J5: 備考 | K5: 設定値 | L5: 設定基準
B6: =ROW() - 5 -> 1 | C6: ユーザーをロールに割り当てる | D6: ロールへのユーザーの動的割り当てルール | F6: メンバーシップ ルール名 | G6: 自動ロールメンバーシップルールの名前 | I6: ー | K6: 「ロールへのユーザーの動的割り当てのルール-設定値」を参照
B7: =ROW() - 5 -> 2 | F7: メンバーシップ ルールの説明 | G7: 自動ロールメンバーシップルールの説明 | I7: ー | K7: 「ロールへのユーザーの動的割り当てのルール-設定値」を参照
B8: =ROW() - 5 -> 3 | F8: クエリプレビュー | G8: ロール自動割り当てルールの基準として使用されるクエリを表示します。 | I8: ー | K8: 「ロールへのユーザーの動的割り当てのルール-設定値」を参照
B9: =ROW() - 5 -> 4 | D9: ロールに割り当てられたユーザー | F9: ID | G9: ユーザーID | I9: ー | K9: ユーザー側の設定に準ずる
B10: =ROW() - 5 -> 5 | F10: ユーザー名 | G10: 名前 | I10: ー | K10: ユーザー側の設定に準ずる
B11: =ROW() - 5 -> 6 | F11: エイリアス | I11: ー | K11: ユーザー側の設定に準ずる
B12: =ROW() - 5 -> 7 | F12: 割り当てモード | I12: ー | K12: ユーザー側の設定に準ずる

Sheet ロールへのユーザーの動的割り当てのルール-設定値
A1: ロールへのユーザーの動的割り当てのルール-設定値 ※基本的には移行データを正とする
A2: ■凡例「必須：システム上必須」「必須(*)：システムで必須ではないが、トランザクション上や業務などで必須」
A3: パラメータ設定一覧へ
B4: # | C4: ロール名 | D4: メンバーシップ ルール名 | E4: メンバーシップ ルールの説明 | F4: クエリプレビュー
C5: （システム自動入力） | D5: （システム自動入力） | E5: 単位（ユーザー定義） | F5: 単位（ユーザー定義）
B6: =ROW() - 5 -> 1
B7: =ROW() - 5 -> 2
B8: =ROW() - 5 -> 3
B9: =ROW() - 5 -> 4
B10: =ROW() - 5 -> 5
B11: =ROW() - 5 -> 6
B12: =ROW() - 5 -> 7
B13: =ROW() - 5 -> 8
B14: =ROW() - 5 -> 9
B15: =ROW() - 5 -> 10
B16: =ROW() - 5 -> 11
B17: =ROW() - 5 -> 12
... B23: =ROW() - 5 -> 18

Sheet ユーザーIDへの作業者の割当
A1: ユーザーIDへの作業者の割当
B2: システム管理＞ユーザー＞ユーザー
B3: System administration > Users > Users
A4: パラメータ設定一覧へ
B5: # | C5: タブ | D5: タブ説明 | E5: 項目分類 | F5: 項目 | G5: 項目説明 | H5: 設定可能値 | I5: デフォルト値 | J5: 備考 | K5: 設定値 | L5: 設定基準
B6: =ROW() - 5 -> 1 | C6: ユーザー | D6: ユーザーの詳細 | F6: ユーザーID | G6: ユーザーID | H6: AADとの連携が必要 | I6: ー | K6: 「ユーザーIDへの作業者の割当-設定値」を参照
B7: =ROW() - 5 -> 2 | F7: ユーザー名 | G7: 名前 | H7: AADとの連携が必要 | I7: ー | K7: 「ユーザーIDへの作業者の割当-設定値」を参照
B8: =ROW() - 5 -> 3 | F8: プロバイダー | I8: ー | K8: 「ユーザーIDへの作業者の割当-設定値」を参照
B9: =ROW() - 5 -> 4 | F9: 電子メール | G9: ユーザーの電子メールアドレス | H9: AADとの連携が必要 | I9: ー | K9: 「ユーザーIDへの作業者の割当-設定値」を参照
B10: =ROW() - 5 -> 5 | F10: テレメトリID | I10: ー | K10: 「ユーザーIDへの作業者の割当-設定値」を参照
B11: =ROW() - 5 -> 6 | F11: 会社 | G11: 選択可能な会社ID（ログイン時のデフォルトの会社ID） | I11: ー | K11: 「ユーザーIDへの作業者の割当-設定値」を参照
B12: =ROW() - 5 -> 7 | F12: 個人 | G12: 従業員（作業者）の割り当て | I12: ー | K12: 「ユーザーIDへの作業者の割当-設定値」を参照
B13: =ROW() - 5 -> 8 | F13: 有効 | G13: FOユーザーとしての有効/無効 | I13: ー | K13: 「ユーザーIDへの作業者の割当-設定値」を参照
B14: =ROW() - 5 -> 9 | D14: ユーザーのロール | F14: ロール | G14: ユーザーに対しての割り当てロール | I14: ー | K14: ユーザー側の設定に準ずる

Sheet ユーザーIDへの作業者の割当-設定値
A1: ユーザーIDへの作業者の割当-設定値 ※基本的には移行データを正とする
A2: ■凡例「必須：システム上必須」「必須(*)：システムで必須ではないが、トランザクション上や業務などで必須」
A3: パラメータ設定一覧へ
B4: # | C4: ユーザーID | D4: ユーザー名 | E4: プロバイダー | F4: 電子メール | G4: テレメトリID | H4: 会社 | I4: 個人 | J4: 有効 | K4: ロール
C5: AADとの連携が必要 ※ユーザーインポート実施時はシステム自動入力 | D5: AADとの連携が必要 ※ユーザーインポート実施時はシステム自動入力 | F5: 単位（ユーザー定義） | G5: （システム自動入力） | H5: ログイン時のデフォルトの会社IDを選択 | I5: 従業員（作業者）マスタから選択 | J5: はい/いいえ | K5: 必要ロールを複数設定
C6: 必須 | D6: 必須 | F6: 必須 | H6: 必須(*) | I6: 必須(*) | J6: 必須 | K6: 必須(*)
B7: 例 | C7: jbsuser001 | D7: JBS User001 | E7: https://sts.windows.net/jbs.com/ | H7: JPMF | J7: はい | K7: システムユーザー システム管理者
B8: =ROW() - 7 -> 1
B9: =ROW() - 7 -> 2
B10: =ROW() - 7 -> 3
B11: =ROW() - 7 -> 4
B12: =ROW() - 7 -> 5
B13: =ROW() - 7 -> 6
B14: =ROW() - 7 -> 7
B15: =ROW() - 7 -> 8
B16: =ROW() - 7 -> 9
B17: =ROW() - 7 -> 10
B18: =ROW() - 7 -> 11
B19: =ROW() - 7 -> 12
... B27: =ROW() - 7 -> 20

Sheet ユーザーグループ
A1: ユーザーグループ ※基本的には移行データを正とする
B2: システム管理＞ユーザー＞ユーザーグループ
B3: System administration > User > User Group
A4: パラメータ設定一覧へ
B5: # | C5: タブ | D5: タブ説明 | E5: 項目分類 | F5: 項目 | G5: Description（標準） | H5: 設定可能値 | I5: デフォルト値 | J5: 備考 | K5: 設定値 | L5: 設定基準
B6: =ROW() - 5 -> 1 | C6: グループ | F6: グループ | H6: 文字列 | I6: - | K6: 「ユーザーグループ-設定値」を参照
B7: =ROW() - 5 -> 2 | F7: ユーザーグループ名 | H7: 文字列 | I7: - | K7: 「ユーザーグループ-設定値」を参照
B8: =ROW() - 5 -> 3 | C8: ユーザー | F8: 選択したユーザー | H8: ユーザー（ユーザー定義） | I8: - | K8: 「ユーザーグループ-設定値」を参照

Sheet ユーザーグループ-設定値
A1: ユーザーグループ-設定値 ※基本的には移行データを正とする
A2: ■凡例「必須：システム上必須」「必須(*)：システムで必須ではないが、トランザクション上や業務などで必須」
A3: パラメータ設定一覧へ
B4: # | C4: グループ | E4: ユーザー
C5: グループ | D5: ユーザーグループ名 | E5: 選択したユーザー
C6: 文字列 | D6: 文字列 | E6: ユーザー（ユーザー定義）
C7: 必須(*) | D7: 必須(*)
B8: 例 | C8: ワークフロー承認者 | D8: ワークフロー承認者用グループ | E8: jbsuser001
E9: jbsuser002
B10: 1
B14: 2
B18: 3
B22: 4
B26: 5

Sheet 通貨の為替レート
A1: 通貨の為替レート
B2: 一般会計＞通貨＞通貨の為替レート
B3: General ledger > Currencies > Currency exchange rates
A4: パラメータ設定一覧へ
B5: # | C5: タブ | D5: タブ説明 | E5: 項目分類 | F5: 項目 | G5: 項目説明 | H5: 設定可能値 | I5: デフォルト値 | J5: 備考 | K5: 設定値 | L5: 設定基準
B6: =ROW() - 5 -> 1 | C6: 通貨の為替レート | F6: 為替レートタイプ | G6: 通貨の為替レートは為替レートの種類を選択します。 | H6: ・予算 ・平均 ・既定 ・終了 | I6: 既定 | J6: 為替レートタイプ（システム定義） ・予算：既定の予算レート ・平均：既定の平均レート ・既定：既定のグローバルレート ・終了：既定の終了レート | K6: 「通貨の為替レート-設定値」を参照
B7: =ROW() - 5 -> 2 | F7: 交換前通貨 | G7: 変換する通貨を選択します。 | H7: 通貨（ユーザー定義） | I7: ー | K7: 「通貨の為替レート-設定値」を参照
B8: =ROW() - 5 -> 3 | F8: 交換後通貨 | G8: 変換する通貨を選択します | H8: 通貨（ユーザー定義） | I8: ー | K8: 「通貨の為替レート-設定値」を参照
B9: =ROW() - 5 -> 4 | F9: 変換係数 | G9: 為替レートのベースとなる他の通貨の単位数を選択します。値は、会計通貨として選択される通貨の通常の規則によって異なります。 | H9: ・1 ・10 ・100 ・1000 ・10000 | I9: 1 | K9: 「通貨の為替レート-設定値」を参照
B10: =ROW() - 5 -> 5 | C10: 為替レートの追加または削除 | F10: 開始日 | G10: 開始日を選択して、グリッドに為替レートを表示します。 | H10: 年月日(yyyy/MM/dd) | I10: 作業日に応じて入る | J10: 参照時のための日付切り替えの機能 | K10: 「通貨の為替レート-設定値」を参照
B11: =ROW() - 5 -> 6 | F11: 終了日 | G11: 終了日を選択して、為替レートをグリッドに表示します。 | H11: 年月日(yyyy/MM/dd) | I11: 作業日に応じて入る | J11: 参照時のための日付切り替えの機能 | K11: 「通貨の為替レート-設定値」を参照
B12: =ROW() - 5 -> 7 | F12: 開始日 | G12: このレコードの有効開始日。 | H12: 年月日(yyyy/MM/dd) | I12: ー | K12: 「通貨の為替レート-設定値」を参照
B13: =ROW() - 5 -> 8 | F13: 為替レート | G13: 現在の為替レートが有効な開始日を選択します。 | H13: 数値 | I13: ー | K13: 「通貨の為替レート-設定値」を参照
B14: =ROW() - 5 -> 9 | F14: 交換価値 | G14: 開始通貨と終了通貨フィールドに表示される通貨の為替レートを入力します。 | H14: システム入力（交換前通貨、交換後通貨、変換係数、為替レートを入力すると自動で反映される） | I14: ー | J14: 例： 交換前通貨：USD 交換後通貨：JPY 変換係数：1 為替レート：109.6100 交換価値：109.61 JPY (1 USD) | K14: 「通貨の為替レート-設定値」を参照

Sheet 通貨の為替レート-設定値
A1: 通貨の為替レート-設定値 ※基本的には移行データを正とする
A2: ■凡例「必須：システム上必須」「必須(*)：システムで必須ではないが、トランザクション上や業務などで必須」
A3: パラメータ設定一覧へ
B4: # | C4: 通貨の為替レート | G4: 為替レートの追加または削除
C5: 為替レートタイプ | D5: 交換前通貨 | E5: 交換後通貨 | F5: 変換係数 | G5: 開始日 | H5: 為替レート | I5: 交換価値
C6: 予算 平均 既定 終了 | D6: 通貨（ユーザー定義） | E6: 通貨（ユーザー定義） | G6: 年月日(yyyy/MM/dd) | H6: 数値 | I6: システム入力（交換前通貨、交換後通貨、変換係数、為替レートを入力すると自動で反映される）
C7: 必須 | D7: 必須 | G7: 必須(*) | H7: 必須 | I7: ※Excel上関数で反映
B8: 例 | C8: 既定 | D8: JPY | E8: USD | F8: 100 | G8: 45017 | H8: 1 | I8: =H8&E8&"（"&D8&F8&"）" -> 1USD（JPY100）
B9: =ROW() - 8 -> 1 | I9: =H9&E9&"（"&D9&F9&"）" -> （）
B10: =ROW() - 8 -> 2 | I10: =H10&E10&"（"&D10&F10&"）" -> （）
B11: =ROW() - 8 -> 3 | I11: =H11&E11&"（"&D11&F11&"）" -> （）
B12: =ROW() - 8 -> 4 | I12: =H12&E12&"（"&D12&F12&"）" -> （）
B13: =ROW() - 8 -> 5 | I13: =H13&E13&"（"&D13&F13&"）" -> （）
B14: =ROW() - 8 -> 6 | I14: =H14&E14&"（"&D14&F14&"）" -> （）
B15: =ROW() - 8 -> 7 | I15: =H15&E15&"（"&D15&F15&"）" -> （）
B16: =ROW() - 8 -> 8 | I16: =H16&E16&"（"&D16&F16&"）" -> （）
B17: =ROW() - 8 -> 9 | I17: =H17&E17&"（"&D17&F17&"）" -> （）
B18: =ROW() - 8 -> 10 | I18: =H18&E18&"（"&D18&F18&"）" -> （）

Sheet 顧客の価格割引グループ
A1: 顧客の価格/割引グループ
B2: 販売とマーケティング ＞ 価格と割引 > 顧客の価格/割引グループ
B3: Sales and marketing > Prices and discounts > Customer price/discount groups
A4: パラメータ設定一覧へ
B5: # | C5: タブ | D5: タブ説明 | E5: 項目分類 | F5: 項目 | G5: Description（標準） | H5: 設定可能値 | I5: デフォルト値 | J5: 備考 | K5: 設定値 | L5: 設定基準
B6: =ROW() - 5 -> 1 | C6: 顧客の価格/割引グループ | F6: 価格グループ | H6: 文字列 | I6: ー | K6: シート「顧客の価格割引グループ-設定値」を参照
B7: =ROW() - 5 -> 2 | F7: 名前 | H7: 文字列 | I7: ー | K7: シート「顧客の価格割引グループ-設定値」を参照
B8: =ROW() - 5 -> 3 | F8: 価格/割引グループ タイプ | H8: 価格グループ 行割引グループ 複数行割引グループ 割引合計グループ | I8: 価格グループ | K8: シート「顧客の価格割引グループ-設定値」を参照

Sheet 顧客の価格割引グループ-設定値
A1: 顧客の価格/割引グループ-設定値 ※基本的には移行データを正とする
A2: ■凡例「必須：システム上必須」「必須(*)：システムで必須ではないが、トランザクション上や業務などで必須」
A3: パラメータ設定一覧へ
B4: # | C4: 顧客の価格/割引グループ
C5: 割引グループ | D5: 名前 | E5: 価格/割引グループ タイプ
C6: 文字列 | D6: 文字列 | E6: 価格グループ 行割引グループ 複数行割引グループ 割引合計グループ
C7: 必須 | E7: 必須
B8: =ROW() - 7 -> 1
B9: =ROW() - 7 -> 2
B10: =ROW() - 7 -> 3
B11: =ROW() - 7 -> 4
B12: =ROW() - 7 -> 5
B13: =ROW() - 7 -> 6
B14: =ROW() - 7 -> 7

Sheet 売買契約仕訳帳名（販売）
A1: 売買契約仕訳帳名（販売）
B2: 販売とマーケティング ＞ 設定 > 価格と割引 ＞ 売買契約仕訳帳名
B3: Sales and marketing> Setup > Prices and discounts > Trade agreement journal names
A4: パラメータ設定一覧へ
B5: # | C5: タブ | D5: タブ説明 | E5: 項目分類 | F5: 項目 | G5: Description（標準） | H5: 設定可能値 | I5: デフォルト値 | J5: 備考 | K5: 設定値 | L5: 設定基準
B6: =ROW() - 5 -> 1 | C6: 売買契約仕訳帳名 | F6: 名前 | H6: 文字列 | I6: ー | K6: シート「売買契約仕訳帳名-設定値」を参照
B7: =ROW() - 5 -> 2 | F7: 説明 | H7: 文字列 | I7: ー | K7: シート「売買契約仕訳帳名-設定値」を参照
B8: =ROW() - 5 -> 3 | F8: 関係 | H8: 価格（購買） 行割引（仕入） 複数行割引（仕入） 割引合計（購買） 価格（販売） 行割引（販売側） 複数行割引（販売側） 割引合計（販売） 送料の割引 | I8: ー | K8: シート「売買契約仕訳帳名-設定値」を参照

Sheet 売買契約仕訳帳名-設定値（販売）
A1: 売買契約仕訳帳名（販売）-設定値
A2: ■凡例「必須：システム上必須」「必須(*)：システムで必須ではないが、トランザクション上や業務などで必須」
A3: パラメータ設定一覧へ
B4: # | C4: 売買契約仕訳帳名
C5: 名前 | D5: 説明 | E5: 関係
C6: 文字列 | D6: 文字列 | E6: 価格（購買） 行割引（仕入） 複数行割引（仕入） 割引合計（購買） 価格（販売） 行割引（販売側） 複数行割引（販売側） 割引合計（販売） 送料の割引
C7: 必須 | E7: 必須
B8: =ROW() - 7 -> 1
B9: =ROW() - 7 -> 2
B10: =ROW() - 7 -> 3
B11: =ROW() - 7 -> 4
B12: =ROW() - 7 -> 5
B13: =ROW() - 7 -> 6
B14: =ROW() - 7 -> 7

Sheet 売買契約仕訳帳（販売）
A1: 売買契約仕訳帳（販売）
B2: 販売とマーケティング ＞ 価格と割引 ＞ 売買契約仕訳帳名
B3: Sales and marketing> Prices and discounts > Trade agreement journal name
A4: パラメータ設定一覧へ
B5: # | C5: タブ | D5: タブ説明 | E5: 項目分類 | F5: 項目 | G5: Description（標準） | H5: 設定可能値 | I5: デフォルト値 | J5: 備考 | K5: 設定値 | L5: 設定基準
B6: =ROW() - 5 -> 1 | C6: 売買契約仕訳帳 | F6: 名前 | H6: 売買仕訳帳名（ユーザー定義） | I6: ー | K6: シート「売買契約仕訳帳-設定値（販売）」を参照
B7: =ROW() - 5 -> 2 | F7: 価格/割引仕訳帳番号 | H7: 自動採番 | I7: ー | J7: 番号順序の設定に準拠する | K7: シート「売買契約仕訳帳-設定値（販売）」を参照
B8: =ROW() - 5 -> 3 | F8: 説明 | H8: 文字列 | I8: ー | K8: シート「売買契約仕訳帳-設定値（販売）」を参照
B9: =ROW() - 5 -> 4 | F9: 転記済 | H9: チェック/チェック無 | I9: ー | J9: 転記したら自動で入る | K9: シート「売買契約仕訳帳-設定値（販売）」を参照
B10: =ROW() - 5 -> 5 | F10: 転記日 | H10: 日付 | I10: ー | J10: 転記したら自動で入る | K10: シート「売買契約仕訳帳-設定値（販売）」を参照
B11: =ROW() - 5 -> 6 | F11: 既定のリレーション | H11: 価格（購買） 行割引（仕入） 複数行割引（仕入） 割引合計（購買） 価格（販売） 行割引（販売側） 複数行割引（販売側） 割引合計（販売） 送料の割引 | I11: 「名前」で売買契約仕訳帳名を選択したら既定値が自動反映される | K11: シート「売買契約仕訳帳-設定値（販売）」を参照
B12: =ROW() - 5 -> 7 | F12: 現在の価格のエクスポート | H12: チェック/チェック無 | I12: チェック無 | K12: シート「売買契約仕訳帳-設定値（販売）」を参照
B13: =ROW() - 5 -> 8 | C13: 仕訳帳明細行 | E13: 概要 | F13: 変更済 | H13: （自動） | I13: ー | J13: 明細の変更によって自動で反映される | K13: シート「売買契約仕訳帳-設定値（販売）」を参照
B14: =ROW() - 5 -> 9 | F14: 関係 | G14: 購買および販売ドキュメントは売買契約を使用し、タイプに応じて価格または割引を適用します。特定の品目、特定の品目グループ、またはすべての品目に対して価格または割引を設定するために、売買契約の仕訳帳明細行を構成することができます。 | H14: 価格（購買） 行割引（仕入） 複数行割引（仕入） 割引合計（購買） 価格（販売） 行割引（販売側） 複数行割引（販売側） 割引合計（販売） 送料の割引 | I14: 「名前」で売買契約仕訳帳名を選択したら既定値が自動反映される | K14: シート「売買契約仕訳帳-設定値（販売）」を参照
B15: =ROW() - 5 -> 10 | F15: 関係者コードタイプ | H15: テーブル グループ すべて | I15: すべて | J15: テーブル：顧客個別に価格を設定する場合に選択 グループ：価格/割引グループ別に価格を設定する場合に選択 すべて：すべての顧客に対して価格を設定する場合に選択 | K15: シート「売買契約仕訳帳-設定値（販売）」を参照
B16: =ROW() - 5 -> 11 | F16: 勘定の選択 | H16: テーブル：顧客（ユーザー定義） グループ：価格/割引グループ（ユーザー定義） すべて：選択不可 | I16: ー | J16: 「関係者コードタイプ」で選択した値によって、価格の設定をする対象を選択 | K16: シート「売買契約仕訳帳-設定値（販売）」を参照
B17: =ROW() - 5 -> 12 | F17: 製品コードタイプ | H17: テーブル グループ すべて | I17: テーブル | J17: テーブル：製品個別に価格を設定する場合に選択 グループ：価格/割引グループ別に価格を設定する場合に選択 すべて：すべての製品に対して価格を設定する場合に選択 | K17: シート「売買契約仕訳帳-設定値（販売）」を参照
B18: =ROW() - 5 -> 13 | F18: 品目関係 | H18: テーブル：製品（ユーザー定義） グループ：価格/割引グループ（ユーザー定義） すべて：選択不可 | I18: ー | J18: 「製品コードタイプ」で選択した値によって、価格の設定をする対象を選択 | K18: シート「売買契約仕訳帳-設定値（販売）」を参照
B19: =ROW() - 5 -> 14 | F19: コンフィギュレーション | G19: [品目コード] フィールドで選択したタイプの品目またはタイプ グループを選択します。 | H19: （製品マスタから反映） | I19: ー | K19: シート「売買契約仕訳帳-設定値（販売）」を参照
B20: =ROW() - 5 -> 15 | F20: サイズ | H20: （製品マスタから反映） | I20: ー | K20: シート「売買契約仕訳帳-設定値（販売）」を参照
B21: =ROW() - 5 -> 16 | F21: 色 | H21: （製品マスタから反映） | I21: ー | K21: シート「売買契約仕訳帳-設定値（販売）」を参照
B22: =ROW() - 5 -> 17 | F22: スタイル | H22: （製品マスタから反映） | I22: ー | K22: シート「売買契約仕訳帳-設定値（販売）」を参照
B23: =ROW() - 5 -> 18 | F23: サイト | H23: サイト（ユーザー定義） | I23: ー | K23: シート「売買契約仕訳帳-設定値（販売）」を参照
B24: =ROW() - 5 -> 19 | F24: 倉庫 | H24: 倉庫（ユーザー定義） | I24: ー | K24: シート「売買契約仕訳帳-設定値（販売）」を参照
B25: =ROW() - 5 -> 20 | F25: 開始数量 | G25: 価格、ライン割引、マルチライン割引が適用される最小数量を入力します。 (ここに入力した数値を含みます。例: この数量が 1 に設定されている場合は、数量が 1 を含むこの値以上の場合に、この契約が適用されます) 。 この値はまた、割引合計のオーダー残高の最小値です。 | H25: 数値 | I25: 0.00 | K25: シート「売買契約仕訳帳-設定値（販売）」を参照
B26: =ROW() - 5 -> 21 | F26: 終了数量 | G26: 価格、ライン割引、マルチライン割引が適用される最大数量を入力します。 (ここに入力した数値は含まれません。例: この数量が 3.00 に設定されている場合は、2.99 までの契約が適用されます)。 この値はまた、割引合計のオーダー残高の上限値です。 | H26: 数値 | I26: ー | K26: シート「売買契約仕訳帳-設定値（販売）」を参照
B27: =ROW() - 5 -> 22 | F27: 単位 | H27: 単位（ユーザー定義） | K27: シート「売買契約仕訳帳-設定値（販売）」を参照
B28: =ROW() - 5 -> 23 | F28: 通貨金額 | H28: 数値 | I28: 0.00 | K28: シート「売買契約仕訳帳-設定値（販売）」を参照
B29: =ROW() - 5 -> 24 | F29: 通貨 | H29: 通貨（ユーザー定義） | J29: ここに設定したい価格を入力する | K29: シート「売買契約仕訳帳-設定値（販売）」を参照
B30: =ROW() - 5 -> 25 | F30: 均一層の金額 | H30: 数値 | I30: 0.00 | K30: シート「売買契約仕訳帳-設定値（販売）」を参照
B31: =ROW() - 5 -> 26 | F31: 属性ベースの価格決定ID | H31: 属性ベースの価格決定データ（ユーザー定義） | I31: ー | K31: シート「売買契約仕訳帳-設定値（販売）」を参照
B32: =ROW() - 5 -> 27 | F32: 分析コードの検証 | H32: （自動） | I32: ー | J32: 検証実施により自動で値が入る | K32: シート「売買契約仕訳帳-設定値（販売）」を参照
B33: =ROW() - 5 -> 28 | F33: 売買契約検証 | H33: （自動） | I33: ー | J33: 検証実施により自動で値が入る | K33: シート「売買契約仕訳帳-設定値（販売）」を参照
B34: =ROW() - 5 -> 29 | E34: 詳細 | F34: 開始日 | H34: 日付 | I34: ー | J34: 価格を使用する開始日を入力する | K34: シート「売買契約仕訳帳-設定値（販売）」を参照
B35: =ROW() - 5 -> 30 | F35: 終了日 | H35: 日付 | I35: ー | J35: 価格を使用する終了日を入力する | K35: シート「売買契約仕訳帳-設定値（販売）」を参照
B36: =ROW() - 5 -> 31 | F36: 諸費用価格 | G36: 価格の固定。これらの請求は請求書ごとに１回、適用されます。 | H36: 数値 | I36: 0.00 | K36: シート「売買契約仕訳帳-設定値（販売）」を参照
B37: =ROW() - 5 -> 32 | F37: 価格単位 | H37: 数値 | I37: 1.00 | K37: シート「売買契約仕訳帳-設定値（販売）」を参照
B38: =ROW() - 5 -> 33 | F38: 割引率１ | G38: 割引率１と割引率２の合計：総額 - パーセンテージ 1% - パーセンテージ 2% | H38: 数値 | I38: 0.00 | K38: シート「売買契約仕訳帳-設定値（販売）」を参照
B39: =ROW() - 5 -> 34 | F39: 割引率２ | G39: 割引率１と割引率２の合計：総額 - パーセンテージ 1% - パーセンテージ 2% | H39: 数値 | I39: 0.00 | K39: シート「売買契約仕訳帳-設定値（販売）」を参照
B40: =ROW() - 5 -> 35 | F40: リードタイム | G40: 日単位のリードタイム | H40: 数値 | I40: 0 | K40: シート「売買契約仕訳帳-設定値（販売）」を参照
...

Sheet 売買契約仕訳帳-設定値（販売）
A1: 売買契約仕訳帳（販売）-設定値 ※基本的には移行データを正とする
A2: ■凡例「必須：システム上必須」「必須(*)：システムで必須ではないが、トランザクション上や業務などで必須」
A3: パラメータ設定一覧へ
B4: # | C4: 売買契約仕訳帳 | J4: 仕訳帳明細行
J5: 概要 | AE5: 詳細 | AP5: エラーログ
C6: 名前 | D6: 価格/割引仕訳帳番号 | E6: 説明 | F6: 転記済 | G6: 転記日 | H6: 既定のリレーション | I6: 現在の価格のエクスポート | J6: 変更済 | K6: 関係 | L6: 関係者コードタイプ | M6: 勘定の選択 | N6: 製品コードタイプ | O6: 品目関係 | P6: コンフィギュレーション | Q6: サイズ | R6: 色 | S6: スタイル | T6: サイト | U6: 倉庫 | V6: 開始数量 | W6: 終了数量 | X6: 単位 | Y6: 通貨金額 | Z6: 通貨 | AA6: 均一層の金額 | AB6: 属性ベースの価格決定ID | AC6: 分析コードの検証 | AD6: 売買契約検証 | AE6: 開始日 | AF6: 終了日 | AG6: 諸費用価格 | AH6: 価格単位 | AI6: 割引率１ | AJ6: 割引率２ | AK6: リードタイム | AL6: 作業日 | AM6: リードタイムの無視 | AN6: 一般通貨を含めます | AO6: 次を検索 | AP6: ログ
C7: 売買仕訳帳名（ユーザー定義） | D7: 自動採番 | E7: 文字列 | F7: チェック/チェック無 | G7: 日付 | H7: 価格（購買） 行割引（仕入） 複数行割引（仕入） 割引合計（購買） 価格（販売） 行割引（販売側） 複数行割引（販売側） 割引合計（販売） 送料の割引 | I7: チェック/チェック無 | J7: （自動） | K7: 価格（購買） 行割引（仕入） 複数行割引（仕入） 割引合計（購買） 価格（販売） 行割引（販売側） 複数行割引（販売側） 割引合計（販売） 送料の割引 | L7: テーブル グループ すべて | M7: テーブル：顧客（ユーザー定義） グループ：価格/割引グループ（ユーザー定義） すべて：選択不可 | N7: テーブル グループ すべて | O7: テーブル：製品（ユーザー定義） グループ：価格/割引グループ（ユーザー定義） すべて：選択不可 | P7: （製品マスタから反映） | Q7: （製品マスタから反映） | R7: （製品マスタから反映） | S7: （製品マスタから反映） | T7: サイト（ユーザー定義） | U7: 倉庫（ユーザー定義） | V7: 数値 | W7: 数値 | X7: 単位（ユーザー定義） | Y7: 数値 | Z7: 通貨（ユーザー定義） | AA7: 数値 | AB7: 属性ベースの価格決定データ（ユーザー定義） | AC7: （自動） | AD7: （自動） | AE7: 日付 | AF7: 日付 | AG7: 数値 | AH7: 数値 | AI7: 数値 | AJ7: 数値 | AK7: 数値 | AL7: はい/いいえ | AM7: はい/いいえ | AN7: はい/いいえ | AO7: はい/いいえ | AP7: （自動）
C8: 必須 | D8: （自動） | F8: （自動） | G8: （自動） | H8: 必須 | J8: （自動） | K8: 必須(*) | L8: 必須(*) | M8: 必須(*) | N8: 必須(*) | O8: 必須(*) | Y8: 必須(*) | Z8: 必須
B9: =ROW() - 8 -> 1
B10: =ROW() - 8 -> 2
B11: =ROW() - 8 -> 3
B12: =ROW() - 8 -> 4
B13: =ROW() - 8 -> 5
B14: =ROW() - 8 -> 6
B15: =ROW() - 8 -> 7
B16: =ROW() - 8 -> 8
B17: =ROW() - 8 -> 9
B18: =ROW() - 8 -> 10
B19: =ROW() - 8 -> 11
B20: =ROW() - 8 -> 12
... B38: =ROW() - 8 -> 30

Sheet 荷渡方法
A1: 荷渡方法
B2: 販売とマーケティング ＞ 設定 > 配分 > 荷渡方法
B3: Sales and marketing > Setup > Distribution > Modes of delivery
A4: パラメータ設定一覧へ
B5: # | C5: タブ | D5: タブ説明 | E5: 項目分類 | F5: 項目 | G5: Description（標準） | H5: 設定可能値 | I5: デフォルト値 | J5: 備考 | K5: 設定値 | L5: 設定基準
B6: =ROW() - 5 -> 1 | C6: 荷渡方法 | F6: 荷渡方法 | G6: 荷渡方法を示すコードを英数字で入力します。コードは最大 10 文字まで入力できます。たとえば、United Parcel Service を UPS と入力し、Federal Express を FedEx と入力します。 | H6: 文字列 | I6: ー | K6: シート「荷渡方法-設定値」を参照
B7: =ROW() - 5 -> 2 | F7: 説明 | G7: 現在の荷渡方法の詳細な説明を入力します。この説明は、販売注文や顧客請求書などの印刷用ページに記載されます。 | H7: 文字列 | I7: ー | K7: シート「荷渡方法-設定値」を参照
B8: =ROW() - 5 -> 3 | F8: 諸掛グループ | H8: 諸掛グループ（ユーザー定義） | I8: ー | K8: シート「荷渡方法-設定値」を参照
B9: =ROW() - 5 -> 4 | F9: 急送 | H9: 急送（ユーザー定義） | I9: ー | K9: シート「荷渡方法-設定値」を参照
B10: =ROW() - 5 -> 5 | C10: 小売チャネル | F10: 名前 | H10: 名前（ユーザー定義） | I10: ー | J10: 組織階層からノードを選択する。 選択したノードの名前がセットされる | K10: シート「荷渡方法-設定値」を参照
B11: =ROW() - 5 -> 6 | F11: 関係者ID | H11: 数値 | I11: ー | J11: 組織階層からノードを選択する。 選択したノードの関係者IDがセットされる | K11: シート「荷渡方法-設定値」を参照
B12: =ROW() - 5 -> 7 | C12: 製品 | F12: カテゴリ | H12: カテゴリ（ユーザー定義） | I12: ー | K12: シート「荷渡方法-設定値」を参照
B13: =ROW() - 5 -> 8 | F13: 製品 | H13: 製品（ユーザー定義） | I13: ー | K13: シート「荷渡方法-設定値」を参照
B14: =ROW() - 5 -> 9 | F14: 製品バリアント | H14: 製品バリアント（ユーザー定義） | I14: ー | K14: シート「荷渡方法-設定値」を参照
F15: 名前 | H15: 文字列 | K15: シート「荷渡方法-設定値」を参照
B16: =ROW() - 5 -> 11 | F16: 行タイプ | G16: Retail では、[製品] や [アドレス] クイック タブで、オンライン店舗で使用される荷渡方法から明細行を追加、または除外するかどうかを選択します。 | H16: 含む 除外 | I16: 含む | K16: シート「荷渡方法-設定値」を参照
B17: =ROW() - 5 -> 12 | C17: 住所 | F17: 国/地域 | H17: 国/地域（ユーザー定義） | I17: ー | K17: シート「荷渡方法-設定値」を参照
B18: =ROW() - 5 -> 13 | F18: 都道府県 | H18: 都道府県（ユーザー定義） | I18: ー | K18: シート「荷渡方法-設定値」を参照
B19: =ROW() - 5 -> 14 | F19: 行タイプ | G19: Retail では、[製品] や [アドレス] クイック タブで、オンライン店舗で使用される荷渡方法から明細行を追加、または除外するかどうかを選択します。 | H19: 含む 除外 | I19: 含む | K19: シート「荷渡方法-設定値」を参照

Sheet 荷渡方法-設定値
A1: 荷渡方法(小売チャネル)-設定値 ※基本的には移行データを正とする
A2: ■凡例「必須：システム上必須」「必須(*)：システムで必須ではないが、トランザクション上や業務などで必須」
A3: パラメータ設定一覧へ
B4: # | C4: 荷渡方法 | G4: 荷渡方法(小売チャネル) | I4: 荷渡方法(製品) | N4: 荷渡方法(住所)
C5: 荷渡方法 | D5: 説明 | E5: 諸掛グループ | F5: 急送 | G5: 名前 | H5: 関係者ID | I5: カテゴリ | J5: 製品 | K5: 製品バリアント | L5: 名前 | M5: 行タイプ | N5: 国/地域 | O5: 都道府県 | P5: 行タイプ
C6: 文字列 | D6: 文字列 | E6: 諸掛グループ（ユーザー定義） | F6: 急送（ユーザー定義） | G6: 名前（ユーザー定義） | H6: 数値 | I6: カテゴリ（ユーザー定義） | J6: 製品（ユーザー定義） | K6: 製品バリアント（ユーザー定義） | L6: 文字列 | M6: 含む/除外 | N6: 国/地域（ユーザー定義） | O6: 都道府県（ユーザー定義） | P6: 含む/除外
C7: 必須
B8: =ROW() - 7 -> 1
B9: =ROW() - 7 -> 2
B10: =ROW() - 7 -> 3
B11: =ROW() - 7 -> 4
B12: =ROW() - 7 -> 5
B13: =ROW() - 7 -> 6
B14: =ROW() - 7 -> 7
B15: =ROW() - 7 -> 8
B16: =ROW() - 7 -> 9
B17: =ROW() - 7 -> 10

Sheet 顧客
A1: 顧客
B2: 売掛金管理＞顧客＞すべての顧客
B3: Accounts receivable > Customers > All customers
A4: パラメータ設定一覧へ
B5: # | C5: タブ | D5: タブ説明 | E5: 項目分類 | F5: 項目 | G5: 項目説明 | H5: 設定可能値 | I5: デフォルト値 | J5: 備考 | K5: 設定値 | L5: 設定基準
B6: =ROW() - 5 -> 1 | C6: 顧客の作成 | E6: 詳細＞タイプ＞組織 | F6: 顧客ID | H6: 文字列 | I6: ー | J6: 番号順序の設定に準拠する | K6: 「顧客-顧客の作成」を参照
B7: =ROW() - 5 -> 2 | F7: タイプ | H7: 組織 個人 | I7: 組織 | K7: 「顧客-顧客の作成」を参照
B8: =ROW() - 5 -> 3 | F8: 名前 | H8: 文字列 | I8: ー | K8: 「顧客-顧客の作成」を参照
B9: =ROW() - 5 -> 4 | F9: 顧客グループ | H9: 顧客グループ（ユーザー定義） | I9: ー | K9: 「顧客-顧客の作成」を参照
B10: =ROW() - 5 -> 5 | F10: 通貨 | H10: 通貨（ユーザー定義） | I10: ー | K10: 「顧客-顧客の作成」を参照
B11: =ROW() - 5 -> 6 | F11: 支払条件 | H11: 支払条件（ユーザー定義） | I11: ー | K11: 「顧客-顧客の作成」を参照
B12: =ROW() - 5 -> 7 | F12: 配送条件 | H12: 配送条件（ユーザー定義） | I12: ー | K12: 「顧客-顧客の作成」を参照
B13: =ROW() - 5 -> 8 | F13: 荷渡方法 | H13: 荷渡方法（ユーザー定義） | I13: ー | K13: 「顧客-顧客の作成」を参照
B14: =ROW() - 5 -> 9 | F14: 消費税グループ | H14: 消費税グループ（ユーザー定義） | I14: ー | K14: 「顧客-顧客の作成」を参照
B15: =ROW() - 5 -> 10 | F15: 課税控除番号 | H15: 課税控除番号（ユーザー定義） | I15: ー | K15: 「顧客-顧客の作成」を参照
B16: =ROW() - 5 -> 11 | F16: ソースコード | H16: ソース コード（ユーザー定義） | I16: ー | K16: 「顧客-顧客の作成」を参照
B17: =ROW() - 5 -> 12 | E17: 詳細＞タイプ＞個人 | F17: 顧客ID | H17: 文字列 | I17: ー | K17: 「顧客-顧客の作成」を参照
B18: =ROW() - 5 -> 13 | F18: タイプ | H18: 組織 個人 | I18: 個人 | K18: 「顧客-顧客の作成」を参照
B19: =ROW() - 5 -> 14 | F19: 名 | H19: 文字列 | I19: ー | K19: 「顧客-顧客の作成」を参照
B20: =ROW() - 5 -> 15 | F20: ミドルネーム | H20: 文字列 | I20: ー | K20: 「顧客-顧客の作成」を参照
B21: =ROW() - 5 -> 16 | F21: 姓の接頭語 | H21: 文字列 | I21: ー | K21: 「顧客-顧客の作成」を参照
B22: =ROW() - 5 -> 17 | F22: 姓 | H22: 文字列 | I22: ー | K22: 「顧客-顧客の作成」を参照
B23: =ROW() - 5 -> 18 | F23: 顧客グループ | H23: 顧客グループ（ユーザー定義） | I23: ー | K23: 「顧客-顧客の作成」を参照
B24: =ROW() - 5 -> 19 | F24: 通貨 | H24: 通貨（ユーザー定義） | I24: ー | K24: 「顧客-顧客の作成」を参照
B25: =ROW() - 5 -> 20 | F25: 支払条件 | H25: 文字列 | I25: ー | K25: 「顧客-顧客の作成」を参照
B26: =ROW() - 5 -> 21 | F26: 配送条件 | H26: 文字列 | I26: ー | K26: 「顧客-顧客の作成」を参照
B27: =ROW() - 5 -> 22 | F27: 荷渡方法 | H27: 文字列 | I27: ー | K27: 「顧客-顧客の作成」を参照
B28: =ROW() - 5 -> 23 | F28: 消費税グループ | H28: 文字列 | I28: ー | K28: 「顧客-顧客の作成」を参照
B29: =ROW() - 5 -> 24 | F29: 課税控除番号 | H29: 文字列 | I29: ー | K29: 「顧客-顧客の作成」を参照
B30: =ROW() - 5 -> 25 | F30: ソースコード | H30: 文字列 | I30: ー | K30: 「顧客-顧客の作成」を参照
B31: =ROW() - 5 -> 26 | E31: 住所 | F31: 国/地域 | H31: 国/地域（システム定義） | I31: JPN | K31: 「顧客-顧客の作成」を参照
B32: =ROW() - 5 -> 27 | F32: 郵便番号 | H32: 文字列 | I32: ー | K32: 「顧客-顧客の作成」を参照
B33: =ROW() - 5 -> 28 | F33: 住所 | H33: 文字列 | I33: ー | K33: 「顧客-顧客の作成」を参照
B34: =ROW() - 5 -> 29 | F34: 市町村 | H34: 文字列 | I34: ー | K34: 「顧客-顧客の作成」を参照
B35: =ROW() - 5 -> 30 | F35: 都道府県 | H35: 文字列 | I35: ー | K35: 「顧客-顧客の作成」を参照
B36: =ROW() - 5 -> 31 | F36: アドレス帳 | H36: アドレス帳（ユーザー定義） | I36: ー | K36: 「顧客-顧客の作成」を参照
B37: =ROW() - 5 -> 32 | E37: 連絡先情報 | F37: 電話 | H37: 文字列 | I37: ー | K37: 「顧客-顧客の作成」を参照
B38: =ROW() - 5 -> 33 | F38: 内線 | H38: 文字列 | I38: ー | K38: 「顧客-顧客の作成」を参照
B39: =ROW() - 5 -> 34 | F39: FAX | H39: 文字列 | I39: ー | K39: 「顧客-顧客の作成」を参照
B40: =ROW() - 5 -> 35 | F40: 電子メールアドレス | H40: 文字列 | I40: ー | K40: 「顧客-顧客の作成」を参照
...

Sheet 顧客-顧客の作成
A1: 顧客-顧客の作成 ※基本的には移行データを正とする
A2: ■凡例「必須：システム上必須」「必須(*)：システムで必須ではないが、トランザクション上や業務などで必須」
A3: パラメータ設定一覧へ
B4: # | C4: 顧客の作成
C5: 詳細 | R5: 住所 | X5: 連絡先情報
C6: 顧客ID | D6: タイプ | E6: 名前 （タイプ：組織） | F6: 名 （タイプ：個人） | G6: ミドルネーム （タイプ：個人） | H6: 姓の接尾語 （タイプ：個人） | I6: 姓 （タイプ：個人） | J6: 顧客グループ | K6: 通貨 | L6: 支払条件 | M6: 配送条件 | N6: 荷渡方法 | O6: 消費税グループ | P6: 課税控除番号 | Q6: ソースコード | R6: 国/地域 | S6: 郵便番号 | T6: 住所 | U6: 市町村 | V6: 都道府県 | W6: アドレス帳 | X6: 電話 | Y6: 内線 | Z6: FAX | AA6: 電子メールアドレス
C7: 文字列（番号順序の設定に準拠するため、手動入力、自動採番どちらも可能） | D7: 組織/個人 | E7: 文字列 | F7: 文字列 | G7: 文字列 | H7: 文字列 | I7: 文字列 | J7: 顧客グループ（ユーザー定義） | K7: 通貨（ユーザー定義） | L7: 支払条件（ユーザー定義） | M7: 配送条件（ユーザー定義） | N7: 荷渡方法（ユーザー定義） | O7: 消費税グループ（ユーザー定義） | P7: 課税控除番号（ユーザー定義） | Q7: ソース コード（ユーザー定義） | R7: 国/地域（システム定義） | S7: 文字列 | T7: 文字列 | U7: 文字列 | V7: 文字列 | W7: アドレス帳（ユーザー定義） | X7: 文字列 | Y7: 文字列 | Z7: 文字列 | AA7: 文字列
C8: 必須 | D8: 必須 | E8: 必須（組織の場合） | F8: 必須（個人の場合） | G8: 必須（個人の場合） | H8: 必須（個人の場合） | I8: 必須（個人の場合） | J8: 必須 | K8: 必須 | L8: 必須(*) | O8: 必須(*) | R8: 必須
B9: 例 | C9: TEST_CUST-001 | D9: 組織 | E9: テスト顧客株式会社 | J9: CG01 ※グループの設定は別途検討 | K9: JPY | L9: 月末締翌月末払い | O9: 国内売上 ※グループの設定は別途検討 | R9: JPN
B10: =ROW() - 9 -> 1
B11: =ROW() - 9 -> 2
B12: =ROW() - 9 -> 3
B13: =ROW() - 9 -> 4
B14: =ROW() - 9 -> 5
B15: =ROW() - 9 -> 6
B16: =ROW() - 9 -> 7
B17: =ROW() - 9 -> 8
B18: =ROW() - 9 -> 9
B19: =ROW() - 9 -> 10
B20: =ROW() - 9 -> 11
B21: =ROW() - 9 -> 12
... B29: =ROW() - 9 -> 20

Sheet 顧客-設定値
A1: 顧客-設定値 ※基本的には移行データを正とする
A2: ■凡例「必須：システム上必須」「必須(*)：システムで必須ではないが、トランザクション上や業務などで必須」
A3: パラメータ設定一覧へ
B4: # | C4: すべての顧客 | R4: 住所 | AD4: 連絡先情報 | AI4: その他の詳細 | AX4: 顧客情報 | BJ4: 与信および回収 | CM4: 販売注文の既定値 | DH4: 支払の既定値 | DZ4: 財務分析コード | EC4: 倉庫 | EG4: 請求書と出荷 | EY4: 輸送管理 | EZ4: 口座引落の委任状 | FG4: コマース
C5: 一般>顧客 | J5: 一般>組織の詳細 | N5: 一般>その他の情報 | AL5: 顧客セルフサービス | AM5: 政府ID | AP5: 送金 | AQ5: 通知と取消の自動処理 | AR5: 会社間 | BG5: マーケティング | BJ5: 一般 | BO5: 合計与信限度額 | BV5: 与信の確認 | BX5: 適格な与信限度額 | CA5: 状態 | CE5: リスク | CG5: メモ | CH5: 取立 | CM5: 販売注文 | CW5: 割引 | DC5: グループ | DF5: 配賦 | DG5: 詳細なメモ | DH5: 支払 | DU5: 中央銀行への通知 | DW5: 小切手の保留 | DY5: 月次締めグループ | DZ5: 既定の財務分析コード ※使用する財務分析コード分列追加 | EC5: ASN | ED5: 倉庫にリリース | EE5: 出荷処理中 | EG5: 請求書 | EK5: 配送日 | EQ5: 消費税 | EU5: 梱包材費用 | EV5: E-INVOICE | EX5: 運賃 | EY5: 船荷証券 | FG5: 小売 | FJ5: レシート | FL5: ロイヤルティ登録 | FM5: プライバシー | FO5: B2B
C6: アカウント | D6: タイプ | E6: 名前 | F6: 検索名 | G6: 顧客グループ | H6: 分類グループ | I6: 支払優先順位 | J6: 従業員数 | K6: 組織番号 | L6: ABCコード | M6: DUNS番号 | N6: アドレス帳 | O6: 言語 | P6: カナ名 | Q6: 呼称 | R6: 名前または説明 | S6: 住所 | T6: 目的 | U6: 主要 | V6: 国/地域 | W6: 郵便番号 | X6: 住所 | Y6: 市町村 | Z6: 都道府県 | AA6: 主要 | AB6: プライベート | AC6: 国/地域に関する基本事項 | AD6: 説明 | AE6: タイプ | AF6: 連絡先の電話番号/住所 | AG6: 内線 | AH6: 主要 | AI6: 一時顧客 | AJ6: 統計グループ | AK6: 取引明細書 | AL6: 利用可能履歴 | AM6: ID番号 | AN6: 国/地域 | AO6: 都道府県 | AP6: 仕入先 | AQ6: 自動的な通知と取消の除外 | AR6: 有効 | AS6: 会社 | AT6: 仕入先 | AU6: 会社間注文の作成 | AV6: 直納 | AW6: 間接注文明細行の作成 | AX6: 基本連絡先 | AY6: 業種 | AZ6: 担当従業員 | BA6: 区分 | BB6: 小区分 | BC6: 会社グループ | BD6: 販売地域 | BE6: 通貨 | BF6: メモ | BG6: ソースコード | BH6: 前回注文のソース | BI6: 前回プロモーションのソース | BJ6: 信用格付け | BK6: 与信限度確認必須 | BL6: 無制限の与信限度額 | BM6: 与信管理から除外 | BN6: 与信管理グループ | BO6: 与信限度額 | BP6: 顧客の通貨 (JPY) での与信限度額 | BQ6: 保険および保証 | BR6: 合計与信限度額 | BS6: 与信限度額の有効期限日 | BT6: 与信限度額の変更日 | BU6: 顧客与信グループ | BV6: 最終確認日 | BW6: 次にスケジュールされた確認日 | BX6: 適格な与信限度額 | BY6: 適格な与信限度額の通貨 | BZ6: 適格な与信限度額の変更日 | CA6: 勘定状態 | CB6: 勘定状態の理由 | CC6: 督促代行業者あり | CD6: 保留されたタイトル | CE6: 事業の設立年 | CF6: 初回購入 | CG6: 注記 | CH6: 請求と出荷は保留中です | CI6: 回収の連絡先 | CJ6: 既定の損金処理の理由 | CK6: 利息を除外します | CL6: 回収手数料を除外 | CM6: 諸掛グループ | CN6: サイト | CO6: 倉庫 | CP6: 品目 - 顧客グループ | CQ6: コミッショングループ | CR6: 売上グループ | CS6: 販売注文管理グループ | CT6: 勘定番号 | CU6: 会社間 | CV6: 注文入力期限 | CW6: 複数割引行 | CX6: 割引合計 | CY6: 価格 | CZ6: 行割引 | DA6: 顧客リベートグループ | DB6: 顧客TWAグループ | DC6: 送料グループ | DD6: 提供品 | DE6: 自動キャンセル | DF6: 優先順位 | DG6: 詳細なメモ グループ | DH6: 支払条件 | DI6: 支払方法 | DJ6: 支払詳細 | DK6: 支払スケジュール | DL6: 支払期日 | DM6: 現金割引 | DN6: 支払期間基準日数 | DO6: 銀行口座 | DP6: 内金の許可 | DQ6: チャネルのフロア制限仕様をブロック | DR6: 適格な分割 | DS6: 銀行口座番号 | DT6: 現金割引の使用 | DU6: 中央銀行目的コード | DV6: メモ | DW6: しきい値 | DX6: 日数 | DY6: 月次締め日 | DZ6: XXXXXX | EA6: XXXXXX | EB6: XXXXXX | EC6: ASNの生成 | ED6: フルフィルメントポリシー | EE6: 出荷全体の入力 | EF6: 既定の在庫状態ID | EG6: 請求先/元 ID | EH6: 請求先住所 | EI6: 番号順序グループ | EJ6: 請求書テンプレート | EK6: UPSゾーン | EL6: 配送条件 | EM6: 荷渡方法 | EN6: 配送理由 | EO6: 出荷先コード | EP6: 入荷カレンダー | EQ6: 消費税グループ | ER6: 課税控除番号 | ES6: 税込価格 | ET6: 梱包税ライセンス番号 | EU6: ライセンス番号 | EV6: eInvoice | EW6: 電子請求書の添付 | EX6: 運賃の見越計上 | EY6: 速達船荷証券の受理 | EZ6: 委任状ID | FA6: 銀行口座 | FB6: 署名日 | FC6: 委任状スキーム | FD6: 支払頻度 | FE6: 委任状の状態 | FF6: 変更日時 | FG6: （転記済金額ではなく）請求金額 | FH6: 出荷として転記する | FI6: 注文番号参照の使用 | FJ6: レシートオプション | FK6: レシートの電子メール | FL6: ロイヤルティ登録に対する顧客のブロック | FM6: 個人用設定の無効化 | FN6: Web活動を追跡しない | FO6: 顧客階層ID | FP6: B2B管理者
C7: システム入力（顧客の作成での入力が引き継がれる） | D7: システム入力（顧客の作成での入力が引き継がれる） | E7: 文字列（顧客の作成での入力が引き継がれる） | F7: 文字列 | G7: 顧客グループ（ユーザー定義）（顧客の作成での入力が引き継がれる） | H7: 顧客分類グループ（ユーザー定義） | I7: 入力不可 | J7: 数値 | K7: 文字列 | L7: なし A B C | M7: 数値 | N7: アドレス帳（ユーザー定義） | O7: 言語（システム定義） | P7: 文字列 | Q7: 文字列 | R7: 文字列 | S7: 文字列 | T7: 業務 委託販売 配送 固定資産 本社 ホーム 請求書 船荷 その他 支払 実際の場所 採用 送金先 サービス 安定した組織 ステートメント SWIFT 船降 | U7: チェック有/チェック無 | V7: 国/地域（システム定義） | W7: 数値 | X7: 文字列 | Y7: 文字列 | Z7: 文字列 | AA7: はい/いいえ | AB7: はい/いいえ | AC7: はい/いいえ | AD7: 文字列 | AE7: 電話 電子メールアドレス URL テレックス FAX Facebook Twitter LinkedIn | AF7: 文字列 | AG7: 文字列 | AH7: チェック有/チェック無 | AI7: はい/いいえ | AJ7: 統計グループ（ユーザー定義） | AK7: 常時 四半期 半年毎 毎年 なし | AL7: Web注文 / すべての注文 | AM7: 文字列 | AN7: 国/地域（システム定義） | AO7: 文字列 | AP7: 仕入先（ユーザー定義） | AQ7: はい/いいえ | AR7: はい/いいえ | AS7: 入力不可 | AT7: 入力不可 | AU7: はい/いいえ | AV7: はい/いいえ | AW7: はい/いいえ | AX7: 連絡先（ユーザー定義） | AY7: 業種（ユーザー定義） | AZ7: 作業者（ユーザー定義） | BA7: 区分（ユーザー定義） | BB7: 小区分（ユーザー定義） | BC7: 会社グループ（ユーザー定義） | BD7: 販売地域（ユーザー定義） | BE7: 通貨（ユーザー定義）（顧客の作成での入力が引き継がれる） | BF7: 文字列 | BG7: ソースコード（ユーザー定義） | BH7: ソースコード（ユーザー定義） | BI7: ソースコード（ユーザー定義） | BJ7: 文字列 | BK7: はい/いいえ | BL7: はい/いいえ | BM7: はい/いいえ | BN7: 与信管理グループ（ユーザー定義） | BO7: 入力不可 | BP7: 入力不可 | BQ7: 入力不可 | BR7: 入力不可 | BS7: 日付 | BT7: 入力不可 | BU7: 入力不可 | BV7: 日付 | BW7: 日付 | BX7: 数値 | BY7: 通貨（ユーザー定義） | BZ7: 入力不可 | CA7: 勘定状態（ユーザー定義） | CB7: 与信管理の理由（ユーザー定義） | CC7: はい/いいえ | CD7: はい/いいえ | CE7: 日付 | CF7: 日付 | CG7: 文字列 | CH7: いいえ 請求書 すべて 支払 要求 なし 発注書 | CI7: 関係者（ユーザー定義） | CJ7: 顧客損金処理理由コード（ユーザー定義） | CK7: はい/いいえ | CL7: はい/いいえ | CM7: 顧客諸掛グループ（ユーザー定義） | CN7: サイト（ユーザー定義） | CO7: 倉庫（ユーザー定義） | CP7: 外部品目説明（ユーザー定義） | CQ7: コミッション顧客グループ（ユーザー定義） | CR7: コミッション売上グループ（ユーザー定義） | CS7: 注文管理グループ（ユーザー定義） | CT7: 文字列 | CU7: 文字列 | CV7: 注文入力期限グループ（ユーザー定義） | CW7: 価格/割引グループ（ユーザー定義） | CX7: 価格/割引グループ（ユーザー定義） | CY7: 価格/割引グループ（ユーザー定義） | CZ7: 価格/割引グループ（ユーザー定義） | DA7: 顧客リベートグループ (複数)（ユーザー定義） | DB7: 顧客TMA グループ（ユーザー定義） | DC7: 価格/割引グループ（ユーザー定義） | DD7: 提供品グループ（ユーザー定義） | DE7: はい/いいえ | DF7: 高-1 高-2 高-3 中-4 中-5 中-6 中-7 低-8 低-9 低-10 | DG7: 詳細なメモ グループ（ユーザー定義） | DH7: 支払条件（ユーザー定義）（顧客の作成での入力が引き継がれる） | DI7: 支払方法（ユーザー定義） | DJ7: 支払詳細（ユーザー定義） | DK7: 支払スケジュール（ユーザー定義） | DL7: 支払期日（ユーザー定義） | DM7: 現金割引（ユーザー定義） | DN7: 数値 | DO7: 銀行口座（ユーザー定義） | DP7: はい/いいえ | DQ7: はい/いいえ | DR7: はい/いいえ | DS7: 文字列 | DT7: 標準 常時 なし | DU7: 支払目的コード（ユーザー定義） | DV7: 文字列 | DW7: 数値 | DX7: 数値 | DY7: 数値 | EC7: はい/いいえ | ED7: フルフィルメント ポリシー（ユーザー定義） | EE7: はい/いいえ | EF7: 在庫状態（ユーザー定義） | EG7: 顧客（ユーザー定義） | EH7: 請求先/元 ID / 注文顧客 | EI7: 番号順序グループ（ユーザー定義） | EJ7: PSAProjInvoice.Report PSAProjInvoice.Report_JP | EK7: 文字列 | EL7: 配送条件（ユーザー定義） | EM7: 荷渡方法（ユーザー定義） | EN7: 配送理由（ユーザー定義） | EO7: 行先コード（ユーザー定義） | EP7: 作業時間カレンダー（ユーザー定義） | EQ7: 消費税グループ（ユーザー定義） | ER7: 課税控除番号（ユーザー定義） | ES7: はい/いいえ | ET7: 文字列 | EU7: 文字列 | EV7: はい/いいえ | EW7: はい/いいえ | EX7: はい/いいえ | EY7: はい/いいえ | EZ7: 変更不可 | FA7: 銀行口座（ユーザー定義） | FB7: 年月日 | FC7: 文字列 | FD7: 繰返し / 一時 | FE7: 文字列 | FF7: 年月日 | FG7: 数値 | FH7: はい/いいえ | FI7: はい/いいえ | FJ7: 標準受領書 電子メール 両方 | FK7: 文字列 | FL7: はい/いいえ | FM7: はい/いいえ | FN7: はい/いいえ | FO7: 入力不可 | FP7: はい/いいえ
C8: 必須 | D8: 必須 | E8: 必須 | G8: 必須 | O8: 必須 | BE8: 必須 | DH8: 必須(*) | DI8: 必須(*)
B9: 例 | C9: ='顧客-顧客の作成'!C9 -> TEST_CUST-001 | D9: ='顧客-顧客の作成'!D9 -> 組織 | E9: ='顧客-顧客の作成'!E9 -> テスト顧客株式会社 | F9: テスト顧客 | G9: ='顧客-顧客の作成'!J9 -> CG01 ※グループの設定は別途検討 | O9: ja | BE9: ='顧客-顧客の作成'!K9 -> JPY | DH9: ='顧客-顧客の作成'!L9 -> 月末締翌月末払い | DI9: 銀行振込
B10: =ROW() - 9 -> 1 | C10: ='顧客-顧客の作成'!C10 -> 0 | D10: ='顧客-顧客の作成'!D10 -> 0 | E10: ='顧客-顧客の作成'!E10 -> 0 | G10: ='顧客-顧客の作成'!J10 -> 0 | BE10: ='顧客-顧客の作成'!K10 -> 0 | DH10: ='顧客-顧客の作成'!L10 -> 0
B11: =ROW() - 9 -> 2 | C11: ='顧客-顧客の作成'!C11 -> 0 | D11: ='顧客-顧客の作成'!D11 -> 0 | E11: ='顧客-顧客の作成'!E11 -> 0 | G11: ='顧客-顧客の作成'!J11 -> 0 | BE11: ='顧客-顧客の作成'!K11 -> 0 | DH11: ='顧客-顧客の作成'!L11 -> 0
B12: =ROW() - 9 -> 3 | C12: ='顧客-顧客の作成'!C12 -> 0 | D12: ='顧客-顧客の作成'!D12 -> 0 | E12: ='顧客-顧客の作成'!E12 -> 0 | G12: ='顧客-顧客の作成'!J12 -> 0 | BE12: ='顧客-顧客の作成'!K12 -> 0 | DH12: ='顧客-顧客の作成'!L12 -> 0
B13: =ROW() - 9 -> 4 | C13: ='顧客-顧客の作成'!C13 -> 0 | D13: ='顧客-顧客の作成'!D13 -> 0 | E13: ='顧客-顧客の作成'!E13 -> 0 | G13: ='顧客-顧客の作成'!J13 -> 0 | BE13: ='顧客-顧客の作成'!K13 -> 0 | DH13: ='顧客-顧客の作成'!L13 -> 0
B14: =ROW() - 9 -> 5 | C14: ='顧客-顧客の作成'!C14 -> 0 | D14: ='顧客-顧客の作成'!D14 -> 0 | E14: ='顧客-顧客の作成'!E14 -> 0 | G14: ='顧客-顧客の作成'!J14 -> 0 | BE14: ='顧客-顧客の作成'!K14 -> 0 | DH14: ='顧客-顧客の作成'!L14 -> 0
B15: =ROW() - 9 -> 6 | C15: ='顧客-顧客の作成'!C15 -> 0 | D15: ='顧客-顧客の作成'!D15 -> 0 | E15: ='顧客-顧客の作成'!E15 -> 0 | G15: ='顧客-顧客の作成'!J15 -> 0 | BE15: ='顧客-顧客の作成'!K15 -> 0 | DH15: ='顧客-顧客の作成'!L15 -> 0
B16: =ROW() - 9 -> 7 | C16: ='顧客-顧客の作成'!C16 -> 0 | D16: ='顧客-顧客の作成'!D16 -> 0 | E16: ='顧客-顧客の作成'!E16 -> 0 | G16: ='顧客-顧客の作成'!J16 -> 0 | BE16: ='顧客-顧客の作成'!K16 -> 0 | DH16: ='顧客-顧客の作成'!L16 -> 0
B17: =ROW() - 9 -> 8 | C17: ='顧客-顧客の作成'!C17 -> 0 | D17: ='顧客-顧客の作成'!D17 -> 0 | E17: ='顧客-顧客の作成'!E17 -> 0 | G17: ='顧客-顧客の作成'!J17 -> 0 | BE17: ='顧客-顧客の作成'!K17 -> 0 | DH17: ='顧客-顧客の作成'!L17 -> 0
B18: =ROW() - 9 -> 9 | C18: ='顧客-顧客の作成'!C18 -> 0 | D18: ='顧客-顧客の作成'!D18 -> 0 | E18: ='顧客-顧客の作成'!E18 -> 0 | G18: ='顧客-顧客の作成'!J18 -> 0 | BE18: ='顧客-顧客の作成'!K18 -> 0 | DH18: ='顧客-顧客の作成'!L18 -> 0
