Workbook
Name io: マスタ!$A$3:$A$5
Name Visivility: マスタ!$F$3:$F$4
Name オブジェクト: マスタ!$H$7:$H$20
Name オブジェクト一覧: マスタ!$H$3:$H$20
Name テーブル種別: マスタ!$G$3:$G$4
Name マスタ: マスタ!$H$3:$H$20
Name 横位置: マスタ!$C$3:$C$6
Name 作成日: DATE(2000,3,21)
Name 縦位置: マスタ!$D$3:$D$6
Name 書式: マスタ!$B$3:$B$5
Name 折り返して全体を表示する: マスタ!$E$3:$E$4

Sheet 表紙
B3: サンスター株式会社 御中
B10: 会計システム刷新プロジェクト（LIBRA）
B14: =変更履歴!W2&"_設計書_"&変更履歴!AE2 -> FO-006_設計書_支払方法・支払サイトマスタ画面
AA21: ＜機能ID>_＜画面名＞画面を入力
B22: ="第"&IF(COUNTA(変更履歴!BF5:BH10000)=1,"",INDIRECT("変更履歴!BE"&COUNTA(変更履歴!BF5:BH10000)+4))&"版" -> 第版
B24: =IF(OR(COUNTA(変更履歴!A:E)=2),"",INDIRECT("変更履歴!A"&COUNTA(変更履歴!A:E)+3)) -> 45589
B26: 日本ビジネスシステムズ株式会社
F29: 作成者 | O29: JBS承認者 | V29: 基本設計部確認者
F30: =変更履歴!AV2 -> 45448 | N30: 45485 | V30: 45523
F31: =変更履歴!BB2 -> JBS井田 | N31: JBS加藤 | V31: サンスター藤田

Sheet 変更履歴
A1: 設計書 | F1: システム名 | Q1: 機能分類 | W1: 機能ＩＤ | AE1: 機能名称 | AT1: 日付 | BB1: 更新者
F2: Dynamics365 for Finance and Operations | Q2: 債権・債務 | W2: FO-006 | AE2: 支払方法・支払サイトマスタ画面 | AT2: 作成 | AV2: =A6 -> 45448 | BB2: =AZ6 -> JBS井田
AT3: 更新 | AV3: {=IF(OR(COUNTA(A:E)=2),"",INDIRECT("A"&COUNTA(A:E)+3))} -> 45589 | BB3: {=IF(COUNTA(AZ5:BE100018)=1,"",INDIRECT("AZ"&COUNTA(AZ5:BE100018)+4))} -> JBS井田
AW4: （表紙同様値）
A5: 変更年月日 | F5: 変更箇所 | T5: 変更内容 | AZ5: 変更者 | BF5: 版数
A6: 45448 | F6: 新規作成 | T6: 新規作成 | AZ6: JBS井田 | BF6: 1.0
A7: 45589 | F7: シート：「処理概要」 | T7: 「処理概要」シート 開発内容 以下のように修正。 ■変更前：必須項目 ■変更後：画面上に追加する項目 | AZ7: JBS井田 | BF7: 1.1
A8: 45589 | F8: シート：「画面項目説明」 | T8: 「画面項目説明」シート 支払条件 必須入力項目の追加。 以下のように修正。 ■変更前：必須：× ■変更後：必須：〇 | AZ8: JBS井田 | BF8: 1.1

Sheet 処理概要
A1: 基本設計書 | F1: =変更履歴!F1 -> システム名 | Q1: =変更履歴!Q1 -> 機能分類 | W1: =変更履歴!W1 -> 機能ＩＤ | AE1: =変更履歴!AE1 -> 機能名称 | AT1: =変更履歴!AT1 -> 日付 | BB1: =変更履歴!BB1 -> 更新者
F2: =変更履歴!F2 -> Dynamics365 for Finance and Operations | Q2: =変更履歴!Q2 -> 債権・債務 | W2: =変更履歴!W2 -> FO-006 | AE2: =変更履歴!AE2 -> 支払方法・支払サイトマスタ画面 | AT2: =変更履歴!AT2 -> 作成 | AV2: =変更履歴!AV2 -> 45448 | BB2: =変更履歴!BB2 -> JBS井田
AT3: =変更履歴!AT3 -> 更新 | AV3: =変更履歴!AV3 -> 45589 | BB3: =変更履歴!BB3 -> JBS井田
A5: 開発目的
B6: 1. | C6: 「FO-008_支払方法・支払サイト更新バッチ」を実行するあたり、必要なマスタを管理するため。
A8: 前提条件
B9: 1. | C9: 請求金額、支払サイトは正の数字のみ登録可能とする。
B10: 2. | C10: 同一の支払方法で登録する請求金額が重複しないこと。 ※補足説明参照
A12: 使用タイミング
B13: 1. | C13: 随時
A15: 開発内容
B16: 1. | C16: 支払方法・支払サイトのマスタ管理する画面の新規作成する。
C17: 画面上に追加する項目
C18: ・支払方法
C19: ・請求金額
C20: ・支払方法(更新後)
C21: ・支払サイト
C22: ・支払条件
A25: 制限事項
B26: 1. | C26: なし

Sheet テーブル一覧
A1: 基本設計書 | F1: =変更履歴!F1 -> システム名 | Q1: =変更履歴!Q1 -> 機能分類 | W1: =変更履歴!W1 -> 機能ＩＤ | AE1: =変更履歴!AE1 -> 機能名称 | AT1: =変更履歴!AT1 -> 日付 | BB1: =変更履歴!BB1 -> 更新者
F2: =変更履歴!F2 -> Dynamics365 for Finance and Operations | Q2: 債権・債務 | W2: =変更履歴!W2 -> FO-006 | AE2: =変更履歴!AE2 -> 支払方法・支払サイトマスタ画面 | AT2: =変更履歴!AT2 -> 作成 | AV2: =変更履歴!AV2 -> 45448 | BB2: =変更履歴!BB2 -> JBS井田
AT3: =変更履歴!AT3 -> 更新 | AV3: =変更履歴!AV3 -> 45589 | BB3: =変更履歴!BB3 -> JBS井田
A5: No. | C5: 種別 | K5: 論理名 | AC5: 物理名 | AS5: I/O | AU5: 備考
A6: =ROW()-5 -> 1 | C6: テーブル | K6: 支払方法・支払サイト | AC6: SJ_PaymModePaymSiteTable | AS6: I/O
A7: =ROW()-5 -> 2 | C7: テーブル | K7: 支払方法 - 仕入先 | AC7: VendPaymModeTable | AS7: I
A8: =ROW()-5 -> 3
A9: =ROW()-5 -> 4
A10: =ROW()-5 -> 5
A11: =ROW()-5 -> 6
A12: =ROW()-5 -> 7
A13: =ROW()-5 -> 8
A14: =ROW()-5 -> 9
A15: =ROW()-5 -> 10
A16: =ROW()-5 -> 11
A17: =ROW()-5 -> 12
A18: =ROW()-5 -> 13
A19: =ROW()-5 -> 14
... A38: =ROW()-5 -> 33

Sheet DFD
A1: 基本設計書 | F1: =変更履歴!F1 -> システム名 | Q1: =変更履歴!Q1 -> 機能分類 | W1: =変更履歴!W1 -> 機能ＩＤ | AE1: =変更履歴!AE1 -> 機能名称 | AT1: =変更履歴!AT1 -> 日付 | BB1: =変更履歴!BB1 -> 更新者
F2: =変更履歴!F2 -> Dynamics365 for Finance and Operations | Q2: =変更履歴!Q2 -> 債権・債務 | W2: =変更履歴!W2 -> FO-006 | AE2: =変更履歴!AE2 -> 支払方法・支払サイトマスタ画面 | AT2: =変更履歴!AT2 -> 作成 | AV2: =変更履歴!AV2 -> 45448 | BB2: =変更履歴!BB2 -> JBS井田
AT3: =変更履歴!AT3 -> 更新 | AV3: =変更履歴!AV3 -> 45589 | BB3: =変更履歴!BB3 -> JBS井田
A5: イベント | O5: 機能 | AN5: DB
A21: 凡例
A22: 記号
AL26: ※DBが複数ある場合は複数DBをまとめるために使用

Sheet イベント説明
A1: 基本設計書 | F1: =変更履歴!F1 -> システム名 | Q1: =変更履歴!Q1 -> 機能分類 | W1: =変更履歴!W1 -> 機能ＩＤ | AE1: =変更履歴!AE1 -> 機能名称 | AT1: =変更履歴!AT1 -> 日付 | BB1: =変更履歴!BB1 -> 更新者
F2: =変更履歴!F2 -> Dynamics365 for Finance and Operations | Q2: =変更履歴!Q2 -> 債権・債務 | W2: =変更履歴!W2 -> FO-006 | AE2: =変更履歴!AE2 -> 支払方法・支払サイトマスタ画面 | AT2: =変更履歴!AT2 -> 作成 | AV2: =変更履歴!AV2 -> 45448 | BB2: =変更履歴!BB2 -> JBS井田
AT3: =変更履歴!AT3 -> 更新 | AV3: =変更履歴!AV3 -> 45589 | BB3: =変更履歴!BB3 -> JBS井田
A5: No. | C5: イベント名 | I5: 処理内容 | AO5: 種別 | AR5: メッセージ | BD5: ID
A6: 1. | C6: 画面初期表示
J7: 1-1. | L7: 画面初期処理
K9: 「画面レイアウト」シート通りに表示する。
A12: 2. | C12: 値入力時 | J12: 2-1. | L12: 登録処理
K14: 入力された値を[支払方法・支払サイト]に登録する。
K15: ※詳細は、「テーブル出力仕様」シートを参照

Sheet 画面レイアウト
A1: 基本設計書 | F1: =変更履歴!F1 -> システム名 | Q1: =変更履歴!Q1 -> 機能分類 | W1: =変更履歴!W1 -> 機能ＩＤ | AE1: =変更履歴!AE1 -> 機能名称 | AT1: =変更履歴!AT1 -> 日付 | BB1: =変更履歴!BB1 -> 更新者
F2: =変更履歴!F2 -> Dynamics365 for Finance and Operations | Q2: =変更履歴!Q2 -> 債権・債務 | W2: =変更履歴!W2 -> FO-006 | AE2: =変更履歴!AE2 -> 支払方法・支払サイトマスタ画面 | AT2: =変更履歴!AT2 -> 作成 | AV2: =変更履歴!AV2 -> 45448 | BB2: =変更履歴!BB2 -> JBS井田
AT3: =変更履歴!AT3 -> 更新 | AV3: =変更履歴!AV3 -> 45589 | BB3: =変更履歴!BB3 -> JBS井田
A5: パス | I5: [買掛金管理] > [支払の設定]
A6: フォーム名 | I6: SJ_PaymModePaymSiteForm
A8: タブ名

Sheet 画面項目説明
A1: 基本設計書 | F1: =変更履歴!F1 -> システム名 | Q1: =変更履歴!Q1 -> 機能分類 | W1: =変更履歴!W1 -> 機能ＩＤ | AE1: =変更履歴!AE1 -> 機能名称 | AT1: =変更履歴!AT1 -> 日付 | BB1: =変更履歴!BB1 -> 更新者
F2: =変更履歴!F2 -> Dynamics365 for Finance and Operations | Q2: =変更履歴!Q2 -> 債権・債務 | W2: =変更履歴!W2 -> FO-006 | AE2: =変更履歴!AE2 -> 支払方法・支払サイトマスタ画面 | AT2: =変更履歴!AT2 -> 作成 | AV2: =変更履歴!AV2 -> 45448 | BB2: =変更履歴!BB2 -> JBS井田
AT3: =変更履歴!AT3 -> 更新 | AV3: =変更履歴!AV3 -> 45589 | BB3: =変更履歴!BB3 -> JBS井田
A5: コントロール | H5: 項目名 | Q5: 種類 | U5: 入力 | W5: 必須 | Y5: 項目説明（概要） | BB5: 備考
A6: タイトル | Q6: タイトル | U6: × | W6: × | Y6: ＜タイトル＞
Y7: ・Caption：支払方法・支払サイト
A9: アクションペイン
H12: 保存 | Q12: ボタン | U12: × | W12: × | Y12: コマンドボタン：保存
H15: 新規 | Q15: ボタン | U15: × | W15: × | Y15: コマンドボタン：レコードの新規追加
H17: 削除 | Q17: ボタン | U17: × | W17: × | Y17: コマンドボタン：レコードの削除
A19: カスタムフィルターグループ
H23: クィックフィルター | Q23: フィルター | U23: ○ | W23: ×
A26: ボディ
H30: 支払方法 | Q30: ListBox | U30: 〇 | W30: 〇 | Y30: <表示内容/入力内容＞
Y31: [支払方法・支払サイト.支払方法]
Y34: ＜ルックアップ＞
Y35: テーブル: | AB35: [支払方法 - 仕入先]
Y36: 表示項目: | AB36: [支払方法 - 仕入先.支払方法]
AB37: [支払方法 - 仕入先.説明(Name)]
H39: 請求金額 | Q39: 数値 | U39: 〇 | W39: × | Y39: <表示内容/入力内容＞
Y40: [支払方法・支払サイト.請求金額]
Y41: ※マイナス入力不可(テーブルのプロパティ設定で対応)
Y42: ※支払方法に登録される請求金額は重複不可(テーブルのプロパティ設定で対応)
H45: 支払方法(更新後) | Q45: ListBox | U45: 〇 | W45: 〇 | Y45: <表示内容/入力内容＞
Y46: [支払方法・支払サイト.支払方法(更新後)]
Y49: ＜ルックアップ＞
Y50: テーブル: | AB50: [支払方法 - 仕入先]
Y51: 表示項目: | AB51: [支払方法 - 仕入先.支払方法]
AB52: [支払方法 - 仕入先.説明(Name)]
H54: 支払サイト | Q54: 数値 | U54: 〇 | W54: × | Y54: <表示内容/入力内容＞
Y55: [支払方法・支払サイト.支払サイト]
Y56: ※マイナス入力不可(テーブルのプロパティ設定で対応)
H57: 支払条件 | Q57: ListBox | U57: 〇 | W57: 〇 | Y57: <表示内容/入力内容＞
Y58: [支払方法・支払サイト.支払条件]
Y59: ＜ルックアップ＞
Y60: テーブル: | AB60: [支払条件 - 支払条件]
Y61: 表示項目: | AB61: [支払条件.支払条件]
AB62: [支払条件.説明]

Sheet 帳票レイアウト
A1: 基本設計書 | F1: =変更履歴!F1 -> システム名 | Q1: =変更履歴!Q1 -> 機能分類 | W1: =変更履歴!W1 -> 機能ＩＤ | AE1: =変更履歴!AE1 -> 機能名称 | AT1: =変更履歴!AT1 -> 日付 | BB1: =変更履歴!BB1 -> 更新者
F2: =変更履歴!F2 -> Dynamics365 for Finance and Operations | Q2: =変更履歴!Q2 -> 債権・債務 | W2: =変更履歴!W2 -> FO-006 | AE2: =変更履歴!AE2 -> 支払方法・支払サイトマスタ画面 | AT2: =変更履歴!AT2 -> 作成 | AV2: =変更履歴!AV2 -> 45448 | BB2: =変更履歴!BB2 -> JBS井田
AT3: =変更履歴!AT3 -> 更新 | AV3: =変更履歴!AV3 -> 45589 | BB3: =変更履歴!BB3 -> JBS井田
A5: レイアウト | AY5: 備考
A6: 帳票タイトル： | AI6: 帳票タイプ：
A7: 用紙サイズ： | L7: 用紙の向き： | X7: 自動サイズ調整： | AI7: フォント：
A8: 余白(cm) | F8: 左： | J8: 右： | N8: 上： | R8: 下： | AI8: テーブルソート設定：

Sheet 帳票出力仕様
A1: 基本設計書 | F1: =変更履歴!F1 -> システム名 | Q1: =変更履歴!Q1 -> 機能分類 | W1: =変更履歴!W1 -> 機能ＩＤ | AE1: =変更履歴!AE1 -> 機能名称 | AT1: =変更履歴!AT1 -> 日付 | BB1: =変更履歴!BB1 -> 更新者
F2: =変更履歴!F2 -> Dynamics365 for Finance and Operations | Q2: =変更履歴!Q2 -> 債権・債務 | W2: =変更履歴!W2 -> FO-006 | AE2: =変更履歴!AE2 -> 支払方法・支払サイトマスタ画面 | AT2: =変更履歴!AT2 -> 作成 | AV2: =変更履歴!AV2 -> 45448 | BB2: =変更履歴!BB2 -> JBS井田
AT3: =変更履歴!AT3 -> 更新 | AV3: =変更履歴!AV3 -> 45589 | BB3: =変更履歴!BB3 -> JBS井田
S5: 表示形式 | AB5: 配置
A6: ヘッダー/フッター/明細 | H6: No. | J6: 項目名 | S6: 書式 | V6: フォーマット | AB6: 横位置 | AE6: 縦位置 | AH6: サイズ | AK6: 最大項目長 （項目幅） | AO6: 出力値 | BL6: 備考 | CC6: 取得元テーブル | CO6: 取得元フィールド | DA6: 折り返して全体を 表示する | DG6: TmpTable | DT6: TmpTableフィールド
A8: ① ヘッダー | H8: =ROW()-7 -> 1 | DA8: ー
H9: =ROW()-7 -> 2 | DA9: ー
H10: =ROW()-7 -> 3 | DA10: ー
H11: =ROW()-7 -> 4 | DA11: ー
H12: =ROW()-7 -> 5 | DA12: ー
H13: =ROW()-7 -> 6 | DA13: ー
H14: =ROW()-7 -> 7 | DA14: ー
H15: =ROW()-7 -> 8 | DA15: ー
H16: =ROW()-7 -> 9 | DA16: ー
A17: ② 明細 | H17: =ROW()-7 -> 10 | DA17: ー
A18: （項目名） | H18: =ROW()-7 -> 11 | DA18: ー
H19: =ROW()-7 -> 12 | DA19: ー
H20: =ROW()-7 -> 13 | DA20: ー
H21: =ROW()-7 -> 14 | DA21: ー
H22: =ROW()-7 -> 15 | DA22: ー
H23: =ROW()-7 -> 16 | DA23: ー
H24: =ROW()-7 -> 17 | DA24: ー
H25: =ROW()-7 -> 18 | DA25: ー
H26: =ROW()-7 -> 19 | DA26: ー
H27: =ROW()-7 -> 20 | DA27: ー
H28: =ROW()-7 -> 21 | DA28: ー
H29: =ROW()-7 -> 22 | DA29: ー
H30: =ROW()-7 -> 23 | DA30: ー
A31: ②明細 | H31: =ROW()-7 -> 24 | DA31: ー
A32: （データ） | H32: =ROW()-7 -> 25 | DA32: ー
H33: =ROW()-7 -> 26 | DA33: ー
H34: =ROW()-7 -> 27 | DA34: ー
H35: =ROW()-7 -> 28 | DA35: ー
H36: =ROW()-7 -> 29 | DA36: ー
H37: =ROW()-7 -> 30 | DA37: ー
H38: =ROW()-7 -> 31 | DA38: ー
H39: =ROW()-7 -> 32 | DA39: ー
H40: =ROW()-7 -> 33 | DA40: ー
H41: =ROW()-7 -> 34 | DA41: ー
H42: =ROW()-7 -> 35 | DA42: ー
...

Sheet ファイルレイアウト
A1: 基本設計書 | F1: =変更履歴!F1 -> システム名 | Q1: =変更履歴!Q1 -> 機能分類 | W1: =変更履歴!W1 -> 機能ＩＤ | AE1: =変更履歴!AE1 -> 機能名称 | AT1: =変更履歴!AT1 -> 日付 | BB1: =変更履歴!BB1 -> 更新者
F2: =変更履歴!F2 -> Dynamics365 for Finance and Operations | Q2: =変更履歴!Q2 -> 債権・債務 | W2: =変更履歴!W2 -> FO-006 | AE2: =変更履歴!AE2 -> 支払方法・支払サイトマスタ画面 | AT2: =変更履歴!AT2 -> 作成 | AV2: =変更履歴!AV2 -> 45448 | BB2: =変更履歴!BB2 -> JBS井田
AT3: =変更履歴!AT3 -> 更新 | AV3: =変更履歴!AV3 -> 45589 | BB3: =変更履歴!BB3 -> JBS井田
A5: 文字コード： | I5: ファイル名称：
A6: 区切り文字： | I6: 文字列：
A7: 改行コード： | I7: ソート： | AT7: タイトル行：
A8: No. | C8: フィールド名 | Q8: 説明 | AT8: 属性 | AX8: 桁数 | AZ8: 備考
A9: =ROW()-8 -> 1
A10: =ROW()-8 -> 2
A11: =ROW()-8 -> 3
A12: =ROW()-8 -> 4
A13: =ROW()-8 -> 5
A14: =ROW()-8 -> 6
A15: =ROW()-8 -> 7
A16: =ROW()-8 -> 8
A17: =ROW()-8 -> 9
A18: =ROW()-8 -> 10
A19: =ROW()-8 -> 11
A20: =ROW()-8 -> 12
... A38: =ROW()-8 -> 30

Sheet テーブル出力仕様
A1: 基本設計書 | F1: =変更履歴!F1 -> システム名 | Q1: =変更履歴!Q1 -> 機能分類 | W1: =変更履歴!W1 -> 機能ＩＤ | AE1: =変更履歴!AE1 -> 機能名称 | AT1: =変更履歴!AT1 -> 日付 | BB1: =変更履歴!BB1 -> 更新者
F2: =変更履歴!F2 -> Dynamics365 for Finance and Operations | Q2: =変更履歴!Q2 -> 債権・債務 | W2: =変更履歴!W2 -> FO-006 | AE2: =変更履歴!AE2 -> 支払方法・支払サイトマスタ画面 | AT2: =変更履歴!AT2 -> 作成 | AV2: =変更履歴!AV2 -> 45448 | BB2: =変更履歴!BB2 -> JBS井田
AT3: =変更履歴!AT3 -> 更新 | AV3: =変更履歴!AV3 -> 45589 | BB3: =変更履歴!BB3 -> JBS井田
A5: テーブル名 | M5: SJ_PaymModePaymSiteTable
A6: ラベル | M6: 支払方法・支払サイト
A7: 拡張名
A8: No. | C8: 論理名 | M8: 物理名 | W8: 説明 | AZ8: 備考
A9: =ROW()-8 -> 1 | C9: 支払方法 | M9: PayｍMode | W9: 入力された[支払方法・支払サイト更新.支払方法]を設定
A10: =ROW()-8 -> 2 | C10: 請求金額 | M10: BillingAmount | W10: 入力された[支払方法・支払サイト更新.請求金額]を設定
A11: =ROW()-8 -> 3 | C11: 支払方法(更新後) | M11: UpdatedPaymMode | W11: 入力された[支払方法・支払サイト更新.支払方法(更新後)]を設定
A12: =ROW()-8 -> 4 | C12: 支払サイト | M12: PaymSite | W12: 入力された[支払方法・支払サイト更新.支払サイト]を設定
A13: =ROW()-8 -> 5 | C13: 支払条件 | M13: PaymTermId | W13: 入力された[支払方法・支払サイト更新.支払条件]を設定
A14: =ROW()-8 -> 6
A15: =ROW()-8 -> 7
A16: =ROW()-8 -> 8
A17: =ROW()-8 -> 9
A18: =ROW()-8 -> 10
A19: =ROW()-8 -> 11
A20: =ROW()-8 -> 12
A21: =ROW()-8 -> 13
A22: =ROW()-8 -> 14
A23: =ROW()-8 -> 15
A24: =ROW()-8 -> 16
A25: =ROW()-8 -> 17
... A40: =ROW()-8 -> 32

Sheet 補足説明 
A1: 基本設計書 | F1: =変更履歴!F1 -> システム名 | Q1: =変更履歴!Q1 -> 機能分類 | W1: =変更履歴!W1 -> 機能ＩＤ | AE1: =変更履歴!AE1 -> 機能名称 | AT1: =変更履歴!AT1 -> 日付 | BB1: =変更履歴!BB1 -> 更新者
F2: =変更履歴!F2 -> Dynamics365 for Finance and Operations | Q2: =変更履歴!Q2 -> 債権・債務 | W2: =変更履歴!W2 -> FO-006 | AE2: =変更履歴!AE2 -> 支払方法・支払サイトマスタ画面 | AT2: =変更履歴!AT2 -> 作成 | AV2: =変更履歴!AV2 -> 45448 | BB2: =変更履歴!BB2 -> JBS井田
AT3: =変更履歴!AT3 -> 更新 | AV3: =変更履歴!AV3 -> 45589 | BB3: =変更履歴!BB3 -> JBS井田
A5: 補足
B7: ●同一支払方法と請求金額のチェック処理について
C9: 支払方法 | G9: 請求金額 | L9: 支払方法(変更後) | R9: 支払サイト | V9: 支払条件
C10: TU | G10: 0 | L10: T | R10: 0 | V10: PTXX
C11: TU | G11: 500000 | L11: W | R11: 95 | V11: PTXX
C12: TU | G12: 500000 | R12: 60 | V12: PTXX
C13: TQ | G13: 0 | L13: T | R13: 0 | V13: PTXX
C14: TQ | G14: 500000 | L14: W | R14: 60 | V14: PTXX
C15: 2-1 | G15: 0 | L15: 2-1 | R15: 0 | V15: PTXX
B27: ●【テーブル定義書】SJ_PaymModePaymSiteTable.xlsx

Sheet 補足説明  (メッセージ)
A1: 基本設計書 | F1: =変更履歴!F1 -> システム名 | Q1: =変更履歴!Q1 -> 機能分類 | W1: =変更履歴!W1 -> 機能ＩＤ | AE1: =変更履歴!AE1 -> 機能名称 | AT1: =変更履歴!AT1 -> 日付 | BB1: =変更履歴!BB1 -> 更新者
F2: =変更履歴!F2 -> Dynamics365 for Finance and Operations | Q2: =変更履歴!Q2 -> 債権・債務 | W2: =変更履歴!W2 -> FO-006 | AE2: =変更履歴!AE2 -> 支払方法・支払サイトマスタ画面 | AT2: =変更履歴!AT2 -> 作成 | AV2: =変更履歴!AV2 -> 45448 | BB2: =変更履歴!BB2 -> JBS井田
AT3: =変更履歴!AT3 -> 更新 | AV3: =変更履歴!AV3 -> 45589 | BB3: =変更履歴!BB3 -> JBS井田
A5: 補足
B8: ●イベント説明2‐１,3-1のwarningのイメージ

Sheet 補足説明(機能関連図) 
A1: 基本設計書 | F1: =変更履歴!F1 -> システム名 | Q1: =変更履歴!Q1 -> 機能分類 | W1: =変更履歴!W1 -> 機能ＩＤ | AE1: =変更履歴!AE1 -> 機能名称 | AT1: =変更履歴!AT1 -> 日付 | BB1: =変更履歴!BB1 -> 更新者
F2: =変更履歴!F2 -> Dynamics365 for Finance and Operations | Q2: =変更履歴!Q2 -> 債権・債務 | W2: =変更履歴!W2 -> FO-006 | AE2: =変更履歴!AE2 -> 支払方法・支払サイトマスタ画面 | AT2: =変更履歴!AT2 -> 作成 | AV2: =変更履歴!AV2 -> 45448 | BB2: =変更履歴!BB2 -> JBS井田
AT3: =変更履歴!AT3 -> 更新 | AV3: =変更履歴!AV3 -> 45589 | BB3: =変更履歴!BB3 -> JBS井田
A5: 補足
B7: ＜機能関連図＞

Sheet 補足説明（２）
A1: 基本設計書 | F1: =変更履歴!F1 -> システム名 | Q1: =変更履歴!Q1 -> 機能分類 | W1: =変更履歴!W1 -> 機能ＩＤ | AE1: =変更履歴!AE1 -> 機能名称 | AT1: =変更履歴!AT1 -> 日付 | BB1: =変更履歴!BB1 -> 更新者
F2: =変更履歴!F2 -> Dynamics365 for Finance and Operations | Q2: =変更履歴!Q2 -> 債権・債務 | W2: =変更履歴!W2 -> FO-006 | AE2: =変更履歴!AE2 -> 支払方法・支払サイトマスタ画面 | AT2: =変更履歴!AT2 -> 作成 | AV2: =変更履歴!AV2 -> 45448 | BB2: =変更履歴!BB2 -> JBS井田
AT3: =変更履歴!AT3 -> 更新 | AV3: =変更履歴!AV3 -> 45589 | BB3: =変更履歴!BB3 -> JBS井田
A5: 補足

Sheet レビュー指摘事項
A1: 基本設計書 | F1: =変更履歴!F1 -> システム名 | Q1: =変更履歴!Q1 -> 機能分類 | W1: =変更履歴!W1 -> 機能ＩＤ | AE1: =変更履歴!AE1 -> 機能名称 | AT1: =変更履歴!AT1 -> 日付 | BB1: =変更履歴!BB1 -> 更新者
F2: =変更履歴!F2 -> Dynamics365 for Finance and Operations | Q2: =変更履歴!Q2 -> 債権・債務 | W2: =変更履歴!W2 -> FO-006 | AE2: =変更履歴!AE2 -> 支払方法・支払サイトマスタ画面 | AT2: =変更履歴!AT2 -> 作成 | AV2: =変更履歴!AV2 -> 45448 | BB2: =変更履歴!BB2 -> JBS井田
AT3: =変更履歴!AT3 -> 更新 | AV3: =変更履歴!AV3 -> 45589 | BB3: =変更履歴!BB3 -> JBS井田
A5: No. | C5: レビュー事項 | Q5: 対応内容 | AF5: 指摘日 | AK5: 指摘者 | AP5: 対応日 | AU5: 対応者 | AZ5: 確認日 | BE5: 確認者
A6: =ROW()-5 -> 1 | C6: 支払方法と支払方法(更新後)が同じ値が入らないよう、チェック処理を追加。 | Q6: 処理概要：前提条件の4追加 画面項目説明：概要を追記。 | AF6: 45517 | AK6: JBS | AP6: 45517 | AU6: JBS井田 | AZ6: 45523 | BE6: サンスター藤田
A7: =ROW()-5 -> 2 | C7: 支払基準日を「20日」で連携される方針で、本機能に支払条件を追加し、以下の場合で使用する。 ・FO-008（支払方法・支払サイト更新バッチ）で期日振込の期日更新 ・FO-010（支払手形仕訳帳の振出）で電子記録債務の期日更新 | Q7: 以下シートに支払条件を追加しました。 ・画面レイアウト ・画面項目説明 ・テーブル出力仕様 | AF7: 45531 | AK7: JBS 秋信 | AP7: 45532 | AU7: JBS井田 | AZ7: 45532 | BE7: サンスター藤田
A8: =ROW()-5 -> 3 | C8: ①支払基準日を規定払いについては、末締翌20日を固定で設定する方針で決定した。それに伴い、支払基準日を使用する機能の修正を行う。 ②支払方法マスタのコード値を文字列から英数字にする方針に決定した。それに伴い、支払方法を使用する機能の修正を行う。 ※2024/09/17の債務チームの定例会で説明済 | Q8: ① シート：処理概要 ・開発内容 項目：支払条件の追加 ・前提条件 「JPYのみ登録する」⇒削除 （海外送金に該当する支払方法も管理対象になるため、文言の削除を行う） 「支払方法と支払方法(更新後)が重複しないこと。」⇒削除 シート：DFD、イベント説明 ・「2.「支払方法」入力時」,「3.「支払方法(更新後)」入力時」の処理⇒削除 （支払方法の重複チェック処理が不要になったため処） シート：画面項目説明 「※支払方法(更新後)と重複しないこと」⇒削除 シート：画面レイアウト・画面項目説明 項目：支払条件の追加 ② シート：画面レイアウト 支払方法の最新化 シート：補足説明 支払方法の最新化 | AF8: 45553 | AK8: JBS 秋信 | AP8: 45561 | AU8: JBS 秋信 | AZ8: 45568 | BE8: サンスター藤田
A9: =ROW()-5 -> 4
A10: =ROW()-5 -> 5
A11: =ROW()-5 -> 6
A12: =ROW()-5 -> 7
A13: =ROW()-5 -> 8
A14: =ROW()-5 -> 9
A15: =ROW()-5 -> 10
A16: =ROW()-5 -> 11
A17: =ROW()-5 -> 12
A18: =ROW()-5 -> 13
A19: =ROW()-5 -> 14
A20: =ROW()-5 -> 15
... A40: =ROW()-5 -> 35

Sheet オブジェクト一覧
A1: 詳細設計書 | F1: =変更履歴!F1 -> システム名 | Q1: =変更履歴!Q1 -> 機能分類 | W1: =変更履歴!W1 -> 機能ＩＤ | AE1: =変更履歴!AE1 -> 機能名称 | AT1: =変更履歴!AT1 -> 日付 | BB1: =変更履歴!BB1 -> 更新者
F2: =変更履歴!F2 -> Dynamics365 for Finance and Operations | Q2: =変更履歴!Q2 -> 債権・債務 | W2: =変更履歴!W2 -> FO-006 | AE2: =変更履歴!AE2 -> 支払方法・支払サイトマスタ画面 | AT2: =変更履歴!AT2 -> 作成 | AV2: =変更履歴!AV2 -> 45448 | BB2: =変更履歴!BB2 -> JBS井田
AT3: =変更履歴!AT3 -> 更新 | AV3: =変更履歴!AV3 -> 45589 | BB3: =変更履歴!BB3 -> JBS井田
A5: No. | C5: オブジェクト名 | S5: 属性 | AA5: 概要 | BD5: 備考
A6: =ROW()-5 -> 1
A7: =ROW()-5 -> 2
A8: =ROW()-5 -> 3
A9: =ROW()-5 -> 4
A10: =ROW()-5 -> 5
A11: =ROW()-5 -> 6
A12: =ROW()-5 -> 7
A13: =ROW()-5 -> 8
A14: =ROW()-5 -> 9
A15: =ROW()-5 -> 10
A16: =ROW()-5 -> 11
A17: =ROW()-5 -> 12
... A38: =ROW()-5 -> 33

Sheet プログラムフロー図
A1: 詳細設計書 | F1: =変更履歴!F1 -> システム名 | Q1: =変更履歴!Q1 -> 機能分類 | W1: =変更履歴!W1 -> 機能ＩＤ | AE1: =変更履歴!AE1 -> 機能名称 | AT1: =変更履歴!AT1 -> 日付 | BB1: =変更履歴!BB1 -> 更新者
F2: =変更履歴!F2 -> Dynamics365 for Finance and Operations | Q2: =変更履歴!Q2 -> 債権・債務 | W2: =変更履歴!W2 -> FO-006 | AE2: =変更履歴!AE2 -> 支払方法・支払サイトマスタ画面 | AT2: =変更履歴!AT2 -> 作成 | AV2: =変更履歴!AV2 -> 45448 | BB2: =変更履歴!BB2 -> JBS井田
AT3: =変更履歴!AT3 -> 更新 | AV3: =変更履歴!AV3 -> 45589 | BB3: =変更履歴!BB3 -> JBS井田
A5: プログラムフロー図
A27: 凡例
A28: 記号

Sheet マスタ
A2: IO | B2: 書式 | C2: 横位置 | D2: 縦位置 | E2: 折り返して全体を表示する | F2: 表示/非表示 Visivility | G2: テーブル種別 | H2: オブジェクト
A3: I/O | B3: テキスト | C3: 標準 | D3: 標準 | E3: 〇 | F3: 表示 | G3: テーブル | H3: Class
A4: I | B4: 日付 | C4: 中央詰 | D4: 中央詰 | E4: ー | F4: 非表示 | G4: ビュー | H4: Form Class
A5: O | B5: 数値 | C5: 左詰 | D5: 上詰 | H5: Table Class
C6: 右詰 | D6: 下詰 | H6: Macro
H7: Enum
H8: EDT
H9: Queries
H10: Data Entities
H11: Maps
H12: Forms
H13: Menus
H14: Menu Items(Display)
H15: Menu Items(Output)
H16: Menu Items(Action)
H17: Repoters
H18: Security Roles
... H20: Security Policies
