Workbook

Sheet 表紙
B3: サンスター株式会社 御中
B10: 会計システム刷新プロジェクト（LIBRA）
B14: ToBe業務フロー（5.固定資産_リース）
B22: ="第"&IF(COUNTA(変更履歴!BE5:BH10004)=1,"",INDIRECT("変更履歴!BE"&COUNTA(変更履歴!BE5:BH10004)+4))&"版" -> 第1.15版
B24: {=IF(OR(COUNTA(変更履歴!A:E)=3),"",INDIRECT("変更履歴!A"&COUNTA(変更履歴!A:E)+2))} -> 45939
B26: 日本ビジネスシステムズ株式会社
F29: 作成者 | O29: JBS承認者 | V29: 承認者
F30: 45362 | N30: 45433
F31: JBS大河原 | N31: JBS加藤

Sheet 変更履歴
A1: システム名 | F1: =表紙!B10 -> 会計システム刷新プロジェクト（LIBRA） | W1: タイトル | AR1: 日付 | BA1: 更新者
A2: 文書名 | F2: =表紙!B14 -> ToBe業務フロー（5.固定資産_リース） | W2: =MID(CELL("filename",$A$1),FIND("]",CELL("filename",$A$1))+1,31) -> #VALUE! | AR2: 作成 | AT2: =A6 -> 45362 | BA2: =AZ6 -> JBS大河原
AR3: 更新 | AT3: {=IF(OR(COUNTA(A:E)=3),"",INDIRECT("A"&COUNTA(A:E)+2))} -> 45939 | BA3: {=IF(COUNTA(AZ5:BD100004)=1,"",INDIRECT("変更履歴!AZ"&COUNTA(AZ5:BD100004)+4))} -> JBS中村
A5: 変更年月日 | F5: 変更箇所 | T5: 変更内容 | AZ5: 変更者 | BE5: 版数
A6: 45362 | F6: 新規作成 | T6: 新規作成 | AZ6: JBS大河原 | BE6: 0.1
A7: 45433 | F7: 初版確定 | T7: 初版確定 | AZ7: JBS大河原 | BE7: 1.0
A8: 45495 | F8: シート「固定資産管理」 | T8: 建設仮勘定の総額を認識するフローを修正。固定資産管理シート １．固定資産取得を修正 | AZ8: JBS大河原 | BE8: 1.1
A9: 45677 | F9: シート「固定資産管理」 | T9: 建設仮勘定に関するフローを修正。固定資産管理シート １．固定資産取得 を修正 | AZ9: JBS中村 | BE9: 1.2
A10: 45701 | F10: シート「固定資産管理」 | T10: ・固定資産の通常取得：購入と資産計上が同時期に実施される場合と建設仮勘定対応：購入と資産計上の時期にずれがある場合のフローを分離 6．固定資産現物管理(分割処理) ⇒ 修正(追記) 8．固定資産台帳（随時）⇒ 追記 9．償却シミュレーション一覧（適宜）⇒ 追記 11．月次レポート（償却資産申告書作成）⇒ 修正(追記) 12．年次レポート(償却資産税情報出力（eLTAX)) ⇒ 追記 | AZ10: JBS大河原 | BE10: 1.3
A11: 45761 | F11: シート「固定資産管理」 | T11: 固定資産取得について、下記修正・追記 ・指図は生産部・研究部門、業務推進・財務にて登録 ・各部署、生産部・研究部門、業務推進・財務それぞれで取得処理を行い、最終確認は業務推進・財務で行う ・入力部署での1段階承認とし、業務推進・財務での最終確認は承認なし ・固定資産登録：少額資産・美術品について帳簿注意、財務分析コードの指定が必要 ・決済勘定へ振替（通常取得）：楽楽精算の処理は「支払」であり、貸方は一律で「未払金(設備)」となる ・振替金額の認識（建設仮勘定対応）：指図コードがない場合は財務タグで判別する | AZ11: JBS中村 | BE11: 1.4
A12: 45762 | F12: シート「固定資産管理」 | T12: 下記フロー修正・追記 ・3．固定資産現物管理（移動）：移動概要（固定資産の場所の移動）の追記 ・4．固定資産現物管理（売却・処分）：未収入金への振替を追記 ・5．固定資産現物管理（減損処理）：一般会計・決算フローとの繋がりを追記 ・11．月次レポート（償却資産申告書作成）：固定資産移動一覧の追記 | AZ12: JBS中村 | BE12: 1.5
A13: 45769 | F13: シート「固定資産管理」 | T13: 下記フロー修正・追記 下記フロー修正・追記 ・ヘッダ部：各部署と生産部・研究部門は同一フローとなるため、同一レーンとして記載 ・1-1．固定資産取得(通常取得)：建設仮勘定対応と同様、決済勘定へ振替→固定資産マスタ登録 の流れとする ・1．固定資産取得(通常取得・建設仮勘定対応)：振替金額の認識や決済勘定へ振替は各部門で行う ・1．固定資産取得(通常取得・建設仮勘定対応)：仕訳帳全体の取消は登録部署で行う ・3．固定資産現物管理（移動）：それぞれの資産の管理部署が移動処理を行う ・4．固定資産現物管理（売却・処分）：それぞれの資産の管理部署が売却・処分処理を行う ・4．固定資産現物管理（売却・処分）：各部門で承認を行い、最終確認は業務推進・財務で行う ・5．固定資産現物管理（減損処理）：減損処理の判断はシステム外となる（FO内での減損処理判断の記載削除） ・5．固定資産現物管理（減損処理）：業務推進・財務にて入力・承認を行う ・7．固定資産現物管理（圧縮記帳処理ー直接減額方式）：業務推進・財務にて入力・承認を行う ・11．年次レポート（償却資産申告書作成）：月次ではなく年次で出力となる | AZ13: JBS中村 | BE13: 1.6
A14: 45777 | F14: シート「固定資産管理」 | T14: 6．固定資産現物管理（分割処理）について、承認フローの追記 | AZ14: JBS中村 | BE14: 1.6
A15: 45779 | F15: シート「固定資産管理」 | T15: 下記フロー修正・追記 ・ヘッダ部：各部署を記載するレーンへ「山梨設備G」を追加 ・5．固定資産現物管理（減損処理）：機能制約条件の文言を削除 ・6．固定資産現物管理（分割処理）：全部署で処理を行うようフロー変更 ・８．固定資産台帳（随時）：全部署で使用するようフロー変更 | AZ15: JBS中村 | BE15: 1.6
A16: 45784 | F16: シート「固定資産管理」 | T16: 決算Gを追加。（※決算Gが固定資産計上することは、イレギュラー） | AZ16: JBS秋信 | BE16: 1.7
A17: 45786 | F17: シート「資産リース管理」 | T17: 結合テストのシナリオ作成の業務ヒアリングの結果を受け、全体的に見直しを実施。 | AZ17: JBS秋信 | BE17: 1.7
... A25: 45939 | F25: シート「固定資産管理」 | T25: ・13．固定資産の休止 新規作成 | AZ25: JBS中村 | BE25: 1.15

Sheet 凡例
A1: システム名 | F1: =変更履歴!F1 -> 会計システム刷新プロジェクト（LIBRA） | V1: タイトル | AJ1: 日付 | AQ1: 更新者
A2: 文書名 | F2: =変更履歴!F2 -> ToBe業務フロー（5.固定資産_リース） | V2: =MID(CELL("filename",$A$1),FIND("]",CELL("filename",$A$1))+1,31) -> #VALUE! | AJ2: 作成 | AL2: =変更履歴!AT2 -> 45362 | AQ2: =変更履歴!BA2 -> JBS大河原
AJ3: 更新 | AL3: =変更履歴!AT3 -> 45939 | AQ3: =変更履歴!BA3 -> JBS中村
A6: 凡例
H10: ： | I10: フローの開始 | AC10: ： | AD10: フローの終了
H15: ： | I15: システムを伴わない業務 | AC15: ： | AD15: システム上での業務
H20: ： | I20: 帳票（システムで作成される帳票） | AC20: ： | AD20: 帳票（システム外で作成される帳票）
H25: ： | I25: 業務の流れ | AC25: ： | AD25: システムへの連携
H30: ： | I30: 分岐 | AC30: ： | AD30: システム
H35: ： | I35: フロー間の繋がりを示す | AC35: ： | AD35: ファイル（CSVファイル等）
A40: 凡例
B43: 社内部署 | J43: ： | K43: フローに登場する社内の部署を記載
K44: 部署内の担当者が分かれる場合は以下の通りに分ける
B46: 社内部署
B47: 担当者 | I47: 責任者
B50: 外部担当者 | J50: ： | K50: フローに登場する社外担当者の部署を記載
K51: 例）得意先、仕入先
B54: システム | J54: ： | K54: フロー上で実施されるシステムの機能を記載する列
B55: XX | K55: XXの部分にフローで登場するシステム名を記載
K56: 例は以下の通り（JBSで導入するシステム外のものは「外部システム」で統一）
B58: システム
B59: FO | I59: CE | P59: 外部システム
B62: 説明 | S62: ： | T62: フロー内容を説明する列
B66: Gap （Add-On） | J66: ： | K66: フローに対してのGapを記載する列
B70: １．パターン１ | AI70: ： | AJ70: フローのパターンごとに記載する

Sheet 固定資産管理
A1: システム名 | F1: =変更履歴!F1 -> 会計システム刷新プロジェクト（LIBRA） | V1: タイトル | AJ1: 日付 | AQ1: 更新者
A2: 文書名 | F2: =変更履歴!F2 -> ToBe業務フロー（5.固定資産_リース） | V2: =MID(CELL("filename",$A$1),FIND("]",CELL("filename",$A$1))+1,31) -> #VALUE! | AJ2: 作成 | AL2: =変更履歴!AT2 -> 45362 | AQ2: =変更履歴!BA2 -> JBS大河原
AJ3: 更新 | AL3: =変更履歴!AT3 -> 45939 | AQ3: =変更履歴!BA3 -> JBS中村
A6: =RIGHT(CELL("filename",A1),LEN(CELL("filename",A1))-FIND("]",CELL("filename",A1))) -> #VALUE!
B8: 高槻設備G・徳島設備G・MC生産技術G・山梨設備G CH生産技術G・CH研究戦略G・購買G・ITDXG・総務G | P8: 事務管理G・決算G | AD8: システム | AR8: 説明 | BH8: Gap （Add-On） | BO8: 質問内容 | CE8: 回答
B10: 担当者 | I10: 責任者 | P10: 担当者 | W10: 責任者 | AD10: FO | AK10: 外部システム
B11: 1-1．固定資産取得(通常取得：購入と資産計上が同時期に実施される場合)
BO12: ・ | BP12: 固定資産登録を行うのは、下記グループでしょうか？ | CE12: →
AS13: ※固定資産番号の発番はFOにて行う | BP13: （仕訳帳名の作成単位となる）
AS14: ※標準承認フローは元帳転記の承認ワークフローが存在します。 | BQ14: - | BR14: 決算G承認 | BX14: … | BY14: 各部署？←こちらはどういう意味でしょうか？ | CK14: ⇒失礼しました。固定資産関連では不要Gでした。
BQ15: - | BR15: 高槻設備G | BX15: … | BY15: 各部署？生産部・研究部門
AS16: ※ | AT16: 決算Gが固定資産計上することは、イレギュラー | BQ16: - | BR16: 徳島設備G | BX16: … | BY16: 各部署？生産部・研究部門
BQ17: - | BR17: 山梨設備G | BX17: … | BY17: 生産部・研究部門
BQ18: - | BR18: MC生産技術G | BX18: … | BY18: 生産部・研究部門
BQ19: - | BR19: CH生産技術G | BX19: … | BY19: 生産部・研究部門
BQ20: - | BR20: CH研究戦略G | BX20: … | BY20: 生産部・研究部門
BQ21: - | BR21: 購買G | BX21: … | BY21: 各部署？生産部・研究部門
BQ22: - | BR22: ITDXG | BX22: … | BY22: 各部署？→はい
BQ23: - | BR23: 業務推進事務管理G | BX23: … | BY23: 業務推進・財務
BQ24: - | BR24: 総務G | BX24: … | BY24: 各部署？→はい
BP25: ⇒ | BQ25: 取得・承認を行うのは以下Gとなり、 | CE25: ⇒ | CF25: 現状は記載頂いた括りで合っております。
AS26: １．財務分析コード値の更新(指図番号の登録) | BQ26: 各括りの定義についても、認識合っておりますでしょうか？ | CF26: 今後追加で取得・承認する部署が発生した場合は
AT27: 財務分析コード値（プロジェクト：指図コード）の登録を行う。 | BQ27: - | BR27: 各部署 | BW27: ： | BX27: ITDXG・総務G | CF27: どのようにすればいいでしょうか。
AT28: ※ | AU28: 指図マスタ情報連携により、FOで登録された指図番号が | BQ28: - | BR28: 生産部・研究部門 | BW28: ： | BX28: 高槻設備G・徳島設備G・山梨設備Ｇ | CF28: ⇒ | CG28: 各種追加設定が必要となります。
AU29: 翌日以降に各外部システムへ連携される。 | BX29: ・MC生産技術G・CH生産技術G・CH研究戦略G・購買G | CG29: ① | CH29: ライセンス足りなければ追加購入（＋FOユーザー登録）
BQ30: - | BR30: 業務推進・財務 | BW30: ： | BX30: 業務推進事務管理G | CG30: ② | CH30: ユーザーグループ作成＋責任者ユーザー追加
CG31: ③ | CH31: WF定義作成＋承認ステップで追加ユーザーグループ指定
CG32: ④ | CH32: 仕訳帳名作成
CF33: ⇒②~④の追加設定は弊社で実施するのでしょうか？
AS34: 2．決済勘定へ振替 | BO34: ・ | BP34: 各部署からの指図申請は、業務推進・財務宛てとなり、 | CG34: ⇒ | CH34: 貴社作業となりますが、権限の兼ね合いでシステム管理者(ITDX？)が行う形となり、
AT35: 未払金を決済勘定へ振り替える。 | BP35: 業務推進・財務にて登録後、各部署へ登録完了連絡を | CH35: 現場の方々が行う作業にはならないかと思われます。
AT36: ※ | AU36: 楽々精算の処理は「支払」となり、 | BP36: 行う流れのイメージでしょうか？ | CE36: → | CF36: 指図コード登録は各部署にて行う
AU37: 会計伝票情報連携により、FO一般仕訳帳のデータとなる。
AU38: 仕訳例：建物決済勘定/未払金（設備） | BO38: ・ | BP38: 楽々精算での支払処理は、 | CE38: → | CF38: 支払処理は各部署(生産、研究、総務、ＩＴなど)にて行う
BP39: 業務推進・財務のみが行う形でしょうか？
BP41: ⇒ | BQ41: 指図コード登録＝財務分析コード値の更新 や支払処理も
BQ42: 各部署で行うとのことであれば、"各部署"と"生産部・研究部門"の
BQ43: 括りを分ける必要はない（業務フローは全て同じになる）
BQ44: という認識で合っていますでしょうか？ | CE44: ⇒基本同様のフローです。
AS45: 3．固定資産登録 | CF45: (現状の運用は、SSJ生産部以外は指図コード必須ではありません。)
...

Sheet 資産リース管理_old
A1: システム名 | F1: =変更履歴!F1 -> 会計システム刷新プロジェクト（LIBRA） | V1: タイトル | AJ1: 日付 | AQ1: 更新者
A2: 文書名 | F2: =変更履歴!F2 -> ToBe業務フロー（5.固定資産_リース） | V2: =MID(CELL("filename",$A$1),FIND("]",CELL("filename",$A$1))+1,31) -> #VALUE! | AJ2: 作成 | AL2: =変更履歴!AT2 -> 45362 | AQ2: =変更履歴!BA2 -> JBS大河原
AJ3: 更新 | AL3: =変更履歴!AT3 -> 45939 | AQ3: =変更履歴!BA3 -> JBS中村
A6: =RIGHT(CELL("filename",A1),LEN(CELL("filename",A1))-FIND("]",CELL("filename",A1))) -> #VALUE! | BK6: 登録は社員サポートグループも実施しているため
BK7: 担当グループ追加が必要
B8: 各部署 | L8: 購買部 | S8: 財務(事務管理) | AG8: システム | AN8: 説明 | BD8: Gap （Add-On）
S9: 担当者 | Z9: 責任者／役員 | AG9: FO
B10: １．資産リース取得
BJ11: ・使用権資産は総務の賃貸借契約を基に更新登録している
AO12: ※再リースはFO管理対象外とする | BJ12: ・車両リースはリース会社から届く車両入替情報を基に更新している
BJ13: ・社宅は社員サポートグループが社宅の賃貸借契約を基に更新している
AO16: 1．自動引落申請書発行
AP17: 各部署は引落申請を行う
AO21: 2．自動引落申請書の受領
AP22: 各部署からの引落申請書を受領する
AO28: 3．リース資産登録
AP29: リース情報を登録する。
AP30: ※50万以下は少額資産リースとして登録（自動判定） | BJ30: 50万円以下、もしくは12か月以下の契約は登録しない
AP31: 12か月以下は短期リースとして登録（自動判定）
AO33: 判定条件
AP34: 300万円以上のリース資産の場合、 | BJ34: 「リース料総額」が300万円以上（税抜）の場合～に変更
AP35: 日本基準・IFRSで固定資産計上 | BJ35: 50万円以上300万円未満（税抜）の資産はIFRS帳簿のみ資産計上
AO38: 4．固定資産登録 | BJ38: 正：資産リース登録
AP39: 固定資産として計上する場合は、固定資産情報 | BJ39: リース資産として登録する場合は、リース資産マスタに情報登録する
AP40: を登録する。
AP41: 登録後、固定資産番号をリース情報に登録する
AO44: 5．支払スケジュールの作成
AP45: リース会社より提示された支払スケジュールを登録
AO50: 6．支払スケジュールの確認 | BJ50: 責任者の支払スケジュール確認は不要
AP51: 作成した支払スケジュールを確認（承認）する
BJ55: 不要
AO65: 7．支払スケジュールの確認
AP66: 初年度負債計上を押下後、資産リース仕訳にて
AP67: リース資産/負債を計上する
BJ69: 担当者が登録後に責任者が承認を行う
BJ70: 責任者は、承認時に4のマスタ登録と5の支払スケジュールも併せて確認
BJ71: した上で承認を行う
B75: 2．リース支払いスケジュールの計上・転記
BJ76: 資産リース取得の5と重複している
AO82: 1．仕訳帳の作成
...

Sheet 資産リース管理_old20250730
A1: システム名 | F1: =変更履歴!F1 -> 会計システム刷新プロジェクト（LIBRA） | AC1: タイトル | AQ1: 日付 | AX1: 更新者
A2: 文書名 | F2: =変更履歴!F2 -> ToBe業務フロー（5.固定資産_リース） | AC2: =MID(CELL("filename",$A$1),FIND("]",CELL("filename",$A$1))+1,31) -> #VALUE! | AQ2: 作成 | AS2: =変更履歴!AT2 -> 45362 | AX2: =変更履歴!BA2 -> JBS大河原
AQ3: 更新 | AS3: =変更履歴!AT3 -> 45939 | AX3: =変更履歴!BA3 -> JBS中村
A6: =RIGHT(CELL("filename",A1),LEN(CELL("filename",A1))-FIND("]",CELL("filename",A1))) -> #VALUE!
B8: 各部署 | L8: 社員サポートG | Z8: 事務管理G | AN8: システム | AU8: 説明 | BK8: Gap （Add-On）
L9: 担当者 | S9: 責任者／役員 | Z9: 担当者 | AG9: 責任者／役員 | AN9: FO
B10: １．資産リース取得
AV12: ※再リースはFO管理対象外とする
AV14: ・使用権資産は総務の賃貸借契約を基に更新登録している
AV15: ・車両リースはリース会社から届く車両入替情報を基に更新している
AV16: ・社宅は社員サポートグループが社宅の賃貸借契約を基に更新している
AV19: 1．自動引落申請書発行
AW20: 各部署は引落申請を行う
AV24: 2．自動引落申請書の受領
AW25: 各部署からの引落申請書を受領する
AV31: 3．リース資産登録
AW32: リース情報を登録する。
AV37: 4．リースに紐づく帳簿の作成
AW38: 登録したリースに帳簿を作成する。
AV43: 支払リース料総額（税抜）が300万円以上かどうかで判断
AV44: 社員サポートGは使用権資産のみ登録
AV50: 5．不要な帳簿の削除
AW51: ファイナンスリースにおいて、300万未満のリースで
AW52: 不要な帳簿（会社会計、税務）の削除を行う。
AV59: 6．支払スケジュール確定処理
AW60: 確認バッチを使用して、登録したリースの支払スケジュール
AW61: の確定処理を行う。
AV66: 7．初期認識
AW67: 初期認識を行い、リース資産計上の仕訳登録を行う。
AW68: ※ | AX68: スケジュールの選択：初期認識
AW69: ※ | AX69: 転記：いいえ を選択
AV73: 8．リース資産計上仕訳の承認依頼
AW74: 作成されたリース資産計上の仕訳の承認依頼を行う。
AW75: ※ | AX75: 各帳簿ごとに承認依頼作業を行う。
AV82: 9．リース資産計上仕訳の承認
AW83: 責任者は作成されたリース資産計上の仕訳の承認を行う。
AW84: 責任者はマスタ登録も併せて内容確認した上で承認を行う
AW85: ※ | AX85: 各帳簿ごとに承認作業を行う。
AW86: 【仕訳例】
AW87: リース資産 | BA87: リース債務(固定)
...

Sheet 資産リース管理
A1: システム名 | F1: =変更履歴!F1 -> 会計システム刷新プロジェクト（LIBRA） | V1: タイトル | AJ1: 日付 | AQ1: 更新者
A2: 文書名 | F2: =変更履歴!F2 -> ToBe業務フロー（5.固定資産_リース） | V2: =MID(CELL("filename",$A$1),FIND("]",CELL("filename",$A$1))+1,31) -> #VALUE! | AJ2: 作成 | AL2: =変更履歴!AT2 -> 45362 | AQ2: =変更履歴!BA2 -> JBS大河原
AJ3: 更新 | AL3: =変更履歴!AT3 -> 45939 | AQ3: =変更履歴!BA3 -> JBS中村
A6: =RIGHT(CELL("filename",A1),LEN(CELL("filename",A1))-FIND("]",CELL("filename",A1))) -> #VALUE!
B8: 各部署 | L8: 社員サポートG | Z8: 事務管理G | AN8: ITDX | AU8: システム | BB8: 説明 | BR8: Gap （Add-On）
L9: 担当者 | S9: 責任者 | Z9: 担当者 | AG9: 責任者 | AU9: FO
B10: １．資産リース取得
BC12: ※再リースはFO管理対象外とする
BC14: ・使用権資産は総務の賃貸借契約を基に更新登録している
BC15: ・車両リースはリース会社から届く車両入替情報を基に更新している
BC16: ・社宅は社員サポートグループが社宅の賃貸借契約を基に更新している
BC18: ※2027年以降の新会計基準での対応検討が必要
BC22: 1．自動引落申請書発行
BD23: 各部署は引落申請を行う
BC27: 2．自動引落申請書の受領
BD28: 各部署からの引落申請書を受領する
BC34: 3．リース資産登録
BD35: リース情報を登録する。
BC40: 4．リースに紐づく帳簿の作成
BD41: 登録したリースに帳簿を作成する。
BC46: 支払リース料総額（税抜）が300万円以上かどうかで判断
BC47: 社員サポートGは使用権資産のみ登録
BC53: 5．不要な帳簿の削除
BD54: ファイナンスリースにおいて、300万未満のリースで
BD55: 不要な帳簿（会社会計、税務）の削除を行う。
BC62: ６．消費税額の登録
BD63: 300万以上ファイナンスリースは、リース債務を
BD64: 税込みで登録を行う。
BD65: リース資産には、消費税を含めないために、
BD66: リースインセンティブ項目を使用して、消費税金額分
BD67: 控除するよう登録を行う。
BD68: ※300万円以上のファイナンスリースは税込の
BD69: 月額リース料、見積購入価格を基に利率を算出
BC71: ７．支払スケジュール確定処理
BD72: 確認バッチを使用して、登録したリースの支払スケジュール
BD73: の確定処理を行う。
BC78: ８．初期認識
BD79: 初期認識を行い、リース資産計上の仕訳登録を行う。
BD80: ※ | BE80: スケジュールの選択：初期認識
BD81: ※ | BE81: 転記：いいえ を選択
...

Sheet 資産リース管理 (JBS整理中)_0509
A1: システム名 | F1: =変更履歴!F1 -> 会計システム刷新プロジェクト（LIBRA） | AC1: タイトル | AQ1: 日付 | AX1: 更新者
A2: 文書名 | F2: =変更履歴!F2 -> ToBe業務フロー（5.固定資産_リース） | AC2: =MID(CELL("filename",$A$1),FIND("]",CELL("filename",$A$1))+1,31) -> #VALUE! | AQ2: 作成 | AS2: =変更履歴!AT2 -> 45362 | AX2: =変更履歴!BA2 -> JBS大河原
AQ3: 更新 | AS3: =変更履歴!AT3 -> 45939 | AX3: =変更履歴!BA3 -> JBS中村
A6: =RIGHT(CELL("filename",A1),LEN(CELL("filename",A1))-FIND("]",CELL("filename",A1))) -> #VALUE!
BQ7: 登録は社員サポートグループも実施しているため
B8: 各部署 | L8: 社員サポートG | Z8: 事務管理G | AN8: システム | AU8: 説明 | BK8: Gap （Add-On） | BQ8: 担当グループ追加が必要
L9: 担当者 | S9: 責任者／役員 | Z9: 担当者 | AG9: 責任者／役員 | AN9: FO | BQ9: ⇒JBS：スイムレーンを追加しました。
B10: １．資産リース取得
BQ11: ・使用権資産は総務の賃貸借契約を基に更新登録している
AV12: ※再リースはFO管理対象外とする | BQ12: ・車両リースはリース会社から届く車両入替情報を基に更新している
BQ13: ・社宅は社員サポートグループが社宅の賃貸借契約を基に更新している
AV16: 1．自動引落申請書発行
AW17: 各部署は引落申請を行う
AV21: 2．自動引落申請書の受領
AW22: 各部署からの引落申請書を受領する
AV28: 3．リース資産登録
AW29: リース情報を登録する。
AV34: 4．リースに紐づく帳簿の作成
AW35: 登録したリースに帳簿を作成する。
BQ39: 支払リース料総額（税抜）が300万円以上かどうかで判断
BQ41: 社員サポートGは使用権資産のみ登録のためファイナンスリース
BQ42: は登録しないため300万円の判定は不要
AV47: 5．不要な帳簿の削除
AW48: ファイナンスリースにおいて、300万未満のリースで | BQ48: IFRS帳簿のみ登録のため、会社会計、税務は登録不要
AW49: 不要な帳簿（会社会計、税務）の削除を行う。
AV56: 6．支払スケジュール確定処理
AW57: 確認バッチを使用して、登録したリースの支払スケジュール
AW58: の確定処理を行う。
AV63: 7．初期認識
AW64: 初期認識を行い、リース資産計上の仕訳登録を行う。
AW65: ※ | AX65: スケジュールの選択：初期認識
AW66: ※ | AX66: 転記：いいえ を選択
AV70: 8．リース資産計上仕訳の承認依頼
AW71: 作成されたリース資産計上の仕訳の承認依頼を行う。
AW72: ※ | AX72: 各帳簿ごとに承認依頼作業を行う。
AV79: 9．リース資産計上仕訳の承認 | BQ79: 担当者が登録後に責任者が承認を行う
AW80: 作成されたリース資産計上の仕訳の承認を行う。 | BQ80: 責任者は、承認時に5のマスタ登録も併せて内容確認した上で承認を行う
AW81: ※ | AX81: 各帳簿ごとに承認作業を行う。
AW82: 【仕訳例】
AW83: リース資産 | BA83: リース債務(固定)
...
