Workbook

Sheet 表紙
B3: サンスター株式会社 御中
B10: 会計システム刷新プロジェクト（LIBRA）
B14: ToBe業務フロー（3.債権）
B22: ="第"&IF(COUNTA(変更履歴!BE5:BH10012)=1,"",INDIRECT("変更履歴!BE"&COUNTA(変更履歴!BE5:BH10012)+4))&"版" -> 第1.12版
B24: {=IF(OR(COUNTA(変更履歴!A:E)=3),"",INDIRECT("変更履歴!A"&COUNTA(変更履歴!A:E)+2))} -> 45846
B26: 日本ビジネスシステムズ株式会社
F29: 作成者 | O29: JBS承認者 | V29: 承認者
F30: 45365 | N30: 45433
F31: JBS加藤 | N31: JBS入井

Sheet 変更履歴
A1: システム名 | F1: =表紙!B10 -> 会計システム刷新プロジェクト（LIBRA） | W1: タイトル | AR1: 日付 | BA1: 更新者
A2: 文書名 | F2: =表紙!B14 -> ToBe業務フロー（3.債権） | W2: =MID(CELL("filename",$A$1),FIND("]",CELL("filename",$A$1))+1,31) -> 変更履歴 | AR2: 作成 | AT2: =A6 -> 45365 | BA2: =AZ6 -> JBS加藤
AR3: 更新 | AT3: {=IF(OR(COUNTA(A:E)=3),"",INDIRECT("A"&COUNTA(A:E)+2))} -> 45846 | BA3: {=IF(COUNTA(AZ5:BD100012)=1,"",INDIRECT("変更履歴!AZ"&COUNTA(AZ5:BD100012)+4))} -> JBS加藤
A5: 変更年月日 | F5: 変更箇所 | T5: 変更内容 | AZ5: 変更者 | BE5: 版数
A6: 45365 | F6: 新規作成 | T6: 新規作成 | AZ6: JBS加藤 | BE6: 0.1
A7: 45433 | F7: 初版確定 | T7: 初版確定 | AZ7: JBS加藤 | BE7: 1.0
A8: 45586 | F8: シート：1.SSJ・SEJ売上計上・請求処理 (売掛金) シート：2.SLJ売上計上・請求処理 (売掛金) シート：3.SSJ・SEJ入金 (売掛金) シート：5.SSJ・SEJ入金消込 (売掛金) | T8: 外部システムからの連携先から自由書式の請求書を削除（一般仕訳帳に登録する） | AZ8: JBS秋信 | BE8: 1.1
A9: 45586 | F9: シート：7.その他取引計上 | T9: 1.未収入金計上 3～5のシステムをFO⇒JUST.DBに変更 | AZ9: JBS秋信 | BE9: 1.1
A10: 45638 | F10: シート：11.SSJ与信管理 シート：12.SEJ与信管理 | T10: スイムレーンを「カスタマーサービスG」 ⇒ 「事務管理G」 に変更 | AZ10: JBS秋信 | BE10: 1.2
A11: 45638 | F11: シート：13.決算処理 | T11: 3.売掛金振替 【SSJ】 外部システムを「楽楽精算」 ⇒ 「mcframe」 に変更 FOシステム「顧客支払仕訳帳」 ⇒ 「一般仕訳帳」 に変更 | AZ11: JBS秋信 | BE11: 1.2
A12: 45638 | F12: シート：7.その他取引計上 | T12: 3. 預り金処理 返金処理 5.委託費 システムを「JUST D.B.」に変更 | AZ12: JBS秋信 | BE12: 1.2
A13: 45649 | F13: シート：7.その他取引計上 | T13: 3. 預り金処理 返金処理 FOでの業務を記載 | AZ13: JBS秋信 | BE13: 1.3
A14: 45652 | F14: シート：8.入金 (未収入金・その他) | T14: ・「2．入金（前受）」から、「2．入金（前受 売掛金）」に変更 ・「2．入金（前受 売掛金）」をカスタマーサービスGがJUST D.B.で入力する流れで、後続の業務フローも修正 ・「2．入金（前受 売掛金）」の接続先を「9.2.前受消込」から、「終了」に変更 | AZ14: JBS秋信 | BE14: 1.4
A15: 45652 | F15: シート：9.入金消込 (未収入金) | T15: 「9.2.前受消込」を削除 | AZ15: JBS秋信 | BE15: 1.4
A16: 45652 | F16: シート：7.その他取引計上 | T16: 「4. 預り金処理 売掛金振替」を削除 上記対応に伴い、番号の見直しを実施 | AZ16: JBS秋信 | BE16: 1.4
A17: 45679 | F17: シート：7.その他取引計上 | T17: 1.未収入金計上 未収入金をFOに登録する業務を追加 | AZ17: JBS秋信 | BE17: 1.5
... A32: 45846 | F32: シート：7.その他取引計上 | T32: 6.家賃収入 収益計上（SLJ） 楽楽精算ではなく、FOの一般仕訳帳アップロードで計上するように変更 | AZ32: JBS加藤 | BE32: 1.12

Sheet 凡例
A1: システム名 | F1: =変更履歴!F1 -> 会計システム刷新プロジェクト（LIBRA） | V1: タイトル | AJ1: 日付 | AQ1: 更新者
A2: 文書名 | F2: =変更履歴!F2 -> ToBe業務フロー（3.債権） | V2: =MID(CELL("filename",$A$1),FIND("]",CELL("filename",$A$1))+1,31) -> 凡例 | AJ2: 作成 | AL2: =変更履歴!AT2 -> 45365 | AQ2: =変更履歴!BA2 -> JBS加藤
AJ3: 更新 | AL3: =変更履歴!AT3 -> 45846 | AQ3: =変更履歴!BA3 -> JBS加藤
A6: 凡例
H10: ： | I10: フローの開始 | AC10: ： | AD10: フローの終了
H15: ： | I15: システムを伴わない業務 | AC15: ： | AD15: システム上での業務
H20: ： | I20: 帳票（システムで作成される帳票） | AC20: ： | AD20: 帳票（システム外で作成される帳票）
H25: ： | I25: 業務の流れ | AC25: ： | AD25: システムへの連携
H30: ： | I30: 分岐 | AC30: ： | AD30: システム
H35: ： | I35: フロー間の繋がりを示す | AC35: ： | AD35: ファイル（CSVファイル等）
A40: 凡例
B43: 社内部署 | J43: ： | K43: フローに登場する社内の部署を記載
K44: 部署内の担当者が分かれる場合は以下の通りに分ける
B46: 社内部署
B47: 担当者 | I47: 責任者
B50: 外部担当者 | J50: ： | K50: フローに登場する社外担当者の部署を記載
K51: 例）得意先、仕入先
B54: システム | J54: ： | K54: フロー上で実施されるシステムの機能を記載する列
B55: XX | K55: XXの部分にフローで登場するシステム名を記載
K56: 例は以下の通り（JBSで導入するシステム外のものは「外部システム」で統一）
B58: システム
B59: FO | I59: CE | P59: 外部システム
B62: 説明 | S62: ： | T62: フロー内容を説明する列
B66: Gap （Add-On） | J66: ： | K66: フローに対してのGapを記載する列
B70: １．パターン１ | AI70: ： | AJ70: フローのパターンごとに記載する

Sheet 1.SSJ・SEJ売上計上・請求処理 (売掛金)
A1: システム名 | F1: =変更履歴!F1 -> 会計システム刷新プロジェクト（LIBRA） | V1: タイトル | AJ1: 日付 | AQ1: 更新者
A2: 文書名 | F2: =変更履歴!F2 -> ToBe業務フロー（3.債権） | V2: =MID(CELL("filename",$A$1),FIND("]",CELL("filename",$A$1))+1,31) -> 1.SSJ・SEJ売上計上・請求処理 (売掛金) | AJ2: 作成 | AL2: =変更履歴!AT2 -> 45365 | AQ2: =変更履歴!BA2 -> JBS加藤
AJ3: 更新 | AL3: =変更履歴!AT3 -> 45846 | AQ3: =変更履歴!BA3 -> JBS加藤
A6: =RIGHT(CELL("filename",A1),LEN(CELL("filename",A1))-FIND("]",CELL("filename",A1))) -> 1.SSJ・SEJ売上計上・請求処理 (売掛金)
B8: 得意先 | I8: カスタマーサービスG 他 | P8: システム | AD8: 説明 | AT8: Gap （Add-On） | BB8: サンスター 担当部署・ 担当者 | BF8: サンスターコメント (現状との違い、補足、その他気になること)
P9: FO | W9: 外部システム
B10: １．売上
AE12: ※ | AF12: 本フローは、売上・債権計上を行い、個別請求・締め請求 | BB12: ｶｽﾀﾏｰｻｰﾋﾞｽ | BF12: SSJ mcframeで対応
AF13: それぞれでの請求書の発行・送付について記載している。 | BB13: ｸﾞﾙｰﾌﾟ | BF13: SEJ AS400で対応
BB14: 房
AE17: １．売上対象伝票の確認
AE22: ２．売上の計上
AE33: 外部システムより、売上実績データを取り込む | AT33: Gap
AF34: SSJ：mcframeから連携 | AT34: 取込機能が必要（IF）
AF35: SEJ：SEJホスト（AS400）から連携 | AU35: FO-001：会計伝票情報取込
AU36: FO-097：会計伝票情報登録
AE37: ※ | AF37: SSJ/SEJについて、
AF38: 受取手形、売掛金勘定はFO上AR管理しない想定。
AE40: ※ | AF40: 未収入金の連携あり
AF41: 仕訳例：未収入金 / 原材料売買額
B57: ２．都度請求
AE63: １．請求書の発行
AE69: ２．請求書の送付
AF70: 得意先へ請求書を送付する。
AE75: ３．請求書の受領
AF76: 得意先が請求書を受領する。
B92: ３．締め請求
AE98: １．請求の締め処理
AF99: 請求締め処理を行う。
AE104: ２．締め処理の確定
AF105: 作成された月次締め請求データの内容を確認し、
AF106: 確定処理を行う。
AE109: ３．請求書の発行
AF110: 月次締め請求書画面より請求書を発行する。
AE115: ４．請求書の送付
AF116: 得意先へ請求書を送付する。
AE120: ５．請求書の受領
AF121: 得意先が請求書を受領する。

Sheet 2.SLJ売上計上・請求処理 (売掛金)
A1: システム名 | F1: =変更履歴!F1 -> 会計システム刷新プロジェクト（LIBRA） | V1: タイトル | AJ1: 日付 | AQ1: 更新者
A2: 文書名 | F2: =変更履歴!F2 -> ToBe業務フロー（3.債権） | V2: =MID(CELL("filename",$A$1),FIND("]",CELL("filename",$A$1))+1,31) -> 2.SLJ売上計上・請求処理 (売掛金) | AJ2: 作成 | AL2: =変更履歴!AT2 -> 45365 | AQ2: =変更履歴!BA2 -> JBS加藤
AJ3: 更新 | AL3: =変更履歴!AT3 -> 45846 | AQ3: =変更履歴!BA3 -> JBS加藤
A6: =RIGHT(CELL("filename",A1),LEN(CELL("filename",A1))-FIND("]",CELL("filename",A1))) -> 2.SLJ売上計上・請求処理 (売掛金)
B8: 得意先 | I8: 顧客G・物流 | W8: ITDX | AD8: システム | AR8: 説明 | BH8: Gap （Add-On） | BP8: サンスター 担当部署・ 担当者 | BT8: サンスターコメント (現状との違い、補足、その他気になること)
I9: 担当者 | P9: 責任者 | W9: 担当者 | AD9: FO | AK9: 外部システム
B10: １．売上
AS12: ※ | AT12: 本フローは、売上・債権計上を行い、個別請求・締め請求 | BP12: SLJ商品売上：SLJ顧客
AT13: それぞれでの請求書の発行・送付について記載している。 | BP13: SLJ物流売上：物流
AS17: １．売上対象伝票の確認
AS22: ２．売上の計上
AS33: 外部システムより、売上実績データを取り込む | BH33: Gap
AT34: SLJ：販売管理システムから連携 | BH34: 取込機能が必要（IF）
BI35: FO-001：会計伝票情報取込
BI36: FO-097：会計伝票情報登録
B57: 2．売上（FO直接計上）
AS59: ※ | AT59: 本フローは、売上・債権計上を行い、個別請求・締め請求
AT60: それぞれでの請求書の発行・送付について記載している。
AS64: 1．売上データ登録
AT65: 売上データの登録を行う。
AT67: 仕訳例：売掛金（得意先）／ 配送収入
AS69: 2．伝票承認申請
AT70: 仕訳帳の承認申請を行う。
AS74: 3．伝票承認
AT75: 申請された仕訳帳を確認し、承認を行う。
AS80: 4．自動転記バッチ
AT81: スケジュールされたバッチ処理により
AT82: 承認済仕訳帳が自動転記処理される
B104: 3．都度請求
AS110: １．請求書の発行
AS116: ２．請求書の送付
AT117: 得意先へ請求書を送付する。
AS122: ３．請求書の受領
AT123: 得意先が請求書を受領する。
B139: 4．締め請求
AS145: １．請求の締め処理
AT146: 請求締め処理を行う。
AS151: ２．締め処理の確定
AT152: 作成された月次締め請求データの内容を確認し、
AT153: 確定処理を行う。
...

Sheet 3.SSJ・SEJ入金 (売掛金)
A1: システム名 | F1: =変更履歴!F1 -> 会計システム刷新プロジェクト（LIBRA） | V1: タイトル | AJ1: 日付 | AQ1: 更新者
A2: 文書名 | F2: =変更履歴!F2 -> ToBe業務フロー（3.債権） | V2: =MID(CELL("filename",$A$1),FIND("]",CELL("filename",$A$1))+1,31) -> 3.SSJ・SEJ入金 (売掛金) | AJ2: 作成 | AL2: =変更履歴!AT2 -> 45365 | AQ2: =変更履歴!BA2 -> JBS加藤
AJ3: 更新 | AL3: =変更履歴!AT3 -> 45846 | AQ3: =変更履歴!BA3 -> JBS加藤
A6: =RIGHT(CELL("filename",A1),LEN(CELL("filename",A1))-FIND("]",CELL("filename",A1))) -> 3.SSJ・SEJ入金 (売掛金)
B8: 得意先 | I8: 銀行 | P8: カスタマーサービスG | AC8: 事務管理G | AP8: システム | BD8: 説明 | BT8: Gap （Add-On） | CC8: サンスター 担当部署・ 担当者 | CG8: サンスターコメント (現状との違い、補足、その他気になること)
AP9: FO | AW9: 外部システム
B10: １．入金（EB取り込み） 売上回収専用口座への入金
BE16: 1．入金情報提示 | CG16: 売上回収用の口座に入金された場合、 | CT16: 業務推進部？SCM部？→売上請求についてはホストで自動入金。
BF17: 銀行から入金情報が提示される。 | CG17: 自動入金処理がされる。自動処理しきれない場合は
CG18: ホスト側で受注管理Gが入金入力をする
CG20: 売上回収専用口座以外で入金がされた場合、
BE21: 2．EBデータダウンロード | CG21: 例えば海外からの入金
BF22: 銀行システムよりEB取り込みデータをダウンロードする。 | CG22: 事務管理Gから受注管理Gに連絡がされ、
CG23: ホスト側で受注管理Gが入金入力をする
BE26: 3．EBデータ取り込み
BF27: ダウンロードしたEBデータの取り込み実施する。
BF28: 自動で入金伝票登録が行われる。
BE35: 4．EBデータ取込結果確認
BF36: EB取り込みを行った結果を確認する。
BF37: ※入金元が特定できない場合を想定
BE46: 6．不明入金調査
BF47: 不明入金の調査を行う。
BE53: 5．入金入力
BF54: 特定した入金の登録を行う。
BT58: Gap
BT59: 取込機能が必要（IF）
BU60: FO-001：会計伝票情報取込
BU61: FO-097：会計伝票情報登録
B68: 2．入金（EB取り込み） 売上回収専用口座以外への入金
CT74: 業務推進部？SCM部？→売上請求についてはホストで自動入金。
BE76: 1．入金情報提示
BF77: 銀行から入金情報が提示される。
CG78: 売上回収専用口座以外で入金がされた場合、
CG79: 例えば海外からの入金
BE80: 2．入金確認 | CG80: 事務管理Gから受注管理Gに連絡がされ、
BF81: 入金を確認する。 | CG81: ホスト側で受注管理Gが入金入力をする
BE84: 3．入金連絡
BF85: 売上回収専用口座以外で入金がされた場合、
BF86: 受注管理Gへ入金の連絡を行う
BE92: 4．入金入力
...

Sheet 4.SLJ入金 (売掛金) 
A1: システム名 | F1: =変更履歴!F1 -> 会計システム刷新プロジェクト（LIBRA） | V1: タイトル | AJ1: 日付 | AQ1: 更新者
A2: 文書名 | F2: =変更履歴!F2 -> ToBe業務フロー（3.債権） | V2: =MID(CELL("filename",$A$1),FIND("]",CELL("filename",$A$1))+1,31) -> 4.SLJ入金 (売掛金) | AJ2: 作成 | AL2: =変更履歴!AT2 -> 45365 | AQ2: =変更履歴!BA2 -> JBS加藤
AJ3: 更新 | AL3: =変更履歴!AT3 -> 45846 | AQ3: =変更履歴!BA3 -> JBS加藤
A6: =RIGHT(CELL("filename",A1),LEN(CELL("filename",A1))-FIND("]",CELL("filename",A1))) -> 4.SLJ入金 (売掛金)
B8: 得意先 | I8: 銀行 | P8: 顧客G・物流 | AP8: ITDX | AW8: システム | BK8: 説明 | CA8: Gap （Add-On） | CH8: サンスター 担当部署・ 担当者 | CL8: サンスターコメント (現状との違い、補足、その他気になること)
P9: 担当者 | AC9: 責任者 | AP9: 担当者 | AW9: FO | BD9: 外部システム
B10: １．入金（EB取り込み）
BL16: 1．入金情報提示
BM17: 銀行から入金情報が提示される。
BL21: 2．EBデータダウンロード
BM22: 銀行システムよりEB取り込みデータをダウンロードする。
BL28: 3．EBデータ取り込み
BM29: FOの顧客支払仕訳帳画面にて仕訳帳を作成し、
BM30: 手順2でダウンロードしたEBデータの取り込み実施する。
BL35: 4．伝票承認申請
BM36: EBデータを取り込んだ仕訳帳の承認申請を行う。
BL40: 5．伝票承認
BM41: 申請された仕訳帳を確認し、承認を行う。
BL45: 6．自動転記バッチ
BM46: スケジュールされたバッチ処理により | CA46: アドオン機能
BM47: 承認済仕訳帳が自動転記処理される | CA47: Req377
CA48: FO-034：自動転記バッチ
B57: ２．入金（EB取り込み以外）
BL66: １．銀行振込確認
BM67: 経理が債権に対する入金がされているかどうかを確認する。 | CY67: 業務推進部？SCM部？
BL70: ２．未回収データ確認
BM71: 経理がFOの期日が超過した顧客請求書画面から | CY71: 業務推進部？SCM部？
BM72: 未回収データを確認する。
BL74: ３．債権データの紐づけ
BM75: FOの顧客支払仕訳帳画面にて仕訳帳を作成し、
BM76: 支払提案の機能から入金対象のデータを選択する。
BM77: ※ | BN77: 入金手段ごと（銀行振込の場合は、銀行口座ごと）
BN78: に仕訳帳名を用意しておき、適切な相手勘定を
BN79: 初期値として設定しておけば入力ミスの予防となる。
BL84: ４．修正連絡
BM85: 入金内容に誤りがある場合は、その旨顧客に連絡する。 | CY85: 入金予定(予定日)とのチェックは無いのか？
BM86: ・過入金
BN87: 顧客了承の元、翌請求分を消し込むor前受け金として処理
BM88: ・入金不足
BN89: 顧客と交渉し、翌請求分にて不足分を請求
...

Sheet 5.SSJ・SEJ入金消込 (売掛金)
A1: システム名 | F1: =変更履歴!F1 -> 会計システム刷新プロジェクト（LIBRA） | V1: タイトル | AJ1: 日付 | AQ1: 更新者
A2: 文書名 | F2: =変更履歴!F2 -> ToBe業務フロー（3.債権） | V2: =MID(CELL("filename",$A$1),FIND("]",CELL("filename",$A$1))+1,31) -> 5.SSJ・SEJ入金消込 (売掛金) | AJ2: 作成 | AL2: =変更履歴!AT2 -> 45365 | AQ2: =変更履歴!BA2 -> JBS加藤
AJ3: 更新 | AL3: =変更履歴!AT3 -> 45846 | AQ3: =変更履歴!BA3 -> JBS加藤
A6: =RIGHT(CELL("filename",A1),LEN(CELL("filename",A1))-FIND("]",CELL("filename",A1))) -> 5.SSJ・SEJ入金消込 (売掛金)
B8: 銀行 | I8: カスタマーサービスG | V8: システム | AJ8: 説明 | AZ8: Gap （Add-On） | BG8: サンスター 担当部署・ 担当者 | BK8: サンスターコメント (現状との違い、補足、その他気になること)
V9: FO | AC9: 外部システム
B10: １．入金消込
BL11: 事務管理グループでは売掛金以外の未収入金の消込を行っております。このフローは売掛金の消込でしょうか？未収入金の消込でしょうか？ 売掛金は現在消込を行っておりませんが、今後発生するフローでしょうか？ （事務管理：藤田、安東）
BG12: 事務管理？
BG13: カスタマー？
AK17: １．入金消込
AL18: 請求データ（債権）と入金データの消込を実施
BK20: 売掛金の消込
BG21: ｶｽﾀﾏｰｻｰﾋﾞｽ | BK21: SSJ mcframeで対応
AZ22: Gap | BG22: ｸﾞﾙｰﾌﾟ | BK22: SEJ AS400で対応
AZ23: 取込機能が必要（IF） | BG23: 房
BA24: FO-001：会計伝票情報取込
BA25: FO-097：会計伝票情報登録
B33: ２．前受消込
AK41: １．前受金データ確認
AL42: 前受金データを確認する | BX42: 前受金の定義は？入金過多？事前に取引先から連絡？
AK48: 2．前受入金と受注データの紐づけ
AL49: 前受け入金と受注データを紐づける

Sheet 6.SLJ入金消込 (売掛金) 
A1: システム名 | F1: =変更履歴!F1 -> 会計システム刷新プロジェクト（LIBRA） | V1: タイトル | AJ1: 日付 | AQ1: 更新者
A2: 文書名 | F2: =変更履歴!F2 -> ToBe業務フロー（3.債権） | V2: =MID(CELL("filename",$A$1),FIND("]",CELL("filename",$A$1))+1,31) -> 6.SLJ入金消込 (売掛金) | AJ2: 作成 | AL2: =変更履歴!AT2 -> 45365 | AQ2: =変更履歴!BA2 -> JBS加藤
AJ3: 更新 | AL3: =変更履歴!AT3 -> 45846 | AQ3: =変更履歴!BA3 -> JBS加藤
A6: =RIGHT(CELL("filename",A1),LEN(CELL("filename",A1))-FIND("]",CELL("filename",A1))) -> 6.SLJ入金消込 (売掛金)
B8: 銀行 | I8: 顧客G・物流 | V8: システム | AJ8: 説明 | AZ8: Gap （Add-On） | BG8: サンスター 担当部署・ 担当者 | BK8: サンスターコメント (現状との違い、補足、その他気になること)
V9: FO | AC9: 外部システム
B10: １．入金消込
BL11: 事務管理グループでは売掛金以外の未収入金の消込を行っております。このフローは売掛金の消込でしょうか？未収入金の消込でしょうか？ 売掛金は現在消込を行っておりませんが、今後発生するフローでしょうか？ （事務管理：藤田、安東）
BG12: 事務管理？
BG13: カスタマー？
AK17: １．入金消込
AL18: FOのトランザクションの決済画面より
AL19: 請求データ（債権）と入金データの消込を実施
AL20: 入金登録時に債権を紐づけていないものが対象となる。 | BK20: 売掛金の消込
BG21: SLJ商品売上：SLJ顧客
BG22: SLJ物流売上：物流
B25: ２．前受消込
AK33: １．前受金データ確認
AL34: 前受金データを確認する
AK38: 2．前受入金と受注データの紐づけ・消込
AL39: 前受け入金と受注データを紐づけて消込を実施する

Sheet 7.その他取引計上old
A1: システム名 | F1: =変更履歴!F1 -> 会計システム刷新プロジェクト（LIBRA） | V1: タイトル | AJ1: 日付 | AQ1: 更新者
A2: 文書名 | F2: =変更履歴!F2 -> ToBe業務フロー（3.債権） | V2: =MID(CELL("filename",$A$1),FIND("]",CELL("filename",$A$1))+1,31) -> 7.その他取引計上old | AJ2: 作成 | AL2: =変更履歴!AT2 -> 45365 | AQ2: =変更履歴!BA2 -> JBS加藤
AJ3: 更新 | AL3: =変更履歴!AT3 -> 45846 | AQ3: =変更履歴!BA3 -> JBS加藤
A6: =RIGHT(CELL("filename",A1),LEN(CELL("filename",A1))-FIND("]",CELL("filename",A1))) -> 7.その他取引計上old
B8: 得意先 | I8: 各部門 | P8: 経営計画G | W8: 事務管理G | AK8: カスタマーサービスG | AR8: システム | BF8: 説明 | BV8: Gap （Add-On） | CD8: サンスター 担当部署・ 担当者 | CH8: サンスターコメント (現状との違い、補足、その他気になること)
W9: 担当者 | AD9: 責任者 | AR9: FO | AY9: 外部システム
B10: 1. 未収入金計上
BG14: 1．請求書発行依頼書作成
BH15: 未収入金に伴う発行依頼書、及び
BH16: 経費明細の作成を行う。
BH17: 作成後、上長の確認・押印をもらう。
BG21: 2．請求書発行依頼
BH22: メールにて、事務管理Gに請求書発行依頼を行う。
BG30: 3．債権登録・承認申請
BH31: 請求書発行依頼書の内容を基に
BH32: 債権（未収入金）の登録を行う。
BH33: ※グループ間の業務委受託契約に基づく請求も含む
BG36: 4．登録内容確認・承認
BH37: 登録された内容を確認・承認を実施する。
BG41: 5．請求書データ転記
BH42: 承認された請求書データを転記する。
BG48: 6．請求書の発行
BH49: BtoBアップロード用のcsvファイルをBtoBにアップロードし、
BH50: 請求書を発行する
BH51: ※アップロードファイルは請求書発行依頼書より作成想定
BG54: 7．請求書の保存
BG60: 8．請求書の送付
BH61: 得意先へ請求書を送付する。
BG66: 9．請求書の受領
BH67: 得意先が請求書を受領する。
B81: 2. 預り金処理 台帳作成
BG86: １．預り金情報抽出
BH87: 預り金の情報を出力する
BH89: ※預り金仕訳登録時に、財務分析コード「顧客」に対象顧客をセットする前提
BG93: 2．預り金台帳作成
BH94: １．で抽出した情報を基に預り金台帳を作成する。
BH95: 顧客毎に処理方法（返金、翌月支払いへの振替）を記載する。
B104: 3. 預り金処理 返金処理
CH108: 2024/11/1ｶｽﾀﾏｰ確認
BG109: １．預り金返金
...

Sheet 7.その他取引計上
A1: システム名 | F1: =変更履歴!F1 -> 会計システム刷新プロジェクト（LIBRA） | V1: タイトル | AJ1: 日付 | AQ1: 更新者
A2: 文書名 | F2: =変更履歴!F2 -> ToBe業務フロー（3.債権） | V2: =MID(CELL("filename",$A$1),FIND("]",CELL("filename",$A$1))+1,31) -> 7.その他取引計上 | AJ2: 作成 | AL2: =変更履歴!AT2 -> 45365 | AQ2: =変更履歴!BA2 -> JBS加藤
AJ3: 更新 | AL3: =変更履歴!AT3 -> 45846 | AQ3: =変更履歴!BA3 -> JBS加藤
A6: =RIGHT(CELL("filename",A1),LEN(CELL("filename",A1))-FIND("]",CELL("filename",A1))) -> 7.その他取引計上
B8: 得意先 | I8: 各部門 | P8: 経営計画G | W8: 事務管理G | AK8: カスタマーサービスG | AR8: ITDX | AY8: システム | BM8: 説明 | CC8: Gap （Add-On） | CK8: サンスター 担当部署・ 担当者 | CO8: サンスターコメント (現状との違い、補足、その他気になること)
W9: 担当者 | AD9: 責任者 | AY9: FO | BF9: 外部システム
B10: 1. 未収入金計上
BN14: 1．請求書発行依頼書作成
BO15: 未収入金に伴う発行依頼書、及び
BO16: 経費明細の作成を行う。
BO17: 作成後、上長の確認・押印をもらう。
CK20: 事務管理深川 | CP20: 未収入金の伝票計上は楽楽精算ではなく一般仕訳帳で計上予定
BN21: 2．請求書発行依頼
BO22: メールにて、事務管理Gに請求書発行依頼を行う。
BN30: 3．債権登録・承認申請
BO31: 請求書発行依頼書の内容を基に
BO32: 債権（未収入金）の登録を行う。
BO33: ※グループ間の業務委受託契約に基づく請求も含む
BN36: 4．登録内容確認・承認
BO37: 登録された内容を確認・承認を実施する。
CC39: アドオン機能
CD40: FO-001：会計伝票情報取込
CD41: FO-097：会計伝票情報登録
BN48: 5．請求書の発行
BO49: BtoBアップロード用のcsvファイルをBtoBにアップロードし、
BO50: 請求書を発行する
BO51: ※アップロードファイルは請求書発行依頼書より作成想定
BN54: 6．請求書の保存
BN60: 7．請求書の送付
BO61: 得意先へ請求書を送付する。
BN66: 8．請求書の受領
BO67: 得意先が請求書を受領する。
B80: 2. 預り金処理 台帳作成
BN85: １．預り金情報抽出
BO86: 預り金の情報を出力する
BO88: ※預り金仕訳登録時に、財務分析コード「顧客」に対象顧客をセットする前提
BO89: ※預り金仕訳登録時に、対象顧客情報を明細の説明に入力いただく
BO90: また、財務タグ：得意先コードに設定されるように入力いただく
BN92: 2．預り金台帳作成
BO93: １．で抽出した情報を基に預り金台帳を作成する。
...

Sheet 8.入金 (未収入金・その他)
A1: システム名 | F1: =変更履歴!F1 -> 会計システム刷新プロジェクト（LIBRA） | V1: タイトル | AJ1: 日付 | AQ1: 更新者
A2: 文書名 | F2: =変更履歴!F2 -> ToBe業務フロー（3.債権） | V2: =MID(CELL("filename",$A$1),FIND("]",CELL("filename",$A$1))+1,31) -> 8.入金 (未収入金・その他) | AJ2: 作成 | AL2: =変更履歴!AT2 -> 45365 | AQ2: =変更履歴!BA2 -> JBS加藤
AJ3: 更新 | AL3: =変更履歴!AT3 -> 45846 | AQ3: =変更履歴!BA3 -> JBS加藤
A6: =RIGHT(CELL("filename",A1),LEN(CELL("filename",A1))-FIND("]",CELL("filename",A1))) -> 8.入金 (未収入金・その他)
B8: 得意先 | I8: 銀行 | P8: 各部署 | AC8: 事務管理G | BC8: ITDX | BJ8: カスタマーG | BW8: システム | CK8: 説明 | DA8: Gap （Add-On） | DH8: サンスター 担当部署・ 担当者 | DL8: サンスターコメント (現状との違い、補足、その他気になること)
AC9: 担当者 | AP9: 責任者 | BC9: 担当者 | BW9: FO | CD9: 外部システム
B10: 1．入金（未収入金）
CL19: 1．入金情報提示
CM20: 銀行から入金情報が提示される。
CL24: 2．EBデータダウンロード
CM25: 銀行システムよりEB取り込みデータをダウンロードする。
CL31: 3．EBデータ取り込み
CM32: FOの顧客支払仕訳帳画面にて仕訳帳を作成し、
CM33: 手順2でダウンロードしたEBデータの取り込み実施する。
CM35: ※取引先毎の未収入金残高確認は
CM36: 「顧客残高リストレポート」「顧客トランザクション」を使用する
CL39: 4．伝票承認申請
CM40: EBデータを取り込んだ仕訳帳の承認申請を行う。
CL44: 5．伝票承認
CM45: 申請された仕訳帳を確認し、承認を行う。
CL48: 6．自動転記バッチ
CM49: スケジュールされたバッチ処理により | DA49: アドオン機能
CM50: 承認済仕訳帳が自動転記処理される | DA50: Req377
DA51: FO-034：自動転記バッチ
B59: 2．入金（前受 売掛金）
CL61: ※前受請求した場合の入金処理
CL67: １．銀行振込確認
CM68: 前受入金がされているかどうかを確認する
CL71: ２．入金データ登録
CM72: 入金仕訳を登録する
DA74: アドオン機能
DB75: FO-001：会計伝票情報取込
DB76: FO-097：会計伝票情報登録
B84: 3．入金（その他）
CL85: Req363～Req365
CL93: １．銀行振込確認
CM94: 債権に対する入金がされているかどうかを確認する。
CL98: 2．入金入力
CM99: 入金登録を行う。
CM100: ※説明欄に顧客情報等を入力する。
...

Sheet 9.入金消込 (未収入金)
A1: システム名 | F1: =変更履歴!F1 -> 会計システム刷新プロジェクト（LIBRA） | V1: タイトル | AJ1: 日付 | AQ1: 更新者
A2: 文書名 | F2: =変更履歴!F2 -> ToBe業務フロー（3.債権） | V2: =MID(CELL("filename",$A$1),FIND("]",CELL("filename",$A$1))+1,31) -> 9.入金消込 (未収入金) | AJ2: 作成 | AL2: =変更履歴!AT2 -> 45365 | AQ2: =変更履歴!BA2 -> JBS加藤
AJ3: 更新 | AL3: =変更履歴!AT3 -> 45846 | AQ3: =変更履歴!BA3 -> JBS加藤
A6: =RIGHT(CELL("filename",A1),LEN(CELL("filename",A1))-FIND("]",CELL("filename",A1))) -> 9.入金消込 (未収入金)
B8: 銀行 | I8: 事務管理G | V8: システム | AJ8: 説明 | AZ8: Gap （Add-On） | BG8: サンスター 担当部署・ 担当者 | BK8: サンスターコメント (現状との違い、補足、その他気になること)
V9: FO | AC9: 外部システム
B10: １．入金消込
BL11: 事務管理グループでは売掛金以外の未収入金の消込を行っております。このフローは売掛金の消込でしょうか？未収入金の消込でしょうか？ 売掛金は現在消込を行っておりませんが、今後発生するフローでしょうか？ （事務管理：藤田、安東）
BG12: 事務管理？
BG13: カスタマー？
AK17: １．入金消込
AL18: FOのトランザクションの決済画面より
AL19: 請求データ（債権）と入金データの消込を実施
AL20: 入金登録時に債権を紐づけていないものが対象となる。 | BK20: 売掛金の消込
BG21: ｶｽﾀﾏｰｻｰﾋﾞｽ | BK21: SSJ mcframeで対応
BG22: ｸﾞﾙｰﾌﾟ | BK22: SEJ AS400で対応
BG23: 房

Sheet 10.債権残高管理
A1: システム名 | F1: =変更履歴!F1 -> 会計システム刷新プロジェクト（LIBRA） | V1: タイトル | AJ1: 日付 | AQ1: 更新者
A2: 文書名 | F2: =変更履歴!F2 -> ToBe業務フロー（3.債権） | V2: =MID(CELL("filename",$A$1),FIND("]",CELL("filename",$A$1))+1,31) -> 10.債権残高管理 | AJ2: 作成 | AL2: =変更履歴!AT2 -> 45365 | AQ2: =変更履歴!BA2 -> JBS加藤
AJ3: 更新 | AL3: =変更履歴!AT3 -> 45846 | AQ3: =変更履歴!BA3 -> JBS加藤
A6: =RIGHT(CELL("filename",A1),LEN(CELL("filename",A1))-FIND("]",CELL("filename",A1))) -> 10.債権残高管理
B8: 得意先 | I8: 決算G | P8: 営業部 | W8: カスタマーサービスG | AD8: 事務管理G | AK8: システム | AY8: 説明 | BO8: Gap （Add-On） | BW8: サンスター 担当部署・ 担当者 | CA8: サンスターコメント (現状との違い、補足、その他気になること)
AK9: FO | AR9: 外部システム
B10: １．売掛金管理
AZ16: １．通販入金予定抽出
BA17: 台帳に記入するため、通販の入金予定を抽出する
AZ20: ２．通販入金予定記入
BA21: 1.で抽出した入金予定情報を台帳に記入する
AZ29: ３．通販入金実績抽出
BA30: 通販の入金実績情報を伝票トランザクションより抽出する
AZ36: 4．入金実績記入・差異確認
BA37: 3.で抽出した入金実績情報を台帳に記入する
BA38: 記入後、入金の予実を確認する。
AZ42: ５．必要帳票出力
BA43: 通販ダイレクトより以下帳票を出力する。
BA44: ・入金照合リスト
BA45: ・クレジット売上表
BA46: ・クレジット経理仕訳伝票
BA47: 他
B54: ２．未収入金管理（クレジット精算金額）
AZ60: １．クレジット精算金額明細情報抽出
BA61: 伝票トランザクションを使用し、
BA62: クレジット精算金額明細を確認する。
AZ66: ２．クレジット精算金額明細確認
BA67: １．で抽出した情報とExcelで管理している情報と
BA68: 照合を行う。
B76: 3．未収入金管理（売掛金以外の債権残高）
AZ82: １．取引先毎の債権残高明細情報抽出
BA83: 月次の取引先毎の債権残高明細情報を抽出する。（SSJ)
AZ86: ２．債権残高明細情報確認
BA87: 1.で抽出した情報を確認する
AZ92: 3．決算G報告資料作成
BA93: 1.で抽出した情報を基に決算Gへの報告資料を作成する。
AZ97: 4．決算G報告資料提出
BA98: 作成した報告用資料を提出する。
AZ101: 5．決算G報告用資料受領
BA102: 報告用資料を受領する。
...

Sheet 11.SSJ与信管理
A1: システム名 | F1: =変更履歴!F1 -> 会計システム刷新プロジェクト（LIBRA） | V1: タイトル | AJ1: 日付 | AQ1: 更新者
A2: 文書名 | F2: =変更履歴!F2 -> ToBe業務フロー（3.債権） | V2: =MID(CELL("filename",$A$1),FIND("]",CELL("filename",$A$1))+1,31) -> 11.SSJ与信管理 | AJ2: 作成 | AL2: =変更履歴!AT2 -> 45365 | AQ2: =変更履歴!BA2 -> JBS加藤
AJ3: 更新 | AL3: =変更履歴!AT3 -> 45846 | AQ3: =変更履歴!BA3 -> JBS加藤
A6: =RIGHT(CELL("filename",A1),LEN(CELL("filename",A1))-FIND("]",CELL("filename",A1))) -> 11.SSJ与信管理
B8: 営業企画部 営業推進G | P8: 事務管理G | AD8: ITDX | AK8: システム | AY8: 説明 | BO8: Gap （Add-On） | BV8: サンスター 担当部署・ 担当者 | BZ8: サンスターコメント (現状との違い、補足、その他気になること)
B9: 担当者 | I9: 責任者 | P9: 担当者 | W9: 責任者 | AD9: 担当者 | AK9: FO | AR9: 外部システム
B10: 1.滞留債権管理
AZ15: １．未回収データ確認
BA16: 期日が超過している未回収データを確認する。
BV26: ｶｽﾀﾏｰｻｰﾋﾞｽ | BZ26: SSJ mcframeで対応
AZ27: 2．期日超過債権原因調査指示 | BV27: ｸﾞﾙｰﾌﾟ | BZ27: SEJ 顧客窓口支援システムで対応
BA28: 期日超過債権の調査をする。 | BV28: 房
AZ31: 3．期日超過債権原因調査指示
BA32: 期日超過債権の調査結果を報告する。
AZ35: 4．期日超過債権原因の結果確認・承認
BA36: 期日超過債権の調査結果を確認し、承認する。
AZ48: 5．与信額変更申請書作成/申請
BA49: 与信額変更の申請書を作成し、申請する。
AZ53: 6．与信額変更申請書承認
BA54: 与信額変更の申請書を承認する。
AZ57: 7．与信限度額変更
BA58: 当該顧客の与信限度額を変更する。
AZ66: 8．貸倒引当額算定
BA67: 当該顧客へ引き当てる貸倒引当金の金額を算定する。
AZ71: 9．貸倒引当金登録依頼
BA72: 算定した金額で貸倒引当金の登録依頼を行う。
AZ75: 10．引当額登録/承認申請
BA76: 貸倒引当金を登録し、承認申請する。 | CA76: 2024/11/1カスタマー確認
CA77: ｶｽﾀﾏｰでは仕訳計上していない
AZ80: 11．貸倒引当の承認
BA81: 登録された貸倒引当金を承認する。
AZ84: 12．自動転記バッチ | BO84: アドオン機能
BA85: スケジュールされたバッチ処理により | BO85: Req377
BA86: 承認済仕訳帳が自動転記処理される | BO86: FO-034：自動転記バッチ

Sheet 12.SEJ与信管理
A1: システム名 | F1: =変更履歴!F1 -> 会計システム刷新プロジェクト（LIBRA） | V1: タイトル | AJ1: 日付 | AQ1: 更新者
A2: 文書名 | F2: =変更履歴!F2 -> ToBe業務フロー（3.債権） | V2: =MID(CELL("filename",$A$1),FIND("]",CELL("filename",$A$1))+1,31) -> 12.SEJ与信管理 | AJ2: 作成 | AL2: =変更履歴!AT2 -> 45365 | AQ2: =変更履歴!BA2 -> JBS加藤
AJ3: 更新 | AL3: =変更履歴!AT3 -> 45846 | AQ3: =変更履歴!BA3 -> JBS加藤
A6: =RIGHT(CELL("filename",A1),LEN(CELL("filename",A1))-FIND("]",CELL("filename",A1))) -> 12.SEJ与信管理
B8: 各営業部 | P8: 事務管理G | AD8: ITDX | AK8: システム | AY8: 説明 | BO8: Gap （Add-On） | BV8: サンスター 担当部署・ 担当者 | BZ8: サンスターコメント (現状との違い、補足、その他気になること)
B9: 担当者 | I9: 責任者 | P9: 担当者 | W9: 責任者 | AD9: 担当者 | AK9: FO | AR9: 外部システム
B10: 1.滞留債権管理
AZ15: １．未回収データ確認
BA16: 経理がFOの期日が超過した顧客請求書画面から
BA17: 未回収データを確認する。
BV26: ｶｽﾀﾏｰｻｰﾋﾞｽ | BZ26: SSJ mcframeで対応
AZ27: 2．期日超過債権原因調査指示 | BV27: ｸﾞﾙｰﾌﾟ | BZ27: SEJ 顧客窓口支援システムで対応
BA28: 期日超過債権の調査をする。 | BV28: 房
AZ31: 3．期日超過債権原因調査指示
BA32: 期日超過債権の調査結果を報告する。
AZ35: 4．期日超過債権原因の結果確認・承認
BA36: 期日超過債権の調査結果を確認し、承認する。
AZ48: 5．与信額変更申請書作成/申請
BA49: 与信額変更の申請書を作成し、申請する。
AZ53: 6．与信額変更申請書承認
BA54: 与信額変更の申請書を承認する。
AZ57: 7．与信限度額変更
BA58: 当該顧客の与信限度額を変更する。
AZ66: 8．貸倒引当額算定
BA67: 当該顧客へ引き当てる貸倒引当金の金額を算定する。
AZ71: 9．貸倒引当金登録依頼
BA72: 算定した金額で貸倒引当金の登録依頼を行う。
AZ76: 10．引当額登録/承認申請
BA77: 貸倒引当金を登録し、承認申請する。
CA79: 2024/11/1カスタマー確認
CA80: ｶｽﾀﾏｰでは仕訳計上していない
AZ81: 11．貸倒引当の承認
BA82: 登録された貸倒引当金を承認する。
AZ85: 12．自動転記バッチ
BA86: スケジュールされたバッチ処理により | BO86: アドオン機能
BA87: 承認済仕訳帳が自動転記処理される | BO87: Req377
BO88: FO-034：自動転記バッチ

Sheet 13.決算処理
A1: システム名 | F1: =変更履歴!F1 -> 会計システム刷新プロジェクト（LIBRA） | V1: タイトル | AJ1: 日付 | AQ1: 更新者
A2: 文書名 | F2: =変更履歴!F2 -> ToBe業務フロー（3.債権） | V2: =MID(CELL("filename",$A$1),FIND("]",CELL("filename",$A$1))+1,31) -> 13.決算処理 | AJ2: 作成 | AL2: =変更履歴!AT2 -> 45365 | AQ2: =変更履歴!BA2 -> JBS加藤
AJ3: 更新 | AL3: =変更履歴!AT3 -> 45846 | AQ3: =変更履歴!BA3 -> JBS加藤
A6: =RIGHT(CELL("filename",A1),LEN(CELL("filename",A1))-FIND("]",CELL("filename",A1))) -> 13.決算処理
B8: 得意先 | I8: 財務部 | P8: 事務管理G | W8: カスタマーサービスG | AD8: システム | AR8: 説明 | BH8: Gap （Add-On） | BP8: サンスター 担当部署・ 担当者 | BT8: サンスターコメント (現状との違い、補足、その他気になること)
AD9: FO | AK9: 外部システム
B10: 1. 現物管理
AS15: 1．仮払現金残高確認
AT16: 仮払現金の残高を確認する。
AS21: 2.報告資料作成
AT22: １．で確認した情報を基に財務部への報告資料を作成する。
AT23: ※所定の書式に記入する
AS26: 3．報告用資料提出
AT27: 作成した報告用資料を財務部へ提出する。
AS34: 4．報告用資料受領
AT35: 報告用資料を受領する。
B41: 2. 外貨取引管理
AS46: １．外貨別売掛金明細抽出
AT47: 外貨別売掛金明細情報を抽出する。
AS53: 2．外貨再評価（シミュレーション）
AT54: 外貨再評価のシミュレーション機能を使用して、
AT55: 再評価結果を確認する。
AS59: 3．外貨再評価
AT60: 外貨再評価のシミュレーションが問題ない場合、
AT61: 外貨再評価を実施する。
B71: 3.売掛金振替 【SSJ】
BT73: 2024/11/1 ｶｽﾀﾏ 房さんに確認
BT74: mcframeにて未収入金計上
BT75: mcframeにて入金計上
AS77: １．売掛金振替
AT78: 売掛金から未収入金へ振替を行う。
AS83: 2．登録内容確認・承認
AT84: 登録された内容を確認・承認を実施する。
BI87: FO-001：会計伝票情報取込
BI88: FO-097：会計伝票情報登録
B99: 4.未払費用計上【SEJ】
AS105: １．未払費用情報抽出
AT106: 伝票トランザクションより未払費用情報を抽出する。
AS111: 2．請求金額表作成
AT112: 大阪・四国・広島・九州の販売手数料の未払費用の得意先に資料、
...

Sheet 14.手形管理
A1: システム名 | F1: =変更履歴!F1 -> 会計システム刷新プロジェクト（LIBRA） | V1: タイトル | AJ1: 日付 | AQ1: 更新者
A2: 文書名 | F2: =変更履歴!F2 -> ToBe業務フロー（3.債権） | V2: =MID(CELL("filename",$A$1),FIND("]",CELL("filename",$A$1))+1,31) -> 14.手形管理 | AJ2: 作成 | AL2: =変更履歴!AT2 -> 45365 | AQ2: =変更履歴!BA2 -> JBS加藤
AJ3: 更新 | AL3: =変更履歴!AT3 -> 45846 | AQ3: =変更履歴!BA3 -> JBS加藤
A6: =RIGHT(CELL("filename",A1),LEN(CELL("filename",A1))-FIND("]",CELL("filename",A1))) -> 14.手形管理
B8: 得意先 | I8: 銀行 | P8: カスタマーサービスG | W8: 事務管理G | AK8: ITDX | AR8: システム | BF8: 説明 | BV8: Gap （Add-On） | CD8: サンスター 担当部署・ 担当者 | CH8: サンスターコメント (現状との違い、補足、その他気になること)
W9: 担当者 | AD9: 責任者 | AK9: 担当者 | AR9: FO | AY9: 外部システム
B10: 1.手形受領処理
BG15: １．手形受け渡し
BG18: 2．手形受領
BH19: 得意先から手形を受領する。
BG24: 3．手形受取処理
BH25: 受領した受取手形について、会計処理を行う。
BH26: 仕訳例：受取手形 / 売掛金
BH28: ※ | BI28: 受取手形、売掛金勘定はFO上
BI29: AR管理しない想定。
BH30: ※ | BI30: 手形については別システム「受手くん」で管理
BV32: Gap
BV33: 取込機能が必要（IF）
BW34: FO-001：会計伝票情報取込
BW35: FO-097：会計伝票情報登録
BG37: 4．手形受け渡し
BH38: 会計処理後の手形を事務管理Gへ連携する。
BG45: 5．手形受領・保管
BH46: カスタマーサービスGより手形を受領・保管する。
B57: 2.手形取立依頼
BG62: １．手形受け渡し
BG65: 2．取立依頼受付
BG71: 3．手形取立依頼処理
BH72: 取立依頼の会計処理を行う。
BH73: 仕訳例：取立手形 / 受取手形
BG76: 4．手形取立依頼 承認
BG79: 5．自動転記バッチ
BH80: スケジュールされたバッチ処理により | BV80: アドオン機能
BH81: 承認済仕訳帳が自動転記処理される | BV81: Req377
BV82: FO-034：自動転記バッチ
B92: 3.手形決済時
BG97: １．手形受け渡し
BH98: 入金がされているかどうかを確認する。
BG102: 2．手形決済処理
BH103: 手形の決済処理を行う。
...

Sheet 【参考】外貨再評価
