Workbook

Sheet 表紙
B3: サンスター株式会社 御中
B10: 会計システム刷新プロジェクト（LIBRA）
B14: ToBe業務フロー（1.一般会計・決算）
B22: ="第"&IF(COUNTA(変更履歴!BE5:BH10015)=1,"",INDIRECT("変更履歴!BE"&COUNTA(変更履歴!BE5:BH10015)+4))&"版" -> 第1.8版
B24: {=IF(OR(COUNTA(変更履歴!A:E)=3),"",INDIRECT("変更履歴!A"&COUNTA(変更履歴!A:E)+2))} -> 45910
B26: 日本ビジネスシステムズ株式会社
F29: 作成者 | O29: JBS承認者 | V29: 承認者
F30: 45362 | N30: 45433
F31: JBS福田 | N31: JBS加藤

Sheet 変更履歴
A1: システム名 | F1: =表紙!B10 -> 会計システム刷新プロジェクト（LIBRA） | W1: タイトル | AR1: 日付 | BA1: 更新者
A2: 文書名 | F2: =表紙!B14 -> ToBe業務フロー（1.一般会計・決算） | W2: =MID(CELL("filename",$A$1),FIND("]",CELL("filename",$A$1))+1,31) -> 変更履歴 | AR2: 作成 | AT2: =A6 -> 45362 | BA2: =AZ6 -> JBS福田
AR3: 更新 | AT3: {=IF(OR(COUNTA(A:E)=3),"",INDIRECT("A"&COUNTA(A:E)+2))} -> 45910 | BA3: {=IF(COUNTA(AZ5:BD100015)=1,"",INDIRECT("変更履歴!AZ"&COUNTA(AZ5:BD100015)+4))} -> JBS加藤
A5: 変更年月日 | F5: 変更箇所 | T5: 変更内容 | AZ5: 変更者 | BE5: 版数
A6: 45362 | F6: 新規作成 | T6: 新規作成 | AZ6: JBS福田 | BE6: 0.1
A7: 45433 | F7: 初版確定 | T7: 初版確定 | AZ7: JBS福田 | BE7: 1.0
A8: 45574 | F8: シート：日次振伝処理(決算G) シート：日次振伝処理(事務管理G) | T8: シート：日次振伝処理(決算G) 各部署でFOに登録するフローから、決算Gが登録するフローに変更 シート：日次振伝処理(事務管理G) 各部署でFOに登録するフローから、JUST.DBに登録・事務管理Gでまとめ、一括登録するフローに変更 | AZ8: JBS秋信 | BE8: 1.1
A9: 45665 | F9: シート：日次振伝処理(決算G) シート：日次振伝処理(事務管理G) | T9: シート：日次振伝処理(決算G) 一般仕訳帳アップロード後にWF提出処理が未記載だったため記載を追加 シート：日次振伝処理(事務管理G) 一般仕訳帳アップロード後にWF提出処理が未記載だったため記載を追加 | AZ9: JBS福田 | BE9: 1.2
A10: 45737 | F10: シート：日次振伝処理(決算G) シート：日次振伝処理(事務管理G) | T10: FO-034：自動転記バッチのプロセスを追加 プロセス番号振り直し | AZ10: JBS福田 | BE10: 1.3
A11: 45737 | F11: シート：実績配賦処理 | T11: FO配賦処理から、Azure Synapse AnalyticsおよびPowerBIでの処理に記載を変更 | AZ11: JBS福田 | BE11: 1.3
A12: 45737 | F12: シート：月次決算処理 | T12: 配賦処理のプロセス削除 WF送信/承認/自動転記バッチのプロセス追加 7．月次MR帳票作成 8．経費実績明細照会 9．財務上 損益計算書 のプロセス追加 プロセス番号振り直し | AZ12: JBS福田 | BE12: 1.3
A13: 45737 | F13: シート：半期決算処理 シート：年次決算処理 | T13: 一般仕訳帳のWF送信/承認/自動転記バッチのプロセスについての注記を追加 | AZ13: JBS福田 | BE13: 1.3
A14: 45737 | F14: シート：IFRS伝票処理 | T14: 一般仕訳帳のWF送信/承認/自動転記バッチのプロセス追加 プロセス番号振り直し | AZ14: JBS福田 | BE14: 1.3
A15: 45737 | F15: シート：税務 | T15: 1. 接待交際費明細 の 1．対象勘定明細出力 に FO-048：経費実績明細照会を追加 2. 消費税申告 の 1．消費税情報出力 に FO-058：消費税レポート出力を追加 4. 事業税申告 の 1．対象勘定明細出力 に FO-048：経費実績明細照会を追加 | AZ15: JBS福田 | BE15: 1.3
A16: 45743 | F16: シート：日次振伝処理(事務管理G) | T16: JUSTDBの処理を楽楽精算に変更 | AZ16: JBS福田 | BE16: 1.4
A17: 45743 | F17: シート：実績配賦処理 | T17: ＜注記＞を追加 実績および予算の配賦処理プロセスについては、 FOでの配賦処理はサンスター要件に合わないため、BIの基盤であるAzure Synapse Analytics内でデータ加工（配賦額算出）、蓄積とし、BIでレポートを出力する方針となった。詳細フローについては、BI側で検討および作成予定 | AZ17: JBS福田 | BE17: 1.4
... A34: 45910 | F34: 月次決算処理 半期決算処理 年次決算処理 | T34: 締め処理（元帳カレンダー）をITDXで実施するように変更 | AZ34: JBS加藤 | BE34: 1.8

Sheet 凡例
A1: システム名 | F1: =変更履歴!F1 -> 会計システム刷新プロジェクト（LIBRA） | V1: タイトル | AJ1: 日付 | AQ1: 更新者
A2: 文書名 | F2: =変更履歴!F2 -> ToBe業務フロー（1.一般会計・決算） | V2: =MID(CELL("filename",$A$1),FIND("]",CELL("filename",$A$1))+1,31) -> 凡例 | AJ2: 作成 | AL2: =変更履歴!AT2 -> 45362 | AQ2: =変更履歴!BA2 -> JBS福田
AJ3: 更新 | AL3: =変更履歴!AT3 -> 45910 | AQ3: =変更履歴!BA3 -> JBS加藤
A6: 凡例
H10: ： | I10: フローの開始 | AC10: ： | AD10: フローの終了
H15: ： | I15: システムを伴わない業務 | AC15: ： | AD15: システム上での業務
H20: ： | I20: 帳票（システムで作成される帳票） | AC20: ： | AD20: 帳票（システム外で作成される帳票）
H25: ： | I25: 業務の流れ | AC25: ： | AD25: システムへの連携
H30: ： | I30: 分岐 | AC30: ： | AD30: システム
H35: ： | I35: フロー間の繋がりを示す | AC35: ： | AD35: ファイル（CSVファイル等）
A40: 凡例
B43: 社内部署 | J43: ： | K43: フローに登場する社内の部署を記載
K44: 部署内の担当者が分かれる場合は以下の通りに分ける
B46: 社内部署
B47: 担当者 | I47: 責任者
B50: 外部担当者 | J50: ： | K50: フローに登場する社外担当者の部署を記載
K51: 例）得意先、仕入先
B54: システム | J54: ： | K54: フロー上で実施されるシステムの機能を記載する列
B55: XX | K55: XXの部分にフローで登場するシステム名を記載
K56: 例は以下の通り（JBSで導入するシステム外のものは「外部システム」で統一）
B58: システム
B59: FO | I59: CE | P59: 外部システム
B62: 説明 | S62: ： | T62: フロー内容を説明する列
B66: Gap （Add-On） | J66: ： | K66: フローに対してのGapを記載する列
B70: １．パターン１ | AI70: ： | AJ70: フローのパターンごとに記載する

Sheet 日次振伝処理(決算G)
A1: システム名 | F1: =変更履歴!F1 -> 会計システム刷新プロジェクト（LIBRA） | AC1: タイトル | AQ1: 日付 | AX1: 更新者
A2: 文書名 | F2: =変更履歴!F2 -> ToBe業務フロー（1.一般会計・決算） | AC2: =MID(CELL("filename",$A$1),FIND("]",CELL("filename",$A$1))+1,31) -> 日次振伝処理(決算G) | AQ2: 作成 | AS2: =変更履歴!AT2 -> 45362 | AX2: =変更履歴!BA2 -> JBS福田
AQ3: 更新 | AS3: =変更履歴!AT3 -> 45910 | AX3: =変更履歴!BA3 -> JBS加藤
A6: =RIGHT(CELL("filename",A1),LEN(CELL("filename",A1))-FIND("]",CELL("filename",A1))) -> 日次振伝処理(決算G)
B8: 経理/財務 | P8: ITDX | W8: システム | AD8: 説明 | AT8: Gap （Add-On） | BA8: サンスター 担当部署・ 担当者 | BE8: サンスターコメント (現状との違い、補足、その他気になること)
B9: 担当者 | I9: 責任者 | P9: 担当者 | W9: FO
B10: １．振伝処理
AE17: 1．伝票入力
AF18: 担当者は、一般仕訳帳に伝票の登録を行う。
AE23: 2．WF送信
AF24: 担当者は、登録した仕訳帳をWF送信を行う。
AE31: 3．承認
AF32: 責任者は、申請された伝票の内容を確認し、 | AT32: アドオン機能
AF33: 承認を行う。 | AT33: Req017
AT34: FO-031：仕訳帳承認対象一覧
AE39: 4．自動転記バッチ | AT39: アドオン機能
AF40: スケジュールされたバッチ処理により | AT40: Req377
AF41: 承認済仕訳帳が自動転記処理される | AT41: FO-034：自動転記バッチ
AE48: 5．残高確認・仕訳伝票照会
AF49: 転記後の残高を確認する
AF50: 転記された伝票トランザクションを確認する

Sheet 日次振伝処理(事務管理G)
A1: システム名 | F1: =変更履歴!F1 -> 会計システム刷新プロジェクト（LIBRA） | V1: タイトル | AQ1: 日付 | AX1: 更新者
A2: 文書名 | F2: =変更履歴!F2 -> ToBe業務フロー（1.一般会計・決算） | V2: =MID(CELL("filename",$A$1),FIND("]",CELL("filename",$A$1))+1,31) -> 日次振伝処理(事務管理G) | AQ2: 作成 | AS2: =変更履歴!AT2 -> 45362 | AX2: =変更履歴!BA2 -> JBS福田
AQ3: 更新 | AS3: =変更履歴!AT3 -> 45910 | AX3: =変更履歴!BA3 -> JBS加藤
A6: =RIGHT(CELL("filename",#REF!),LEN(CELL("filename",#REF!))-FIND("]",CELL("filename",#REF!))) -> #REF!
B8: 各部署 | P8: 事務管理G | AD8: ITDX | AK8: システム | AR8: システム | AY8: 説明 | BO8: Gap （Add-On） | BV8: サンスター 担当部署・ 担当者 | BZ8: サンスターコメント (現状との違い、補足、その他気になること)
B9: 担当者 | I9: 責任者 | P9: 担当者 | W9: 責任者 | AD9: 担当者 | AK9: FO | AR9: 外部システム
B10: １．振伝処理
BZ16: JUSTDBから楽楽精算に変更
AZ17: １．伝票入力
BA18: 各部署の担当者が一般仕訳帳画面から
BA19: 振替伝票を入力
AZ22: ２．承認申請
BA23: 入力した伝票を承認申請
AZ28: 3．部門承認
BA29: 担当者から申請された伝票の内容を確認し、
BA30: 承認を行う。
AZ36: 4．会計伝票情報取込 | BO36: アドオン
BA37: 会計伝票情報取込処理で楽楽精算の伝票データを | BO37: FO-001：会計伝票情報取込
BA38: FOにインターフェース
AZ45: 5．残高確認・仕訳伝票照会
BA46: 転記後の残高を確認する
BA47: 転記された伝票トランザクションを確認する

Sheet 実績配賦処理
A1: システム名 | F1: =変更履歴!F1 -> 会計システム刷新プロジェクト（LIBRA） | V1: タイトル | AJ1: 日付 | AQ1: 更新者
A2: 文書名 | F2: =変更履歴!F2 -> ToBe業務フロー（1.一般会計・決算） | V2: =MID(CELL("filename",$A$1),FIND("]",CELL("filename",$A$1))+1,31) -> 実績配賦処理 | AJ2: 作成 | AL2: =変更履歴!AT2 -> 45362 | AQ2: =変更履歴!BA2 -> JBS福田
AJ3: 更新 | AL3: =変更履歴!AT3 -> 45910 | AQ3: =変更履歴!BA3 -> JBS加藤
A6: =RIGHT(CELL("filename",A1),LEN(CELL("filename",A1))-FIND("]",CELL("filename",A1))) -> 実績配賦処理
B8: 各部署 | I8: 事業計画部 | W8: 財務部 経営計画G | AK8: ITDX | AR8: システム | AY8: システム | BF8: 説明 | BV8: Gap （Add-On） | CC8: サンスター 担当部署・ 担当者 | CG8: サンスターコメント (現状との違い、補足、その他気になること)
I9: 担当者 | P9: 責任者 | W9: 担当者 | AD9: 責任者 | AK9: 担当者 | AR9: FO | AY9: 外部システム
B10: 1. FO→BI実績連携
BV16: ※イメージを記載
BG17: 1．実績BI連携 | BV17: 詳細機能等未確定
BH18: FOの実績データをBIへ連携する
B29: 2. 部課別損益配賦処理
CG35: 事務管理Ｇではやっていない
BG36: １．部課振替配賦処理 | BV36: ※イメージを記載 | CG36: →事業計画部へ記載変更(JBS)
BH37: 部課別損益用の配賦処理を行う | BV37: 詳細機能等未確定
BG43: 2．部課別予実帳票出力 | BV43: ※イメージを記載
BH44: 各種 部課別予実帳票を出力する | BV44: 詳細機能等未確定
B55: 3. 利益センター損益配賦処理
BG64: １．利益センター損益配賦処理 | BV64: ※イメージを記載
BH65: 利益センタ損益用の配賦処理を行う | BV65: 詳細機能等未確定
BV71: ※イメージを記載
BG72: 2．利益センタ別予実帳票出力 | BV72: 詳細機能等未確定
BH73: 各種 利益センタ別予実帳票を出力する
B83: 4. チャネル損益用配賦処理
BG92: １．チャネル損益配賦処理 | BV92: ※イメージを記載
BH93: チャネル損益用の配賦処理を行う | BV93: 詳細機能等未確定
BV99: ※イメージを記載
BG100: 2．チャネル別予実帳票出力 | BV100: 詳細機能等未確定
BH101: 各種 チャネル別予実帳票を出力する
B111: 5. ブランド別損益用配賦処理
BG120: １．ブランド損益配賦処理 | BV120: ※イメージを記載
BH121: ブランド損益用の配賦処理を行う | BV121: 詳細機能等未確定
BV127: ※イメージを記載
BG128: 2．ブランド別予実帳票出力 | BV128: 詳細機能等未確定
BH129: 各種 ブランド別予実帳票を出力する
B139: 6. カテゴリ別損益用配賦処理
BG148: １．カテゴリ損益配賦処理 | BV148: ※イメージを記載
BH149: カテゴリ損益用の配賦処理を行う | BV149: 詳細機能等未確定
BV155: ※イメージを記載
BG156: 2．カテゴリ別予実帳票出力 | BV156: 詳細機能等未確定
BH157: 各種 カテゴリ別予実帳票を出力する

Sheet 外貨再評価
A1: システム名 | F1: =変更履歴!F1 -> 会計システム刷新プロジェクト（LIBRA） | V1: タイトル | AJ1: 日付 | AQ1: 更新者
A2: 文書名 | F2: =変更履歴!F2 -> ToBe業務フロー（1.一般会計・決算） | V2: =MID(CELL("filename",$A$1),FIND("]",CELL("filename",$A$1))+1,31) -> 外貨再評価 | AJ2: 作成 | AL2: =変更履歴!AT2 -> 45362 | AQ2: =変更履歴!BA2 -> JBS福田
AJ3: 更新 | AL3: =変更履歴!AT3 -> 45910 | AQ3: =変更履歴!BA3 -> JBS加藤
A6: =RIGHT(CELL("filename",A1),LEN(CELL("filename",A1))-FIND("]",CELL("filename",A1))) -> 外貨再評価
B8: 各部署 | I8: カスタマーサービスG | P8: 購買 | W8: 財務部 決算G | AK8: 業務推進部 事務管理G | AY8: システム | BM8: 説明 | CC8: Gap （Add-On） | CJ8: サンスター 担当部署・ 担当者 | CN8: サンスターコメント (現状との違い、補足、その他気になること)
I9: 担当者 | P9: 担当者 | W9: 担当者 | AD9: 責任者 | AK9: 担当者 | AR9: 責任者 | AY9: FO | BF9: 外部システム
B10: 1. 為替レートマスタ登録
BN24: １．為替レート情報取得
BO25: 銀行WEB等からレート情報を確認
BN30: 2．為替レート登録
BO31: 月1回月末日に
BO32: 為替レートマスタにレートを登録する
B40: 2. 売掛金管理モジュール 外貨再評価
BN47: １．AR外貨再評価シミュレーション
BO48: 外貨再評価シミュレーション計算を実行する
BN55: 2．シミュレーション結果確認
BO56: シミュレーション計算結果を確認する
BO57: 担当者からメール等で提出された
BO58: シミュレーション結果(EXCEL)の内容を確認する
BN64: 3．AR外貨再評価
BO65: 外貨再評価計算を実行する
BN71: 4．外貨再評価仕訳確認
BO72: 伝票トランザクション画面で
BO73: 作成された外貨評価仕訳を確認する
BO75: 洗替方式の仕訳作成
B85: 3. 買掛金管理モジュール 外貨再評価
BN92: １．AP外貨再評価シミュレーション
BO93: 外貨再評価シミュレーション計算を実行する
BN100: 2．シミュレーション結果確認
BO101: シミュレーション計算結果を確認する
BO102: 担当者からメール等で提出された
BO103: 担当者からメール等で提出されたEXCELの内容を確認する
BN109: 3．AP外貨再評価
BO110: 外貨再評価計算を実行する
BN116: 4．外貨再評価仕訳確認
BO117: 伝票トランザクション画面で
BO118: 作成された外貨評価仕訳を確認する
BO121: 洗替方式の仕訳作成
B129: 4. 一般会計モジュール 外貨再評価
BN136: １．外貨再評価シミュレーション
...

Sheet 月次決算処理
A1: システム名 | F1: =変更履歴!F1 -> 会計システム刷新プロジェクト（LIBRA） | V1: タイトル | AQ1: 日付 | AX1: 更新者
A2: 文書名 | F2: =変更履歴!F2 -> ToBe業務フロー（1.一般会計・決算） | V2: =MID(CELL("filename",$A$1),FIND("]",CELL("filename",$A$1))+1,31) -> 月次決算処理 | AQ2: 作成 | AS2: =変更履歴!AT2 -> 45362 | AX2: =変更履歴!BA2 -> JBS福田
AQ3: 更新 | AS3: =変更履歴!AT3 -> 45910 | AX3: =変更履歴!BA3 -> JBS加藤
A6: =RIGHT(CELL("filename",A1),LEN(CELL("filename",A1))-FIND("]",CELL("filename",A1))) -> 月次決算処理
B8: 各部署 | I8: 財務部 決算G | W8: ITDX | AD8: システム | AK8: システム | AR8: 説明 | BH8: Gap （Add-On） | BO8: サンスター 担当部署・ 担当者 | BS8: サンスターコメント (現状との違い、補足、その他気になること)
I9: 担当者 | P9: 責任者 | W9: 担当者 | AD9: FO | AK9: 外部システム
B10: 1. 月次処理
AS18: 1．月次決算仕訳
AT19: 月次決算伝票の計上処理を行う。 | BO19: 業務推進部 事務管理G | BS19: 主な担当者:寺澤、山口
BO20: 財務部 決算G | BS20: SSJ:正野 SEJ:渕 SLJ:北山
BS21: 消費税レポート関係や税金関係の調整についてはこちらに含まれているという理解でよろしいでしょうか？（正野）
BS22: →こちらは仕訳の計上のみを記載しております。
AS27: 2．WF送信
AT28: 担当者は、登録した仕訳帳をWF送信を行う。
AS35: 3．承認
AT36: 責任者は、申請された伝票の内容を確認し、 | BH36: アドオン機能
AT37: 承認を行う。 | BH37: Req017
BH38: FO-031：仕訳帳承認対象一覧
AS43: 4．自動転記バッチ | BH43: アドオン機能
AT44: スケジュールされたバッチ処理により | BH44: Req377
AT45: 承認済仕訳帳が自動転記処理される | BH45: FO-034：自動転記バッチ
AS51: 5．残高試算表確認 | BO51: 業務推進部 事務管理G
AT52: 転記後の残高を確認する | BO52: 財務部 決算G | BS52: SSJ:正野 SEJ:渕 SLJ:北山
AT53: 転記された伝票トランザクションを確認する
AS57: 6．月次締め処理依頼
AT58: 月次締め処理の依頼を行う。
AS65: 7．月次締め処理
AT66: 元帳カレンダーをクローズして
AT67: 該当月の伝票の転記を禁止する
AS74: 8．月次MR帳票作成 | BO74: 業務推進部 事務管理G
AT75: 各種 月次MR帳票を作成する。 | BO75: 財務部 決算G | BS75: SSJ:正野 SEJ:渕 SLJ:北山
BS76: SAP残高を基にExcelで作成しているケースもあり
BS79: 税金支払に関するフローはこちらに含まれているのでしょうか？（正野）
BS81: →こちらは仕訳の計上のみを記載しております。
BS82: e-taxでの支払いはシート「税務」での
BS83: 税務会計ソフトでの処理を想定しております。
AS97: 9．財務上 損益計算書
AT98: FO-069 財務上 損益計算書を出力する
AS106: 10．各種管理会計帳票出力
AT107: PowerBIから各種管理会計帳を出力する

Sheet 半期決算処理
A1: システム名 | F1: =変更履歴!F1 -> 会計システム刷新プロジェクト（LIBRA） | V1: タイトル | AJ1: 日付 | AQ1: 更新者
A2: 文書名 | F2: =変更履歴!F2 -> ToBe業務フロー（1.一般会計・決算） | V2: =MID(CELL("filename",$A$1),FIND("]",CELL("filename",$A$1))+1,31) -> 半期決算処理 | AJ2: 作成 | AL2: =変更履歴!AT2 -> 45362 | AQ2: =変更履歴!BA2 -> JBS福田
AJ3: 更新 | AL3: =変更履歴!AT3 -> 45910 | AQ3: =変更履歴!BA3 -> JBS加藤
A6: =RIGHT(CELL("filename",A1),LEN(CELL("filename",A1))-FIND("]",CELL("filename",A1))) -> 半期決算処理
B8: 各部署 | I8: 業務推進部 事務管理G | W8: 財務部 経営計画G | AK8: 財務部 決算G | AY8: ITDX | BF8: システム | BT8: 説明 | CJ8: Gap （Add-On） | CQ8: サンスター 担当部署・ 担当者 | CU8: サンスターコメント (現状との違い、補足、その他気になること)
I9: 担当者 | P9: 責任者 | W9: 担当者 | AD9: 責任者 | AK9: 担当者 | AR9: 責任者 | AY9: 担当者 | BF9: FO | BM9: 外部システム
B10: 1. 1次〆
BU23: 1．資産除去債務・償却費 資料作成・共有
BV24: 資産除去債務・償却費計上用の資料を作成し、
BV25: 事務管理Gに共有する。
BU30: 2．資産除去債務・償却費 計上 | CU30: 資産除去債務・償却費は決算Ｇが楽楽精算にて計上
BV31: 資産除去債務・償却費 計上資料を基に | CU31: → 修正済
BV32: 資産除去債務・償却費の仕訳登録を行う。
CU39: 資料の作成を決算Gに修正をお願い致します（2025年4月2日正野）
BU40: 3．投資有価証券時価洗替 資料作成 | CU40: → 修正済
BV41: 投資有価証券時価洗替 資料を作成する
CU46: 決算Ｇが楽楽精算にて計上
BU47: 4．投資有価証券時価洗替 計上 | CU47: → 修正済
BV48: 投資有価証券時価洗替資料を基に
BV49: 投資有価証券時価洗替の仕訳登録を行う。
BU59: 5．前払計上･洗替（社宅洗替、各事務所家賃）資料作成
BV60: 前払計上･洗替（社宅洗替、各事務所家賃）資料を作成する | CU60: 各部署が楽楽精算にて計上
BV61: 事業所家賃は総務、社宅家賃は業務推進部(社員サポート) | CU61: ・事業所家賃は総務、社宅家賃は業務推進部(社員サポート)
CU62: → 修正済
BU69: 6．前払計上･洗替（社宅洗替、各事務所家賃 計上 | CU69: 各部署が楽楽精算にて計上
BV70: 前払計上･洗替（社宅洗替、各事務所家賃）資料を基に | CU70: ・事業所家賃は総務、社宅家賃は業務推進部(社員サポート)
BV71: 前払計上･洗替（社宅洗替、各事務所家賃）の仕訳登録を行う。 | CU71: → 修正済
BV72: 事業所家賃は総務、社宅家賃は業務推進部(社員サポート)
BU80: 7. Amazon通販売上計上 | CU80: 各部署(ダイレクト事業部)が楽楽精算にて計上
BV81: Amazon通販売上の仕訳登録を行う。 | CU81: → 修正済
BV82: 各部署(ダイレクト事業部)が楽楽精算にて計上
CU91: 各部署(Eサイエンス事業開発部)が楽楽精算にて計上
BU92: 8. ECサイト売上計上 | CU92: → 修正済
BV93: ECサイト売上の仕訳登録を行う。
BV94: 各部署(Eサイエンス事業開発部)が楽楽精算にて計上
CU97: 9. 阪食 建設協力金長短振替
CU98: この仕訳計上は現状無し
CU99: → 修正済
BU102: 9．締め処理依頼
BV103: 締め処理の依頼を行う。
...

Sheet 年次決算処理
A1: システム名 | F1: =変更履歴!F1 -> 会計システム刷新プロジェクト（LIBRA） | V1: タイトル | AJ1: 日付 | AQ1: 更新者
A2: 文書名 | F2: =変更履歴!F2 -> ToBe業務フロー（1.一般会計・決算） | V2: =MID(CELL("filename",$A$1),FIND("]",CELL("filename",$A$1))+1,31) -> 年次決算処理 | AJ2: 作成 | AL2: =変更履歴!AT2 -> 45362 | AQ2: =変更履歴!BA2 -> JBS福田
AJ3: 更新 | AL3: =変更履歴!AT3 -> 45910 | AQ3: =変更履歴!BA3 -> JBS加藤
A6: =RIGHT(CELL("filename",A1),LEN(CELL("filename",A1))-FIND("]",CELL("filename",A1))) -> 年次決算処理
B8: 各部署 | I8: 業務推進部 事務管理G | W8: 財務部 経営計画G | AK8: 財務部 決算G | AY8: ITDX | BF8: システム | BT8: 説明 | CJ8: Gap （Add-On） | CQ8: サンスター 担当部署・ 担当者 | CU8: サンスターコメント (現状との違い、補足、その他気になること)
I9: 担当者 | P9: 責任者 | W9: 担当者 | AD9: 責任者 | AK9: 担当者 | AR9: 責任者 | AY9: 担当者 | BF9: FO | BM9: 外部システム
B10: 1. 決算事前準備
CU18: 1．資料依頼(前払家賃) 実施していない
CU19: → 修正済
CU20: 2．資料準備(前払家賃) 実施していない
CU21: → 修正済
CU23: 4．資料準備(MC有償支給) と
BU24: 1．資料依頼(MC有償支給) | CU24: 5．資料依頼(クレーム)は
BV25: 部署担当に資料を依頼して受領する。 | CU25: 一連の作業ではなくそれぞれ独立した業務
CU27: 6．資料準備(クレーム)と
CU28: 7．資料依頼(ECサイト売上データ)は
BU29: 2．資料準備(MC有償支給) | CU29: 一連の作業ではなくそれぞれ独立した業務
BV30: 部署担当は資料を作成して提出する。
CU31: 7．資料依頼(ECサイト売上データ)は実施していない
CU32: → 修正済
CU34: 8．資料準備(ECサイト売上データ)は実施していない
CU35: → 修正済
BU43: 3．資料依頼(クレーム)
BV44: 部署担当に資料を依頼して受領する。
BU47: 4．資料準備(クレーム)
BV48: 部署担当は資料を作成して提出する。
B57: 2. １次〆(1/5～1/9)
BU67: 1．資産除去債務・償却費 資料作成
BV68: 資産除去債務・償却費計上用の資料を作成する。
BU75: 2．資産除去債務・償却費 計上
BV76: 資産除去債務・償却費 計上資料を基に
BV77: 資産除去債務・償却費の仕訳登録を行う。
BU82: 3．投資有価証券時価洗替 資料作成
BV83: 投資有価証券時価洗替 資料を作成する
BU89: 4．投資有価証券時価洗替 計上
BV90: 投資有価証券時価洗替資料を基に
BV91: 投資有価証券時価洗替の仕訳登録を行う。
BU95: 5．前払計上･洗替（社宅洗替、各事務所家賃）確認 | DG95: 各部署が楽楽精算にて計上
BV96: 前払計上･洗替（社宅洗替、各事務所家賃）仕訳を確認する | DG96: ・事業所家賃は総務、社宅家賃は業務推進部(社員サポート)
CU103: 各部署(ダイレクト事業部)が楽楽精算にて計上
...

Sheet IFRS伝票処理
A1: システム名 | F1: =変更履歴!F1 -> 会計システム刷新プロジェクト（LIBRA） | V1: タイトル | AJ1: 日付 | AQ1: 更新者
A2: 文書名 | F2: =変更履歴!F2 -> ToBe業務フロー（1.一般会計・決算） | V2: =MID(CELL("filename",$A$1),FIND("]",CELL("filename",$A$1))+1,31) -> IFRS伝票処理 | AJ2: 作成 | AL2: =変更履歴!AT2 -> 45362 | AQ2: =変更履歴!BA2 -> JBS福田
AJ3: 更新 | AL3: =変更履歴!AT3 -> 45910 | AQ3: =変更履歴!BA3 -> JBS加藤
A6: =RIGHT(CELL("filename",A1),LEN(CELL("filename",A1))-FIND("]",CELL("filename",A1))) -> IFRS伝票処理
B8: 各部署 | I8: 業務推進部 事務管理G | W8: 財務部 経営計画G | AK8: 財務部 決算G | AY8: システム | BF8: 説明 | BV8: Gap （Add-On） | CC8: サンスター 担当部署・ 担当者 | CG8: サンスターコメント (現状との違い、補足、その他気になること)
I9: 担当者 | P9: 責任者 | W9: 担当者 | AD9: 責任者 | AK9: 担当者 | AR9: 責任者 | AY9: FO
B10: 1. IFRS帳票作成
BG18: 1．IFRS調整伝票入力 | CG18: １～４．事務管理Gでは実施していない
BH19: IFRS調整伝票の登録を行う。 | CG19: （現状アウトソーサー）
CG20: → 決算Gのプロセスに集約
BG21: ※ | BH21: IFRS用の調整伝票は
BH22: 転記階層：カスタムレイヤ1に作成されるように
BH23: 仕訳帳を設定する
BG26: 2．WF送信
BH27: 担当者は、登録した仕訳帳をWF送信を行う。
BG33: 3．承認
BH34: 責任者は、申請された伝票の内容を確認し、 | BV34: アドオン機能
BH35: 承認を行う。 | BV35: Req017
BV36: FO-031：仕訳帳承認対象一覧
BG40: 4．自動転記バッチ | BV40: アドオン機能
BH41: スケジュールされたバッチ処理により | BV41: Req377
BH42: 承認済仕訳帳が自動転記処理される | BV42: FO-034：自動転記バッチ
BG49: 5．残高試算表確認
BH50: 残高試算表を確認する。
BG52: ※ | BH52: 国内会計伝票とIFRS調整伝票を集計して表示する
BG60: 6．IFRS財務諸表作成
BH61: BSやPL等、財務諸表を作成する。
BG63: ※ | BH63: 国内会計伝票とIFRS調整伝票を集計して表示する
B77: 2. 固定資産モジュール仕訳の IFRS伝票作成
BG86: 1．国内会計減価償却費計上
BH87: 固定資産モジュールで
BH88: 国内会計用の仕訳伝票を作成
BG90: ※ | BH90: 固定資産モジュールで、
BH91: 国内会計用の仕訳伝票は
BH92: 転記階層：現行に作成されるように
BH93: 設定する
BG98: 2．IFRS減価償却費計上
BH99: 固定資産モジュールで
BH100: IFRS用の仕訳伝票を作成
BG102: ※ | BH102: 固定資産モジュールで、
...

Sheet 税務
A1: システム名 | F1: =変更履歴!F1 -> 会計システム刷新プロジェクト（LIBRA） | V1: タイトル | AJ1: 日付 | AQ1: 更新者
A2: 文書名 | F2: =変更履歴!F2 -> ToBe業務フロー（1.一般会計・決算） | V2: =MID(CELL("filename",$A$1),FIND("]",CELL("filename",$A$1))+1,31) -> 税務 | AJ2: 作成 | AL2: =変更履歴!AT2 -> 45362 | AQ2: =変更履歴!BA2 -> JBS福田
AJ3: 更新 | AL3: =変更履歴!AT3 -> 45910 | AQ3: =変更履歴!BA3 -> JBS加藤
A6: =RIGHT(CELL("filename",A1),LEN(CELL("filename",A1))-FIND("]",CELL("filename",A1))) -> 税務
B8: 各部署 | I8: 業務推進部 事務管理G | W8: 財務部 経営計画G | AK8: 財務部 決算G | AY8: システム | BM8: 説明 | CC8: Gap （Add-On） | CJ8: サンスター 担当部署・ 担当者 | CN8: サンスターコメント (現状との違い、補足、その他気になること)
I9: 担当者 | P9: 責任者 | W9: 担当者 | AD9: 責任者 | AK9: 担当者 | AR9: 責任者 | AY9: FO | BF9: 外部システム
B10: 1. 接待交際費明細
BN19: 1．接待交際費明細出力 | CN19: 事務管理Gにて対応（2025年4月2日正野）
BO20: 経費実績明細照会または、伝票トランザクションで | CC20: アドオン | CN20: → 修正済
BO21: 接待交際費の仕訳明細情報を出力する | CC21: FO-048：経費実績明細照会
B32: 2. 消費税申告
BN40: 1．消費税情報出力
BO41: 消費税レポート出力または消費税詳細を出力して
BO42: 消費税情報を出力する | CC42: アドオン
CC43: FO-058：消費税レポート出力
BN50: 2．消費税申告書EXCEL作成
BO51: 消費税申告書EXCELの各シートを編集
BN58: 3．税申告用ソフトへ登録
BO59: 税務会計ソフトへデータ登録
BN65: 4．申告書作成
BO66: 申告書を作成する
B76: 3. 法人税申告
BN84: 1．財務諸表
BO85: 法人税申告に必要なデータを出力
BO86: 各種対象科目の残高と明細を出力する
BN96: 2．税金計算ファイルEXCEL作成
BO97: 税金計算ファイルEXCELの各シートを編集
BO98: 各種別表作成
BN104: 3．税申告用ソフトへ登録
BO105: 税務会計ソフトへデータ登録
BN111: 4．申告書作成
BO112: 申告書を作成する
B122: 4. 事業税申告
BN130: 1．対象勘定明細出力
BO131: 経費実績明細照会で | CC131: アドオン
BO132: 事業税申告に必要な科目データを出力 | CC132: Req041
BO133: 対象勘定明細出力（相手勘定あり） | CC133: FO-048：経費実績明細照会
BO134: 業務委託料や支払賃料
BN145: 2．外形標準資料EXCEL作成
BO146: 外形標準資料EXCELの各シートを編集
...

Sheet 監査
A1: システム名 | F1: =[1]変更履歴!F1 -> プロジェクト名 | AJ1: タイトル | AX1: 日付 | BE1: 更新者
A2: 文書名 | F2: =[1]変更履歴!F2 -> FO標準フロー（会計） | AJ2: =MID(CELL("filename",$A$1),FIND("]",CELL("filename",$A$1))+1,31) -> 監査 | AX2: 作成 | AZ2: =[1]変更履歴!AT2 -> YYYY/MM/DD | BE2: =[1]変更履歴!BA2 -> 更新者名
AX3: 更新 | AZ3: =[1]変更履歴!AT3 -> YYYY/MM/DD | BE3: =[1]変更履歴!BA3 -> 更新者名
A6: =RIGHT(CELL("filename",A1),LEN(CELL("filename",A1))-FIND("]",CELL("filename",A1))) -> 監査
B8: 監査法人 | P8: 財務部 決算G | AD8: システム | AR8: 説明 | BH8: Gap （Add-On） | BO8: サンスター 担当部署・ 担当者 | BS8: サンスターコメント (現状との違い、補足、その他気になること)
B9: 担当者 | I9: 責任者 | P9: 担当者 | W9: 責任者 | AD9: FO | AK9: 外部システム
B10: １．監査
AS21: 1．財務諸表確認
AT22: 監査担当者は財務諸表を参照確認する
AS23: ※ | AT23: 監査担当者に
AT24: 各種財務諸表の参照権限を付与する
AS28: 2．科目残高/明細確認
AT29: 監査担当者は各種科目残高と関連明細を参照確認する
AS30: ※ | AT30: 監査担当者に
AT31: 試算表と伝票トランザクションの参照権限を付与する
AS35: 3．補助簿明細確認
AT36: 監査担当者は各種補助簿残高を参照確認する
AS37: ※ | AT37: 監査担当者に
AT38: 分析コード別の残高および明細の参照権限を付与する
AS42: 4．仕訳伝票確認
AT43: 監査担当者は個別仕訳伝票の詳細を参照確認する
AS44: ※ | AT44: 監査担当者に
AT45: 伝票トランザクションの検索参照権限を付与する
AS49: 5．証票確認
AT50: 監査担当者は伝票に付随する証票を参照確認する
AS51: ※ | AT51: 監査担当者に
AT52: 電子証票の検索参照権限を付与する

Sheet 自動転記バッチエラー仕訳帳の対応
A1: システム名 | F1: =変更履歴!F1 -> 会計システム刷新プロジェクト（LIBRA） | AC1: タイトル | AQ1: 日付 | AX1: 更新者
A2: 文書名 | F2: =変更履歴!F2 -> ToBe業務フロー（1.一般会計・決算） | AC2: =MID(CELL("filename",$A$1),FIND("]",CELL("filename",$A$1))+1,31) -> 自動転記バッチエラー仕訳帳の対応 | AQ2: 作成 | AS2: =変更履歴!AT2 -> 45362 | AX2: =変更履歴!BA2 -> JBS福田
AQ3: 更新 | AS3: =変更履歴!AT3 -> 45910 | AX3: =変更履歴!BA3 -> JBS加藤
A6: =RIGHT(CELL("filename",A1),LEN(CELL("filename",A1))-FIND("]",CELL("filename",A1))) -> 自動転記バッチエラー仕訳帳の対応
B8: 経理G/事務管理G | P8: ITDX | W8: システム | AD8: 説明 | AT8: Gap （Add-On） | BA8: サンスター 担当部署・ 担当者 | BE8: サンスターコメント (現状との違い、補足、その他気になること)
B9: 担当者 | I9: 責任者 | P9: 担当者 | W9: FO
B10: １．自動転記バッチでエラーとなった仕訳帳の対応
AE22: 1．自動転記ログ確認
AF23: 担当者は、定期的に自動転記ログを参照し
AF24: エラーとなった仕訳帳がないか確認する
AE28: ※申請者が修正不可のケース
AF29: 申請者が退職や移動で権限の変更があり
AF30: 仕訳帳のステータスを変更できないケースなど
AE33: ※申請者が修正可能のケース
AF34: 申請者側で編集(一般仕訳帳＞明細行＞編集)
AF35: することで
AF36: 承認ステータスが「承認済」から「ドラフト」に変更できる
AE41: 2．未転記の仕訳帳のワークフロー承認状態をリセット
AF42: ITDXの担当者に依頼して、該当仕訳帳の承認状態
AF43: をリセットする。
AE50: 3．伝票修正
AF51: 担当者は、該当仕訳帳のエラー内容を修正する。
AE56: 4．WF送信
AF57: 担当者は、修正した仕訳帳をWF送信を行う。
AE64: 5．承認
AF65: 責任者は、申請された伝票の内容を確認し、 | AT65: アドオン機能
AF66: 承認を行う。 | AT66: Req017
AT67: FO-031：仕訳帳承認対象一覧
AE72: 6．自動転記バッチ | AT72: アドオン機能
AF73: スケジュールされたバッチ処理により | AT73: Req377
AF74: 承認済仕訳帳が自動転記処理される | AT74: FO-034：自動転記バッチ
AE81: 7．残高確認・仕訳伝票照会
AF82: 転記後の残高を確認する
AF83: 転記された伝票トランザクションを確認する
