Workbook

Sheet 表紙
B3: サンスター株式会社 御中
B10: 会計システム刷新プロジェクト（LIBRA）
B14: ToBe業務フロー（4.債務）
B22: ="第"&IF(COUNTA(変更履歴!BE5:BH10008)=1,"",INDIRECT("変更履歴!BE"&COUNTA(変更履歴!BE5:BH10008)+4))&"版" -> 第1.9版
B24: {=IF(OR(COUNTA(変更履歴!A:E)=3),"",INDIRECT("変更履歴!A"&COUNTA(変更履歴!A:E)+2))} -> 45890
B26: 日本ビジネスシステムズ株式会社
F29: 作成者 | O29: JBS承認者 | V29: 承認者
F30: 45362 | N30: 45433
F31: JBS秋信 | N31: JBS加藤

Sheet 変更履歴
A1: システム名 | F1: =表紙!B10 -> 会計システム刷新プロジェクト（LIBRA） | W1: タイトル | AR1: 日付 | BA1: 更新者
A2: 文書名 | F2: =表紙!B14 -> ToBe業務フロー（4.債務） | W2: =MID(CELL("filename",$A$1),FIND("]",CELL("filename",$A$1))+1,31) -> #VALUE! | AR2: 作成 | AT2: =A6 -> 45362 | BA2: =AZ6 -> JBS秋信
AR3: 更新 | AT3: {=IF(OR(COUNTA(A:E)=3),"",INDIRECT("A"&COUNTA(A:E)+2))} -> 45890 | BA3: {=IF(COUNTA(AZ5:BD100008)=1,"",INDIRECT("変更履歴!AZ"&COUNTA(AZ5:BD100008)+4))} -> JBS秋信
A5: 変更年月日 | F5: 変更箇所 | T5: 変更内容 | AZ5: 変更者 | BE5: 版数
A6: 45362 | F6: 新規作成 | T6: 新規作成 | AZ6: JBS秋信 | BE6: 0.1
A7: 45433 | F7: 初版確定 | T7: 初版確定 | AZ7: JBS秋信 | BE7: 1.0
A8: 45649 | F8: A．銀行口座マスタ登録 B．相殺契約登録 | T8: 以下業務フローを新規作成 A．銀行口座マスタ登録 B．相殺契約登録 | AZ8: JBS秋信 | BE8: 1.1
A9: 45740 | F9: シート：２．前払 | T9: ２．前払（費用発生時）に承認業務、自動転記バッチの業務を追加 | AZ9: JBS秋信 | BE9: 1.2
A10: 45740 | F10: シート：４．支払予定修正・保留 | T10: １．支払予定修正 修正前：仕入先トランザクション 修正後：仕入先トランザクション（トランザクションの決済） | AZ10: JBS秋信 | BE10: 1.2
A11: 45740 | F11: シート：４．支払予定修正・保留 | T11: １．支払予定修正 に支払方法・支払サイト更新バッチの再実行についての記載を追加 | AZ11: JBS秋信 | BE11: 1.2
A12: 45740 | F12: シート：４．支払予定修正・保留 | T12: ３．支払保留解除 を作成 | AZ12: JBS秋信 | BE12: 1.2
A13: 45740 | F13: シート：５．支払前 | T13: １．相殺処理（滋賀ホスト）、２．支払前に承認業務、自動転記バッチの業務を追加 | AZ13: JBS秋信 | BE13: 1.2
A14: 45740 | F14: シート：５．支払前 | T14: ２．支払前 の売上計上のFO連携先を「一般仕訳帳」に変更 | AZ14: JBS秋信 | BE14: 1.2
A15: 45740 | F15: シート：５．支払前 | T15: ９．支払合計表/明細表確認・出力 に、「債務残高明細」を追加 | AZ15: JBS秋信 | BE15: 1.2
A16: 45740 | F16: C．仕入先マスタ・仕入先の銀行口座 | T16: 新規作成 | AZ16: JBS秋信 | BE16: 1.2
A17: 45754 | F17: シート：５．支払前 | T17: １．相殺処理（滋賀ホスト） ８．相殺完了連絡受領（滋賀ホスト）を削除 | AZ17: JBS秋信 | BE17: 1.3
... A29: 45890 | F29: シート：B．相殺決済契約 | T29: 相殺決済契約の有効化の担当をITDX⇒事務管理Gに変更 | AZ29: JBS秋信 | BE29: 1.9

Sheet 凡例
A1: システム名 | F1: =変更履歴!F1 -> 会計システム刷新プロジェクト（LIBRA） | V1: タイトル | AJ1: 日付 | AQ1: 更新者
A2: 文書名 | F2: =変更履歴!F2 -> ToBe業務フロー（4.債務） | V2: =MID(CELL("filename",$A$1),FIND("]",CELL("filename",$A$1))+1,31) -> #VALUE! | AJ2: 作成 | AL2: =変更履歴!AT2 -> 45362 | AQ2: =変更履歴!BA2 -> JBS秋信
AJ3: 更新 | AL3: =変更履歴!AT3 -> 45890 | AQ3: =変更履歴!BA3 -> JBS秋信
A6: 凡例
H10: ： | I10: フローの開始 | AC10: ： | AD10: フローの終了
H15: ： | I15: システムを伴わない業務 | AC15: ： | AD15: システム上での業務
H20: ： | I20: 帳票（システムで作成される帳票） | AC20: ： | AD20: 帳票（システム外で作成される帳票）
H25: ： | I25: 業務の流れ | AC25: ： | AD25: システムへの連携
H30: ： | I30: 分岐 | AC30: ： | AD30: システム
H35: ： | I35: フロー間の繋がりを示す | AC35: ： | AD35: ファイル（CSVファイル等）
A40: 凡例
B43: 社内部署 | J43: ： | K43: フローに登場する社内の部署を記載
K44: 部署内の担当者が分かれる場合は以下の通りに分ける
B46: 社内部署
B47: 担当者 | I47: 責任者
B50: 外部担当者 | J50: ： | K50: フローに登場する社外担当者の部署を記載
K51: 例）得意先、仕入先
B54: システム | J54: ： | K54: フロー上で実施されるシステムの機能を記載する列
B55: XX | K55: XXの部分にフローで登場するシステム名を記載
K56: 例は以下の通り（JBSで導入するシステム外のものは「外部システム」で統一）
B58: システム
B59: FO | I59: CE | P59: 外部システム
B62: 説明 | S62: ： | T62: フロー内容を説明する列
B66: Gap （Add-On） | J66: ： | K66: フローに対してのGapを記載する列
B70: １．パターン１ | AI70: ： | AJ70: フローのパターンごとに記載する

Sheet １．仕入計上・請求処理
A1: システム名 | F1: =変更履歴!F1 -> 会計システム刷新プロジェクト（LIBRA） | V1: タイトル | AJ1: 日付 | AQ1: 更新者
A2: 文書名 | F2: =変更履歴!F2 -> ToBe業務フロー（4.債務） | V2: =MID(CELL("filename",$A$1),FIND("]",CELL("filename",$A$1))+1,31) -> #VALUE! | AJ2: 作成 | AL2: =変更履歴!AT2 -> 45362 | AQ2: =変更履歴!BA2 -> JBS秋信
AJ3: 更新 | AL3: =変更履歴!AT3 -> 45890 | AQ3: =変更履歴!BA3 -> JBS秋信
A6: =RIGHT(CELL("filename",A1),LEN(CELL("filename",A1))-FIND("]",CELL("filename",A1))) -> #VALUE!
B8: 仕入先 | I8: 各工場、購買 | P8: 各部門 | W8: 事務管理 | AD8: 総務 | AK8: 物流企画 | AR8: システム | BF8: 説明 | BV8: Gap （Add-On） | CC8: サンスター 担当部署・ 担当者 | CG8: サンスターコメント (現状との違い、補足、その他気になること)
AR9: FO | AY9: 外部システム
B10: １．仕入計上・請求処理
BG19: 1．請求書の送付
BH20: 仕入先が請求書の送付を行う。 | CT20: BtoBプラットフォーム(電子請求書)有り。
CT21: 会計システムへ伝送する。
BG26: 2．請求書受領
BH27: 仕入先から請求書を受領する。
BG31: 3．仕入計上 | CH31: 仕入計上システム： MCF、AS400、楽楽精算、BtoB、広告費システム、販売管理システム、EDIL ＜仕訳例＞ 仕入／買掛金 費用／未払金 固定資産／未払金（設備） 販促費／未払金（販促費） 販促費／未払金（リベート他） システム、伝票種別により、データ項目「伝票タイプ」「支払日」が設定されている MCF、AS400、BtoB、広告費は翌月20日固定
BH32: 各担当部署・担当者が該当システムに | CC32: MCF AS400 各工場、購買 楽楽精算 BtoB 各部門 広告費 事務管理 販売管理システム 総務 EDIL 物流企画
BH33: 仕入計上をする。
BH34: 以下の会計転記が行われる。
BH35: 【仕訳例】
BH36: 仕入 | BL36: 買掛金
BH37: 費用 | BL37: 未払金
BH38: 固定資産 | BL38: 未払金（設備）
BH39: 販促費 | BL39: 未払金（販促費）
BH40: 販促費 | BL40: 未払金（リベート他）
BG44: ※ | BH44: 連携される債務データは以下。
BH45: mcframe,SEJホスト | BN45: - | BO45: 資材購買、商品購買
BH46: 楽楽精算 | BN46: - | BO46: 経費支払
BH47: BtoBプラットフォーム | BN47: - | BO47: 経費支払
BH48: 広告費システム | BN48: - | BO48: 広告費支払
BH49: EDIL | BN49: - | BO49: 物流費会社間請求
BH50: SLJ販売管理 | BN50: - | BO50: 印刷費会社間請求
BH51: Company | BN51: - | BO51: 給与
BG54: ※ | BH54: mcframe、SEJホストは、納品書を工場で保管。
BG55: ※ | BH55: 楽楽精算、BtoBプラットフォーム上に、請求書を
BH56: 保存、経理が確認を行う。
BG57: ※ | BH57: SLJ販売管理は、BtoBプラットフォームを使用し、
BH58: 総務から経理が請求書を受領する。
BG59: ※ | BH59: EDILは、物流計画から経理が請求書を受領する。
BV63: IF機能の開発
BG65: 外部システムより、仕入実績データを取り込む
BG66: ※ | BH66: システム、伝票種別により、データ項目
BH67: 「伝票タイプ」「支払日」が設定されている
...

Sheet ２．前払
A1: システム名 | F1: =変更履歴!F1 -> 会計システム刷新プロジェクト（LIBRA） | V1: タイトル | AJ1: 日付 | AQ1: 更新者
A2: 文書名 | F2: =変更履歴!F2 -> ToBe業務フロー（4.債務） | V2: =MID(CELL("filename",$A$1),FIND("]",CELL("filename",$A$1))+1,31) -> #VALUE! | AJ2: 作成 | AL2: =変更履歴!AT2 -> 45362 | AQ2: =変更履歴!BA2 -> JBS秋信
AJ3: 更新 | AL3: =変更履歴!AT3 -> 45890 | AQ3: =変更履歴!BA3 -> JBS秋信
A6: =RIGHT(CELL("filename",A1),LEN(CELL("filename",A1))-FIND("]",CELL("filename",A1))) -> #VALUE!
B8: 事務管理G | P8: ITDX | W8: システム | AK8: 説明 | BA8: Gap （Add-On） | BH8: サンスター 担当部署・ 担当者 | BL8: サンスターコメント (現状との違い、補足、その他気になること)
B9: 担当者 | I9: 責任者 | P9: 担当者 | W9: FO | AD9: 外部システム
B10: １．前払（計上）
BH12: 事務管理
AL23: １．前払登録
AM24: 事務管理Gは、楽楽精算、BtoBプラットフォームにて
AM25: 前払の仕訳と計上する。
AM26: 【仕訳例】
AM27: 前払 | AQ27: 未払金
BA30: IF機能の開発
BL32: ※前払は楽楽精算、BtoBで「前払／未払金」の仕訳を計上し、通常の支払処理に入れる。 費用発生月に「費用／前払」の振替処理を行う
B38: ２．前払（費用発生時）
AL49: １．前払振替登録・申請
AM50: 事務管理Gは、一般仕訳帳にて
AM51: 前払の振替仕訳を登録・申請する。
AL56: ２．前払振替承認
AM57: 承認者は、一般仕訳帳にて
AM58: 前払の振替仕訳の承認を行う。
AM59: 【仕訳例】
AM60: 費用 | AQ60: 前払
AL64: ３．自動転記バッチ
AM65: スケジュールされたバッチ処置により
AM66: 承認済仕訳帳が自動転記処理される

Sheet ３．経費精算
A1: システム名 | F1: =変更履歴!F1 -> 会計システム刷新プロジェクト（LIBRA） | V1: タイトル | AJ1: 日付 | AQ1: 更新者
A2: 文書名 | F2: =変更履歴!F2 -> ToBe業務フロー（4.債務） | V2: =MID(CELL("filename",$A$1),FIND("]",CELL("filename",$A$1))+1,31) -> #VALUE! | AJ2: 作成 | AL2: =変更履歴!AT2 -> 45362 | AQ2: =変更履歴!BA2 -> JBS秋信
AJ3: 更新 | AL3: =変更履歴!AT3 -> 45890 | AQ3: =変更履歴!BA3 -> JBS秋信
A6: =RIGHT(CELL("filename",A1),LEN(CELL("filename",A1))-FIND("]",CELL("filename",A1))) -> #VALUE!
B8: 各部署 | P8: 事務管理G | W8: システム | AK8: 説明 | BA8: Gap （Add-On） | BH8: サンスター 担当部署・ 担当者 | BL8: サンスターコメント (現状との違い、補足、その他気になること)
B9: 担当者 | I9: 責任者 | P9: 担当者 | W9: FO | AD9: 外部システム
B10: １．個別精算
AL16: １．精算内容入力
AM17: 各部署の担当者が楽楽精算に精算内容の入力を行う。
AM18: 【仕訳例】
AM19: （社員経費の場合）
AM20: 費用 | AS20: 未払金（社員経費）
AM21: 交際費
AM22: （仮払金申請-振込の場合）
AM23: 仮払金（社員経費） | AS23: 未払金（社員経費）
AM24: （仮払金申請-現金の場合）
AM25: 仮払金（社員経費） | AS25: 現金
AM27: ※ | AN27: 仮払金申請後の精算仕訳
AM28: 【仕訳例】
AM29: 費用 | AS29: 仮払金（社員経費）
BA31: IF機能の開発
BH35: 事務管理 （深川） | BL35: ＜楽楽精算からの連携仕訳＞ 費用／未払金（社員経費） 社員の口座への振込は、SAPでファイル作成し、銀行システムにアップロードしています
AL37: ２．従業員別債務残高確認
AM38: 事務管理Gが財務分析コードを仕入先を指定し、
AM39: 試算表を出力し、従業員別の債務残高を
AM40: 確認する。
BH46: 事務管理 （山口） | BL46: 経費精算、交際費精算とは別で仮払金申請
BL47: があります。

Sheet ４．支払予定修正・保留
A1: システム名 | F1: =変更履歴!F1 -> 会計システム刷新プロジェクト（LIBRA） | V1: タイトル | AJ1: 日付 | AQ1: 更新者
A2: 文書名 | F2: =変更履歴!F2 -> ToBe業務フロー（4.債務） | V2: =MID(CELL("filename",$A$1),FIND("]",CELL("filename",$A$1))+1,31) -> #VALUE! | AJ2: 作成 | AL2: =変更履歴!AT2 -> 45362 | AQ2: =変更履歴!BA2 -> JBS秋信
AJ3: 更新 | AL3: =変更履歴!AT3 -> 45890 | AQ3: =変更履歴!BA3 -> JBS秋信
A6: =RIGHT(CELL("filename",A1),LEN(CELL("filename",A1))-FIND("]",CELL("filename",A1))) -> #VALUE!
B8: 事務管理G | P8: システム | AD8: 説明 | AT8: Gap （Add-On）
B9: 担当者 | I9: 責任者 | P9: FO | W9: 外部システム
B10: １．支払予定修正
AE20: １．支払基準日の変更
AF21: 事務管理Gは仕入先トランザクション | AT21: 一括更新機能
AF22: （トランザクションの決済）画面にて、 | AT22: ⇒Add-Onなし
AF23: 支払基準日の修正を行う。
AF24: ※ | AG24: 洗替処理で計算された支払日を変更することは
AG25: ない。
AF26: ※ | AG26: 支払方法・支払サイト更新バッチの
AG27: 再実行時は以下項目をバッチ実施前の状態に戻すこと。
AG28: ・ | AH28: 期日
AG29: ・ | AH29: 支払方法・支払サイト更新フラグ
AG30: ・ | AH30: 支払サイト
B35: ２．支払保留
AE45: １．支払保留
AF46: 事務管理Gは仕入先トランザクション画面にて、 | AT46: 一括更新機能
AF47: 「請求書支払リリース日」の更新し、支払保留を行う。 | AT47: ⇒Add-Onなし
AF48: ※ | AG48: 基本、洗替処理前に保留を実施。
AG49: 計上誤り等で洗替処理後に保留する場合もある。
AF50: ※ | AG50: 仕入先トランザクション
AG51: （トランザクションの決済）画面でも可
B56: ３．支払保留解除
AE66: １．支払保留解除
AF67: 事務管理Gは仕入先トランザクション画面にて、
AF68: 「支払基準日」の更新する。
AF69: 「請求書支払リリース日」を空欄に更新する。
AF70: ※ | AG70: 本作業は、支払方法・支払サイト更新バッチ
AG71: 処理前に完了すること。
AF72: ※ | AG72: 仕入先トランザクション
AG73: （トランザクションの決済）画面でも可

Sheet ５．支払前
A1: システム名 | F1: =変更履歴!F1 -> 会計システム刷新プロジェクト（LIBRA） | V1: タイトル | AJ1: 日付 | AQ1: 更新者
A2: 文書名 | F2: =変更履歴!F2 -> ToBe業務フロー（4.債務） | V2: =MID(CELL("filename",$A$1),FIND("]",CELL("filename",$A$1))+1,31) -> #VALUE! | AJ2: 作成 | AL2: =変更履歴!AT2 -> 45362 | AQ2: =変更履歴!BA2 -> JBS秋信
AJ3: 更新 | AL3: =変更履歴!AT3 -> 45890 | AQ3: =変更履歴!BA3 -> JBS秋信
A6: =RIGHT(CELL("filename",A1),LEN(CELL("filename",A1))-FIND("]",CELL("filename",A1))) -> #VALUE!
B8: 事務管理G | P8: カスタマーサービスG | W8: ITDX | AD8: システム | AR8: 説明 | BH8: Gap （Add-On） | BO8: サンスター 担当部署・ 担当者 | BS8: サンスターコメント (現状との違い、補足、その他気になること)
B9: 担当者 | I9: 責任者 | AD9: FO | AK9: 外部システム
B10: １．相殺処理（滋賀ホスト）
BH17: IF機能の開発
AS18: １．預かり売掛金振替処理（滋賀ホスト）
AT19: SEJ滋賀工場がSEJホストで相殺対象の
AT20: 滋賀ホスト分の売掛金を預かり売掛金に振替を行う。
AT21: 【仕訳例】
AT22: 預かり売掛金 | AX22: 売掛金
AS27: ２．相殺依頼（滋賀ホスト）
AT28: SEJ滋賀工場が事務管理Gに相殺依頼の
AT29: 連絡を行う。
AS34: ３．相殺依頼内容確認（滋賀ホスト）
AT35: 事務管理Gに受領した相殺依頼内容の確認を行う。
AS40: ４．買掛金残高確認（滋賀ホスト）
AT41: 事務管理Gに対象の仕入先の残高の確認を行う。
AT42: ￥
AS47: ５．預かり売掛金相殺登録（滋賀ホスト）
AT48: 事務管理Gが仕入先支払仕訳帳にて、買掛金と
AT49: 預かり売掛金の相殺仕訳の登録を行う。
AT50: 債務データは「トランザクションの決済」で選択し、
AT51: 相手勘定は預かり売掛金を設定する。
AS54: ６．預かり売掛金相殺承認（滋賀ホスト）
AT55: 事務管理Gが仕入先支払仕訳帳にて、買掛金と
AT56: 預かり売掛金の相殺仕訳の承認を行う。
AS61: ７．転記
AT62: 承認後、担当者は仕入先支払仕訳帳で、
AT63: 転記を実施する。
AT64: 【仕訳例】
AT65: 買掛金 | AX65: 預かり売掛金
BO68: 事務管理
BO69: 藤田 | BS69: ８，操作完了連絡は行いませんので、削除をお願いします
B80: ２．支払前 | BS80: 支払処理の種類 ５種類行っております。 処理日、集計内容がそれぞれ異なります。 ・規定払（翌月20日払) ・規定外支払（10日20日25日末日) ・リベート支払(10日20日末日) ・販促費支払（10日20日末日) ・外国送金（10日20日25日末日) <仕入先コード> 21から始まる7桁 SSJ 22から始まる7桁 SEJ 23から始まる7桁 SLJ <得意先コード> 11から始まる７桁～8桁 | CE80: ※支払は内容が多岐に渡
CE81: るため、現状との違いを
CE82: 書ききれません。
CE83: 別途フローを提出いたします。
...

Sheet ６．支払（銀行振込・海外送金・小切手）
A1: システム名 | F1: =変更履歴!F1 -> 会計システム刷新プロジェクト（LIBRA） | V1: タイトル | AJ1: 日付 | AQ1: 更新者
A2: 文書名 | F2: =変更履歴!F2 -> ToBe業務フロー（4.債務） | V2: =MID(CELL("filename",$A$1),FIND("]",CELL("filename",$A$1))+1,31) -> #VALUE! | AJ2: 作成 | AL2: =変更履歴!AT2 -> 45362 | AQ2: =変更履歴!BA2 -> JBS秋信
AJ3: 更新 | AL3: =変更履歴!AT3 -> 45890 | AQ3: =変更履歴!BA3 -> JBS秋信
A6: =RIGHT(CELL("filename",$A$1),LEN(CELL("filename",$A$1))-FIND("]",CELL("filename",$A$1))) -> #VALUE!
B8: 事務管理G | P8: ITDX | W8: システム | AK8: 説明 | BA8: Gap （Add-On） | BH8: サンスター 担当部署・ 担当者 | BL8: サンスターコメント (現状との違い、補足、その他気になること)
B9: 担当者 | I9: 責任者 | W9: FO | AD9: 外部システム
B10: １．支払（銀行振込、海外送金、小切手） | BL10: 支払処理の種類 ５種類行っております。 処理日、集計内容がそれぞれ異なります。 ・規定払（翌月20日払) ・規定外支払（10日20日25日末日) ・リベート支払(10日20日末日) ・販促費支払（10日20日末日) ・外国送金（10日20日25日末日) <仕入先コード> 21から始まる7桁 SSJ 22から始まる7桁 SEJ 23から始まる7桁 SLJ <得意先コード> 11から始まる７桁～8桁 | BX10: ※支払は内容が多岐に渡
BX11: るため、現状との違いを
BX12: 書ききれません。
BX13: 別途フローを提出いたします。
BH17: 事務管理 （安東）
BL22: 楽楽精算、BtoB上で請求書保存・経理チェックは完了している。 MCF、AS400は納品書を工場で保管。販売管理システムはBtoBで総務から経理が請求書を受領。EDILはPDFで物流企画から経理が受領。
BH31: 事務管理 （藤田、深川）
AL35: １．債務データの紐づけ
AM36: FOの仕入先支払仕訳帳画面にて仕訳帳を作成し、
AM37: 支払提案の機能から支払対象のデータを選択する
AM38: ※ | AN38: 債務データの紐づけを後で実施する場合、 | BL38: ＜現状＞ファクタリング、電債、でんさい、期日振込 １．支払提案をして「支払日」「仕入先コード」「転記日付」「最終入力日」「支払方法」「支払元会社（108,191,817)」を設定、抽出 ２．20日までのデータ（1月計上の場合、2月20日の転記日付のデータ）を抽出し、未決済のデータで支払対象の金額を確認。（20日を指定する理由：相殺のデータが20日で計上されている為） ３．50万円未満（SSJ）、10万円未満(SEJ）の仕入先を確認 ４．１．ー２．＝３．の金額になっていたら差異がないので、支払処理を実行 （買掛金／銀行仮勘定の仕訳発生） （電債とでんさいのみ、支払手形義務見返／電子記録債務 の仕訳も発生） ５．４で作成されたファイルを銀行システムにアップロード→上長承認 ６．電債、ファクタリング、でんさいは期日到来日の仕訳をSAPで計上
AN39: 別途消込を行う。
AL41: ２．支払承認申請
AM42: 事務管理G担当者が責任者に支払の承認を申請する。
AM43: 承認者にシステムとメール上で承認依頼通知がくる。
AL49: ３．支払の承認/変更依頼
AM50: 事務管理G責任者が該当する仕入先支払仕訳帳の内容を
AM51: 確認し、仕入先支払仕訳帳（承認）画面から、承認
AM52: または変更依頼を行う。
AM53: 承認および変更依頼ともに申請者にシステムとメール上で
AM54: 通知がくる。
AL60: ４．不備修正 | BL60: 不備の修正は元の計上システムで取消・訂正の計上を行う。 MCF、AS400から計上する支払データは支払日が指定できない為、SAPの画面で「支払基準日」のみ変更するプロセスが発生 支払銀行について SSJ50万円未満、SEJ10万円未満の振込、支払方法が「全額振込」の支払は、三菱UFJ銀行当座預金から出金。 期日振込で50万円以上の振込は、三井住友銀行から出金 販促費支払（11から始まる仕入先コードの支払）の振込は、みずほ銀行から出金 海外送金は、仕入先ごとに出金する銀行が決定している 税の納付等、納付書で支払を行う場合は小切手を振り出し、銀行に持ち込み。仕訳は「未払金／当座預金」で振替伝票を起票 <気になること> SAPでは支払処理前に支払金額を確認できかなかった為、下記確認を実施 ・マイナス残高の確認 ・振替伝票で支払の仕訳が入っていないか 支払処理後に出力される帳票必要 ・ご拡売協力金 仕入先別、会社別、期間指定、貸方勘定科目（統制勘定）で抽出した一覧が画面で確認できるか？ ・外部システム（BtoBや楽楽精算等）との連携頻度（現在は上記２システムは8時12時15時に連携）設定できるか ・支払方法別の仕入先残高を確認する方法はありますか？（決算明細で提出する為、Excelでの出力が望ましい） ・支払処理の過程で相殺を行う為、相殺のフローが必要です ・検収明細と実際の支払金額の差額調整を行っている為、検収明細金額の一覧が必要です ・支払後に手数料差し引き前、差し引き後の支払金額の一覧を作成しています。支払処理時に自動出力することは可能ですか？
AM61: 事務管理G担当者が変更依頼された仕入先支払仕訳帳の
AM62: 内容を確認し、不備の内容を修正する。
AL69: ※ | AM69: 小切手は手動で行う。
AL74: ５．EBデータ出力
AM75: 承認された内容でEBデータを作成する
AL86: ６．EBデータ取り込み
AM87: 銀行システムにてEBデータの取り込みを実施する
AL101: ７．承認
AM102: 事務管理G責任者は、銀行システムにて、
AM103: 確認・承認を行う。
AL109: ８．支払データ転記 | BA109: 自動転記は開発が必要。
AM110: 手順１で作成した仕訳帳を転記する。 | BA110: ⇒Add-Onなし
...

Sheet ７．電子記録債務計上・決済
A1: システム名 | F1: =変更履歴!F1 -> 会計システム刷新プロジェクト（LIBRA） | V1: タイトル | AJ1: 日付 | AQ1: 更新者
A2: 文書名 | F2: =変更履歴!F2 -> ToBe業務フロー（4.債務） | V2: =MID(CELL("filename",$A$1),FIND("]",CELL("filename",$A$1))+1,31) -> #VALUE! | AJ2: 作成 | AL2: =変更履歴!AT2 -> 45362 | AQ2: =変更履歴!BA2 -> JBS秋信
AJ3: 更新 | AL3: =変更履歴!AT3 -> 45890 | AQ3: =変更履歴!BA3 -> JBS秋信
A6: =RIGHT(CELL("filename",A1),LEN(CELL("filename",A1))-FIND("]",CELL("filename",A1))) -> #VALUE!
B8: 事務管理G | P8: システム | AD8: 説明 | AT8: Gap （Add-On） | BA8: サンスター 担当部署・ 担当者 | BE8: サンスターコメント (現状との違い、補足、その他気になること)
B9: 担当者 | I9: 責任者 | P9: FO | W9: 外部システム
B10: １．電子記録債務計上
AE21: １．債務データの紐づけ
AF22: FOの支払手形仕訳帳の振出画面にて仕訳帳を作成し、
AF23: 支払提案の機能から対象のデータを選択する
AF24: ※ | AG24: 債務データの紐づけを後で実施する場合、 | BE24: ＜現状＞ファクタリング、電債、でんさい、期日振込 １．支払提案をして「支払日」「仕入先コード」「転記日付」「最終入力日」「支払方法」「支払元会社（108,191,817)」を設定、抽出 ２．20日までのデータ（1月計上の場合、2月20日の転記日付のデータ）を抽出し、未決済のデータで支払対象の金額を確認。（20日を指定する理由：相殺のデータが20日で計上されている為） ３．50万円未満（SSJ）、10万円未満(SEJ）の仕入先を確認 ４．１．ー２．＝３．の金額になっていたら差異がないので、支払処理を実行 （買掛金／銀行仮勘定の仕訳発生） （電債とでんさいのみ、支払手形義務見返／電子記録債務 の仕訳も発生） ５．４で作成されたファイルを銀行システムにアップロード→上長承認 ６．電債、ファクタリング、でんさいは期日到来日の仕訳をSAPで計上
AG25: 別途消込を行う。
AF26: ※ | AG26: この時、期日を決済日に更新を行う。 | AT26: ←自動化。
AE28: ２．電子記録債務計上承認申請
AF29: 事務管理G担当者が責任者に申請する。
AF30: 承認者にシステムとメール上で承認依頼通知がくる。
AE36: ３．電子記録債務計上承認/変更依頼
AF37: 事務管理G責任者が該当する支払手形仕訳帳の振出の内容を
AF38: 確認し、支払手形仕訳帳の振出（承認）画面から、承認
AF39: または変更依頼を行う。
AF40: 承認および変更依頼ともに申請者にシステムとメール上で
AF41: 通知がくる。
AE47: ４．不備修正 | BE47: 不備の修正は元の計上システムで取消・訂正の計上を行う。 MCF、AS400から計上する支払データは支払日が指定できない為、SAPの画面で「支払基準日」のみ変更するプロセスが発生 支払銀行について SSJ50万円未満、SEJ10万円未満の振込、支払方法が「全額振込」の支払は、三菱UFJ銀行当座預金から出金。 期日振込で50万円以上の振込は、三井住友銀行から出金 販促費支払（11から始まる仕入先コードの支払）の振込は、みずほ銀行から出金 海外送金は、仕入先ごとに出金する銀行が決定している 税の納付等、納付書で支払を行う場合は小切手を振り出し、銀行に持ち込み。仕訳は「未払金／当座預金」で振替伝票を起票 <気になること> SAPでは支払処理前に支払金額を確認できかなかった為、下記確認を実施 ・マイナス残高の確認 ・振替伝票で支払の仕訳が入っていないか 支払処理後に出力される帳票必要 ・ご拡売協力金 仕入先別、会社別、期間指定、貸方勘定科目（統制勘定）で抽出した一覧が画面で確認できるか？ ・外部システム（BtoBや楽楽精算等）との連携頻度（現在は上記２システムは8時12時15時に連携）設定できるか ・支払方法別の仕入先残高を確認する方法はありますか？（決算明細で提出する為、Excelでの出力が望ましい） ・支払処理の過程で相殺を行う為、相殺のフローが必要です ・検収明細と実際の支払金額の差額調整を行っている為、検収明細金額の一覧が必要です ・支払後に手数料差し引き前、差し引き後の支払金額の一覧を作成しています。支払処理時に自動出力することは可能ですか？
AF48: 事務管理G担当者が変更依頼された支払手形仕訳帳の振出の
AF49: 内容を確認し、不備の内容を修正する。
AE61: ５．EBデータ出力
AF62: 承認された内容でデータを出力する。 | AT62: データ出力機能の開発（×2）
AE71: ６．EBデータ取り込み
AF72: 銀行システムにてデータの取り込みを実施する。
AF73: ※ | AG73: SEJは電債。三菱UFJ銀行へ。
AF74: ※ | AG74: SSJはでんさい、三井住友銀行へ。
AE86: ７．承認
AF87: 事務管理G責任者は、銀行システムにて、
AF88: 確認・承認を行う。
AE97: ８．電子記録債務計上 | AT97: 自動転記は開発が必要。
AF98: 手順１で作成した仕訳帳を転記する。 | AT98: ⇒Add-Onなし
AF99: 【仕訳例】
AF100: 買掛金 | AL100: 電子記録債務
AF101: 未払金（設備）
AF102: 未払金（販促費）
...

Sheet ８．口座引落
A1: システム名 | F1: =変更履歴!F1 -> 会計システム刷新プロジェクト（LIBRA） | V1: タイトル | AJ1: 日付 | AQ1: 更新者
A2: 文書名 | F2: =変更履歴!F2 -> ToBe業務フロー（4.債務） | V2: =MID(CELL("filename",$A$1),FIND("]",CELL("filename",$A$1))+1,31) -> #VALUE! | AJ2: 作成 | AL2: =変更履歴!AT2 -> 45362 | AQ2: =変更履歴!BA2 -> JBS秋信
AJ3: 更新 | AL3: =変更履歴!AT3 -> 45890 | AQ3: =変更履歴!BA3 -> JBS秋信
A6: =RIGHT(CELL("filename",A1),LEN(CELL("filename",A1))-FIND("]",CELL("filename",A1))) -> #VALUE!
B8: 事務管理G | P8: システム | AD8: 説明 | AT8: Gap （Add-On）
B9: 担当者 | I9: 責任者 | P9: FO | W9: 外部システム
B10: １．契約内容登録
AE19: １．契約内容登録 | AT19: アドオン
AF20: 事務管理Gは、口座引落契約台帳に契約内容
AF21: （Excel台帳）をもとに、登録を行う。
AF22: ※ | AG22: Excel Addinでも登録可。
AF23: ※ | AG23: 入力内容
AG24: 引落会社、需要家番号、計上費用科目、計上部課
B34: ２．口座引落
AT57: IF機能
AT65: アドオン
AE72: １．引落結果確認 | AT72: アドオン
AF73: 事務管理Gは、口座引落結果を確認する。
AF74: 【仕訳例】
AF75: 費用 | AJ75: 預金
AE90: ２．口座引落契約台帳修正
AF91: 事務管理Gは、引落マッチング不備となったもので、
AF92: 口座引落契約台帳の修正対象の契約の
AF93: 修正を行う。
AE97: ３．引落データ対象外のステータス更新
AF98: 事務管理Gは、引落マッチング不備となったもので、
AF99: 引落データ対象外のデータについて、ステータス
AF100: 「転記対象外」に変更する。
AE105: ４．マッチング再実行
AF106: 事務管理Gは、引落結果出力画面より、
AF107: 「再実行」ボタンを押下し、マッチング処理を行う。
B114: 参考．口座引落（As-Is）
AF140: ※ | AG140: Excel台帳に勘定科目、計上部課ごとにデータを作成
AF141: ※ | AG141: 入出金データの出金データで、依頼人コード、需要家番号、金額が一致するものを確認。
AF156: 【仕訳例】
AF157: 費用 | AJ157: 預金

Sheet Ａ．銀行口座マスタ登録
A1: システム名 | F1: =変更履歴!F1 -> 会計システム刷新プロジェクト（LIBRA） | V1: タイトル | AJ1: 日付 | AQ1: 更新者
A2: 文書名 | F2: =変更履歴!F2 -> ToBe業務フロー（4.債務） | V2: =MID(CELL("filename",$A$1),FIND("]",CELL("filename",$A$1))+1,31) -> #VALUE! | AJ2: 作成 | AL2: =変更履歴!AT2 -> 45362 | AQ2: =変更履歴!BA2 -> JBS秋信
AJ3: 更新 | AL3: =変更履歴!AT3 -> 45890 | AQ3: =変更履歴!BA3 -> JBS秋信
A6: =RIGHT(CELL("filename",A1),LEN(CELL("filename",A1))-FIND("]",CELL("filename",A1))) -> #VALUE!
B8: ITDX | P8: システム | AD8: 説明 | AT8: Gap （Add-On）
B9: 担当者 | I9: 責任者 | P9: FO | W9: 外部システム
B10: １．銀行口座登録
AE15: １．主勘定登録
AF16: 主勘定を登録する。
AF17: ※ | AG17: 「手動入力を許可しない」にチェックを入れること。
AE26: ２．銀行グループ登録
AF27: 銀行口座に紐づく銀行グループを登録する。
AF28: ※ | AG28: 銀行グループコード：銀行コード_+支店コード
AE34: ３．銀行口座登録
AF35: 銀行口座を登録する。
AF36: ※ | AG36: 銀行口座コード：主勘定コード
AF37: ※ | AG37: 銀行口座と主勘定は1:1で登録する形となる。

Sheet B．相殺決済契約
A1: システム名 | F1: =変更履歴!F1 -> 会計システム刷新プロジェクト（LIBRA） | AC1: タイトル | AQ1: 日付 | AX1: 更新者
A2: 文書名 | F2: =変更履歴!F2 -> ToBe業務フロー（4.債務） | AC2: =MID(CELL("filename",$A$1),FIND("]",CELL("filename",$A$1))+1,31) -> #VALUE! | AQ2: 作成 | AS2: =変更履歴!AT2 -> 45362 | AX2: =変更履歴!BA2 -> JBS秋信
AQ3: 更新 | AS3: =変更履歴!AT3 -> 45890 | AX3: =変更履歴!BA3 -> JBS秋信
A6: =RIGHT(CELL("filename",A1),LEN(CELL("filename",A1))-FIND("]",CELL("filename",A1))) -> #VALUE!
B8: 事務管理G | P8: ITDX | W8: システム | AK8: 説明 | BA8: Gap （Add-On）
B9: 担当者 | I9: 責任者 | W9: FO | AD9: 外部システム
B10: １．契約内容登録
AL16: １．相殺決済契約登録
AM17: 顧客と仕入先の紐づきを登録する。
AM18: ※ | AN18: 仕訳名：相殺用の仕訳帳名を指定
AM19: ※ | AN19: 勘定：相殺時に使用される経過勘定を指定
AL24: 2．有効化
AM25: 相殺決済契約の有効化する。

Sheet C．仕入先マスタ・仕入先の銀行口座
A1: システム名 | F1: =変更履歴!F1 -> 会計システム刷新プロジェクト（LIBRA） | V1: タイトル | AJ1: 日付 | AQ1: 更新者
A2: 文書名 | F2: =変更履歴!F2 -> ToBe業務フロー（4.債務） | V2: =MID(CELL("filename",$A$1),FIND("]",CELL("filename",$A$1))+1,31) -> #VALUE! | AJ2: 作成 | AL2: =変更履歴!AT2 -> 45362 | AQ2: =変更履歴!BA2 -> JBS秋信
AJ3: 更新 | AL3: =変更履歴!AT3 -> 45890 | AQ3: =変更履歴!BA3 -> JBS秋信
A6: =RIGHT(CELL("filename",A1),LEN(CELL("filename",A1))-FIND("]",CELL("filename",A1))) -> #VALUE!
B8: 事務管理G | P8: ITDX | AD8: システム | AR8: 説明 | BH8: Gap （Add-On）
B9: 担当者 | I9: 責任者 | P9: 担当者 | W9: 責任者 | AD9: FO | AK9: 外部システム
B10: １．仕入先マスタ・仕入先の銀行口座登録
AS16: １．銀行グループの登録
AT17: 国内仕入先の場合、
AT18: 銀行グループ（銀行コード＋支店コード）
AT19: 海外仕入先の場合、
AT20: 銀行グループ（SWIFTコードの先頭8ケタ）
AT21: が登録されているか確認する。
AT22: 登録されていない場合、銀行グループの
AT23: 登録を行う。
AT24: ※ | AU24: 海外仕入先の場合は、
AU25: 項目：銀行名 (カナ) の登録必須
AS28: ２．仕入先マスタ・仕入先の銀行口座登録
AT29: 担当者は、仕入先マスタ・
AT30: 仕入先の銀行口座情報の登録を行う。
AT31: ※ | AU31: SSJ | AW31: : | AX31: JUST D.B.
AU32: SEJ | AW32: : | AX32: SEJホスト
AU33: SLJ | AW33: : | AX33: JUST D.B.
AT34: ※ | AU34: 海外送金で、以下仕入先の住所情報を
AU35: 出力する。
AU36: StrtNm（町域/番地）：FO項目名「住所」
AU37: TwnNm（市区町村）：FO項目名「市町村」
AU38: Ctry（国名/国コード）：FO項目名「国/地域」
AS58: ３．仕入先マスタの更新
AT59: 事務管理Gは、海外送金ISO20022対象の
AT60: 仕入先の更新を行う。
AT61: ・ | AU61: 支払 ID：「DEBT」or「SHAR」を設定。
AU62: （支払銀行手数料負担区分）
AS70: ４．仕入先マスタの住所更新
AT71: 事務管理Gは、海外送金ISO20022対象の
AT72: 仕入先の住所更新を行う。
AT73: ※ | AU73: 上流システムで更新があった際、
AU74: 随時対応を行う。
AS77: ５．仕入先の銀行口座更新
AT78: 事務管理Gは、海外送金ISO20022対象の
...
