Workbook
Name io: #REF!
Name IO: マスタ!$B$3:$B$5
Name LinkType: マスタ!$A$3:$A$9
Name オブジェクト: マスタ!$I$3:$I$20
Name オブジェクト一覧: #REF!
Name クラス属性: マスタ!$H$3:$H$6
Name テーブル種別: #REF!
Name テーブル種別: マスタ!$G$3:$G$6
Name 横位置: #REF!
Name 横位置: マスタ!$D$3:$D$6
Name 作成日: DATE(2000,3,21)
Name 縦位置: #REF!
Name 縦位置: マスタ!$E$3:$E$6
Name 書式: #REF!
Name 書式: マスタ!$C$3:$C$5
Name 折り返して全体を表示する: #REF!
Name 折り返して全体を表示する: マスタ!$F$3:$F$4

Sheet 表紙
B3: サンスター株式会社 御中
B10: 会計システム刷新プロジェクト（LIBRA）
B14: FO-014_詳細設計書_支払案内書
B22: ="第"&IF(COUNTA(変更履歴!BE5:BI10016)=1,"",INDIRECT("変更履歴!BE"&COUNTA(変更履歴!BE5:BI10016)+4))&"版" -> 第1.13版
B24: =IF(OR(COUNTA(変更履歴!A:E)=2),"",INDIRECT("変更履歴!A"&COUNTA(変更履歴!A:E)+3)) -> 45800
B26: 日本ビジネスシステムズ株式会社
F29: 作成者 | O29: JBS承認者 | V29: 基本設計部確認者
F30: =変更履歴!AV2 -> 45446 | N30: 45449 | V30: 45502
F31: =変更履歴!BB2 -> JBS秋信 | N31: JBS加藤 | V31: サンスター藤田

Sheet 変更履歴
A1: 設計書 | F1: システム名 | Q1: 機能分類 | W1: 機能ＩＤ | AE1: 機能名称 | AT1: 日付 | BB1: 更新者
F2: Dynamics365 for Finance and Operations | Q2: 債権・債務 | W2: FO-014 | AE2: 支払案内書 | AT2: 作成 | AV2: =A6 -> 45446 | BB2: =AZ6 -> JBS秋信
AT3: 更新 | AV3: {=IF(OR(COUNTA(A:E)=2),"",INDIRECT("A"&COUNTA(A:E)+3))} -> 45800 | BB3: {=IF(COUNTA(AZ5:BD100016)=1,"",INDIRECT("AZ"&COUNTA(AZ5:BD100016)+4))} -> JBS秋信
AW4: （表紙同様値）
A5: 変更年月日 | F5: 変更箇所 | T5: 変更内容 | AZ5: 変更者 | BE5: 版数
A6: 45446 | F6: 新規作成 | T6: 新規作成 | AZ6: JBS秋信 | BE6: 1.0
A7: 45582 | F7: シート：画面項目説明 | T7: 項目：仕入先、支払方法 の入力必須に変更 | AZ7: JBS秋信 | BE7: 1.1
A8: 45713 | F8: シート：処理概要 | T8: 以下内容を追記 ・開発内容：No.2、CSVで出力する。 ・制限事項：No.2、仕入先の住所が登録されていること。 | AZ8: JBS秋信 | BE8: 1.2
A9: 45714 | F9: シート：イベント説明 | T9: 2-1-2.支払元情報（法人）を取得の抽出条件を修正 | AZ9: JBS秋信 | BE9: 1.3
A10: 45726 | F10: シート：テーブル出力仕様 | T10: No.19：銀行手数料金額、No.20：支払金額 の設定値を修正 | AZ10: JBS秋信 | BE10: 1.4
A11: 45726 | F11: シート：テーブル出力仕様 | T11: No.19：銀行手数料金額、No.20：支払金額 の設定値を修正 | AZ11: JBS秋信 | BE11: 1.5
A12: 45726 | F12: シート：イベント説明 | T12: 処理2-1-5-5：銀行手数料の消費税の取得 を追加 | AZ12: JBS秋信 | BE12: 1.5
A13: 45727 | F13: シート：テーブル出力仕様 | T13: No.20：支払金額 の設定値を修正 | AZ13: JBS秋信 | BE13: 1.6
A14: 45727 | F14: シート：イベント説明 | T14: 2-1-.データ取得 対象データが取得できなかった場合のメッセージの変更（20～24行目） | AZ14: JBS井田 | BE14: 1.7
A15: 45728 | F15: シート：イベント説明 | T15: 2-1-3、2-1-5-3.②、2-1-5-4、2-1-5-5 に法人の抽出条件を追加 | AZ15: JBS秋信 | BE15: 1.8
A16: 45730 | F16: シート：画面レイアウト | T16: メニューパスを記載 | AZ16: JBS北井 | BE16: 1.9
A17: 45737 | F17: シート：テーブル一覧 シート：DFD シート：イベント説明 シート：テーブル出力仕様 | T17: 処理2-1-5-4：銀行手数料金額の取得 を修正 | AZ17: JBS秋信 | BE17: 1.10
... A21: 45800 | F21: シート：テーブル出力仕様 | T21: 仕入先住所 の設定値を変更 | AZ21: JBS秋信 | BE21: 1.13

Sheet 処理概要
A1: 基本設計書 | F1: =変更履歴!F1 -> システム名 | Q1: =変更履歴!Q1 -> 機能分類 | W1: =変更履歴!W1 -> 機能ＩＤ | AE1: =変更履歴!AE1 -> 機能名称 | AT1: =変更履歴!AT1 -> 日付 | BB1: =変更履歴!BB1 -> 更新者
F2: =変更履歴!F2 -> Dynamics365 for Finance and Operations | Q2: =変更履歴!Q2 -> 債権・債務 | W2: =変更履歴!W2 -> FO-014 | AE2: =変更履歴!AE2 -> 支払案内書 | AT2: =変更履歴!AT2 -> 作成 | AV2: =変更履歴!AV2 -> 45446 | BB2: =変更履歴!BB2 -> JBS秋信
AT3: =変更履歴!AT3 -> 更新 | AV3: =変更履歴!AV3 -> 45800 | BB3: =変更履歴!BB3 -> JBS秋信
A5: 開発目的
B6: 1. | C6: 標準機能で支払案内書に対応できる機能がないため。
C7: 対象となる支払は、以下。
D8: ・ | E8: 規定支払「当月計上翌月20日払」の銀行振込
D9: ・ | E9: 期日振込
A11: 前提条件
B12: 1. | C12: 仕入先支払仕訳帳で転記済みのものを対象とする。
B13: 2. | C13: 1仕入先に登録する口座情報は1つである運用とする。
B14: 3. | C14: 1仕入先に登録する住所情報は1つである運用とする。
A17: 使用タイミング
B18: 1. | C18: 月次
A23: 開発内容
B24: 1. | C24: 仕入先への振込金額の通知のための帳票を作成する。
B25: 2. | C25: 1.の内容をCSVで出力する。
A30: 制限事項
B31: 1. | C31: 表示通貨は、JPY固定とする。
B32: 2. | C32: 出力対象の仕入先は住所が登録されていること。

Sheet テーブル一覧
A1: 基本設計書 | F1: =変更履歴!F1 -> システム名 | Q1: =変更履歴!Q1 -> 機能分類 | W1: =変更履歴!W1 -> 機能ＩＤ | AE1: =変更履歴!AE1 -> 機能名称 | AT1: =変更履歴!AT1 -> 日付 | BB1: =変更履歴!BB1 -> 更新者
F2: =変更履歴!F2 -> Dynamics365 for Finance and Operations | Q2: =変更履歴!Q2 -> 債権・債務 | W2: =変更履歴!W2 -> FO-014 | AE2: =変更履歴!AE2 -> 支払案内書 | AT2: =変更履歴!AT2 -> 作成 | AV2: =変更履歴!AV2 -> 45446 | BB2: =変更履歴!BB2 -> JBS秋信
AT3: =変更履歴!AT3 -> 更新 | AV3: =変更履歴!AV3 -> 45800 | BB3: =変更履歴!BB3 -> JBS秋信
A5: No. | C5: 種別 | K5: 論理名 | AC5: 物理名 | AS5: I/O | AU5: 備考
A6: =ROW()-5 -> 1 | C6: テーブル | K6: 支払案内書Tmp | AC6: SJ_PaymentNotificationTmp | AS6: I/O | AU6: アドオン
A7: =ROW()-5 -> 2 | C7: テーブル | K7: 仕入先 | AC7: VendTable | AS7: I
A8: =ROW()-5 -> 3 | C8: テーブル | K8: 住所 | AC8: LogisticsPostalAddress | AS8: I
A9: =ROW()-5 -> 4 | C9: テーブル | K9: グローバルアドレス帳 | AC9: DirPartyAddress | AS9: I
A10: =ROW()-5 -> 5 | C10: テーブル | K10: 法人 | AC10: CompanyInfo | AS10: I
A11: =ROW()-5 -> 6 | C11: テーブル | K11: 通信の詳細 | AC11: LogisticsElectronicAddress | AS11: I
A12: =ROW()-5 -> 7 | C12: テーブル | K12: 仕入先の銀行口座 | AC12: VendBankAccount | AS12: I
A13: =ROW()-5 -> 8 | C13: テーブル | K13: 関係者と場所の関係 | AC13: DirPartyLocation | AS13: I
A14: =ROW()-5 -> 9 | C14: テーブル | K14: 銀行グループ | AC14: BankGroup | AS14: I
A15: =ROW()-5 -> 10 | C15: テーブル | K15: 仕入先トランザクション | AC15: VendTrans | AS15: I
A16: =ROW()-5 -> 11 | C16: テーブル | K16: 一般仕訳入力 | AC16: GeneralJournalEntry | AS16: I
A17: =ROW()-5 -> 12 | C17: テーブル | K17: 一般仕訳帳勘定項目 | AC17: GeneralJournalAccountEntry | AS17: I
A18: =ROW()-5 -> 13 | C18: テーブル | K18: 汎用パラメータ | AC18: SJ_GeneralParameter | AS18: I | AU18: アドオン
A19: =ROW()-5 -> 14 | C19: テーブル | K19: 支払仕訳帳手数料 | AC19: CustVendPaymJournalFee | AS19: I
A20: =ROW()-5 -> 15 | C20: テーブル | K20: 仕訳帳明細行 | AC20: LedgerJournalTrans | AS20: I
A21: =ROW()-5 -> 16
A22: =ROW()-5 -> 17
A23: =ROW()-5 -> 18
A24: =ROW()-5 -> 19
A25: =ROW()-5 -> 20
A26: =ROW()-5 -> 21
A27: =ROW()-5 -> 22
A28: =ROW()-5 -> 23
A29: =ROW()-5 -> 24
A30: =ROW()-5 -> 25
A31: =ROW()-5 -> 26
A32: =ROW()-5 -> 27
... A39: =ROW()-5 -> 34

Sheet DFD
A1: 基本設計書 | F1: =変更履歴!F1 -> システム名 | Q1: =変更履歴!Q1 -> 機能分類 | W1: =変更履歴!W1 -> 機能ＩＤ | AE1: =変更履歴!AE1 -> 機能名称 | AT1: =変更履歴!AT1 -> 日付 | BB1: =変更履歴!BB1 -> 更新者
F2: =変更履歴!F2 -> Dynamics365 for Finance and Operations | Q2: =変更履歴!Q2 -> 債権・債務 | W2: =変更履歴!W2 -> FO-014 | AE2: =変更履歴!AE2 -> 支払案内書 | AT2: =変更履歴!AT2 -> 作成 | AV2: =変更履歴!AV2 -> 45446 | BB2: =変更履歴!BB2 -> JBS秋信
AT3: =変更履歴!AT3 -> 更新 | AV3: =変更履歴!AV3 -> 45800 | BB3: =変更履歴!BB3 -> JBS秋信
A5: イベント | P5: 機能 | AR5: DB
A62: 凡例
A63: 記号
AL67: ※DBが複数ある場合は複数DBをまとめるために使用

Sheet イベント説明
A1: 基本設計書 | F1: =変更履歴!F1 -> システム名 | Q1: =変更履歴!Q1 -> 機能分類 | W1: =変更履歴!W1 -> 機能ＩＤ | AE1: =変更履歴!AE1 -> 機能名称 | AT1: =変更履歴!AT1 -> 日付 | BB1: =変更履歴!BB1 -> 更新者
F2: =変更履歴!F2 -> Dynamics365 for Finance and Operations | Q2: =変更履歴!Q2 -> 債権・債務 | W2: =変更履歴!W2 -> FO-014 | AE2: =変更履歴!AE2 -> 支払案内書 | AT2: =変更履歴!AT2 -> 作成 | AV2: =変更履歴!AV2 -> 45446 | BB2: =変更履歴!BB2 -> JBS秋信
AT3: =変更履歴!AT3 -> 更新 | AV3: =変更履歴!AV3 -> 45800 | BB3: =変更履歴!BB3 -> JBS秋信
A5: No. | C5: イベント名 | I5: 処理内容 | AO5: 種別 | AR5: メッセージ | BD5: ID
A6: 1. | C6: レポートダイアログ初期表示
J7: 1-1. | L7: 前回値を設定
L9: 下記の前回入力値をダイアログに設定する。
L11: ・ | M11: 支払年月日
L12: ・ | M12: 仕入先
L13: ・ | M13: 支払方法
J15: 1-2.レポートダイアログ表示処理
A18: 2. | C18: [OK]ボタン押下時 | J18: 2-1. | L18: データ取得
L19: 以下の条件で仕入先、支払方法ごとにデータを取得する。
L20: 一件も取得できなかった場合は、メッセージを表示し処理を終了する。 | AO20: 情報ログ | AR20: 入力されたパラメーターでは%1の対象となるデータは存在しません。 | BD20: SJ00343
AO21: Warning
L22: 取得した仕入先、支払方法ごとに2-1-1~2-1-5をループして処理を行う。
AR23: %1: 支払案内書 （ラベル：SJ00701）
K25: 2-1-1. | N25: 支払先（仕入先）情報を取得
L27: <項目>
M28: [住所.郵便番号(ZipCode)]
M29: [住所.都道府県(State)]
M30: [住所.市町村(City)]
M31: [住所.住所(Street)]
M32: [住所.建物名 (補足)(BuildingCompliment)]
M33: [グローバルアドレス帳.名前(Name)]
M34: [仕入先.仕入先(AccountNum)]
L35: <取得テーブル>
M36: [住所(LogisticsPostalAddress)]
M37: [グローバルアドレス帳(DirPartyTable)]
M38: [仕入先(VendTable)]
L39: <結合条件>
K40: Inner | M40: [住所.場所(Location)] | Z40: = | AA40: [グローバルアドレス帳.場所(PrimaryAddressLocation)]
K41: Inner | M41: [グローバルアドレス帳.レコードID(RecId)] | Z41: = | AA41: [仕入先(VendTable).名前(Party)]
L42: <抽出条件>
M43: [仕入先.仕入先(AccountNum)] | Z43: = | AA43: [画面.仕入先]
K46: 2-1-2. | N46: 支払元情報（法人）を取得
L48: 2-1-2-1.住所情報,会社名
L50: <項目>
M51: [住所.郵便番号(ZipCode)]
M52: [住所.住所(Street)]
...

Sheet 画面項目説明
A1: 基本設計書 | F1: =変更履歴!F1 -> システム名 | Q1: =変更履歴!Q1 -> 機能分類 | W1: =変更履歴!W1 -> 機能ＩＤ | AE1: =変更履歴!AE1 -> 機能名称 | AT1: =変更履歴!AT1 -> 日付 | BB1: =変更履歴!BB1 -> 更新者
F2: =変更履歴!F2 -> Dynamics365 for Finance and Operations | Q2: =変更履歴!Q2 -> 債権・債務 | W2: =変更履歴!W2 -> FO-014 | AE2: =変更履歴!AE2 -> 支払案内書 | AT2: =変更履歴!AT2 -> 作成 | AV2: =変更履歴!AV2 -> 45446 | BB2: =変更履歴!BB2 -> JBS秋信
AT3: =変更履歴!AT3 -> 更新 | AV3: =変更履歴!AV3 -> 45800 | BB3: =変更履歴!BB3 -> JBS秋信
A5: コントロール | H5: 項目名 | Q5: 種類 | U5: 入力 | W5: 必須 | Y5: 項目説明（概要） | BB5: 備考
A6: タイトル | Q6: タイトル | U6: × | W6: × | Y6: ＜タイトル＞
Y7: ・Caption：支払案内書
A9: パラメーター
H12: 支払年月日 | Q12: 日付 | U12: ○ | W12: ○ | Y12: ＜入力内容＞
Y13: 日付形式：”YYYY/MM/DD”
Y14: ＜初期値＞
Y15: 空欄
H17: 仕入先 | Q17: テキスト | U17: ○ | W17: ○ | Y17: ＜入力内容＞ | BB17: 仕入先コードでルックアップ
Y18: 仕入先コードを入力する。
Y19: ※ | Z19: 「,」で複数入力可能にする。
Y20: ※ | Z20: 「..」で範囲指定入力可能にする。
Y21: ＜初期値＞ | BB21: 前回設定値は、法人ごとに保持
Y22: 前回設定値
H24: 支払方法 | Q24: テキスト | U24: ○ | W24: ○ | Y24: ＜入力内容＞ | BB24: 支払方法でルックアップ
Y25: 支払方法を入力する。
Y26: ※ | Z26: 「,」で複数入力可能にする。
Y27: ＜初期値＞ | BB27: 前回設定値は、法人ごとに保持
Y28: 前回設定値

Sheet ファイルレイアウト
A1: 基本設計書 | F1: =変更履歴!F1 -> システム名 | Q1: =変更履歴!Q1 -> 機能分類 | W1: =変更履歴!W1 -> 機能ＩＤ | AE1: =変更履歴!AE1 -> 機能名称 | AT1: =変更履歴!AT1 -> 日付 | BB1: =変更履歴!BB1 -> 更新者
F2: =変更履歴!F2 -> Dynamics365 for Finance and Operations | Q2: =変更履歴!Q2 -> 債権・債務 | W2: =変更履歴!W2 -> FO-014 | AE2: =変更履歴!AE2 -> 支払案内書 | AT2: =変更履歴!AT2 -> 作成 | AV2: =変更履歴!AV2 -> 45446 | BB2: =変更履歴!BB2 -> JBS秋信
AT3: =変更履歴!AT3 -> 更新 | AV3: =変更履歴!AV3 -> 45800 | BB3: =変更履歴!BB3 -> JBS秋信
A5: 文字コード： | I5: ファイル名称：
A6: 区切り文字： | I6: 文字列：
A7: 改行コード： | I7: ソート： | AT7: タイトル行：
A8: No. | C8: フィールド名 | Q8: 説明 | AT8: 属性 | AX8: 桁数 | AZ8: 備考
A9: =ROW()-8 -> 1
A10: =ROW()-8 -> 2
A11: =ROW()-8 -> 3
A12: =ROW()-8 -> 4
A13: =ROW()-8 -> 5
A14: =ROW()-8 -> 6
A15: =ROW()-8 -> 7
A16: =ROW()-8 -> 8
A17: =ROW()-8 -> 9
A18: =ROW()-8 -> 10
A19: =ROW()-8 -> 11
A20: =ROW()-8 -> 12
... A38: =ROW()-8 -> 30

Sheet 帳票レイアウト
A1: 基本設計書 | F1: =変更履歴!F1 -> システム名 | Q1: =変更履歴!Q1 -> 機能分類 | W1: =変更履歴!W1 -> 機能ＩＤ | AE1: =変更履歴!AE1 -> 機能名称 | AT1: =変更履歴!AT1 -> 日付 | BB1: =変更履歴!BB1 -> 更新者
F2: =変更履歴!F2 -> Dynamics365 for Finance and Operations | Q2: =変更履歴!Q2 -> 債権・債務 | W2: =変更履歴!W2 -> FO-014 | AE2: =変更履歴!AE2 -> 支払案内書 | AT2: =変更履歴!AT2 -> 作成 | AV2: =変更履歴!AV2 -> 45446 | BB2: =変更履歴!BB2 -> JBS秋信
AT3: =変更履歴!AT3 -> 更新 | AV3: =変更履歴!AV3 -> 45800 | BB3: =変更履歴!BB3 -> JBS秋信
A5: レイアウト | AY5: 備考
A6: 帳票タイトル：支払案内書 | AI6: 帳票タイプ：SSRS
A7: 用紙サイズ：A4 | L7: 用紙の向き：縦 | X7: 自動サイズ調整： | AI7: フォント：ＭＳ ゴシック
A8: 余白(cm) | F8: 左： | J8: 右： | N8: 上： | R8: 下： | AI8: テーブルソート設定：

Sheet 画面レイアウト
A1: 基本設計書 | F1: =変更履歴!F1 -> システム名 | Q1: =変更履歴!Q1 -> 機能分類 | W1: =変更履歴!W1 -> 機能ＩＤ | AE1: =変更履歴!AE1 -> 機能名称 | AT1: =変更履歴!AT1 -> 日付 | BB1: =変更履歴!BB1 -> 更新者
F2: =変更履歴!F2 -> Dynamics365 for Finance and Operations | Q2: =変更履歴!Q2 -> 債権・債務 | W2: =変更履歴!W2 -> FO-014 | AE2: =変更履歴!AE2 -> 支払案内書 | AT2: =変更履歴!AT2 -> 作成 | AV2: =変更履歴!AV2 -> 45446 | BB2: =変更履歴!BB2 -> JBS秋信
AT3: =変更履歴!AT3 -> 更新 | AV3: =変更履歴!AV3 -> 45800 | BB3: =変更履歴!BB3 -> JBS秋信
A5: パス | I5: 買掛金管理＞照会およびレポート＞支払案内書
A6: フォーム名
A8: タブ名

Sheet 帳票レイアウト（サンプル）
AE2: XXXX年XX月XX日
B3: 〒XXX-XXXX
B4: 全全全全全全全全全全全全全全全全全全全全全全全全全
B5: 全全全全全全全全全全全全全全全全全全全全全全全全全 | T5: お取引先コード：全全全全全全全全全全
B6: 全全全全全全全全全全全全全全全全全全全全全全全全全
B7: 全全全全全全全全全全全全全全全全全全全全全全全全全
B8: 全全全全全全全全全全全全全全全全全全全全全全全全全 | T8: 〒XXX-XXXX
B9: 全全全全全全全全全全全全全全全全全全全全全全全全全 | R9: 様 | T9: 全全全全全全全全全全全全全全全全全全
T10: 全全全全全全全全全全全全全全全全全全
T11: 全全全全全全全全全全全全全全全全全全
T12: 全全全全全全全全全全全全全全全全全全
C14: お支払案内書
T15: お問合せ部署
B16: 拝啓 貴社益々ご隆盛のこととお喜び申しあげます。 | U16: 全全全全全全全全全全全全全全全
B17: 平素は格別のお引き立てにあずかり厚くお礼申しあげます。 | T17: TEL：XXX-XXXX-XXXX
B18: さて、弊社の納入代金を下記の通りお支払いしますので | T18: FAX：XXX-XXXX-XXXX
B19: ご案内します。
B20: 今後ともご支援のほどよろしくお願い申しあげます。
P21: 敬具
B24: ー 記 ー
B26: 1．弊社仕入月度 | I26: XXXX年XX月
B28: 2．お支払金額 | I28: ###,###,### | M28: 円
B30: 3．振込日 | I30: XXXX年XX月XX日
B32: 4．振込銀行
C34: 振込先 | I34: XXXXXXXXXXXXXXXXXXXXXXXXX XXXXXXXXXXXXXXXXXXXXXXXXX
C35: 預金種別 | I35: 全全全全全全全全全全 | P35: 口座番号 | T35: XXXXXXXXXX
C36: 口座名称 | I36: XXXXXXXXXXXXXXXXXXXXXXXXXXXXXXXXXXXXXXXX
B39: 5．お支払金額の内訳
C41: 納入金額 | I41: ###,###,### | M41: 円
C42: 相殺 | D42: 物品代金 | I42: ###,###,### | M42: 円
D43: 振込手数料 | I43: ###,###,### | M43: 円
C44: 差引支払金額 | I44: ###,###,### | M44: 円

Sheet 帳票出力仕様
A1: 基本設計書 | F1: =変更履歴!F1 -> システム名 | Q1: =変更履歴!Q1 -> 機能分類 | W1: =変更履歴!W1 -> 機能ＩＤ | AE1: =変更履歴!AE1 -> 機能名称 | AT1: =変更履歴!AT1 -> 日付 | BB1: =変更履歴!BB1 -> 更新者
F2: =変更履歴!F2 -> Dynamics365 for Finance and Operations | Q2: =変更履歴!Q2 -> 債権・債務 | W2: =変更履歴!W2 -> FO-014 | AE2: =変更履歴!AE2 -> 支払案内書 | AT2: =変更履歴!AT2 -> 作成 | AV2: =変更履歴!AV2 -> 45446 | BB2: =変更履歴!BB2 -> JBS秋信
AT3: =変更履歴!AT3 -> 更新 | AV3: =変更履歴!AV3 -> 45800 | BB3: =変更履歴!BB3 -> JBS秋信
S5: 表示形式 | AB5: 配置
A6: ヘッダー/フッター/明細 | H6: No. | J6: 項目名 | S6: 書式 | V6: フォーマット | AB6: 横位置 | AE6: 縦位置 | AH6: サイズ | AK6: 最大項目長 （項目幅） | AO6: 出力値 | BL6: 備考 | CC6: 取得元テーブル | CO6: 取得元フィールド | DA6: 折り返して全体を 表示する | DG6: TmpTable | DT6: TmpTableフィールド
A8: ① ヘッダー | H8: =ROW()-7 -> 1 | J8: 発行日 | S8: 日付 | V8: YYYY年MM月DD日 | AB8: 右詰 | AE8: 下詰 | AH8: 10 | AK8: - | AO8: システム日付 | CC8: ー | CO8: ー | DA8: ー | DG8: ー | DT8: ー
H9: =ROW()-7 -> 2 | J9: 支払先郵便番号 | S9: テキスト | V9: - | AB9: 左詰 | AE9: 下詰 | AH9: 10 | AK9: 10 | AO9: 固定値「〒」＋[支払案内書Tmp].[支払先郵便番号] | CC9: LogisticsPostalAddress | CO9: ZipCode | DA9: ー | DG9: SJ_PaymentNotificationTmp | DT9: VendZipCode
H10: =ROW()-7 -> 3 | J10: 支払先住所 | S10: テキスト | V10: - | AB10: 左詰 | AE10: 上詰 | AH10: 10 | AK10: 100 | AO10: [支払案内書Tmp].[支払先住所] | BL10: 仕入先に登録する住所は、1つ。 | CC10: LogisticsPostalAddress | CO10: Street | DA10: ー | DG10: SJ_PaymentNotificationTmp | DT10: VendStreet
H11: =ROW()-7 -> 4 | J11: 支払先会社名 | S11: テキスト | V11: - | AB11: 左詰 | AE11: 下詰 | AH11: 10 | AK11: 50 | AO11: [支払案内書Tmp].[仕入先名] | CC11: DirPartyTable | CO11: Name | DA11: ー | DG11: SJ_PaymentNotificationTmp | DT11: VendName
H12: =ROW()-7 -> 5 | J12: 支払先敬称 | S12: テキスト | V12: - | AB12: 左詰 | AE12: 下詰 | AH12: 10 | AK12: - | AO12: 固定値「様」 | CC12: ー | CO12: ー | DA12: ー | DG12: ー | DT12: ー
H13: =ROW()-7 -> 6 | J13: 支払先コード | S13: テキスト | V13: - | AB13: 左詰 | AE13: 下詰 | AH13: 10 | AK13: 20 | AO13: 固定値「お取引先コード：」＋[支払案内書Tmp].[仕入先] | CC13: VendTable | CO13: AccountNum | DA13: ー | DG13: SJ_PaymentNotificationTmp | DT13: VendAccount
H14: =ROW()-7 -> 7 | J14: 支払元郵便番号 | S14: テキスト | V14: - | AB14: 左詰 | AE14: 下詰 | AH14: 10 | AK14: 11 | AO14: 固定値「〒」＋[支払案内書Tmp].[法人郵便番号] | CC14: LogisticsPostalAddress | CO14: ZipCode | DA14: ー | DG14: SJ_PaymentNotificationTmp | DT14: CompanyZipCode
H15: =ROW()-7 -> 8 | J15: 支払元住所 | S15: テキスト | V15: - | AB15: 左詰 | AE15: 上詰 | AH15: 10 | AK15: 36 | AO15: [支払案内書Tmp].[法人住所] | CC15: LogisticsPostalAddress | CO15: Street | DA15: ー | DG15: SJ_PaymentNotificationTmp | DT15: CompanyStreet
H16: =ROW()-7 -> 9 | J16: 支払元会社名 | S16: テキスト | V16: - | AB16: 左詰 | AE16: 下詰 | AH16: 10 | AK16: 36 | AO16: [支払案内書Tmp].[法人会社名] | CC16: DirPartyTable | CO16: Name | DA16: ー | DG16: SJ_PaymentNotificationTmp | DT16: CompanyName
H17: =ROW()-7 -> 10 | J17: 問合せ先部署 | S17: テキスト | V17: - | AB17: 左詰 | AE17: 下詰 | AH17: 10 | AK17: - | AO17: 固定値「お問合せ部署」 | CC17: ー | CO17: ー | DA17: ー | DG17: ー | DT17: ー
H18: =ROW()-7 -> 11 | J18: 問合せ先部署名 | S18: テキスト | V18: - | AB18: 左詰 | AE18: 下詰 | AH18: 10 | AK18: 15 | AO18: [支払案内書Tmp].[法人部署名］ | BL18: タイプ：電話 目的：支払案内書 | CC18: LogisticsElectronicAddress | CO18: Description | DA18: ー | DG18: SJ_PaymentNotificationTmp | DT18: CompanyDepartmentName
H19: =ROW()-7 -> 12 | J19: 問合せ先TEL | S19: テキスト | V19: - | AB19: 左詰 | AE19: 下詰 | AH19: 10 | AK19: 20 | AO19: 固定値「TEL：」＋[支払案内書Tmp].[法人TEL] | BL19: タイプ：電話 目的：支払案内書 | CC19: LogisticsElectronicAddress | CO19: Locator | DA19: ー | DG19: SJ_PaymentNotificationTmp | DT19: CompanyTEL
H20: =ROW()-7 -> 13 | J20: 問合せ先FAX | S20: テキスト | V20: - | AB20: 左詰 | AE20: 下詰 | AH20: 10 | AK20: 20 | AO20: 固定値「FAX：」＋[支払案内書Tmp].[法人FAX] | BL20: タイプ：FAX 目的：支払案内書 | CC20: LogisticsElectronicAddress | CO20: Locator | DA20: ー | DG20: SJ_PaymentNotificationTmp | DT20: CompanyFAX
A21: ② 明細 | H21: =ROW()-7 -> 14 | J21: お支払案内書 | S21: テキスト | AB21: 左詰 | AE21: 下詰 | AH21: 10 | AK21: - | AO21: 固定値「お支払案内書」 | CC21: ー | CO21: ー | DA21: ー | DG21: ー | DT21: ー
A22: （項目名） | H22: =ROW()-7 -> 15 | J22: 固定文言 | S22: テキスト | AB22: 左詰 | AE22: 上詰 | AH22: 10 | AK22: - | AO22: 固定値 「 拝啓 貴社益々ご隆盛のこととお喜び申しあげます。 平素は格別のお引き立てにあずかり厚くお礼申しあげます。 さて、弊社の納入代金を下記の通りお支払いしますので ご案内します。 今後ともご支援のほどよろしくお願い申しあげます。」 | CC22: ー | CO22: ー | DA22: ー | DG22: ー | DT22: ー
H23: =ROW()-7 -> 16 | J23: 敬具 | S23: テキスト | AB23: 右詰 | AE23: 下詰 | AH23: 10 | AK23: - | AO23: 固定値「敬具」 | CC23: ー | CO23: ー | DA23: ー | DG23: ー | DT23: ー
H24: =ROW()-7 -> 17 | J24: 記 | S24: テキスト | AB24: 中央詰 | AE24: 下詰 | AH24: 10 | AK24: - | AO24: 固定値「ー 記 ー」 | CC24: ー | CO24: ー | DA24: ー | DG24: ー | DT24: ー
H25: =ROW()-7 -> 18 | J25: セクション１ | S25: テキスト | AB25: 左詰 | AE25: 下詰 | AH25: 10 | AK25: - | AO25: 固定値「１．弊社仕入月度」 | CC25: ー | CO25: ー | DA25: ー | DG25: ー | DT25: ー
H26: =ROW()-7 -> 19 | J26: セクション２ | S26: テキスト | AB26: 左詰 | AE26: 下詰 | AH26: 10 | AK26: - | AO26: 固定値「２．お支払金額」 | CC26: ー | CO26: ー | DA26: ー | DG26: ー | DT26: ー
H27: =ROW()-7 -> 20 | J27: セクション３ | S27: テキスト | AB27: 左詰 | AE27: 下詰 | AH27: 10 | AK27: - | AO27: 固定値「３．振込日」 | CC27: ー | CO27: ー | DA27: ー | DG27: ー | DT27: ー
H28: =ROW()-7 -> 21 | J28: セクション４ | S28: テキスト | AB28: 左詰 | AE28: 下詰 | AH28: 10 | AK28: - | AO28: 固定値「４．振込銀行」 | CC28: ー | CO28: ー | DA28: ー | DG28: ー | DT28: ー
H29: =ROW()-7 -> 22 | J29: 振込先 | S29: テキスト | AB29: 左詰 | AE29: 下詰 | AH29: 10 | AK29: - | AO29: 固定値「振込先」 | CC29: ー | CO29: ー | DA29: ー | DG29: ー | DT29: ー
H30: =ROW()-7 -> 23 | J30: 預金種別 | S30: テキスト | AB30: 左詰 | AE30: 下詰 | AH30: 10 | AK30: - | AO30: 固定値「預金種別」 | CC30: ー | CO30: ー | DA30: ー | DG30: ー | DT30: ー
H31: =ROW()-7 -> 24 | J31: 口座番号 | S31: テキスト | AB31: 左詰 | AE31: 下詰 | AH31: 10 | AK31: - | AO31: 固定値「口座番号」 | CC31: ー | CO31: ー | DA31: ー | DG31: ー | DT31: ー
H32: =ROW()-7 -> 25 | J32: 口座名称 | S32: テキスト | AB32: 左詰 | AE32: 下詰 | AH32: 10 | AK32: - | AO32: 固定値「口座名称」 | CC32: ー | CO32: ー | DA32: ー | DG32: ー | DT32: ー
H33: =ROW()-7 -> 26 | J33: セクション５ | S33: テキスト | AB33: 左詰 | AE33: 下詰 | AH33: 10 | AK33: - | AO33: 固定値「５．お支払金額の内訳」 | CC33: ー | CO33: ー | DA33: ー | DG33: ー | DT33: ー
H34: =ROW()-7 -> 27 | J34: 納入金額 | S34: テキスト | AB34: 左詰 | AE34: 下詰 | AH34: 10 | AK34: - | AO34: 固定値「納入金額」 | CC34: ー | CO34: ー | DA34: ー | DG34: ー | DT34: ー
H35: =ROW()-7 -> 28 | J35: 相殺 | S35: テキスト | AB35: 左詰 | AE35: 下詰 | AH35: 10 | AK35: - | AO35: 固定値「相殺」 | BL35: 縦書き | CC35: ー | CO35: ー | DA35: ー | DG35: ー | DT35: ー
H36: =ROW()-7 -> 29 | J36: 物品代金 | S36: テキスト | AB36: 左詰 | AE36: 下詰 | AH36: 10 | AK36: - | AO36: 固定値「物品代金」 | CC36: ー | CO36: ー | DA36: ー | DG36: ー | DT36: ー
H37: =ROW()-7 -> 30 | J37: 振込手数料 | S37: テキスト | AB37: 左詰 | AE37: 下詰 | AH37: 10 | AK37: - | AO37: 固定値「振込手数料」 | CC37: ー | CO37: ー | DA37: ー | DG37: ー | DT37: ー
H38: =ROW()-7 -> 31 | J38: 差引支払金額 | S38: テキスト | AB38: 左詰 | AE38: 下詰 | AH38: 10 | AK38: - | AO38: 固定値「差引支払金額」 | CC38: ー | CO38: ー | DA38: ー | DG38: ー | DT38: ー
A39: ②明細 | H39: =ROW()-7 -> 32 | J39: 仕入月度 | S39: 日付 | V39: YYYY年MM月 | AB39: 左詰 | AE39: 下詰 | AH39: 10 | AK39: - | AO39: [支払案内書Tmp].[仕入月度]をYYYY年MM月で表示 | CC39: ー | CO39: ー | DA39: ー | DG39: SJ_PaymentNotificationTmp | DT39: PurchaseMonth
A40: （データ） | H40: =ROW()-7 -> 33 | J40: 支払金額 | S40: テキスト | V40: ###,###,### | AB40: 右詰 | AE40: 下詰 | AH40: 10 | AK40: 11 | AO40: [支払案内書Tmp].[支払金額] | CC40: VendTrans | CO40: AmountMST | DA40: ー | DG40: SJ_PaymentNotificationTmp | DT40: AmountOfPayment
H41: =ROW()-7 -> 34 | J41: 支払金額（通貨） | S41: テキスト | AB41: 左詰 | AE41: 下詰 | AH41: 10 | AK41: - | AO41: 固定値「円」 | CC41: ー | CO41: ー | DA41: ー | DG41: ー | DT41: ー
H42: =ROW()-7 -> 35 | J42: 振込日 | S42: 日付 | V42: YYYY年MM月DD日 | AB42: 左詰 | AE42: 下詰 | AH42: 10 | AK42: - | AO42: [画面].[支払年月日] | CC42: ー | CO42: ー | DA42: ー | DG42: ー | DT42: ー
...

Sheet テーブル出力仕様
A1: 基本設計書 | F1: =変更履歴!F1 -> システム名 | Q1: =変更履歴!Q1 -> 機能分類 | W1: =変更履歴!W1 -> 機能ＩＤ | AE1: =変更履歴!AE1 -> 機能名称 | AT1: =変更履歴!AT1 -> 日付 | BB1: =変更履歴!BB1 -> 更新者
F2: =変更履歴!F2 -> Dynamics365 for Finance and Operations | Q2: =変更履歴!Q2 -> 債権・債務 | W2: =変更履歴!W2 -> FO-014 | AE2: =変更履歴!AE2 -> 支払案内書 | AT2: =変更履歴!AT2 -> 作成 | AV2: =変更履歴!AV2 -> 45446 | BB2: =変更履歴!BB2 -> JBS秋信
AT3: =変更履歴!AT3 -> 更新 | AV3: =変更履歴!AV3 -> 45800 | BB3: =変更履歴!BB3 -> JBS秋信
A5: テーブル名 | M5: SJ_PaymentNotificationTmp
A6: ラベル
A7: 拡張名
A8: No. | C8: 論理名 | M8: 物理名 | W8: 説明 | AZ8: 備考
A9: =ROW()-8 -> 1 | C9: 仕入先郵便番号 | M9: VendZipCode | W9: 2-1-1 で取得した、仕入先の[住所].[郵便番号]
A10: =ROW()-8 -> 2 | C10: 仕入先住所 | M10: VendStreet | W10: 2-1-1 で取得した、仕入先の[住所].[都道府県] +2-1-1 で取得した、仕入先の[住所].[市町村] +2-1-1 で取得した、仕入先の[住所].[住所] +2-1-1 で取得した、仕入先の[住所].[建物名 (補足)]
A11: =ROW()-8 -> 3 | C11: 仕入先名 | M11: VendName | W11: 2-1-1 で取得した、仕入先の[グローバルアドレス帳].[名前]
A12: =ROW()-8 -> 4 | C12: 仕入先 | M12: VendAccount | W12: 2-1-1 で取得した、仕入先の[仕入先].[仕入先]
A13: =ROW()-8 -> 5 | C13: 法人郵便番号 | M13: CompanyZipCode | W13: 2-1-2 で取得した、支払元（法人）の[住所].[郵便番号]
A14: =ROW()-8 -> 6 | C14: 法人住所 | M14: CompanyStreet | W14: 2-1-2 で取得した、支払元（法人）の[住所].[住所]
A15: =ROW()-8 -> 7 | C15: 法人会社名 | M15: CompanyName | W15: 2-1-2 で取得した、支払元（法人）の[グローバルアドレス帳].[名前]
A16: =ROW()-8 -> 8 | C16: 法人部署名 | M16: CompanyDepartmentName | W16: 2-1-2 で取得した、支払元（法人）の[通信の詳細].[説明] | AZ16: タイプ：電話 目的：支払案内書
A17: =ROW()-8 -> 9 | C17: 法人TEL | M17: CompanyTEL | W17: 2-1-2 で取得した、支払元（法人）の[通信の詳細].[連絡先の電話番号/住所] | AZ17: タイプ：電話 目的：支払案内書
A18: =ROW()-8 -> 10 | C18: 法人FAX | M18: CompanyFAX | W18: 2-1-2 で取得した、支払元（法人）の[通信の詳細].[連絡先の電話番号/住所] | AZ18: タイプ：FAX 目的：支払案内書
A19: =ROW()-8 -> 11 | C19: 仕入月度 | M19: PurchaseMonth | W19: 2-1-4で取得した、[仕入先トランザクション].[支払基準日]- 1月
A20: =ROW()-8 -> 12 | C20: 仕入先銀行名(カナ) | M20: VendBankNameKana | W20: 2-1-5 で取得した、[銀行グループ].[銀行名(カナ)]
A21: =ROW()-8 -> 13 | C21: 仕入先銀行支店名(カナ) | M21: VendBankBranchNameKana | W21: 2-1-5 で取得した、[銀行グループ].[支店名(カナ)]
A22: =ROW()-8 -> 14 | C22: 仕入先銀行トランザクションタイプ | M22: VendBankTransType | W22: 2-1-5 で取得した、[仕入先の銀行口座].[銀行トランザクションタイプ]
A23: =ROW()-8 -> 15 | C23: 仕入先銀行口座番号 | M23: VendBankAccountNum | W23: 2-1-5 で取得した、[仕入先の銀行口座].[銀行口座番号]
A24: =ROW()-8 -> 16 | C24: 仕入先銀行口座(カナ) | M24: VendBankAccountNameKana | W24: 2-1-5 で取得した、[仕入先の銀行口座].[銀行口座(カナ)]
A25: =ROW()-8 -> 17 | C25: 納入金額 | M25: DeliveryPaymentAmount | W25: No.20：支払金額 + No.18：物品代金相殺金額 + No.19：銀行手数料金額
A26: =ROW()-8 -> 18 | C26: 物品代金相殺金額 | M26: OffsetAmountForGoods | W26: 2-1-6-2で取得した[仕入先トランザクション].[金額] + 2-1-6-3で取得した[仕入先トランザクション].[金額] | AZ26: 未収入金および預かり売掛金との相殺金額
A27: =ROW()-8 -> 19 | C27: 銀行手数料金額 | M27: BankTransferFeeAmount | W27: 2-1-6-4で取得した[支払仕訳帳手数料].[手数料金額]
A28: =ROW()-8 -> 20 | C28: 支払金額 | M28: AmountOfPayment | W28: (2-1-6-1で取得した[仕入先トランザクション].[金額] -2-1-6-4で取得した[支払仕訳帳手数料].[手数料金額] | AZ28: 例：支払額50000円、手数料660円の場合、 支払額(処理2-1-5-1) ：50000、 手数料(処理2-1-5-4) ：660、 ⇒50000-660 ＝49340
A29: =ROW()-8 -> 21
A30: =ROW()-8 -> 22
A31: =ROW()-8 -> 23
A32: =ROW()-8 -> 24
A33: =ROW()-8 -> 25
A34: =ROW()-8 -> 26
A35: =ROW()-8 -> 27
A36: =ROW()-8 -> 28
A37: =ROW()-8 -> 29
A38: =ROW()-8 -> 30
A39: =ROW()-8 -> 31
A40: =ROW()-8 -> 32
... A45: =ROW()-8 -> 37

Sheet 補足説明 (汎用パラメータ)
A1: 基本設計書 | F1: システム名 | Q1: 機能分類 | W1: 機能ＩＤ | AE1: 機能名称 | AT1: 日付 | BB1: 更新者
F2: =変更履歴!F2 -> Dynamics365 for Finance and Operations | Q2: =変更履歴!Q2 -> 債権・債務 | W2: =変更履歴!W2 -> FO-014 | AE2: =変更履歴!AE2 -> 支払案内書 | AT2: =変更履歴!AT2 -> 作成 | AV2: =変更履歴!AV2 -> 45446 | BB2: =変更履歴!BB2 -> JBS秋信
AT3: =変更履歴!AT3 -> 更新 | AV3: =変更履歴!AV3 -> 45800 | BB3: =変更履歴!BB3 -> JBS秋信
A5: 補足
B7: ■汎用パラメータについて
C8: 事前に本機能で使用する下記汎用パラメータを設定する。
C11: 機能ID(FunctionId) | J11: 項目ID(ItemId) | P11: Key(Key) | V11: 値(Value) | AF11: 説明(Description)
C12: COMMON | J12: MAINACCOUNT | P12: 1 | V12: 2090144 | AF12: 預り（売掛金）

Sheet 補足説明
A1: 基本設計書 | F1: =変更履歴!F1 -> システム名 | Q1: =変更履歴!Q1 -> 機能分類 | W1: =変更履歴!W1 -> 機能ＩＤ | AE1: =変更履歴!AE1 -> 機能名称 | AT1: =変更履歴!AT1 -> 日付 | BB1: =変更履歴!BB1 -> 更新者
F2: =変更履歴!F2 -> Dynamics365 for Finance and Operations | Q2: =変更履歴!Q2 -> 債権・債務 | W2: =変更履歴!W2 -> FO-014 | AE2: =変更履歴!AE2 -> 支払案内書 | AT2: =変更履歴!AT2 -> 作成 | AV2: =変更履歴!AV2 -> 45446 | BB2: =変更履歴!BB2 -> JBS秋信
AT3: =変更履歴!AT3 -> 更新 | AV3: =変更履歴!AV3 -> 45800 | BB3: =変更履歴!BB3 -> JBS秋信
A5: 補足
B7: ＜問合せ先部署名、問合せ先TEL、問合せ先FAXの取得元＞
C8: 問合せ先部署名、問合せ先TEL
D9: ⇒ | E9: 問合せ先部署名：「法人」の「連絡先情報」の「説明」（条件：タイプ：電話、目的：支払案内書）
E10: 問合せ先TEL：「法人」の「連絡先情報」の「電話」（条件：タイプ：電話、目的：支払案内書）
C35: 問合せ先FAX
D36: ⇒ | E36: 問合せ先FAX：「法人」の「連絡先情報」の「説明」（条件：タイプ：FAX、目的：支払案内書）
C61: ・目的：支払案内書 の設定箇所
D62: 組織管理＞グローバルアドレス帳＞住所と連絡先情報の目的 で設定
B77: ＜支払伝票の取得＞
C78: 仕入先トランザクションで、ステータス：請求済、トランザクションタイプ：支払 の伝票の伝票トランザクションが、転記タイプ：銀行 を取得。
D79: ・仕入先トランザクション
D98: ・伝票トランザクション
D99: （銀行手数料金額は、転記タイプ：仕訳元帳、トランザクションタイプ：手数料 を取得。）
B116: ＜支払先銀行口座情報の取得＞
C117: 仕入先トランザクションで、支払伝票の支払タブ＞銀行＞仕入先 から取得
D118: ・仕入先トランザクション
U139: 仕入先マスタの支払＞銀行口座 に設定している仕入先の銀行口座が設定されています。
B158: ＜未収入金の相殺伝票の取得＞
C159: 仕入先トランザクションで、トランザクションタイプ：相殺決済 を取得
D160: ・仕入先トランザクション
B179: ＜預かり売掛金の相殺伝票の取得＞
C180: 仕入先トランザクションで、ステータス：請求済、トランザクションタイプ：支払 の伝票の伝票トランザクションが、転記タイプ：仕訳元帳、主勘定：2090144（預かり売掛金） を取得。
D181: ・仕入先トランザクション
D202: ・伝票トランザクション
B219: ＜現行帳票＞

Sheet レビュー指摘事項
A1: 基本設計書 | F1: =変更履歴!F1 -> システム名 | Q1: =変更履歴!Q1 -> 機能分類 | W1: =変更履歴!W1 -> 機能ＩＤ | AE1: =変更履歴!AE1 -> 機能名称 | AT1: =変更履歴!AT1 -> 日付 | BB1: =変更履歴!BB1 -> 更新者
F2: =変更履歴!F2 -> Dynamics365 for Finance and Operations | Q2: =変更履歴!Q2 -> 債権・債務 | W2: =変更履歴!W2 -> FO-014 | AE2: =変更履歴!AE2 -> 支払案内書 | AT2: =変更履歴!AT2 -> 作成 | AV2: =変更履歴!AV2 -> 45446 | BB2: =変更履歴!BB2 -> JBS秋信
AT3: =変更履歴!AT3 -> 更新 | AV3: =変更履歴!AV3 -> 45800 | BB3: =変更履歴!BB3 -> JBS秋信
A5: No. | C5: レビュー事項 | Q5: 対応内容 | AF5: 指摘日 | AK5: 指摘者 | AP5: 対応日 | AU5: 対応者 | AZ5: 確認日 | BE5: 確認者
A6: =ROW()-5 -> 1 | C6: シート：画面レイアウト 自社/他社 の項目の削除 | Q6: 【シート：画面レイアウト】対応いたしました。 【シート：画面項目説明】対応しました。 | AF6: 45454 | AK6: サンスター | AP6: 45454 | AU6: JBS 秋信 | AZ6: 45502 | BE6: サンスター藤田
A7: =ROW()-5 -> 2 | C7: シート：画面レイアウト 仕入先（From）、仕入先（To）の項目を削除 仕入先 の項目追加 仕入先の複数選択できること | Q7: ①仕入先（From）、仕入先（To）の項目を削除 ⇒対応いたしました。 ②仕入先の項目追加、仕入先の複数 ⇒対応しました。仕入先の複数選択の方法について、シート：画面レイアウト にイメージ記載しましたので、ご確認をお願いします。 | AF7: 45454 | AK7: サンスター | AP7: 45457 | AU7: JBS 秋信 | AZ7: 45502 | BE7: サンスター藤田
A8: =ROW()-5 -> 3 | C8: シート：帳票レイアウト お問合せ部署の「事務管理グループ」を固定値ではなく、データとして取得できること | Q8: 【シート：帳票レイアウト】修正しました。 【シート：帳票出力仕様】No.10,11を修正しました。 No.10（問合せ先部署）⇒固定値 No.11（問合せ先部署名）⇒「法人」の「連絡先情報」の「説明」（条件：タイプ：電話、目的：支払案内書）から取得するように修正しました。 取得もとについて、シート：補足説明 をご参照ください。 【シート：テーブル出力項目】 No.8（支払元部署）を追加しました。 | AF8: 45454 | AK8: サンスター | AP8: 45457 | AU8: JBS 秋信 | AZ8: 45502 | BE8: サンスター藤田
A9: =ROW()-5 -> 4 | C9: シート：テーブル出力仕様 支払元TEL,支払元FAX に関して、目的の抽出条件を「支払案内書」に変更 | Q9: 対応いたしました。 | AF9: 45454 | AK9: サンスター | AP9: 45457 | AU9: JBS 秋信 | AZ9: 45502 | BE9: サンスター藤田
A10: =ROW()-5 -> 5 | C10: シート：画面レイアウト 帳票機能で「バックグラウンドの実行」を使用することはないため、画面レイアウトから「バックグラウンドの実行」を削除することで統一・修正する。 | Q10: 対応いたしました。 | AF10: 45457 | AK10: JBS 秋信 | AP10: 45457 | AU10: JBS 秋信 | AZ10: 45502 | BE10: サンスター藤田
A11: =ROW()-5 -> 6 | C11: 相殺額の取得に関して、FOバージョン10.0.40で確認し、追記する。 | Q11: 追記いたしました。 取得方法は、シート：補足説明 の以下をご参照ください。 ＜支払伝票の取得＞ ＜未収入金の相殺伝票の取得＞ ＜預かり売掛金の相殺伝票の取得＞ | AF11: 45457 | AK11: JBS 秋信 | AP11: 45492 | AU11: JBS 秋信 | AZ11: 45502 | BE11: サンスター藤田
A12: =ROW()-5 -> 7 | C12: 指摘事項２につきまして、仕入先ｺｰﾄﾞを複数コードを直接入力できるようにしたいと考えております。一つのボックス内で10件くらいをカンマで区切って複数選択できるようになりませんでしょうか。 | Q12: シート：画面レイアウト を修正いたしました。 対象に含めるレコードで、複数仕入先選択できるようにしております。 | AF12: 45491 | AK12: サンスター 藤田様 | AP12: 45492 | AU12: JBS 秋信 | AZ12: 45502 | BE12: サンスター藤田
A13: =ROW()-5 -> 8 | C13: 仕入月度の設定値の修正 | Q13: 旧：[画面].[支払年月日]をYYYY年MM月で表示 新：支払伝票の「支払基準日」から、-1月した日付をYYYY年MM月で表示 | AF13: 45492 | AK13: JBS 秋信 | AP13: 45492 | AU13: JBS 秋信 | AZ13: 45502 | BE13: サンスター藤田
A14: =ROW()-5 -> 9 | C14: シート：画面レイアウト、画面項目説明 支払年月日の初期値を空欄に変更する。 （支払年月日は毎月条件が変更される項目になるため、空欄にいたしました。） | Q14: 対応いたしました。 | AF14: 45518 | AK14: JBS 秋信 | AP14: 45518 | AU14: JBS 秋信 | AZ14: 45520 | BE14: サンスター藤田
A15: =ROW()-5 -> 10 | C15: シート：帳票出力仕様 以下、項目について最大項目長に問題がないかご確認をお願いいたします。 No.3：支払先住所 No.4：支払先会社名 No.8：支払元住所 No.9：支払元会社名 No.11：お問合せ先部署名 他項目についても、ご意見ございましたら、ご指摘をお願いいたします。 サンスター 藤田 項目長に問題ありません | Q15: 対応無し。 | AF15: 45518 | AK15: JBS 秋信 | AP15: 45530 | AU15: JBS 秋信 | AZ15: 45523 | BE15: サンスター藤田
A16: =ROW()-5 -> 11 | C16: 支払案内書に出力対象の支払伝票が複数になる可能性はありますでしょうか？ 例えば、 ①規定外支払（20日払、当月計上当月払い）と ②規定払い（20日払、当月計上翌月払い)を合わせて支払案内書に出力しますでしょうか。 それとも、規定払いのみを出力しますでしょうか。 2024/8/16 藤田さま No.11のご質問の件、「支払伝票」と記載されていますが、支払実行したときの伝票という認識であっておりますでしょうか。支払案内は規定支払「当月計上翌月２０日払」振込と期日振込のみ発行します。１件の振込に対し、１支払案内書を発行します。 | Q16: シート：画面レイアウト、画面項目説明 支払方法の項目を追加しました。 支払方法の条件指定は、任意にしております。 | AF16: 45518 | AK16: JBS 秋信 | AP16: 45523 | AU16: JBS 秋信 | AZ16: 45530 | BE16: サンスター藤田
A17: =ROW()-5 -> 12 | C17: シート：補足説明（汎用パラメータ） 預り売掛金の勘定科目コードを汎用パラメータから取得するように変更いたしました。 | Q17: 対応いたしました。 | AF17: 45518 | AK17: JBS 秋信 | AP17: 45518 | AU17: JBS 秋信 | AZ17: 45520 | BE17: サンスター藤田
A18: =ROW()-5 -> 13 | C18: 仕入先、支払方法の複数条件指定方法を統一する。 | Q18: シート：画面レイアウト、画面項目説明 複数条件指定の場合は、「,」を使用して設定する方針で統一することになりましたので、修正いたしました。 | AF18: 45524 | AK18: JBS 秋信 | AP18: 45524 | AU18: JBS 秋信 | AZ18: 45530 | BE18: サンスター藤田
A19: =ROW()-5 -> 14
A20: =ROW()-5 -> 15
A21: =ROW()-5 -> 16
A22: =ROW()-5 -> 17
A23: =ROW()-5 -> 18
A24: =ROW()-5 -> 19
A25: =ROW()-5 -> 20
A26: =ROW()-5 -> 21
A27: =ROW()-5 -> 22
A28: =ROW()-5 -> 23
A29: =ROW()-5 -> 24
A30: =ROW()-5 -> 25
... A40: =ROW()-5 -> 35

Sheet オブジェクト一覧
A1: 詳細設計書 | F1: =変更履歴!F1 -> システム名 | Q1: =変更履歴!Q1 -> 機能分類 | W1: =変更履歴!W1 -> 機能ＩＤ | AE1: =変更履歴!AE1 -> 機能名称 | AT1: =変更履歴!AT1 -> 日付 | BB1: =変更履歴!BB1 -> 更新者
F2: =変更履歴!F2 -> Dynamics365 for Finance and Operations | Q2: =変更履歴!Q2 -> 債権・債務 | W2: =変更履歴!W2 -> FO-014 | AE2: =変更履歴!AE2 -> 支払案内書 | AT2: =変更履歴!AT2 -> 作成 | AV2: =変更履歴!AV2 -> 45446 | BB2: =変更履歴!BB2 -> JBS秋信
AT3: =変更履歴!AT3 -> 更新 | AV3: =変更履歴!AV3 -> 45800 | BB3: =変更履歴!BB3 -> JBS秋信
A5: No. | C5: オブジェクト名 | S5: 属性 | AA5: 概要 | BD5: 備考
A6: =ROW()-5 -> 1 | C6: SJ_PaymentGuideBookContract | S6: Class | AA6: コントラクタクラス
A7: =ROW()-5 -> 2 | C7: SJ_PaymentGuideBookController | S7: Class | AA7: コントローラークラス
A8: =ROW()-5 -> 3 | C8: SJ_PaymentGuideBookRDP | S8: Class | AA8: データプロバイダークラス
A9: =ROW()-5 -> 4 | C9: SJ_PaymentGuideBookUIBuilder | S9: Class | AA9: ビルダークラス
A10: =ROW()-5 -> 5 | C10: AccountsPayable.SJ_Extension | S10: Menus | AA10: 買掛金管理モジュール
A11: =ROW()-5 -> 6 | C11: SJ_PaymentGuideBook | S11: Menu Items(Output) | AA11: 支払案内書ダイアログ起動用メニューアイテム
A12: =ROW()-5 -> 7 | C12: SJ_PaymentGuideBookReport | S12: Repoters | AA12: 帳票デザイン
A13: =ROW()-5 -> 8
A14: =ROW()-5 -> 9
A15: =ROW()-5 -> 10
A16: =ROW()-5 -> 11
A17: =ROW()-5 -> 12
A18: =ROW()-5 -> 13
A19: =ROW()-5 -> 14
A20: =ROW()-5 -> 15
A21: =ROW()-5 -> 16
A22: =ROW()-5 -> 17
A23: =ROW()-5 -> 18
A24: =ROW()-5 -> 19
... A38: =ROW()-5 -> 33

Sheet プログラムフロー図
A1: 詳細設計書 | F1: =変更履歴!F1 -> システム名 | Q1: =変更履歴!Q1 -> 機能分類 | W1: =変更履歴!W1 -> 機能ＩＤ | AE1: =変更履歴!AE1 -> 機能名称 | AT1: =変更履歴!AT1 -> 日付 | BB1: =変更履歴!BB1 -> 更新者
F2: =変更履歴!F2 -> Dynamics365 for Finance and Operations | Q2: =変更履歴!Q2 -> 債権・債務 | W2: =変更履歴!W2 -> FO-014 | AE2: =変更履歴!AE2 -> 支払案内書 | AT2: =変更履歴!AT2 -> 作成 | AV2: =変更履歴!AV2 -> 45446 | BB2: =変更履歴!BB2 -> JBS秋信
AT3: =変更履歴!AT3 -> 更新 | AV3: =変更履歴!AV3 -> 45800 | BB3: =変更履歴!BB3 -> JBS秋信
A5: プログラムフロー図
A28: 凡例
A29: 記号

Sheet マスタ
A2: LinkType | B2: IO | C2: 書式 | D2: 横位置 | E2: 縦位置 | F2: 折り返して全体を表示する | G2: テーブル種別 | H2: クラス属性 | I2: オブジェクト
A3: Passive | B3: I/O | C3: テキスト | D3: 標準 | E3: 標準 | F3: 〇 | G3: テーブル | H3: Class | I3: Class
A4: Delayed | B4: I | C4: 日付 | D4: 中央詰 | E4: 中央詰 | F4: ー | G4: ビュー | H4: Form Class | I4: Form Class
A5: Active | B5: O | C5: 数値 | D5: 左詰 | E5: 上詰 | G5: CSV | H5: Table Class | I5: Table Class
A6: Inner | D6: 右詰 | E6: 下詰 | G6: Excel | H6: Macro | I6: Macro
A7: Outer | I7: Enum
A8: Exsits | I8: EDT
A9: Not Exsits | I9: Queries
I10: Data Entities
I11: Maps
I12: Forms
I13: Menus
I14: Menu Items(Display)
I15: Menu Items(Output)
I16: Menu Items(Action)
I17: Repoters
I18: Security Roles
I19: Security Duties
I20: Security Policies
