Workbook

Sheet 表紙
D3: サンスター株式会社 御中
V6: 会計システム刷新プロジェクト
V10: 非機能要件定義書_データ容量・パフォーマンス
B17: 第1.0版
B19: 45435
B21: 日本ビジネスシステムズ株式会社

Sheet テナント・インスタンス容量の考え方
B2: システム名 | G2: =表紙!V6 -> 会計システム刷新プロジェクト | U2: 章 | AS2: 日付 | BA2: 更新者
B3: 文書名 | G3: =表紙!V10 -> 非機能要件定義書_データ容量・パフォーマンス | U3: データ容量 | AS3: 作成 | AU3: 45369 | BA3: JBS
AS4: 更新
B6: ■ | C6: テナント・インスタンス容量の考え方
C8: Dynamicsのストレージ容量はインスタンスごとではなく、テナント全体に付与されたストレージ容量を
C9: テナント内の全インスタンスで共用する形となる。
C11: テナント・インスタンス容量の考え方については以下のファイルを参照
D12: 【サンスター様】テナントで使用可能な容量とインスタンスの関係図.pptx

Sheet 現在の容量試算
B2: システム名 | G2: =表紙!V6 -> 会計システム刷新プロジェクト | U2: 章 | AS2: 日付 | BA2: 更新者
B3: 文書名 | G3: =表紙!V10 -> 非機能要件定義書_データ容量・パフォーマンス | U3: データ容量 | AS3: 作成 | AU3: 45379 | BA3: JBS
AS4: 更新 | AU4: 45435 | BA4: JBS
B6: ■ | C6: データ容量試算の進め方
B8: 1）全体的な進め方
C10: ・D365は定期的に機能が追加されていくSaaSである(半年に１回機能が追加され、テーブルカラムが増えていく)
C11: ・アドオンとして追加するテーブルの項目長などは要件定義では決定されない
C12: ・単純な項目ではなく、可変長やblobなど実容量が読めない項目がある
C14: 上記の理由により、現時点で「稼働時点のデータ消費量はどれくらいか」「１年間の増加データ量はどれくらいか」を正確に見積もることはできない。
C15: そのため、複数回データ容量の試算を実施し、想定容量の精度を上げていく必要がある。
G17: 試算タイミング | Q17: 備考
D18: 試算① | G18: 要件定義 完了時点 | H18: 要件定義 完了時点 | I18: 要件定義 完了時点 | J18: 要件定義 完了時点 | K18: 要件定義 完了時点 | L18: 要件定義 完了時点 | M18: 要件定義 完了時点 | N18: 要件定義 完了時点 | O18: 要件定義 完了時点 | P18: 要件定義 完了時点 | Q18: モックアップ＋標準テーブルでの算出となるため、アドオンで追加される分の容量は算出できない
D19: 試算③ | G19: 基本設計 完了時点 | H19: 基本設計 完了時点 | I19: 基本設計 完了時点 | J19: 基本設計 完了時点 | K19: 基本設計 完了時点 | L19: 基本設計 完了時点 | M19: 基本設計 完了時点 | N19: 基本設計 完了時点 | O19: 基本設計 完了時点 | P19: 基本設計 完了時点 | Q19: テーブルの物理設計が完了し、ある程度精度が上がってくる | R19: ←テーブルの物理設計が完了し、ある程度精度が上がってくる | S19: ←テーブルの物理設計が完了し、ある程度精度が上がってくる | T19: ←テーブルの物理設計が完了し、ある程度精度が上がってくる | U19: ←テーブルの物理設計が完了し、ある程度精度が上がってくる | V19: ←テーブルの物理設計が完了し、ある程度精度が上がってくる | W19: ←テーブルの物理設計が完了し、ある程度精度が上がってくる | X19: ←テーブルの物理設計が完了し、ある程度精度が上がってくる | Y19: ←テーブルの物理設計が完了し、ある程度精度が上がってくる | Z19: ←テーブルの物理設計が完了し、ある程度精度が上がってくる | AA19: ←テーブルの物理設計が完了し、ある程度精度が上がってくる | AB19: ←テーブルの物理設計が完了し、ある程度精度が上がってくる | AC19: ←テーブルの物理設計が完了し、ある程度精度が上がってくる | AD19: ←テーブルの物理設計が完了し、ある程度精度が上がってくる | AE19: ←テーブルの物理設計が完了し、ある程度精度が上がってくる | AF19: ←テーブルの物理設計が完了し、ある程度精度が上がってくる | AG19: ←テーブルの物理設計が完了し、ある程度精度が上がってくる | AH19: ←テーブルの物理設計が完了し、ある程度精度が上がってくる | AI19: ←テーブルの物理設計が完了し、ある程度精度が上がってくる | AJ19: ←テーブルの物理設計が完了し、ある程度精度が上がってくる | AK19: ←テーブルの物理設計が完了し、ある程度精度が上がってくる | AL19: ←テーブルの物理設計が完了し、ある程度精度が上がってくる | AM19: ←テーブルの物理設計が完了し、ある程度精度が上がってくる | AN19: ←テーブルの物理設計が完了し、ある程度精度が上がってくる | AO19: ←テーブルの物理設計が完了し、ある程度精度が上がってくる | AP19: ←テーブルの物理設計が完了し、ある程度精度が上がってくる | AQ19: ←テーブルの物理設計が完了し、ある程度精度が上がってくる | AR19: ←テーブルの物理設計が完了し、ある程度精度が上がってくる | AS19: ←テーブルの物理設計が完了し、ある程度精度が上がってくる | AT19: ←テーブルの物理設計が完了し、ある程度精度が上がってくる | AU19: ←テーブルの物理設計が完了し、ある程度精度が上がってくる
D20: 試算④ | G20: 移行リハーサル①完了時点 | H20: 移行リハーサル①完了時点 | I20: 移行リハーサル①完了時点 | J20: 移行リハーサル①完了時点 | K20: 移行リハーサル①完了時点 | L20: 移行リハーサル①完了時点 | M20: 移行リハーサル①完了時点 | N20: 移行リハーサル①完了時点 | O20: 移行リハーサル①完了時点 | P20: 移行リハーサル①完了時点 | Q20: 実際に環境に投入されたデータとの差分を確認し、考慮漏れ等がないか確認していく | R20: ←実際に環境に投入されたデータとの差分を確認し、考慮漏れ等がないか確認していく | S20: ←実際に環境に投入されたデータとの差分を確認し、考慮漏れ等がないか確認していく | T20: ←実際に環境に投入されたデータとの差分を確認し、考慮漏れ等がないか確認していく | U20: ←実際に環境に投入されたデータとの差分を確認し、考慮漏れ等がないか確認していく | V20: ←実際に環境に投入されたデータとの差分を確認し、考慮漏れ等がないか確認していく | W20: ←実際に環境に投入されたデータとの差分を確認し、考慮漏れ等がないか確認していく | X20: ←実際に環境に投入されたデータとの差分を確認し、考慮漏れ等がないか確認していく | Y20: ←実際に環境に投入されたデータとの差分を確認し、考慮漏れ等がないか確認していく | Z20: ←実際に環境に投入されたデータとの差分を確認し、考慮漏れ等がないか確認していく | AA20: ←実際に環境に投入されたデータとの差分を確認し、考慮漏れ等がないか確認していく | AB20: ←実際に環境に投入されたデータとの差分を確認し、考慮漏れ等がないか確認していく | AC20: ←実際に環境に投入されたデータとの差分を確認し、考慮漏れ等がないか確認していく | AD20: ←実際に環境に投入されたデータとの差分を確認し、考慮漏れ等がないか確認していく | AE20: ←実際に環境に投入されたデータとの差分を確認し、考慮漏れ等がないか確認していく | AF20: ←実際に環境に投入されたデータとの差分を確認し、考慮漏れ等がないか確認していく | AG20: ←実際に環境に投入されたデータとの差分を確認し、考慮漏れ等がないか確認していく | AH20: ←実際に環境に投入されたデータとの差分を確認し、考慮漏れ等がないか確認していく | AI20: ←実際に環境に投入されたデータとの差分を確認し、考慮漏れ等がないか確認していく | AJ20: ←実際に環境に投入されたデータとの差分を確認し、考慮漏れ等がないか確認していく | AK20: ←実際に環境に投入されたデータとの差分を確認し、考慮漏れ等がないか確認していく | AL20: ←実際に環境に投入されたデータとの差分を確認し、考慮漏れ等がないか確認していく | AM20: ←実際に環境に投入されたデータとの差分を確認し、考慮漏れ等がないか確認していく | AN20: ←実際に環境に投入されたデータとの差分を確認し、考慮漏れ等がないか確認していく | AO20: ←実際に環境に投入されたデータとの差分を確認し、考慮漏れ等がないか確認していく | AP20: ←実際に環境に投入されたデータとの差分を確認し、考慮漏れ等がないか確認していく | AQ20: ←実際に環境に投入されたデータとの差分を確認し、考慮漏れ等がないか確認していく | AR20: ←実際に環境に投入されたデータとの差分を確認し、考慮漏れ等がないか確認していく | AS20: ←実際に環境に投入されたデータとの差分を確認し、考慮漏れ等がないか確認していく | AT20: ←実際に環境に投入されたデータとの差分を確認し、考慮漏れ等がないか確認していく | AU20: ←実際に環境に投入されたデータとの差分を確認し、考慮漏れ等がないか確認していく
D21: 試算⑤ | G21: 移行リハーサル②完了時点 | H21: 移行リハーサル②完了時点 | I21: 移行リハーサル②完了時点 | J21: 移行リハーサル②完了時点 | K21: 移行リハーサル②完了時点 | L21: 移行リハーサル②完了時点 | M21: 移行リハーサル②完了時点 | N21: 移行リハーサル②完了時点 | O21: 移行リハーサル②完了時点 | P21: 移行リハーサル②完了時点
D22: 試算⑥ | G22: 移行リハーサル③完了時点 | H22: 移行リハーサル③完了時点 | I22: 移行リハーサル③完了時点 | J22: 移行リハーサル③完了時点 | K22: 移行リハーサル③完了時点 | L22: 移行リハーサル③完了時点 | M22: 移行リハーサル③完了時点 | N22: 移行リハーサル③完了時点 | O22: 移行リハーサル③完了時点 | P22: 移行リハーサル③完了時点
C24: 各試算タイミングにて、容量超過が明らかである場合は、
C25: ・データアーカイブ、削除可能なデータの削除の検討
C26: ・ライセンス追加
C27: といった手段を事前に検討し、採用要否を判断していく形となる。（削除可能データ、ライセンス追加については「容量追加方法」シートを参照）
C28: ・環境のランドスケープについては、本番同等、本番の1/2のデータ量などの基準を設けて算出する
C29: ・グループ会社については、「サンスター株式会社」を "割合1" とした場合、グループ会社5社合計"0.3"として算出する
B31: 2）各試算の進め方
C33: ①テーブル一覧の作成(JBS) | AI33: ①と②の情報を元に算出 | BJ33: ②データ区分別の想定レコード数を設定(サンスター様)
D34: System | H34: table ID | Q34: データ区分 | AA34: 想定レコード長(byte)※ | AI34: 移行件数 | AO34: 移行想定容量 | AU34: 増加件数 | BA34: 増加想定容量 | BJ34: データ区分 | BT34: 移行件数 | BZ34: 増加件数
D35: FO | E35: salestable | F35: 受注 | G35: 1000 | H35: Free Text Invoice | Q35: 債権 | AI35: =VLOOKUP(Q35,BJ:CE,11,FALSE) -> 4000 | AO35: =AA35*AI35 -> 0 | AU35: =VLOOKUP(Q35,BJ:CE,17,FALSE) -> 20000 | BA35: =AA35*AU35 -> 0 | BJ35: 債権 | BK35: 営業案件 | BL35: 営業案件 | BM35: 営業案件 | BN35: 営業案件 | BO35: 営業案件 | BP35: 営業案件 | BQ35: 営業案件 | BR35: 営業案件 | BS35: 営業案件 | BT35: 4000 | BU35: 4000 | BV35: 4000 | BW35: 4000 | BX35: 4000 | BY35: 4000 | BZ35: 20000 | CA35: 20000 | CB35: 20000 | CC35: 20000 | CD35: 20000 | CE35: 20000
D36: FO | E36: logisticspostaladdress | F36: 受注 | G36: 1000 | H36: VendInvoiceJournalT | Q36: 債務 | AI36: =VLOOKUP(Q36,BJ:CE,11,FALSE) -> 4000 | AO36: =AA36*AI36 -> 0 | AU36: =VLOOKUP(Q36,BJ:CE,17,FALSE) -> 20000 | BA36: =AA36*AU36 -> 0 | BJ36: 債務 | BK36: 営業案件明細 | BL36: 営業案件明細 | BM36: 営業案件明細 | BN36: 営業案件明細 | BO36: 営業案件明細 | BP36: 営業案件明細 | BQ36: 営業案件明細 | BR36: 営業案件明細 | BS36: 営業案件明細 | BT36: 4000 | BU36: 4000 | BV36: 4000 | BW36: 4000 | BX36: 4000 | BY36: 4000 | BZ36: 20000 | CA36: 20000 | CB36: 20000 | CC36: 20000 | CD36: 20000 | CE36: 20000
D37: FO | E37: salesline | F37: 受注明細 | G37: 3000 | H37: LedgerJournalLineEntry | I37: salesline2 | J37: salesline2 | K37: salesline2 | L37: salesline2 | M37: salesline2 | N37: salesline2 | O37: salesline2 | P37: salesline2 | Q37: 経費等(楽々精算より） | AI37: =VLOOKUP(Q37,BJ:CE,11,FALSE) -> 8000 | AO37: =AA37*AI37 -> 0 | AU37: =VLOOKUP(Q37,BJ:CE,17,FALSE) -> 40000 | BA37: =AA37*AU37 -> 0 | BJ37: 経費等(楽々精算より） | BK37: 見積 | BL37: 見積 | BM37: 見積 | BN37: 見積 | BO37: 見積 | BP37: 見積 | BQ37: 見積 | BR37: 見積 | BS37: 見積 | BT37: 8000 | BU37: 8000 | BV37: 8000 | BW37: 8000 | BX37: 8000 | BY37: 8000 | BZ37: 40000 | CA37: 40000 | CB37: 40000 | CC37: 40000 | CD37: 40000 | CE37: 40000
D38: FO | E38: salesline2 | F38: 受注明細 | G38: 3000 | H38: LedgerJournalLineEntry | I38: salesline2 | J38: salesline2 | K38: salesline2 | L38: salesline2 | M38: salesline2 | N38: salesline2 | O38: salesline2 | P38: salesline2 | Q38: 一般仕訳(手入力) | AI38: =VLOOKUP(Q38,BJ:CE,11,FALSE) -> 8000 | AO38: =AA38*AI38 -> 0 | AU38: =VLOOKUP(Q38,BJ:CE,17,FALSE) -> 40000 | BA38: =AA38*AU38 -> 0 | BJ38: 一般仕訳(手入力) | BK38: 見積明細 | BL38: 見積明細 | BM38: 見積明細 | BN38: 見積明細 | BO38: 見積明細 | BP38: 見積明細 | BQ38: 見積明細 | BR38: 見積明細 | BS38: 見積明細 | BT38: 8000 | BU38: 8000 | BV38: 8000 | BW38: 8000 | BX38: 8000 | BY38: 8000 | BZ38: 40000 | CA38: 40000 | CB38: 40000 | CC38: 40000 | CD38: 40000 | CE38: 40000
D39: FO | E39: project | F39: プロジェクト | G39: 4000 | H39: AssetJournalLineEntity | I39: project | J39: project | K39: project | L39: project | M39: project | N39: project | O39: project | P39: project | Q39: 固定資産 | AI39: =VLOOKUP(Q39,BJ:CE,11,FALSE) -> 10000 | AO39: =AA39*AI39 -> 0 | AU39: =VLOOKUP(Q39,BJ:CE,17,FALSE) -> 20000 | BA39: =AA39*AU39 -> 0 | BJ39: 固定資産 | BK39: 受注 | BL39: 受注 | BM39: 受注 | BN39: 受注 | BO39: 受注 | BP39: 受注 | BQ39: 受注 | BR39: 受注 | BS39: 受注 | BT39: 10000 | BU39: 10000 | BV39: 10000 | BW39: 10000 | BX39: 10000 | BY39: 10000 | BZ39: 20000 | CA39: 20000 | CB39: 20000 | CC39: 20000 | CD39: 20000 | CE39: 20000
D40: FO | E40: project | F40: プロジェクト | G40: 4000 | H40: AssetLeaseLedgerJournalLineEntry | I40: project | J40: project | K40: project | L40: project | M40: project | N40: project | O40: project | P40: project | Q40: リース | AI40: =VLOOKUP(Q40,BJ:CE,11,FALSE) -> 10000 | AO40: =AA40*AI40 -> 0 | AU40: =VLOOKUP(Q40,BJ:CE,17,FALSE) -> 20000 | BA40: =AA40*AU40 -> 0 | BJ40: リース | BK40: 受注 | BL40: 受注 | BM40: 受注 | BN40: 受注 | BO40: 受注 | BP40: 受注 | BQ40: 受注 | BR40: 受注 | BS40: 受注 | BT40: 10000 | BU40: 10000 | BV40: 10000 | BW40: 10000 | BX40: 10000 | BY40: 10000 | BZ40: 20000 | CA40: 20000 | CB40: 20000 | CC40: 20000 | CD40: 20000 | CE40: 20000
D41: FO | E41: projectContract | F41: プロジェクト | G41: 5000 | H41: Customer | I41: projectContract | J41: projectContract | K41: projectContract | L41: projectContract | M41: projectContract | N41: projectContract | O41: projectContract | P41: projectContract | Q41: 顧客 | AI41: =VLOOKUP(Q41,BJ:CE,11,FALSE) -> 500000 | AO41: =AA41*AI41 -> 0 | AU41: =VLOOKUP(Q41,BJ:CE,17,FALSE) -> 1000000 | BA41: =AA41*AU41 -> 0 | BJ41: 顧客 | BK41: 受注明細 | BL41: 受注明細 | BM41: 受注明細 | BN41: 受注明細 | BO41: 受注明細 | BP41: 受注明細 | BQ41: 受注明細 | BR41: 受注明細 | BS41: 受注明細 | BT41: =BT39*50 -> 500000 | BU41: =BU39*50 -> 500000 | BV41: =BV39*50 -> 500000 | BW41: =BW39*50 -> 500000 | BX41: =BX39*50 -> 500000 | BY41: =BY39*50 -> 500000 | BZ41: =BZ39*50 -> 1000000 | CA41: =CA39*50 -> 1000000 | ... CE41: =CE39*50 -> 1000000
D42: FO | E42: projectDetail | F42: プロジェクト | G42: 6000 | H42: Vendor | I42: projectDetail | J42: projectDetail | K42: projectDetail | L42: projectDetail | M42: projectDetail | N42: projectDetail | O42: projectDetail | P42: projectDetail | Q42: 仕入先 | AI42: =VLOOKUP(Q42,BJ:CE,11,FALSE) -> 500 | AO42: =AA42*AI42 -> 0 | AU42: =VLOOKUP(Q42,BJ:CE,17,FALSE) -> 5000 | BA42: =AA42*AU42 -> 0 | BJ42: 仕入先 | BK42: プロジェクト | BL42: プロジェクト | BM42: プロジェクト | BN42: プロジェクト | BO42: プロジェクト | BP42: プロジェクト | BQ42: プロジェクト | BR42: プロジェクト | BS42: プロジェクト | BT42: 500 | BU42: 500 | BV42: 500 | BW42: 500 | BX42: 500 | BY42: 500 | BZ42: 5000 | CA42: 5000 | CB42: 5000 | CC42: 5000 | CD42: 5000 | CE42: 5000
D43: ※各テーブルは、ヘッダと明細に分かれており、かつ、関連テーブルも存在するテーブルもあるが、おおよそのレコード長とおおよそのデータ量にての概算見積としている
C45: ③システム別の想定容量の算出
D46: 行ラベル | H46: 合計 / 移行想定容量 | S46: 合計 / 増加想定容量
D47: FO | H47: =SUMIF(D35:G42,"FO",AO35:AT42) -> 0 | S47: =SUMIF(D35:G42,"FO",BA35:BF42) -> 0
D48: 総計 | H48: =SUM(H47:R47) -> 0 | S48: =SUM(S47:AH47) -> 0
C50: ④稼働時、１年後、５年後の消費容量想定を試算
H51: 稼働時 | S51: 1年後 | AI51: 5年後
...

Sheet 容量追加方法
B2: システム名 | G2: =表紙!V6 -> 会計システム刷新プロジェクト | U2: 章 | AS2: 日付 | BA2: 更新者
B3: 文書名 | G3: =表紙!V10 -> 非機能要件定義書_データ容量・パフォーマンス | U3: データ容量 | AS3: 作成 | AU3: 45379 | BA3: JBS
AS4: 更新
B6: ■ | C6: 追加ライセンスと価格について
C8: 追加ライセンスのSKUと参考価格は下記の通り
H9: 製品名(各ライセンスにつき、追加単位は1SKU = 1GB) | J9: 製品名(各ライセンスにつき、追加単位は1SKU = 1GB) | L9: 製品名(各ライセンスにつき、追加単位は1SKU = 1GB) | N9: 製品名(各ライセンスにつき、追加単位は1SKU = 1GB) | P9: 製品名(各ライセンスにつき、追加単位は1SKU = 1GB) | R9: 製品名(各ライセンスにつき、追加単位は1SKU = 1GB) | T9: 製品名(各ライセンスにつき、追加単位は1SKU = 1GB) | V9: 製品名(各ライセンスにつき、追加単位は1SKU = 1GB) | X9: 製品名(各ライセンスにつき、追加単位は1SKU = 1GB) | Z9: 製品名(各ライセンスにつき、追加単位は1SKU = 1GB) | AB9: 製品名(各ライセンスにつき、追加単位は1SKU = 1GB) | AD9: 製品名(各ライセンスにつき、追加単位は1SKU = 1GB) | AF9: ご参考価格/月 | AG9: ご参考価格/月 | AH9: ご参考価格/月 | AI9: ご参考価格/月 | AJ9: ご参考価格/月 | AK9: ご参考価格/月 | AL9: ご参考価格/月 | AM9: 100GB追加/月 | AN9: 100GB追加/月 | AO9: 100GB追加/月 | AP9: 100GB追加/月 | AQ9: 100GB追加/月 | AR9: 100GB追加/月 | AS9: 100GB追加/月
D10: FO-DB | E10: FO-DB | F10: FO-DB | G10: FO-DB | H10: D365 Operations Additional Database Capacity Sub Add-on | I10: D365 Operations Additional Database Capacity Sub Add-on | J10: D365 Operations Additional Database Capacity Sub Add-on | K10: D365 Operations Additional Database Capacity Sub Add-on | L10: D365 Operations Additional Database Capacity Sub Add-on | M10: D365 Operations Additional Database Capacity Sub Add-on | N10: D365 Operations Additional Database Capacity Sub Add-on | O10: D365 Operations Additional Database Capacity Sub Add-on | P10: D365 Operations Additional Database Capacity Sub Add-on | Q10: D365 Operations Additional Database Capacity Sub Add-on | R10: D365 Operations Additional Database Capacity Sub Add-on | S10: D365 Operations Additional Database Capacity Sub Add-on | T10: D365 Operations Additional Database Capacity Sub Add-on | U10: D365 Operations Additional Database Capacity Sub Add-on | V10: D365 Operations Additional Database Capacity Sub Add-on | W10: D365 Operations Additional Database Capacity Sub Add-on | X10: D365 Operations Additional Database Capacity Sub Add-on | Y10: D365 Operations Additional Database Capacity Sub Add-on | Z10: D365 Operations Additional Database Capacity Sub Add-on | AA10: D365 Operations Additional Database Capacity Sub Add-on | AB10: D365 Operations Additional Database Capacity Sub Add-on | AC10: D365 Operations Additional Database Capacity Sub Add-on | AD10: D365 Operations Additional Database Capacity Sub Add-on | AE10: D365 Operations Additional Database Capacity Sub Add-on | AF10: 5000 | AG10: 5000 | AH10: 5000 | AI10: 5000 | AJ10: 5000 | AK10: 5000 | AL10: 5000 | AM10: =AL10*100 -> 500000 | AN10: =AM10*100 -> 50000000 | AO10: =AN10*100 -> 5000000000 | AP10: =AO10*100 -> 500000000000 | AQ10: =AP10*100 -> 50000000000000 | AR10: =AQ10*100 -> 5e+15 | AS10: =AR10*100 -> 5e+17
D11: FO-ファイル | E11: FO-ファイル | F11: FO-ファイル | G11: FO-ファイル | H11: D365 Operations Additional File Capacity Sub Add-on | I11: D365 Operations Additional File Capacity Sub Add-on | J11: D365 Operations Additional File Capacity Sub Add-on | K11: D365 Operations Additional File Capacity Sub Add-on | L11: D365 Operations Additional File Capacity Sub Add-on | M11: D365 Operations Additional File Capacity Sub Add-on | N11: D365 Operations Additional File Capacity Sub Add-on | O11: D365 Operations Additional File Capacity Sub Add-on | P11: D365 Operations Additional File Capacity Sub Add-on | Q11: D365 Operations Additional File Capacity Sub Add-on | R11: D365 Operations Additional File Capacity Sub Add-on | S11: D365 Operations Additional File Capacity Sub Add-on | T11: D365 Operations Additional File Capacity Sub Add-on | U11: D365 Operations Additional File Capacity Sub Add-on | V11: D365 Operations Additional File Capacity Sub Add-on | W11: D365 Operations Additional File Capacity Sub Add-on | X11: D365 Operations Additional File Capacity Sub Add-on | Y11: D365 Operations Additional File Capacity Sub Add-on | Z11: D365 Operations Additional File Capacity Sub Add-on | AA11: D365 Operations Additional File Capacity Sub Add-on | AB11: D365 Operations Additional File Capacity Sub Add-on | AC11: D365 Operations Additional File Capacity Sub Add-on | AD11: D365 Operations Additional File Capacity Sub Add-on | AE11: D365 Operations Additional File Capacity Sub Add-on | AF11: 300 | AG11: 300 | AH11: 300 | AI11: 300 | AJ11: 300 | AK11: 300 | AL11: 300 | AM11: =AL11*100 -> 30000 | AN11: =AM11*100 -> 3000000 | AO11: =AN11*100 -> 300000000 | AP11: =AO11*100 -> 30000000000 | AQ11: =AP11*100 -> 3000000000000 | AR11: =AQ11*100 -> 300000000000000 | AS11: =AR11*100 -> 3e+16
D12: ※近日中に環境の考え方が変わるとMicrosoft社より発表があったが、現状は上記の通り
B15: ■ | C15: データ削除について
C17: 1）データクリーンアップ
D18: 不要なレコード、添付ファイル、ログ情報などを削除することでその分のストレージ容量を確保することが可能。
D19: システム | I19: データ種別 | T19: クリーンアップ処理(標準) | AE19: クリーンアップ処理(アドオン) | AP19: 本PJでの方針
D20: FO | I20: マスタ/トランザクション | T20: 削除可 (★1) | AE20: 削除可 | AP20: 削除しない （★2）
I22: 会計データ | T22: 削除可 (★1) | AE22: 削除不可 | AP22: 削除しない
I24: システム系ログ | T24: 削除可 (★1) | AE24: 削除可 | AP24: 「【サンスター】非機能要件定義書_システム運用 .xlsx」参照
D26: ★1： | F26: 標準のクリーンアップ処理で削除可能なデータについては以下の公開ドキュメントを参照
E27: https://learn.microsoft.com/ja-jp/dynamics365/fin-ops-core/dev-itpro/sysadmin/cleanuproutines
D29: ★2： | F29: 基本的にマスタ/トランザクションのデータは削除しない方針とするが、データ容量試算によりデータ容量が多いマスタ/トランザクション（製品マスタ等）についてはデータ削除機能を検討する。
F30: 検討の場は各業務領域とする。

Sheet データバックアップ
B2: システム名 | G2: =表紙!V6 -> 会計システム刷新プロジェクト | U2: 章 | AS2: 日付 | BA2: 更新者
B3: 文書名 | G3: =表紙!V10 -> 非機能要件定義書_データ容量・パフォーマンス | U3: データ容量 | AS3: 作成 | AU3: 45379 | BA3: JBS
AS4: 更新
B6: ■ | C6: データバックアップ
C8: 環境を構築すると自動的にシステムバックアップが実行される。
C9: 本資料ではデータバックアップでのデータ容量にまつわる部分のみ記載し、データバックアップの仕様については以下を参照する。
D10: 【サンスター様】バックアップについて.pptx
B12: ■ | C12: バックアップの使用容量について
C14: ■ | D14: 自動バックアップ
E15: FOの自動バックアップは15分に1回の頻度で自動取得されているが、ストレージ容量にはカウントされない。
C17: ■ | D17: 手動バックアップ
E18: 手動バックアップはLCSのAsset libraryに保存される。LCS自体に容量制限はなく、消費されるリソースもMicrosoftのシステムとなるため、
E19: 手動バックアップを取得したことによる容量消費やキャパシティアドオンの追加購入等は必要ない（2023/10/31時点）。
E21: ただしLCSの仕様として、Sandbox環境で手動バックアップを取得する際、バックアップファイル（bacpac）のサイズが50GBを超過するとバックアップできない。
E22: 超過していた場合は、手動バックアップを取得する前にクリーンアップ機能を使用し、Sandbox環境で削除できるデータを事前に削除する必要がある。
E24: ※参考： | H24: https://learn.microsoft.com/ja-jp/dynamics365/fin-ops-core/dev-itpro/database/export-database#maximum-limit-50-gb-on-exported-bacpacs

Sheet データ長期保存
B2: システム名 | G2: =表紙!V6 -> 会計システム刷新プロジェクト | U2: 章 | AS2: 日付 | BA2: 更新者
B3: 文書名 | G3: =表紙!V10 -> 非機能要件定義書_データ容量・パフォーマンス | U3: データ容量 | AS3: 作成 | AU3: 45379 | BA3: JBS
AS4: 更新
B6: ■ | C6: データ長期保存の目的
C7: データ長期保存の目的は以下の通り。
C9: ■ | D9: 容量やパフォーマンスの観点からFOのデータをクリーンアップしたり他のストレージ領域（BI等）に移動させる際、その時点のデータを後々参照できるように退避しておく。
D10: →ユーザーからどのような過去データを参照したいかというリクエストが来るか想定できないため、対象テーブルやデータは絞らずその時点での環境すべてを参照できるようにしておく方針とする。
D11: →以下に記載の通り、Sandbox環境でのバックアップを用いて長期保存に対応する想定のため、JBSの保守の範囲で対応する。
D12: →改正電子帳簿保存法への対応については非機能要件定義書では扱わない。
D13: 販売はmcframe、購買側は楽楽精算のため、FOでは対応しない想定。BOXでの保管を検討中
D14: FOでは添付ファイル保存はしない想定だが、「Azure Storage」を保存先としてパラメータを設定しておく
D15: (FOとしては、保存先にSharepointサーバーも指定可能だが、FO管理者ユーザーにM365ライセンスが紐づかない想定のため、「Azure Storage」としている。)
B17: ■ | C17: データ長期保存の実施概要
C19: 1）データ長期保存を実施する頻度
D20: データ長期保存の処置を実施するタイミングは以下の通り。
D21: なお、実際のDB消費量やパフォーマンスの観点から間隔は増減する可能性がある。
D23: データ長期保存実施頻度
D24: 5年
B27: ■ | C27: 長期保存
C29: 1）長期保存の手法
D30: データそのものを長期保存するという観点から"Sandbox環境でのバックアップ"で対応する。
C33: 2）長期保存に用いる環境
D34: 長期保存には以下2つの環境を用いる。
D35: ランニングコストを下げる観点から、データを参照するための環境（データ長期保存用環境）はクラウドホスト環境を用いる。
D37: 環境の種類 | K37: 使用用途
D38: Sandbox環境 （Tier2） | K38: 本番環境のDBを取得するために使用。 また本番環境DB取得後、DBのbacpacファイルを作成するためにも使用する。
D40: データ長期保存用環境 （クラウドホスト環境） | K40: データを参照するための参照専用環境。 Sandbox環境で取得した本番環境DBのbacpacファイルをリストアする。 クラウドホスト環境のため、データを参照する時のみ起動することでランニングコストを抑えることが可能。
C46: 3）留意点
D47: ■ | E47: データ長期保存用環境ではAdminユーザー以外は全て参照専用のセキュリティロール（アドオンで作成）を付与し、システム管理者ロールを持つのはAdminユーザーのみとする。
D48: ■ | E48: 「データ長期保存用環境の構築の流れ」のNo.5にて行うSandbox環境の手動バックアップの際、DBの容量が50GBを超過しているとバックアップ不可となる。
E49: そのため、データベースログやバッチログなと削除可能なデータを削除した上で手動バックアップを実施する。
B53: ■ | C53: データ長期保存用環境の構築の流れ
D54: 以下の流れでデータ長期保存用環境を構築する。
D56: No. | F56: 作業内容 | M56: CE | AJ56: FO | BG56: 環境
D57: 1 | F57: データ断面の決定 | M57: 本番環境のどの時刻の自動バックアップからDBを取得するか決定する。 ※FOは15分間隔（毎時00分/15分/30分/45分）で時間を指定して復元できるのに対し、CEは時間を指定することができない。よって、CEで環境コピーを開始する時間を指定する必要がある。 ※データ不整合を防ぐため、復元時間を指定する際はCE・FOともに同じ時間を指定する必要がある。 | BG57: -
D58: 2 | F58: 作業日程の調整 | M58: 作業実施日程を決定する。 データの不整合を避けるため、作業タイミングはFO同時に実施する。 ※CEの環境コピーは時間を指定することができず、コピー作業開始時点の環境がコピーされるため、どのタイミングで作業を開始する必要があるか決定する。 ※実際に作業を実施するタイミングは業務時間外とする。 | BG58: -
D62: 3 | F62: 環境の準備 | M62: コピー先となるサンドボックス環境を作成する。 | AJ62: "長期保存に用いる環境" に記載の環境を構築する。 Sandbox環境については使用できる環境がない場合、新たに環境ライセンス（Tier2）が必要となる。 データ長期保存用環境はクラウドホスト環境となるため、LCSから構築する。 | BG62: Sandbox環境 データ長期保存用環境
D67: 4 | F67: Sandbox環境リストア実施 | M67: - | AJ67: LCSでSandbox環境の詳細ページを開き、No.1で決定した時刻を指定して本番環境のDBをリストアする。 Sandbox環境ではダウンタイムが発生する（本番環境には影響なし）。 | BG67: 本番環境 Sandbox環境
D70: 5 | F70: 環境コピー実施 | M70: 本番環境をNo.3で作成した環境にコピーする。 データの不整合を避けるため、作業タイミングはLCSで指定した時刻と同時に実施する。また、作業時間は業務時間外とする。 | AJ70: - | BG70: 本番環境 データ長期保存用環境
D73: 6 | F73: 不要データの削除 | M73: - | AJ73: DBの容量が50GBを超過している場合、データ長期保存用環境にリストアするためのバックアップの取得が不可となる。 そのため、データベースログやバッチログなと削除可能なデータをクリーンアップする。 | BG73: Sandbox環境
...
