Workbook
Name io: マスタ!$A$3:$A$5
Name Visivility: マスタ!$F$3:$F$4
Name オブジェクト: マスタ!$H$7:$H$20
Name オブジェクト一覧: マスタ!$H$3:$H$20
Name テーブル種別: マスタ!$G$3:$G$4
Name マスタ: マスタ!$H$3:$H$20
Name 横位置: マスタ!$C$3:$C$6
Name 作成日: DATE(2000,3,21)
Name 縦位置: マスタ!$D$3:$D$6
Name 書式: マスタ!$B$3:$B$5
Name 折り返して全体を表示する: マスタ!$E$3:$E$4

Sheet 表紙
B3: サンスター株式会社 御中
B10: 会計システム刷新プロジェクト（LIBRA）
B14: =変更履歴!W2&"_設計書_"&変更履歴!AE2 -> FO-087_設計書_入金データ連携
AA21: ＜機能ID>_＜画面名＞画面を入力
B22: ="第"&IF(COUNTA(変更履歴!BF5:BI10000)=1,"",INDIRECT("変更履歴!BF"&COUNTA(変更履歴!BF5:BI10000)+4))&"版" -> 第1.3版
B24: =IF(OR(COUNTA(変更履歴!A:E)=2),"",INDIRECT("変更履歴!A"&COUNTA(変更履歴!A:E)+3)) -> 45624
B26: 日本ビジネスシステムズ株式会社
F29: 作成者 | O29: JBS承認者 | V29: 基本設計部確認者
F30: =変更履歴!AV2 -> 45492 | N30: 45505 | V30: 45509
F31: =変更履歴!BB2 -> JBS石岡 | N31: JBS加藤 | V31: サンスター佐保

Sheet 変更履歴
A1: 設計書 | F1: システム名 | Q1: 機能分類 | W1: 機能ＩＤ | AE1: 機能名称 | AT1: 日付 | BB1: 更新者
F2: Dynamics365 for Finance and Operations | Q2: 債権・債務 | W2: FO-087 | AE2: 入金データ連携 | AT2: 作成 | AV2: =A6 -> 45492 | BB2: =AZ6 -> JBS石岡
AT3: 更新 | AV3: {=IF(OR(COUNTA(A:E)=2),"",INDIRECT("A"&COUNTA(A:E)+3))} -> 45624 | BB3: {=IF(COUNTA(AZ5:BE100018)=1,"",INDIRECT("AZ"&COUNTA(AZ5:BE100018)+4))} -> JBS加藤
AW4: （表紙同様値）
A5: 変更年月日 | F5: 変更箇所 | T5: 変更内容 | AZ5: 変更者 | BF5: 版数
A6: 45492 | F6: 新規作成 | T6: 新規作成 | AZ6: JBS石岡 | BF6: 1.0
A7: 45623 | F7: シート：イベント説明 | T7: ・48,49行目の項目名を修正（画面.月 → 画面.会計期間） ・全体的に物理名を追記 | AZ7: JBS加藤 | BF7: 1.1
A8: 45623 | F8: シート：画面項目説明 | T8: 会計年度を必須に変更 | AZ8: JBS加藤 | BF8: 1.1
A9: 45623 | F9: シート：ファイルレイアウト(区切り) | T9: 物理名を追記 | AZ9: JBS加藤 | BF9: 1.2
A10: 45624 | F10: シート：イベント説明 | T10: 会計期間の必須チェック追加 | AZ10: JBS加藤 | BF10: 1.3

Sheet 処理概要
A1: 基本設計書 | F1: =変更履歴!F1 -> システム名 | Q1: =変更履歴!Q1 -> 機能分類 | W1: =変更履歴!W1 -> 機能ＩＤ | AE1: =変更履歴!AE1 -> 機能名称 | AT1: =変更履歴!AT1 -> 日付 | BB1: =変更履歴!BB1 -> 更新者
F2: =変更履歴!F2 -> Dynamics365 for Finance and Operations | Q2: =変更履歴!Q2 -> 債権・債務 | W2: =変更履歴!W2 -> FO-087 | AE2: =変更履歴!AE2 -> 入金データ連携 | AT2: =変更履歴!AT2 -> 作成 | AV2: =変更履歴!AV2 -> 45492 | BB2: =変更履歴!BB2 -> JBS石岡
AT3: =変更履歴!AT3 -> 更新 | AV3: =変更履歴!AV3 -> 45624 | BB3: =変更履歴!BB3 -> JBS加藤
A5: 開発目的
B6: 1. | C6: 連携先システム(SLJ販売システム)にて今回入金額や請求残高を含めた請求書出力するため
A9: 前提条件
B10: 1. | C10: 出力単位はログインしている法人ごととする。
C11: ※(手動実行時)データ出力する際は、事前にFO画面右上部で法人を「SLJ」に切り替えていただいたうえで本機能を実行すること。
B12: 2. | C12: 本機能で出力されるファイルの格納先はブラウザ指定先とする。
B13: 3. | C13: 決済データについて、文書=DZ(得意先入金)となる仕訳データを抽出対象とする。
H14: (現:伝票タイプ)
A16: 使用タイミング
B17: 1. | C17: 月次
A20: 開発内容
B21: 1. | C21: SLJ販売システムへ連携する入金(未決済/決済)情報の出力指示画面を新設する。
B22: 2. | C22: 指定した会計年度や会計期間をもとに未決済/決済データを取得し、ファイル出力を行う。
A26: 制限事項
B27: 1. | C27: 特になし

Sheet テーブル一覧
A1: 基本設計書 | F1: =変更履歴!F1 -> システム名 | Q1: =変更履歴!Q1 -> 機能分類 | W1: =変更履歴!W1 -> 機能ＩＤ | AE1: =変更履歴!AE1 -> 機能名称 | AT1: =変更履歴!AT1 -> 日付 | BB1: =変更履歴!BB1 -> 更新者
F2: =変更履歴!F2 -> Dynamics365 for Finance and Operations | Q2: =変更履歴!Q2 -> 債権・債務 | W2: =変更履歴!W2 -> FO-087 | AE2: =変更履歴!AE2 -> 入金データ連携 | AT2: =変更履歴!AT2 -> 作成 | AV2: =変更履歴!AV2 -> 45492 | BB2: =変更履歴!BB2 -> JBS石岡
AT3: =変更履歴!AT3 -> 更新 | AV3: =変更履歴!AV3 -> 45624 | BB3: =変更履歴!BB3 -> JBS加藤
A5: No. | C5: 種別 | K5: 論理名 | AC5: 物理名 | AS5: I/O | AU5: 備考
A6: =ROW()-5 -> 1 | C6: テーブル | K6: 一般仕訳入力 | AC6: GeneralJournalEntry | AS6: I
A7: =ROW()-5 -> 2 | C7: テーブル | K7: 一般仕訳帳勘定項目 | AC7: GeneralJournalAccountEntry | AS7: I
A8: =ROW()-5 -> 3 | C8: テーブル | K8: 主勘定 | AC8: MainAccount | AS8: I
A9: =ROW()-5 -> 4 | C9: テーブル | K9: 分析コード値 | AC9: DimensionAttributeLevelValueView | AS9: I
A10: =ROW()-5 -> 5 | C10: テーブル | K10: 分析コード | AC10: DimensionAttributeValue | AS10: I
A11: =ROW()-5 -> 6 | C11: テーブル | K11: 分析コード | AC11: DimensionAttribute | AS11: I
A12: =ROW()-5 -> 7
A13: =ROW()-5 -> 8
A14: =ROW()-5 -> 9
A15: =ROW()-5 -> 10
A16: =ROW()-5 -> 11
A17: =ROW()-5 -> 12
A18: =ROW()-5 -> 13
A19: =ROW()-5 -> 14
A20: =ROW()-5 -> 15
A21: =ROW()-5 -> 16
A22: =ROW()-5 -> 17
A23: =ROW()-5 -> 18
... A30: =ROW()-5 -> 25

Sheet DFD
A1: 基本設計書 | F1: =変更履歴!F1 -> システム名 | Q1: =変更履歴!Q1 -> 機能分類 | W1: =変更履歴!W1 -> 機能ＩＤ | AE1: =変更履歴!AE1 -> 機能名称 | AT1: =変更履歴!AT1 -> 日付 | BB1: =変更履歴!BB1 -> 更新者
F2: =変更履歴!F2 -> Dynamics365 for Finance and Operations | Q2: =変更履歴!Q2 -> 債権・債務 | W2: =変更履歴!W2 -> FO-087 | AE2: =変更履歴!AE2 -> 入金データ連携 | AT2: =変更履歴!AT2 -> 作成 | AV2: =変更履歴!AV2 -> 45492 | BB2: =変更履歴!BB2 -> JBS石岡
AT3: =変更履歴!AT3 -> 更新 | AV3: =変更履歴!AV3 -> 45624 | BB3: =変更履歴!BB3 -> JBS加藤
A5: イベント | O5: 機能 | AN5: DB
A56: 凡例
A57: 記号
AL61: ※DBが複数ある場合は複数DBをまとめるために使用

Sheet イベント説明
A1: 基本設計書 | F1: =変更履歴!F1 -> システム名 | Q1: =変更履歴!Q1 -> 機能分類 | W1: =変更履歴!W1 -> 機能ＩＤ | AE1: =変更履歴!AE1 -> 機能名称 | AT1: =変更履歴!AT1 -> 日付 | BB1: =変更履歴!BB1 -> 更新者
F2: =変更履歴!F2 -> Dynamics365 for Finance and Operations | Q2: =変更履歴!Q2 -> 債権・債務 | W2: =変更履歴!W2 -> FO-087 | AE2: =変更履歴!AE2 -> 入金データ連携 | AT2: =変更履歴!AT2 -> 作成 | AV2: =変更履歴!AV2 -> 45492 | BB2: =変更履歴!BB2 -> JBS石岡
AT3: =変更履歴!AT3 -> 更新 | AV3: =変更履歴!AV3 -> 45624 | BB3: =変更履歴!BB3 -> JBS加藤
A5: No. | C5: イベント名 | I5: 処理内容 | AO5: 種別 | AR5: メッセージ | BF5: ID
A6: 1. | C6: 画面初期表示
J7: 1-1. | L7: 画面表示処理
K9: 対象モジュール： | P9: Classes/SJ_ARCashApplicationOutput
K10: 対象メソッド： | P10: dialog()
L12: 「画面レイアウト」シート通りに表示する。
A15: 2. | C15: OKボタン押下時
J16: 2-1. | L16: データ入力チェック
K18: 対象モジュール： | P18: Classes/SJ_ARCashApplicationOutput
K19: 対象メソッド： | P19: validate()
K21: 2-1-1. | N21: 会計年度の必須チェック
L23: [画面.会計年度]が空欄の場合、警告メッセージを出力する。 | AO23: 情報ログ | AR23: %1 が指定されていません。 | BF23: SYS321809
AO24: warning
AR25: %1： | AT25: "会計年度" | BF25: SJ00647
K27: 2-1-2. | N27: 会計期間の必須チェック
L29: [画面.会計期間]が空欄の場合、警告メッセージを出力する。 | AO29: 情報ログ | AR29: %1 が指定されていません。 | BF29: SYS321809
AO30: warning
AR31: %1： | AT31: "会計期間" | BF31: SJ00648
J33: 2-2. | L33: 対象データ取得
K35: 対象モジュール： | P35: Classes/SJ_ARCashApplicationOutput
K36: 対象メソッド： | P36: run()
K38: 2-2-1. | N38: 未決済/決済データ
L40: 対象モジュール： | Q40: Classes/SJ_ARCashApplicationOutput
L41: 対象メソッド： | Q41: 実装時に記載
L43: 以下の条件で対象データを取得し、保持する。
L44: 取得内容は「ファイルレイアウト（区切り）」シートを参照。
L46: 対象テーブル： | P46: [一般仕訳入力(GeneralJournalEntry)]
P47: [一般仕訳帳勘定項目(GeneralJournalAccountEntry)]
P48: [主勘定(MainAccount)]
L50: 結合条件：
P51: [一般仕訳入力.レコードID(RecId)] | AH51: = | AJ51: [一般仕訳帳勘定項目.参照(GeneralJournalEntry)]
P52: [一般仕訳帳勘定項目.主勘定(MainAccount)] | AH52: = | AJ52: [主勘定.レコードID(RecId)]
L54: 抽出条件： | P54: ([一般仕訳入力.日付(AccountingDate)] | AH54: >= | AJ54: [画面.会計期間]の1日
N55: and | P55: [一般仕訳入力.日付(AccountingDate)] | AH55: <= | AJ55: [画面.会計期間]の末日)
N56: ※未決済データを抽出するための条件
N57: and | P57: ([一般仕訳入力.トランザクション タイプ(JournalCategory)] | AH57: = | AJ57: 【LedgerTransType::Payment(15:支払)】
N58: and | P58: [一般仕訳入力.文書(DocumentNumber)] | AH58: = | AJ58: "DZ"(得意先入金)
...

Sheet 画面レイアウト
A1: 基本設計書 | F1: =変更履歴!F1 -> システム名 | Q1: =変更履歴!Q1 -> 機能分類 | W1: =変更履歴!W1 -> 機能ＩＤ | AE1: =変更履歴!AE1 -> 機能名称 | AT1: =変更履歴!AT1 -> 日付 | BB1: =変更履歴!BB1 -> 更新者
F2: =変更履歴!F2 -> Dynamics365 for Finance and Operations | Q2: =変更履歴!Q2 -> 債権・債務 | W2: =変更履歴!W2 -> FO-087 | AE2: =変更履歴!AE2 -> 入金データ連携 | AT2: =変更履歴!AT2 -> 作成 | AV2: =変更履歴!AV2 -> 45492 | BB2: =変更履歴!BB2 -> JBS石岡
AT3: =変更履歴!AT3 -> 更新 | AV3: =変更履歴!AV3 -> 45624 | BB3: =変更履歴!BB3 -> JBS加藤
A5: パス | J5: [売掛金管理] > [定期処理] > [入金データ連携]
A6: フォーム名 | J6: Class/SJ_ARCashApplicationOutput
A8: タブ名 | J8: パラメータータブ

Sheet 画面項目説明
A1: 基本設計書 | F1: =変更履歴!F1 -> システム名 | Q1: =変更履歴!Q1 -> 機能分類 | W1: =変更履歴!W1 -> 機能ＩＤ | AE1: =変更履歴!AE1 -> 機能名称 | AT1: =変更履歴!AT1 -> 日付 | BB1: =変更履歴!BB1 -> 更新者
F2: =変更履歴!F2 -> Dynamics365 for Finance and Operations | Q2: =変更履歴!Q2 -> 債権・債務 | W2: =変更履歴!W2 -> FO-087 | AE2: =変更履歴!AE2 -> 入金データ連携 | AT2: =変更履歴!AT2 -> 作成 | AV2: =変更履歴!AV2 -> 45492 | BB2: =変更履歴!BB2 -> JBS石岡
AT3: =変更履歴!AT3 -> 更新 | AV3: =変更履歴!AV3 -> 45624 | BB3: =変更履歴!BB3 -> JBS加藤
A5: コントロール | H5: 項目名 | Q5: 種類 | U5: 入力 | W5: 必須 | Y5: 項目説明（概要） | BB5: 備考
A6: タイトル | Q6: タイトル | U6: × | W6: × | Y6: ＜タイトル＞
Y7: ・Caption：入金データ連携
A9: ボディ
E11: パラメータータブ
H12: 会計年度 | Q12: ListBox | U12: 〇 | W12: 〇 | Y12: ＜入力内容＞
Y13: 出力対象とする会計年度を指定
Y15: ＜初期値＞
Y16: システム日付が該当する[会計暦年.名前]
Y18: ＜ルックアップ＞
Y19: 標準の会計年度のルックアップを使用
Y20: ※「補足説明(画面項目イメージ)」を参照
Y22: ＜チェック内容＞
Y23: ルックアップと同じ
Y24: ※標準EDT：FiscalYearNameにて実装
H26: 会計期間 | Q26: コンボボックス | U26: 〇 | W26: 〇 | Y26: ＜入力内容＞
Y27: 出力対象とする会計期間(月)を指定
Y29: ＜初期値＞
Y30: システム日付(MM)
Y32: ＜ルックアップ＞
Y33: 標準の月のコンボボックスを使用（標準BaseEnum：FiscalPeriodMonthを使用）
Y34: 「1」
Y35: 「2」
Y36: 「3」
Y37: 「4」
Y38: 「5」
Y39: 「6」
Y40: 「7」
... Y45: 「12」 から選択
E47: ボタングループ
H48: OK | Q48: ボタン | U48: 〇 | W48: × | Y48: ＜後処理＞
Y49: イベント説明 「2.OKボタン押下時」を参照
H51: キャンセル | Q51: ボタン | U51: 〇 | W51: × | Y51: ＜後処理＞
Y52: 画面を閉じる（D365FO標準処理）
H54: 顧客 | Q54: ListBox | U54: 〇 | W54: 〇 | Y54: ＜入力内容＞
Y55: 財務分析コード.Customer(顧客)より選択
Y57: ＜ルックアップ＞
...

Sheet ファイルレイアウト(区切り)
A1: 基本設計書 | F1: =変更履歴!F1 -> システム名 | Q1: =変更履歴!Q1 -> 機能分類 | W1: =変更履歴!W1 -> 機能ＩＤ | AE1: =変更履歴!AE1 -> 機能名称 | AT1: =変更履歴!AT1 -> 日付 | BB1: =変更履歴!BB1 -> 更新者
F2: =変更履歴!F2 -> Dynamics365 for Finance and Operations | Q2: =変更履歴!Q2 -> 債権・債務 | W2: =変更履歴!W2 -> FO-087 | AE2: =変更履歴!AE2 -> 入金データ連携 | AT2: =変更履歴!AT2 -> 作成 | AV2: =変更履歴!AV2 -> 45492 | BB2: =変更履歴!BB2 -> JBS石岡
AT3: =変更履歴!AT3 -> 更新 | AV3: =変更履歴!AV3 -> 45624 | BB3: =変更履歴!BB3 -> JBS加藤
A5: 文字コード：UTF-8 | Q5: ファイル名称：TO_IncomingPayment.csv
A6: 区切り文字：コンマ | Q6: 文字列：囲い文字無し
A7: 改行コード：CRLF | Q7: ソート：伝票番号、転記日付 | AT7: タイトル行：なし
A8: No. | C8: フィールド名 | Q8: 説明 | AT8: 属性 | AX8: 桁数 | AZ8: 備考
A9: =ROW()-8 -> 1 | C9: 会社コード | Q9: ログインしている会社コード | AT9: STRING | AX9: 4
A10: =ROW()-8 -> 2 | C10: 顧客 | Q10: [一般仕訳帳勘定項目.勘定科目(LedgerDimension)]の顧客 | AT10: STRING | AX10: 20
A11: =ROW()-8 -> 3 | C11: 会計年度 | Q11: [画面.会計年度] | AT11: STRING | AX11: 4
A12: =ROW()-8 -> 4 | C12: 伝票番号 | Q12: [一般仕訳入力.伝票(SubledgerVoucher)] | AT12: STRING | AX12: 20
A13: =ROW()-8 -> 5 | C13: 会計期間 | Q13: [画面.会計期間] | AT13: ENUM | AX13: ー
A14: =ROW()-8 -> 6 | C14: 借方/貸方フラグ | Q14: ■[一般仕訳帳勘定項目.貸方]=「いいえ」の場合 固定値「借方」 ■[一般仕訳帳勘定項目.貸方]=「はい」の場合 固定値「貸方」 | AT14: ENUM | AX14: ー
A15: =ROW()-8 -> 7 | C15: 主勘定 | Q15: [一般仕訳帳勘定項目.主勘定(MainAccount)]に紐づく[主勘定.主勘定(MainAccountId)] | AT15: STRING | AX15: 20
A16: =ROW()-8 -> 8 | C16: 金額 | Q16: [一般仕訳帳勘定項目.金額(AccountingCurrencyAmount)] | AT16: REAL | AX16: ー
A17: =ROW()-8 -> 9 | C17: 転記日付 | Q17: [一般仕訳入力.日付(AccountingDate)] | AT17: DATE | AX17: ー | AZ17: YYYYMMDD
A18: =ROW()-8 -> 10 | C18: 明細テキスト | Q18: [一般仕訳帳勘定項目.説明(Text)] | AT18: STRING | AX18: 60

Sheet テーブル出力仕様(インターフェース件数管理)
A1: 基本設計書 | F1: =変更履歴!F1 -> システム名 | Q1: =変更履歴!Q1 -> 機能分類 | W1: =変更履歴!W1 -> 機能ＩＤ | AE1: =変更履歴!AE1 -> 機能名称 | AT1: =変更履歴!AT1 -> 日付 | BB1: =変更履歴!BB1 -> 更新者
F2: =変更履歴!F2 -> Dynamics365 for Finance and Operations | Q2: =変更履歴!Q2 -> 債権・債務 | W2: =変更履歴!W2 -> FO-087 | AE2: =変更履歴!AE2 -> 入金データ連携 | AT2: =変更履歴!AT2 -> 作成 | AV2: =変更履歴!AV2 -> 45492 | BB2: =変更履歴!BB2 -> JBS石岡
AT3: =変更履歴!AT3 -> 更新 | AV3: =変更履歴!AV3 -> 45624 | BB3: =変更履歴!BB3 -> JBS加藤
A5: テーブル名 | N5: SJ_InterfaceNumberManagement
A6: ラベル | N6: インターフェース件数管理
A7: 拡張名 | N7: ー
A8: No. | C8: 論理名 | M8: 物理名 | W8: 説明 | AZ8: 備考
A9: =ROW()-8 -> 1 | C9: 会社 | M9: CompanyId | W9: ログインしている法人
A10: =ROW()-8 -> 2 | C10: バッチ ジョブID | M10: BatchJobId | W10: ""(ブランク)
A11: =ROW()-8 -> 3 | C11: 機能ID | M11: FunctionId | W11: 固定値「FO-087」
A12: =ROW()-8 -> 4 | C12: 処理名 | M12: ProcessingName | W12: 固定値「入金データ連携」
A13: =ROW()-8 -> 5 | C13: 処理開始日時 | M13: RunFromDateTime | W13: 処理開始時に取得したシステム日時(YYYY/MM/DD hh:mm:ss)
A14: =ROW()-8 -> 6 | C14: 処理終了日時 | M14: RunToDateTime | W14: 処理終了時に取得したシステム日時(YYYY/MM/DD hh:mm:ss)
A15: =ROW()-8 -> 7 | C15: 明細件数 | M15: LineNumber | W15: 出力対象となる行数
A16: =ROW()-8 -> 8 | C16: ファイル名 | M16: FileName | W16: 出力されたファイル名
A17: =ROW()-8 -> 9
A18: =ROW()-8 -> 10

Sheet 補足説明(画面マッピング)
A1: 基本設計書 | F1: =変更履歴!F1 -> システム名 | Q1: =変更履歴!Q1 -> 機能分類 | W1: =変更履歴!W1 -> 機能ＩＤ | AE1: =変更履歴!AE1 -> 機能名称 | AT1: =変更履歴!AT1 -> 日付 | BB1: =変更履歴!BB1 -> 更新者
F2: =変更履歴!F2 -> Dynamics365 for Finance and Operations | Q2: =変更履歴!Q2 -> 債権・債務 | W2: =変更履歴!W2 -> FO-087 | AE2: =変更履歴!AE2 -> 入金データ連携 | AT2: =変更履歴!AT2 -> 作成 | AV2: =変更履歴!AV2 -> 45492 | BB2: =変更履歴!BB2 -> JBS石岡
AT3: =変更履歴!AT3 -> 更新 | AV3: =変更履歴!AV3 -> 45624 | BB3: =変更履歴!BB3 -> JBS加藤
A5: 補足
B7: ■伝票トランザクション

Sheet 補足説明(機能関連図)
A1: 基本設計書 | F1: =変更履歴!F1 -> システム名 | Q1: =変更履歴!Q1 -> 機能分類 | W1: =変更履歴!W1 -> 機能ＩＤ | AE1: =変更履歴!AE1 -> 機能名称 | AT1: =変更履歴!AT1 -> 日付 | BB1: =変更履歴!BB1 -> 更新者
F2: =変更履歴!F2 -> Dynamics365 for Finance and Operations | Q2: =変更履歴!Q2 -> 債権・債務 | W2: =変更履歴!W2 -> FO-087 | AE2: =変更履歴!AE2 -> 入金データ連携 | AT2: =変更履歴!AT2 -> 作成 | AV2: =変更履歴!AV2 -> 45492 | BB2: =変更履歴!BB2 -> JBS石岡
AT3: =変更履歴!AT3 -> 更新 | AV3: =変更履歴!AV3 -> 45624 | BB3: =変更履歴!BB3 -> JBS加藤
A5: 補足
B8: ■機能関連図

Sheet 補足説明(汎用パラメータ)
A1: 基本設計書 | F1: =変更履歴!F1 -> システム名 | Q1: =変更履歴!Q1 -> 機能分類 | W1: =変更履歴!W1 -> 機能ＩＤ | AE1: =変更履歴!AE1 -> 機能名称 | AT1: =変更履歴!AT1 -> 日付 | BB1: =変更履歴!BB1 -> 更新者
F2: =変更履歴!F2 -> Dynamics365 for Finance and Operations | Q2: =変更履歴!Q2 -> 債権・債務 | W2: =変更履歴!W2 -> FO-087 | AE2: =変更履歴!AE2 -> 入金データ連携 | AT2: =変更履歴!AT2 -> 作成 | AV2: =変更履歴!AV2 -> 45492 | BB2: =変更履歴!BB2 -> JBS石岡
AT3: =変更履歴!AT3 -> 更新 | AV3: =変更履歴!AV3 -> 45624 | BB3: =変更履歴!BB3 -> JBS加藤
A5: 補足
B7: ■汎用パラメータについて
C8: 事前に本機能で使用する下記汎用パラメータを設定する。
C10: 機能ID(FeatureId) | J10: 項目ID(ItemId) | P10: Key(Key) | V10: 値(Value) | AF10: 説明(Description)
C11: FO-081 | J11: 001 | P11: 1 | V11: 108,121,211 | AF11: 連携対象外となる固定資産グループ

Sheet 補足説明(画面項目イメージ)
A1: 基本設計書 | F1: =変更履歴!F1 -> システム名 | Q1: =変更履歴!Q1 -> 機能分類 | W1: =変更履歴!W1 -> 機能ＩＤ | AE1: =変更履歴!AE1 -> 機能名称 | AT1: =変更履歴!AT1 -> 日付 | BB1: =変更履歴!BB1 -> 更新者
F2: =変更履歴!F2 -> Dynamics365 for Finance and Operations | Q2: =変更履歴!Q2 -> 債権・債務 | W2: =変更履歴!W2 -> FO-087 | AE2: =変更履歴!AE2 -> 入金データ連携 | AT2: =変更履歴!AT2 -> 作成 | AV2: =変更履歴!AV2 -> 45492 | BB2: =変更履歴!BB2 -> JBS石岡
AT3: =変更履歴!AT3 -> 更新 | AV3: =変更履歴!AV3 -> 45624 | BB3: =変更履歴!BB3 -> JBS加藤
A5: 補足
B7: ■画面項目イメージ
C8: ログインしている法人に紐づく[元帳.会計カレンダー]として登録されているデータが表示される
C10: ＜元帳＞ | AF10: ＜会計年度ルックアップイメージ＞
C32: ＜参考ソースコード＞

Sheet レビュー指摘事項
A1: 基本設計書 | F1: =変更履歴!F1 -> システム名 | Q1: =変更履歴!Q1 -> 機能分類 | W1: =変更履歴!W1 -> 機能ＩＤ | AE1: =変更履歴!AE1 -> 機能名称 | AT1: =変更履歴!AT1 -> 日付 | BB1: =変更履歴!BB1 -> 更新者
F2: =変更履歴!F2 -> Dynamics365 for Finance and Operations | Q2: =変更履歴!Q2 -> 債権・債務 | W2: =変更履歴!W2 -> FO-087 | AE2: =変更履歴!AE2 -> 入金データ連携 | AT2: =変更履歴!AT2 -> 作成 | AV2: =変更履歴!AV2 -> 45492 | BB2: =変更履歴!BB2 -> JBS石岡
AT3: =変更履歴!AT3 -> 更新 | AV3: =変更履歴!AV3 -> 45624 | BB3: =変更履歴!BB3 -> JBS加藤
A5: No. | C5: レビュー事項 | Q5: 対応内容 | AF5: 指摘日 | AK5: 指摘者 | AP5: 対応日 | AU5: 対応者 | AZ5: 確認日 | BE5: 確認者
A6: =ROW()-5 -> 1 | C6: 販売管理システム(SLJ販売システム)刷新PJの状況次第では本機能が取下げになる可能性がある。 | Q6: 基本設計時点では現行仕様をもとに設計を進める。 ※シート「補足説明(機能関連図)」に追記 | AF6: 45506 | AK6: サンスター佐保 | AP6: 45506 | AU6: JBS石岡 | AZ6: 45509 | BE6: サンスター佐保
A7: =ROW()-5 -> 2 | C7: 項目の名称（会計年度、会計期間）を統一いただきたい。 | Q7: 左記の通りに修正。 シート：「画面レイアウト」「画面項目説明」「ファイルレイアウト(区切り)」 ※他IF機能の項目名については、修正対応後に各設計書のシート「レビュー指摘事項」にその旨を記載予定。 | AF7: 45506 | AK7: サンスター佐保 | AP7: 45506 | AU7: JBS石岡 | AZ7: 45509 | BE7: サンスター佐保
A8: =ROW()-5 -> 3 | C8: [インターフェース件数管理]テーブルの管理対象はAzure Filesを介した自動連携のIF機能のみとする。 | Q8: 左記の通りに修正。 シート：「DFD」 ※他IF機能の項目名については、修正対応後に各設計書のシート「レビュー指摘事項」にその旨を記載予定。 | AF8: 45506 | AK8: サンスター佐保 | AP8: 45506 | AU8: JBS石岡 | AZ8: 45509 | BE8: サンスター佐保
A9: =ROW()-5 -> 4
A10: =ROW()-5 -> 5
A11: =ROW()-5 -> 6
A12: =ROW()-5 -> 7
A13: =ROW()-5 -> 8
A14: =ROW()-5 -> 9
A15: =ROW()-5 -> 10
A16: =ROW()-5 -> 11
A17: =ROW()-5 -> 12
A18: =ROW()-5 -> 13
A19: =ROW()-5 -> 14
A20: =ROW()-5 -> 15
... A40: =ROW()-5 -> 35

Sheet オブジェクト一覧
A1: 詳細設計書 | F1: =変更履歴!F1 -> システム名 | Q1: =変更履歴!Q1 -> 機能分類 | W1: =変更履歴!W1 -> 機能ＩＤ | AE1: =変更履歴!AE1 -> 機能名称 | AT1: =変更履歴!AT1 -> 日付 | BB1: =変更履歴!BB1 -> 更新者
F2: =変更履歴!F2 -> Dynamics365 for Finance and Operations | Q2: =変更履歴!Q2 -> 債権・債務 | W2: =変更履歴!W2 -> FO-087 | AE2: =変更履歴!AE2 -> 入金データ連携 | AT2: =変更履歴!AT2 -> 作成 | AV2: =変更履歴!AV2 -> 45492 | BB2: =変更履歴!BB2 -> JBS石岡
AT3: =変更履歴!AT3 -> 更新 | AV3: =変更履歴!AV3 -> 45624 | BB3: =変更履歴!BB3 -> JBS加藤
A5: No. | C5: オブジェクト名 | S5: 属性 | AA5: 概要 | BD5: 備考
A6: =ROW()-5 -> 1
A7: =ROW()-5 -> 2
A8: =ROW()-5 -> 3
A9: =ROW()-5 -> 4
A10: =ROW()-5 -> 5
A11: =ROW()-5 -> 6
A12: =ROW()-5 -> 7
A13: =ROW()-5 -> 8
A14: =ROW()-5 -> 9
A15: =ROW()-5 -> 10
A16: =ROW()-5 -> 11
A17: =ROW()-5 -> 12
... A38: =ROW()-5 -> 33

Sheet プログラムフロー図
A1: 詳細設計書 | F1: =変更履歴!F1 -> システム名 | Q1: =変更履歴!Q1 -> 機能分類 | W1: =変更履歴!W1 -> 機能ＩＤ | AE1: =変更履歴!AE1 -> 機能名称 | AT1: =変更履歴!AT1 -> 日付 | BB1: =変更履歴!BB1 -> 更新者
F2: =変更履歴!F2 -> Dynamics365 for Finance and Operations | Q2: =変更履歴!Q2 -> 債権・債務 | W2: =変更履歴!W2 -> FO-087 | AE2: =変更履歴!AE2 -> 入金データ連携 | AT2: =変更履歴!AT2 -> 作成 | AV2: =変更履歴!AV2 -> 45492 | BB2: =変更履歴!BB2 -> JBS石岡
AT3: =変更履歴!AT3 -> 更新 | AV3: =変更履歴!AV3 -> 45624 | BB3: =変更履歴!BB3 -> JBS加藤
A5: プログラムフロー図
A29: 凡例
A30: 記号

Sheet マスタ
A2: IO | B2: 書式 | C2: 横位置 | D2: 縦位置 | E2: 折り返して全体を表示する | F2: 表示/非表示 Visivility | G2: テーブル種別 | H2: オブジェクト
A3: I/O | B3: テキスト | C3: 標準 | D3: 標準 | E3: 〇 | F3: 表示 | G3: テーブル | H3: Class
A4: I | B4: 日付 | C4: 中央詰 | D4: 中央詰 | E4: ー | F4: 非表示 | G4: ビュー | H4: Form Class
A5: O | B5: 数値 | C5: 左詰 | D5: 上詰 | H5: Table Class
C6: 右詰 | D6: 下詰 | H6: Macro
H7: Enum
H8: EDT
H9: Queries
H10: Data Entities
H11: Maps
H12: Forms
H13: Menus
H14: Menu Items(Display)
H15: Menu Items(Output)
H16: Menu Items(Action)
H17: Repoters
H18: Security Roles
... H20: Security Policies
