Workbook
Name io: マスタ!$A$3:$A$5
Name Visivility: マスタ!$F$3:$F$4
Name オブジェクト: マスタ!$H$7:$H$20
Name オブジェクト一覧: マスタ!$H$3:$H$20
Name テーブル種別: マスタ!$G$3:$G$4
Name マスタ: マスタ!$H$3:$H$20
Name 横位置: マスタ!$C$3:$C$6
Name 作成日: DATE(2000,3,21)
Name 縦位置: マスタ!$D$3:$D$6
Name 書式: マスタ!$B$3:$B$5
Name 折り返して全体を表示する: マスタ!$E$3:$E$4

Sheet 表紙
B3: サンスター株式会社 御中
B10: 会計システム刷新プロジェクト（LIBRA）
B14: =変更履歴!W2&"_詳細設計書_"&変更履歴!AE2 -> FO-088_詳細設計書_AzureFiles連携共通インターフェース
AA21: ＜機能ID>_＜画面名＞画面を入力
B22: ="第"&IF(COUNTA(変更履歴!BF5:BI10000)=1,"",INDIRECT("変更履歴!BF"&COUNTA(変更履歴!BF5:BI10000)+4))&"版" -> 第1.1版
B24: =IF(OR(COUNTA(変更履歴!A:E)=2),"",INDIRECT("変更履歴!A"&COUNTA(変更履歴!A:E)+3)) -> 45726
B26: 日本ビジネスシステムズ株式会社
F29: 作成者 | O29: JBS承認者 | V29: 基本設計部確認者
F30: =変更履歴!AV2 -> 45453 | N30: 45457 | V30: 45489
F31: =変更履歴!BB2 -> JBS石岡 | N31: JBS加藤 | V31: サンスター 佐保

Sheet 変更履歴
A1: 設計書 | F1: システム名 | Q1: 機能分類 | W1: 機能ＩＤ | AE1: 機能名称 | AT1: 日付 | BB1: 更新者
F2: Dynamics365 for Finance and Operations | Q2: システム共通 | W2: FO-088 | AE2: AzureFiles連携共通インターフェース | AT2: 作成 | AV2: =A6 -> 45453 | BB2: =AZ6 -> JBS石岡
AT3: 更新 | AV3: {=IF(OR(COUNTA(A:E)=2),"",INDIRECT("A"&COUNTA(A:E)+3))} -> 45726 | BB3: {=IF(COUNTA(AZ5:BE100018)=1,"",INDIRECT("AZ"&COUNTA(AZ5:BE100018)+4))} -> JBS石岡
AW4: （表紙同様値）
A5: 変更年月日 | F5: 変更箇所 | T5: 変更内容 | AZ5: 変更者 | BF5: 版数
A6: 45453 | F6: 新規作成 | T6: 新規作成 | AZ6: JBS石岡 | BF6: 1.0
A7: 45726 | F7: イベント説明 | T7: 囲み文字対応に伴う追記 | AZ7: JBS石岡 | BF7: 1.1

Sheet 処理概要
A1: 基本設計書 | F1: =変更履歴!F1 -> システム名 | Q1: =変更履歴!Q1 -> 機能分類 | W1: =変更履歴!W1 -> 機能ＩＤ | AE1: =変更履歴!AE1 -> 機能名称 | AT1: =変更履歴!AT1 -> 日付 | BB1: =変更履歴!BB1 -> 更新者
F2: =変更履歴!F2 -> Dynamics365 for Finance and Operations | Q2: =変更履歴!Q2 -> システム共通 | W2: =変更履歴!W2 -> FO-088 | AE2: =変更履歴!AE2 -> AzureFiles連携共通インターフェース | AT2: =変更履歴!AT2 -> 作成 | AV2: =変更履歴!AV2 -> 45453 | BB2: =変更履歴!BB2 -> JBS石岡
AT3: =変更履歴!AT3 -> 更新 | AV3: =変更履歴!AV3 -> 45726 | BB3: =変更履歴!BB3 -> JBS石岡
A5: 開発目的
B6: 1. | C6: 外部システムに対しての連携用のファイルを所定のAzure Filesに格納するため
B7: 2. | C7: 外部システムより連携されるD365向けのファイルを所定のAzure Filesから取込むため
A10: 前提条件
B11: 1. | C11: Azure Filesへ出力するファイルはテキスト形式のファイルを対象とする。
B12: 2. | C12: Azure Filesから取込するファイルはテキスト形式のファイルを対象とする。
B13: 3. | C13: Azure Filesマウント定義マスタ、ファイル取込定義マスタ、ファイル出力定義マスタはDIXF にてメンテナンスする。
B14: 4. | C14: 連携用のファイルのアーカイブ処理は受領側のシステムが実施する。
A18: 使用タイミング
B19: ※ | C19: 本機能を呼び出す、各機能側にて定義する。
A22: 開発内容
B23: 1. | C23: ファイルデータ出力処理
C24: ・本機能を呼び出す際に各機能から渡された引数を基に、Azure Filesへファイル出力する。
B26: 2. | C26: ファイルデータ取込処理
C27: ・本機能を呼び出す際に各機能から渡された引数を基に、Azure Filesに受領したファイルを読み取り、呼び出し元の各機能へ返す。
C28: ・受領したファイルのアーカイブ処理を実施する。
A31: 制限事項
B32: 1. | C32: 特になし

Sheet テーブル一覧
A1: 基本設計書 | F1: =変更履歴!F1 -> システム名 | Q1: =変更履歴!Q1 -> 機能分類 | W1: =変更履歴!W1 -> 機能ＩＤ | AE1: =変更履歴!AE1 -> 機能名称 | AT1: =変更履歴!AT1 -> 日付 | BB1: =変更履歴!BB1 -> 更新者
F2: =変更履歴!F2 -> Dynamics365 for Finance and Operations | Q2: =変更履歴!Q2 -> システム共通 | W2: =変更履歴!W2 -> FO-088 | AE2: =変更履歴!AE2 -> AzureFiles連携共通インターフェース | AT2: =変更履歴!AT2 -> 作成 | AV2: =変更履歴!AV2 -> 45453 | BB2: =変更履歴!BB2 -> JBS石岡
AT3: =変更履歴!AT3 -> 更新 | AV3: =変更履歴!AV3 -> 45726 | BB3: =変更履歴!BB3 -> JBS石岡
A5: No. | C5: 種別 | K5: 論理名 | AC5: 物理名 | AS5: I/O | AU5: 備考
A6: =ROW()-5 -> 1 | C6: テーブル | K6: AzureFilesマウント定義マスタ | AC6: SJ_AzureFilesDefineTable | AS6: I | AU6: 新規
A7: =ROW()-5 -> 2 | C7: テーブル | K7: ファイル取込定義マスタ | AC7: SJ_FileInDefineTable | AS7: I | AU7: 新規
A8: =ROW()-5 -> 3 | C8: テーブル | K8: ファイル出力定義マスタ | AC8: SJ_FileOutDefineTable | AS8: I | AU8: 新規
A9: =ROW()-5 -> 4
A10: =ROW()-5 -> 5
A11: =ROW()-5 -> 6
A12: =ROW()-5 -> 7
A13: =ROW()-5 -> 8
A14: =ROW()-5 -> 9
A15: =ROW()-5 -> 10
A16: =ROW()-5 -> 11
A17: =ROW()-5 -> 12
A18: =ROW()-5 -> 13
A19: =ROW()-5 -> 14
A20: =ROW()-5 -> 15
... A38: =ROW()-5 -> 33

Sheet DFD
A1: 基本設計書 | F1: =変更履歴!F1 -> システム名 | Q1: =変更履歴!Q1 -> 機能分類 | W1: =変更履歴!W1 -> 機能ＩＤ | AE1: =変更履歴!AE1 -> 機能名称 | AT1: =変更履歴!AT1 -> 日付 | BB1: =変更履歴!BB1 -> 更新者
F2: =変更履歴!F2 -> Dynamics365 for Finance and Operations | Q2: =変更履歴!Q2 -> システム共通 | W2: =変更履歴!W2 -> FO-088 | AE2: =変更履歴!AE2 -> AzureFiles連携共通インターフェース | AT2: =変更履歴!AT2 -> 作成 | AV2: =変更履歴!AV2 -> 45453 | BB2: =変更履歴!BB2 -> JBS石岡
AT3: =変更履歴!AT3 -> 更新 | AV3: =変更履歴!AV3 -> 45726 | BB3: =変更履歴!BB3 -> JBS石岡
A5: イベント | O5: 機能 | AN5: DB | BA5: Azure Files
A89: 凡例
A90: 記号
AL94: ※DBが複数ある場合は複数DBをまとめるために使用

Sheet イベント説明
A1: 基本設計書 | F1: =変更履歴!F1 -> システム名 | Q1: =変更履歴!Q1 -> 機能分類 | W1: =変更履歴!W1 -> 機能ＩＤ | AE1: =変更履歴!AE1 -> 機能名称 | AT1: =変更履歴!AT1 -> 日付 | BB1: =変更履歴!BB1 -> 更新者
F2: =変更履歴!F2 -> Dynamics365 for Finance and Operations | Q2: =変更履歴!Q2 -> システム共通 | W2: =変更履歴!W2 -> FO-088 | AE2: =変更履歴!AE2 -> AzureFiles連携共通インターフェース | AT2: =変更履歴!AT2 -> 作成 | AV2: =変更履歴!AV2 -> 45453 | BB2: =変更履歴!BB2 -> JBS石岡
AT3: =変更履歴!AT3 -> 更新 | AV3: =変更履歴!AV3 -> 45726 | BB3: =変更履歴!BB3 -> JBS石岡
A5: No. | C5: イベント名 | I5: 処理内容 | AO5: 種別 | AR5: メッセージ | BF5: ID
A6: 1. | C6: ファイル出力処理
J7: 対象モジュール： | O7: Classes/SJ_AzureFilesUtils
J8: 対象メソッド： | O8: outPutTextFile()
J9: 引数1： | O9: ファイル出力機能ID（SJ_FileOutFunctionId） | AE9: ※必須
J10: 引数2： | O10: コンテナ（container [[ファイル内容]]） | AE10: ※必須
J11: 引数3： | O11: ファイル名（String） | AE11: ※デフォルト：""（ブランク）
J12: 引数4： | O12: 起動回（SJ_RunTiming） | AE12: ※デフォルト：【Once:1回目】
J13: 戻り値： | O13: 結果 (Boolean True：正常終了／False：異常終了)
J16: 1-1. | L16: 引数チェック
K18: 引数を条件に下記の対象テーブルを取得する。
L20: 対象テーブル： | Q20: [ファイル出力定義マスタ]
Q21: [AzureFilesマウント定義マスタ] | AA21: Outer
L23: 結合条件： | Q23: [ファイル出力定義マスタ.共有コンテナID]
Z24: = | AA24: [AzureFilesマウント定義マスタ.共有コンテナID]
L26: 検索条件： | Q26: [ファイル出力定義マスタ.ファイル出力機能ID] | AD26: ＝ | AF26: 引数1.ファイル出力機能ID
Q27: [ファイル出力定義マスタ.起動回] | AD27: ＝ | AF27: 引数4.起動タイミング
K30: 取得できない場合、エラーメッセージを表示して処理を終了する。（戻り値:false） | AO30: 情報ログ | AR30: %1の設定がされていません。%2を確認してください。%3：%4 | BF30: SJ00041
AO31: warning
AR33: %1："ファイル出力" | BF33: SJ00045
AR34: %2："ファイル出力定義マスタ" | BF34: SJ00039
AR35: ％3："ファイル出力機能ID" | BF35: SJ00046
AR36: %4：[引数2.ファイル出力機能ID]
J39: 1-2. | L39: Azure Files認証
K41: [AzureFilesマウント定義マスタ.共有ルートパス]にアクセス可能の場合は手順[1-3]へ。
K43: netUseコマンドを使用し、AzureFilesのRootディレクトリをネット作業ドライブとしてマウントする。
K44: すでにマウント済の場合は処理を行わない。
M46: デバイス： | Q46: [AzureFilesマウント定義マスタ.共有ルートパス]
M47: ユーザー： | Q47: [AzureFilesマウント定義マスタ.共有パス接続ユーザーID]
M48: パスワード： | Q48: [AzureFilesマウント定義マスタ.共有パス接続パスワード]
K50: エラーが発生した場合、エラーメッセージを表示して処理を終了する。（戻り値:false） | AO50: 情報ログ | AR50: Azure Files認証に失敗しました。%1を確認してください。%2：%3 | BF50: SJ00042
AO51: warning
AR53: %1："AzureFilesマウント定義マスタ" | BF53: SJ00037
AR54: %2："共有コンテナ" | BF54: SJ00047
AR55: %3：[ファイル出力定義マスタ.共有コンテナID]
J58: 1-3. | L58: フォルダ存在チェック
K60: 本処理で使用する各フォルダが存在するかチェックする。
...

Sheet 補足説明
A1: 基本設計書 | F1: =変更履歴!F1 -> システム名 | Q1: =変更履歴!Q1 -> 機能分類 | W1: =変更履歴!W1 -> 機能ＩＤ | AE1: =変更履歴!AE1 -> 機能名称 | AT1: =変更履歴!AT1 -> 日付 | BB1: =変更履歴!BB1 -> 更新者
F2: =変更履歴!F2 -> Dynamics365 for Finance and Operations | Q2: =変更履歴!Q2 -> システム共通 | W2: =変更履歴!W2 -> FO-088 | AE2: =変更履歴!AE2 -> AzureFiles連携共通インターフェース | AT2: =変更履歴!AT2 -> 作成 | AV2: =変更履歴!AV2 -> 45453 | BB2: =変更履歴!BB2 -> JBS石岡
AT3: =変更履歴!AT3 -> 更新 | AV3: =変更履歴!AV3 -> 45726 | BB3: =変更履歴!BB3 -> JBS石岡
A5: 補足
B7: ■処理イメージ
C9: → | D9: （黒線） | G9: ： | H9: D365機能の処理
C10: → | D10: （赤線） | G10: ： | H10: D365 AzureFiles連携共通IFの処理
C11: → | D11: （青線） | G11: ： | H11: D365外（外部システム）の処理
C13: 1. ファイルデータ出力（D365 → Azure Files → 外部システム）
D16: D365 | AH16: Azure Files
D17: 機能 | R17: AzureFiles連携共通IF | AH17: Work | AN17: Send | AT17: Archive | AZ17: Error
C55: 2. ファイルデータ取込（外部システム → Azure Files → D365）
D58: D365 | AH58: Azure Files
D59: 機能 | R59: AzureFiles連携共通IF | AH59: Work | AN59: Receive | AT59: Archive | AZ59: Error
B89: ■D365機能側で必要となる設計
C91: 1. ファイルデータ出力（D365 → Azure Files → 外部システム）
D93: [ファイル出力定義マスタ.ファイル出力機能ID] | T93: ※D365機能毎にファイル出力機能IDを登録
D94: [ファイル出力定義マスタ.起動回] | T94: ※ファイル出力機能ID内で処理を分ける場合に使用。通常【Once:1回目】とする。
D95: [ファイル出力定義マスタ.文字コード]
D96: [ファイル出力定義マスタ.ファイル名拡張子]
D97: [ファイル出力定義マスタ.固定ファイル名]
D98: [ファイル出力定義マスタ.上書き種別] | T98: ※Azure Filesに同一ファイルの存在を許可しない場合【NonUpdate:上書き禁止】とする。
C100: 2. ファイルデータ取込（外部システム → Azure Files → D365）
D102: [ファイル取込定義マスタ.ファイル取込機能ID] | T102: ※D365機能毎にファイル取込機能IDを登録
D103: [ファイル取込定義マスタ.起動回] | T103: ※ファイル取込機能ID内で処理を分ける場合に使用。通常【Once:1回目】とする。
D104: [ファイル取込定義マスタ.文字コード]
D105: [ファイル取込定義マスタ.ファイル名拡張子]
D106: [ファイル取込定義マスタ.固定ファイル名]
D107: [ファイル取込定義マスタ.読み込み種別] | T107: ※受領ファイルを必須とする場合に【NonError:ファイル存在必須】とする。
D108: [ファイル取込定義マスタ.読み込み開始行] | T108: ※受領ファイルに対し、ファイル内容を何行目から読み込みするかの設定。通常「1」(1行目)とする。

Sheet 画面レイアウト
A1: 基本設計書 | F1: =変更履歴!F1 -> システム名 | Q1: =変更履歴!Q1 -> 機能分類 | W1: =変更履歴!W1 -> 機能ＩＤ | AE1: =変更履歴!AE1 -> 機能名称 | AT1: =変更履歴!AT1 -> 日付 | BB1: =変更履歴!BB1 -> 更新者
F2: =変更履歴!F2 -> Dynamics365 for Finance and Operations | Q2: =変更履歴!Q2 -> システム共通 | W2: =変更履歴!W2 -> FO-088 | AE2: =変更履歴!AE2 -> AzureFiles連携共通インターフェース | AT2: =変更履歴!AT2 -> 作成 | AV2: =変更履歴!AV2 -> 45453 | BB2: =変更履歴!BB2 -> JBS石岡
AT3: =変更履歴!AT3 -> 更新 | AV3: =変更履歴!AV3 -> 45726 | BB3: =変更履歴!BB3 -> JBS石岡
A5: パス
A6: フォーム名
A8: タブ名

Sheet 画面項目説明
A1: 基本設計書 | F1: =変更履歴!F1 -> システム名 | Q1: =変更履歴!Q1 -> 機能分類 | W1: =変更履歴!W1 -> 機能ＩＤ | AE1: =変更履歴!AE1 -> 機能名称 | AT1: =変更履歴!AT1 -> 日付 | BB1: =変更履歴!BB1 -> 更新者
F2: =変更履歴!F2 -> Dynamics365 for Finance and Operations | Q2: =変更履歴!Q2 -> システム共通 | W2: =変更履歴!W2 -> FO-088 | AE2: =変更履歴!AE2 -> AzureFiles連携共通インターフェース | AT2: =変更履歴!AT2 -> 作成 | AV2: =変更履歴!AV2 -> 45453 | BB2: =変更履歴!BB2 -> JBS石岡
AT3: =変更履歴!AT3 -> 更新 | AV3: =変更履歴!AV3 -> 45726 | BB3: =変更履歴!BB3 -> JBS石岡
A5: コントロール | H5: 項目名 | Q5: 種類 | U5: 入力 | W5: 必須 | Y5: 項目説明（概要） | BB5: 備考

Sheet 帳票レイアウト
A1: 基本設計書 | F1: =変更履歴!F1 -> システム名 | Q1: =変更履歴!Q1 -> 機能分類 | W1: =変更履歴!W1 -> 機能ＩＤ | AE1: =変更履歴!AE1 -> 機能名称 | AT1: =変更履歴!AT1 -> 日付 | BB1: =変更履歴!BB1 -> 更新者
F2: =変更履歴!F2 -> Dynamics365 for Finance and Operations | Q2: =変更履歴!Q2 -> システム共通 | W2: =変更履歴!W2 -> FO-088 | AE2: =変更履歴!AE2 -> AzureFiles連携共通インターフェース | AT2: =変更履歴!AT2 -> 作成 | AV2: =変更履歴!AV2 -> 45453 | BB2: =変更履歴!BB2 -> JBS石岡
AT3: =変更履歴!AT3 -> 更新 | AV3: =変更履歴!AV3 -> 45726 | BB3: =変更履歴!BB3 -> JBS石岡
A5: レイアウト | AY5: 備考
A6: 帳票タイトル： | AI6: 帳票タイプ：
A7: 用紙サイズ： | L7: 用紙の向き： | X7: 自動サイズ調整： | AI7: フォント：
A8: 余白(cm) | F8: 左： | J8: 右： | N8: 上： | R8: 下： | AI8: テーブルソート設定：

Sheet 帳票出力仕様
A1: 基本設計書 | F1: =変更履歴!F1 -> システム名 | Q1: =変更履歴!Q1 -> 機能分類 | W1: =変更履歴!W1 -> 機能ＩＤ | AE1: =変更履歴!AE1 -> 機能名称 | AT1: =変更履歴!AT1 -> 日付 | BB1: =変更履歴!BB1 -> 更新者
F2: =変更履歴!F2 -> Dynamics365 for Finance and Operations | Q2: =変更履歴!Q2 -> システム共通 | W2: =変更履歴!W2 -> FO-088 | AE2: =変更履歴!AE2 -> AzureFiles連携共通インターフェース | AT2: =変更履歴!AT2 -> 作成 | AV2: =変更履歴!AV2 -> 45453 | BB2: =変更履歴!BB2 -> JBS石岡
AT3: =変更履歴!AT3 -> 更新 | AV3: =変更履歴!AV3 -> 45726 | BB3: =変更履歴!BB3 -> JBS石岡
S5: 表示形式 | AB5: 配置
A6: ヘッダー/フッター/明細 | H6: No. | J6: 項目名 | S6: 書式 | V6: フォーマット | AB6: 横位置 | AE6: 縦位置 | AH6: サイズ | AK6: 最大項目長 （項目幅） | AO6: 出力値 | BL6: 備考 | CC6: 取得元テーブル | CO6: 取得元フィールド | DA6: 折り返して全体を 表示する | DG6: TmpTable | DT6: TmpTableフィールド
A8: ① ヘッダー | H8: =ROW()-7 -> 1 | DA8: ー
H9: =ROW()-7 -> 2 | DA9: ー
H10: =ROW()-7 -> 3 | DA10: ー
H11: =ROW()-7 -> 4 | DA11: ー
H12: =ROW()-7 -> 5 | DA12: ー
H13: =ROW()-7 -> 6 | DA13: ー
H14: =ROW()-7 -> 7 | DA14: ー
H15: =ROW()-7 -> 8 | DA15: ー
H16: =ROW()-7 -> 9 | DA16: ー
A17: ② 明細 | H17: =ROW()-7 -> 10 | DA17: ー
A18: （項目名） | H18: =ROW()-7 -> 11 | DA18: ー
H19: =ROW()-7 -> 12 | DA19: ー
H20: =ROW()-7 -> 13 | DA20: ー
H21: =ROW()-7 -> 14 | DA21: ー
H22: =ROW()-7 -> 15 | DA22: ー
H23: =ROW()-7 -> 16 | DA23: ー
H24: =ROW()-7 -> 17 | DA24: ー
H25: =ROW()-7 -> 18 | DA25: ー
H26: =ROW()-7 -> 19 | DA26: ー
H27: =ROW()-7 -> 20 | DA27: ー
H28: =ROW()-7 -> 21 | DA28: ー
H29: =ROW()-7 -> 22 | DA29: ー
H30: =ROW()-7 -> 23 | DA30: ー
A31: ②明細 | H31: =ROW()-7 -> 24 | DA31: ー
A32: （データ） | H32: =ROW()-7 -> 25 | DA32: ー
H33: =ROW()-7 -> 26 | DA33: ー
H34: =ROW()-7 -> 27 | DA34: ー
H35: =ROW()-7 -> 28 | DA35: ー
H36: =ROW()-7 -> 29 | DA36: ー
H37: =ROW()-7 -> 30 | DA37: ー
H38: =ROW()-7 -> 31 | DA38: ー
H39: =ROW()-7 -> 32 | DA39: ー
H40: =ROW()-7 -> 33 | DA40: ー
H41: =ROW()-7 -> 34 | DA41: ー
H42: =ROW()-7 -> 35 | DA42: ー
...

Sheet ファイルレイアウト
A1: 基本設計書 | F1: =変更履歴!F1 -> システム名 | Q1: =変更履歴!Q1 -> 機能分類 | W1: =変更履歴!W1 -> 機能ＩＤ | AE1: =変更履歴!AE1 -> 機能名称 | AT1: =変更履歴!AT1 -> 日付 | BB1: =変更履歴!BB1 -> 更新者
F2: =変更履歴!F2 -> Dynamics365 for Finance and Operations | Q2: =変更履歴!Q2 -> システム共通 | W2: =変更履歴!W2 -> FO-088 | AE2: =変更履歴!AE2 -> AzureFiles連携共通インターフェース | AT2: =変更履歴!AT2 -> 作成 | AV2: =変更履歴!AV2 -> 45453 | BB2: =変更履歴!BB2 -> JBS石岡
AT3: =変更履歴!AT3 -> 更新 | AV3: =変更履歴!AV3 -> 45726 | BB3: =変更履歴!BB3 -> JBS石岡
A5: 文字コード： | I5: ファイル名称：
A6: 区切り文字： | I6: 文字列：
A7: 改行コード： | I7: ソート： | AT7: タイトル行：
A8: No. | C8: フィールド名 | Q8: 説明 | AT8: 属性 | AX8: 桁数 | AZ8: 備考
A9: =ROW()-8 -> 1
A10: =ROW()-8 -> 2
A11: =ROW()-8 -> 3
A12: =ROW()-8 -> 4
A13: =ROW()-8 -> 5
A14: =ROW()-8 -> 6
A15: =ROW()-8 -> 7
A16: =ROW()-8 -> 8
A17: =ROW()-8 -> 9
A18: =ROW()-8 -> 10
A19: =ROW()-8 -> 11
A20: =ROW()-8 -> 12
... A38: =ROW()-8 -> 30

Sheet テーブル出力項目
A1: 基本設計書 | F1: =変更履歴!F1 -> システム名 | Q1: =変更履歴!Q1 -> 機能分類 | W1: =変更履歴!W1 -> 機能ＩＤ | AE1: =変更履歴!AE1 -> 機能名称 | AT1: =変更履歴!AT1 -> 日付 | BB1: =変更履歴!BB1 -> 更新者
F2: =変更履歴!F2 -> Dynamics365 for Finance and Operations | Q2: =変更履歴!Q2 -> システム共通 | W2: =変更履歴!W2 -> FO-088 | AE2: =変更履歴!AE2 -> AzureFiles連携共通インターフェース | AT2: =変更履歴!AT2 -> 作成 | AV2: =変更履歴!AV2 -> 45453 | BB2: =変更履歴!BB2 -> JBS石岡
AT3: =変更履歴!AT3 -> 更新 | AV3: =変更履歴!AV3 -> 45726 | BB3: =変更履歴!BB3 -> JBS石岡
A5: テーブル名
A6: ラベル
A7: 拡張名
A8: No. | C8: 論理名 | M8: 物理名 | W8: 説明 | AZ8: 備考
A9: =ROW()-8 -> 1
A10: =ROW()-8 -> 2
A11: =ROW()-8 -> 3
A12: =ROW()-8 -> 4
A13: =ROW()-8 -> 5
A14: =ROW()-8 -> 6
A15: =ROW()-8 -> 7
A16: =ROW()-8 -> 8
A17: =ROW()-8 -> 9
A18: =ROW()-8 -> 10
A19: =ROW()-8 -> 11
A20: =ROW()-8 -> 12
... A40: =ROW()-8 -> 32

Sheet レビュー指摘事項
A1: 基本設計書 | F1: =変更履歴!F1 -> システム名 | Q1: =変更履歴!Q1 -> 機能分類 | W1: =変更履歴!W1 -> 機能ＩＤ | AE1: =変更履歴!AE1 -> 機能名称 | AT1: =変更履歴!AT1 -> 日付 | BB1: =変更履歴!BB1 -> 更新者
F2: =変更履歴!F2 -> Dynamics365 for Finance and Operations | Q2: =変更履歴!Q2 -> システム共通 | W2: =変更履歴!W2 -> FO-088 | AE2: =変更履歴!AE2 -> AzureFiles連携共通インターフェース | AT2: =変更履歴!AT2 -> 作成 | AV2: =変更履歴!AV2 -> 45453 | BB2: =変更履歴!BB2 -> JBS石岡
AT3: =変更履歴!AT3 -> 更新 | AV3: =変更履歴!AV3 -> 45726 | BB3: =変更履歴!BB3 -> JBS石岡
A5: No. | C5: レビュー事項 | Q5: 対応内容 | AF5: 指摘日 | AK5: 指摘者 | AP5: 対応日 | AU5: 対応者 | AZ5: 確認日 | BE5: 確認者
A6: =ROW()-5 -> 1 | C6: この機能を手動実行する場合(再送、再取込など)、そのような実行イメージになるか、補足説明等に記載いただけますでしょうか。 (画面で実行、コマンドラインで引数指定など) | Q6: 本機能は各機能から受け取った情報をもとにAzure Filesへファイル出力する、もしくは、各機能から受け取った情報をもとにAzure Filesからファイル取込を行うための共通部品となるため、手動実行できる仕組みとなっておりません。 再送や再取込の際は、各機能側で手動実行いただく必要がございます。 | AF6: 45468 | AK6: サンスター佐保 | AP6: 45475 | AU6: JBS石岡 | AZ6: 45489 | BE6: サンスター佐保
A7: =ROW()-5 -> 2 | C7: 「イベント説明」の2-5-2 ファイル読み込みにて、エラーデータがある場合はどのように格納・判別されますでしょうか。 | Q7: 2-5-2 ファイル読み込みでは受領ファイルのデータをコンテナ(動的リスト)というオブジェクトを使用して、共通IFを呼び出した各機能へ受け渡す仕組みとなります。 データ不備などとは異なる理由で異常終了となった場合は、2-5-4 エラー処理として対象ファイルをWorkフォルダ→Errorフォルダへ移動するかたちとなります。 ※その後、各機能側の処理内で桁数や必須などの整合性チェックを行うかたちとなります。 | AF7: 45468 | AK7: サンスター佐保 | AP7: 45475 | AU7: JBS石岡 | AZ7: 45489 | BE7: サンスター佐保
A8: =ROW()-5 -> 3 | C8: 2-5-4のエラー処理における対象ファイルのErrorフォルダへの移動について、例えば取込ファイルに100件のデータが含まれており、99件は正常で1件のみエラーである場合、正常の99件は取込み、1件のみ取り込まないという仕様でしょうか。 また、上記のようなファイルの場合、Errorフォルダに格納されるファイルはError1件のみが含まれるファイルか、正常に取り込まれる99件も含めた100件全てが含まれるファイルのどちらでしょうか。 | Q8: 結論としましては、1件でもエラーとなる場合、Errorフォルダに格納されるファイルは100件すべてが含まれた状態(受領した当時)のものとなります。 共通IFにより、Azure Filesからファイル読込を行う際はファイルの中身についてはチェックせず、受領したものをそのまま保持する仕組みとなります。ファイル読込のタイミングでシステムエラー等により異常が発生した場合はErrorフォルダにファイルが格納されます。（この場合、FOには受領したデータは保持されず、Errorフォルダに対象ファイルのみ残る状態） ファイル読込後は、各機能で必須チェックや型・桁数チェックの実施(受領システム側でもデータチェックを行うか決めの問題ではありますが)とあわせて機能要件次第ではログテーブルのようなかたちで受領データをFOで保持する流れとなります。このタイミングで1件でもエラーが発生した場合、Archive→Errorフォルダへファイルが移動されます（FOで受領したファイルデータを保持しつつ、Errorファルダに対象ファイルが格納されている状態） | AF8: 45476 | AK8: サンスター佐保 | AP8: 45481 | AU8: JBS石岡 | AZ8: 45489 | BE8: サンスター佐保
A9: =ROW()-5 -> 4 | C9: No.3に関連して、取込ファイルの一部のみエラーである場合にも、その他の正常データを含むファイル全体がErrorフォルダに移動されると理解しましたが、データの取り込み(一部データのみエラーである場合にエラー分を除いて取り込むか、ファイル全体のデータを取り込まないか)についてはこのプログラムではなく個別の取込プログラムでコントロールするという理解で合っていますでしょうか。 | Q9: 本機能ではなく、各取込機能でコントロールするという点に関しましてはご認識の通りとなります。 機能要件次第ではありますが、基本的には一部データのみエラーがある場合には該当データを除外し正常データのみ取込む想定です。 | AF9: 45483 | AK9: サンスター佐保 | AP9: 45485 | AU9: JBS石岡 | AZ9: 45489 | BE9: サンスター佐保
A10: =ROW()-5 -> 5
A11: =ROW()-5 -> 6
A12: =ROW()-5 -> 7
A13: =ROW()-5 -> 8
A14: =ROW()-5 -> 9
A15: =ROW()-5 -> 10
A16: =ROW()-5 -> 11
A17: =ROW()-5 -> 12
A18: =ROW()-5 -> 13
A19: =ROW()-5 -> 14
A20: =ROW()-5 -> 15
A21: =ROW()-5 -> 16
... A40: =ROW()-5 -> 35

Sheet オブジェクト一覧
A1: 詳細設計書 | F1: =変更履歴!F1 -> システム名 | Q1: =変更履歴!Q1 -> 機能分類 | W1: =変更履歴!W1 -> 機能ＩＤ | AE1: =変更履歴!AE1 -> 機能名称 | AT1: =変更履歴!AT1 -> 日付 | BB1: =変更履歴!BB1 -> 更新者
F2: =変更履歴!F2 -> Dynamics365 for Finance and Operations | Q2: =変更履歴!Q2 -> システム共通 | W2: =変更履歴!W2 -> FO-088 | AE2: =変更履歴!AE2 -> AzureFiles連携共通インターフェース | AT2: =変更履歴!AT2 -> 作成 | AV2: =変更履歴!AV2 -> 45453 | BB2: =変更履歴!BB2 -> JBS石岡
AT3: =変更履歴!AT3 -> 更新 | AV3: =変更履歴!AV3 -> 45726 | BB3: =変更履歴!BB3 -> JBS石岡
A5: No. | C5: オブジェクト名 | S5: 属性 | AA5: 概要 | BD5: 備考
A6: =ROW()-5 -> 1 | C6: SJ_AzureFilesUtils | S6: Class | AA6: Azure Files連携における共通処理(ファイル出力/取込)
A7: =ROW()-5 -> 2 | C7: SJ_LoadTextFileValue | S7: Class | AA7: 呼出し元クラス側でファイル取込処理の戻り値(取込データやファイル名等)を取得するために使用
A8: =ROW()-5 -> 3
A9: =ROW()-5 -> 4
A10: =ROW()-5 -> 5
A11: =ROW()-5 -> 6
A12: =ROW()-5 -> 7
A13: =ROW()-5 -> 8
A14: =ROW()-5 -> 9
A15: =ROW()-5 -> 10
A16: =ROW()-5 -> 11
A17: =ROW()-5 -> 12
A18: =ROW()-5 -> 13
A19: =ROW()-5 -> 14
... A38: =ROW()-5 -> 33

Sheet プログラムフロー図
A1: 詳細設計書 | F1: =変更履歴!F1 -> システム名 | Q1: =変更履歴!Q1 -> 機能分類 | W1: =変更履歴!W1 -> 機能ＩＤ | AE1: =変更履歴!AE1 -> 機能名称 | AT1: =変更履歴!AT1 -> 日付 | BB1: =変更履歴!BB1 -> 更新者
F2: =変更履歴!F2 -> Dynamics365 for Finance and Operations | Q2: =変更履歴!Q2 -> システム共通 | W2: =変更履歴!W2 -> FO-088 | AE2: =変更履歴!AE2 -> AzureFiles連携共通インターフェース | AT2: =変更履歴!AT2 -> 作成 | AV2: =変更履歴!AV2 -> 45453 | BB2: =変更履歴!BB2 -> JBS石岡
AT3: =変更履歴!AT3 -> 更新 | AV3: =変更履歴!AV3 -> 45726 | BB3: =変更履歴!BB3 -> JBS石岡
A5: プログラムフロー図
B7: ■ファイル出力処理
B110: ■ファイル取込処理
V133: ■共通処理（Azure Files認証）へ
B256: ■共通処理（Azure Files認証）
A293: 凡例
A294: 記号

Sheet マスタ
A2: IO | B2: 書式 | C2: 横位置 | D2: 縦位置 | E2: 折り返して全体を表示する | F2: 表示/非表示 Visivility | G2: テーブル種別 | H2: オブジェクト
A3: I/O | B3: テキスト | C3: 標準 | D3: 標準 | E3: 〇 | F3: 表示 | G3: テーブル | H3: Class
A4: I | B4: 日付 | C4: 中央詰 | D4: 中央詰 | E4: ー | F4: 非表示 | G4: ビュー | H4: Form Class
A5: O | B5: 数値 | C5: 左詰 | D5: 上詰 | H5: Table Class
C6: 右詰 | D6: 下詰 | H6: Macro
H7: Enum
H8: EDT
H9: Queries
H10: Data Entities
H11: Maps
H12: Forms
H13: Menus
H14: Menu Items(Display)
H15: Menu Items(Output)
H16: Menu Items(Action)
H17: Repoters
H18: Security Roles
... H20: Security Policies
