Workbook
Name Page: #REF!
Name スコープ: マスタ!$B$18:$B$19
Name 開発: マスタ!$B$14:$B$15
Name 確認結果: マスタ!#REF!
Name 対象システム: マスタ!$B$8:$B$11
Name 優先度: マスタ!$B$2:$B$5
Name 要件区分: マスタ!#REF!

Sheet 要求事項
C1: 要求事項一覧
D2: ※１行には１要件としてください。複数要件がある場合は行を分けて記載お願いいたします。 | G2: ※追加 | K2: ※追加 | P2: ※追加
E3: 要求事項入力欄 | L3: 要求事項詳細内容確認 | N3: 要求事項内容整理 | T3: 確認欄 | V3: PMO記入欄 | Z3: 提案時
B4: 結合キー | D4: No. | E4: 要求事項 | F4: 現行業務 | G4: 業務要件回答表からの事前回答案_v1.0.xlsxより | H4: 要求者 | I4: 優先度 | J4: 対象部門 | K4: 確認先 | L4: 確認事項 | M4: 回答 | N4: 関連Req | O4: 対象システム | P4: ファイル名 | Q4: 対象業務フロー | R4: 開発 | S4: 実現案 | T4: スコープ | U4: 備考 | V4: 審査対象 | W4: コメント | X4: 列1 | Y4: 要求事項一覧 判定 | Z4: システム対応可否 | AA4: 会計システム標準機能以外の場合、実現方法詳細 | AB4: 列2 | AC4: 列3
A5: =テーブル1[[#This Row],[対象部門]]&テーブル1[[#This Row],[業務要件回答表からの事前回答案_v1.0.xlsxより]] -> 一般会計全般・決算1.1 | B5: 一般会計全般・決算1.1 | D5: Req001 | E5: 画面入力で仕訳伝票を登録できること (勘定科目を変更せず、仕訳の入力項目の修正のための振替伝票も起票可能であること) ⇒()内の記述は、登録ミスした仕訳伝票の訂正伝票の登録方法に関する記述 | F5: 仕訳伝票の登録機能 | G5: 1.1 | H5: サンスター | J5: 一般会計全般・決算 | K5: 決算G | O5: FO | Q5: 日次振伝処理 | R5: 不要 | S5: 一般仕訳帳入力で仕訳伝票の登録が可能 伝票テンプレート機能や定期伝票仕訳帳の機能あり。 登録ミスした伝票を「取消」ボタンで逆仕訳を作成する機能や、登録済伝票を呼び出して新規伝票として編集転記する機能などあり。 | T5: IN | X5: =テーブル1[[#This Row],[開発]]&テーブル1[[#This Row],[スコープ]] -> 不要IN | Y5: =IF(テーブル1[[#This Row],[列1]]="不要IN","標準",IF(テーブル1[[#This Row],[列1]]="不要OUT","スコープアウト",IF(テーブル1[[#This Row],[列1]]="必要IN","アドオン",IF(テーブル1[[#This Row],[列1]]="OUT","スコープアウト","")))) -> 標準 | Z5: =VLOOKUP($B5,Sheet1!$C$2:$L$315,9,) -> 会計システム標準機能 | AA5: =VLOOKUP($B5,Sheet1!$C$2:$L$315,10,) -> 0 | AB5: 標準 | AC5: =テーブル1[[#This Row],[要求事項一覧 判定]]=テーブル1[[#This Row],[列2]] -> TRUE
A6: =テーブル1[[#This Row],[対象部門]]&テーブル1[[#This Row],[業務要件回答表からの事前回答案_v1.0.xlsxより]] -> 一般会計全般・決算1.2 | B6: 一般会計全般・決算1.2 | D6: Req002 | E6: 多通貨で仕訳伝票が登録でき、入力通貨金額が報告通貨金額（邦貨）に換算した額も登録できること | F6: 多通貨の仕訳伝票の登録機能 | G6: 1.2 | H6: サンスター | J6: 一般会計全般・決算 | K6: 共通 | O6: FO | Q6: 日次振伝処理 | R6: 不要 | S6: 他通貨での伝票登録可能。仕訳トランザクションでは、入力通貨金額と報告通貨金額（邦貨）に換算した額を保持している。 | T6: IN | X6: =テーブル1[[#This Row],[開発]]&テーブル1[[#This Row],[スコープ]] -> 不要IN | Y6: =IF(テーブル1[[#This Row],[列1]]="不要IN","標準",IF(テーブル1[[#This Row],[列1]]="不要OUT","スコープアウト",IF(テーブル1[[#This Row],[列1]]="必要IN","アドオン",IF(テーブル1[[#This Row],[列1]]="OUT","スコープアウト","")))) -> 標準 | Z6: =VLOOKUP($B6,Sheet1!$C$2:$L$315,9,) -> 会計システム標準機能 | AA6: =VLOOKUP($B6,Sheet1!$C$2:$L$315,10,) -> 0 | AB6: 標準 | AC6: =テーブル1[[#This Row],[要求事項一覧 判定]]=テーブル1[[#This Row],[列2]] -> TRUE
A7: =テーブル1[[#This Row],[対象部門]]&テーブル1[[#This Row],[業務要件回答表からの事前回答案_v1.0.xlsxより]] -> 一般会計全般・決算1.3 | B7: 一般会計全般・決算1.3 | C7: ◎ | D7: Req003 | E7: Excelフォーマット（取引先、取引内容、部門、消費税区分、金額、伝票日付、相手科目等）のアップロード機能で仕訳作成できること ※機能通貨への換算、消費税明細計上(内税/外税)、為替差損益明細計上への対応、および相互通貨バランスチェック、最新データの取得が可能であること | F7: 仕訳アップロード機能で仕訳を作成する機能 | G7: 1.3 | H7: サンスター | J7: 一般会計全般・決算 | K7: 事務管理G | L7: 現在、SAPのEXCELバッチインプット機能は使用していますか？ | M7: 現状SAPのEXCELバッチ取込は使用していないため、新システムのやり方に合わせられるのではないか？ 大量の仕訳データの改善・検討については事務管理Gが検討（武市） | O7: FO | Q7: 日次振伝処理 | R7: 必要 | S7: ExcelアドインでExcelフォーマットでの伝票登録機能があるが、毎回仕訳帳画面からExcelフォーマットをダウンロードしてフォーマットにデータ貼り付けをして取り込むイメージのため、あらかじめ作成しておいたExcelをそのまま取り込むイメージとは少し異なる。財務分析コードの入力欄が個別にはなく、科目欄に科目コードとハイフン(-)つなぎで入力する方式のため注意が必要 ※会社間立替金で使用する想定。会社間も考慮する必要あり | T7: IN | V7: 〇 | W7: 標準のExcelアドインでのオペレーションでどれだけ不便があるか、実務でのシチュエーションと照らし合わせて要確認。 | X7: =テーブル1[[#This Row],[開発]]&テーブル1[[#This Row],[スコープ]] -> 必要IN | Y7: =IF(テーブル1[[#This Row],[列1]]="不要IN","標準",IF(テーブル1[[#This Row],[列1]]="不要OUT","スコープアウト",IF(テーブル1[[#This Row],[列1]]="必要IN","アドオン",IF(テーブル1[[#This Row],[列1]]="OUT","スコープアウト","")))) -> アドオン | Z7: =VLOOKUP($B7,Sheet1!$C$2:$L$315,9,) -> 会計システム標準機能 | AA7: =VLOOKUP($B7,Sheet1!$C$2:$L$315,10,) -> 0 | AB7: 標準 | AC7: =テーブル1[[#This Row],[要求事項一覧 判定]]=テーブル1[[#This Row],[列2]] -> FALSE
A8: =テーブル1[[#This Row],[対象部門]]&テーブル1[[#This Row],[業務要件回答表からの事前回答案_v1.0.xlsxより]] -> 一般会計全般・決算1.4 | B8: 一般会計全般・決算1.4 | C8: ◎ | D8: Req004 | E8: 勘定科目別に入力条件が設定でき、条件外の場合はエラーアラートが表示できること ⇒例えば経費科目であれば経費発生部門(原価センタ)の入力が必須になるなど、勘定科目の種類に応じて入力の必須・任意(入力フィールドの表示・非表示)をコントロールする機能のイメージです。(SAPでは項目ステータスと呼ばれる機能に該当します。) | F8: 勘定科目別に入力条件を指定する機能 | G8: 1.4 | H8: サンスター | J8: 一般会計全般・決算 | K8: 決算G | O8: FO | Q8: 日次振伝処理 | R8: 不要 | S8: 勘定構造のコンフィグレーションという機能で、勘定科目別に入力させる財務分析コードを制御することが可能。 | T8: IN | X8: =テーブル1[[#This Row],[開発]]&テーブル1[[#This Row],[スコープ]] -> 不要IN | Y8: =IF(テーブル1[[#This Row],[列1]]="不要IN","標準",IF(テーブル1[[#This Row],[列1]]="不要OUT","スコープアウト",IF(テーブル1[[#This Row],[列1]]="必要IN","アドオン",IF(テーブル1[[#This Row],[列1]]="OUT","スコープアウト","")))) -> 標準 | Z8: =VLOOKUP($B8,Sheet1!$C$2:$L$315,9,) -> 会計システム標準機能 | AA8: =VLOOKUP($B8,Sheet1!$C$2:$L$315,10,) -> 0 | AB8: 標準 | AC8: =テーブル1[[#This Row],[要求事項一覧 判定]]=テーブル1[[#This Row],[列2]] -> TRUE
A9: =テーブル1[[#This Row],[対象部門]]&テーブル1[[#This Row],[業務要件回答表からの事前回答案_v1.0.xlsxより]] -> 一般会計全般・決算1.5 | B9: 一般会計全般・決算1.5 | C9: ◎ | D9: Req005 | E9: 複数の仕訳をまとめて仕訳アップロード機能で作成することができること | F9: 複数仕訳を同時で起票できる機能 | G9: 1.5 | H9: サンスター | J9: 一般会計全般・決算 | K9: 決算G/事務管理G | M9: 大量の仕訳データの改善・検討については事務管理Gが検討（武市） | O9: FO | Q9: 日次振伝処理 | R9: 不要 | S9: Excelアドインで１仕訳内に複数伝票を登録可能。 | T9: IN | X9: =テーブル1[[#This Row],[開発]]&テーブル1[[#This Row],[スコープ]] -> 不要IN | Y9: =IF(テーブル1[[#This Row],[列1]]="不要IN","標準",IF(テーブル1[[#This Row],[列1]]="不要OUT","スコープアウト",IF(テーブル1[[#This Row],[列1]]="必要IN","アドオン",IF(テーブル1[[#This Row],[列1]]="OUT","スコープアウト","")))) -> 標準 | Z9: =VLOOKUP($B9,Sheet1!$C$2:$L$315,9,) -> 会計システム標準機能 | AA9: =VLOOKUP($B9,Sheet1!$C$2:$L$315,10,) -> 0 | AB9: 標準 | AC9: =テーブル1[[#This Row],[要求事項一覧 判定]]=テーブル1[[#This Row],[列2]] -> TRUE
A10: =テーブル1[[#This Row],[対象部門]]&テーブル1[[#This Row],[業務要件回答表からの事前回答案_v1.0.xlsxより]] -> 一般会計全般・決算1.6 | B10: 一般会計全般・決算1.6 | C10: ◎ | D10: Req006 | E10: 転記済みの仕訳をコピーして登録できること | F10: 転記済みの仕訳をコピーして一部内容を修正することで新たな仕訳として登録できる機能 | G10: 1.6 | H10: サンスター | J10: 一般会計全般・決算 | K10: 決算G | L10: 「元帳トランザクションの呼び出し」があるが、元帳タイプどうしの仕訳パターン以外のケースが対応していない。 | M10: 20240326 保留 コピー不可パターンを確認して判断 | O10: FO | Q10: 日次振伝処理 | R10: 不要 | S10: 「元帳トランザクションの呼び出し」という機能で転記済伝票を呼び出し修正して新規仕訳として登録する機能があるが、「勘定タイプ＝元帳」のみの伝票しか対象とならない。「勘定タイプ＝銀行/顧客/仕入先/固定資産」などの伝票は対応不可。 ⇒実務上は標準機能利用で対応可 | T10: IN | X10: =テーブル1[[#This Row],[開発]]&テーブル1[[#This Row],[スコープ]] -> 不要IN | Y10: =IF(テーブル1[[#This Row],[列1]]="不要IN","標準",IF(テーブル1[[#This Row],[列1]]="不要OUT","スコープアウト",IF(テーブル1[[#This Row],[列1]]="必要IN","アドオン",IF(テーブル1[[#This Row],[列1]]="OUT","スコープアウト","")))) -> 標準 | Z10: =VLOOKUP($B10,Sheet1!$C$2:$L$315,9,) -> 会計システム標準機能 | AA10: =VLOOKUP($B10,Sheet1!$C$2:$L$315,10,) -> 仕訳帳のテンプレート登録にて対応 | AB10: 標準 | AC10: =テーブル1[[#This Row],[要求事項一覧 判定]]=テーブル1[[#This Row],[列2]] -> TRUE
A11: =テーブル1[[#This Row],[対象部門]]&テーブル1[[#This Row],[業務要件回答表からの事前回答案_v1.0.xlsxより]] -> 一般会計全般・決算1.7 | B11: 一般会計全般・決算1.7 | D11: Req007 | E11: 転記前に、転記後の残高を事前にシミュレーション表示できること | F11: 登録は済んでいるが、まだ転記されていない仕訳について、転記後の残高を事前に確認できるように、シミュレーション表示できる機能 | G11: 1.7 | H11: サンスター | J11: 一般会計全般・決算 | K11: 決算G | L11: ※事前に残高シミュレーションしたいのは、特定の科目でしょうか？それとも全科目で転記前の確認対象でしょうか？ | M11: 現状の業務としては、入力後確認して間違えていたら逆仕訳をして訂正している。 今の運用イメージはなく、今後利用していきたい機能である。 対象の科目として、特定の科目があるわけではない。 | O11: FO | Q11: 日次振伝処理 | R11: 不要 | S11: 銀行口座勘定については、統制残高勘定機能により転記後の残高を確認することが可能。 その他の勘定については、仕訳帳画面の残高レポート機能で転記前に、転記後の残高を確認することが可能。 | T11: IN | X11: =テーブル1[[#This Row],[開発]]&テーブル1[[#This Row],[スコープ]] -> 不要IN | Y11: =IF(テーブル1[[#This Row],[列1]]="不要IN","標準",IF(テーブル1[[#This Row],[列1]]="不要OUT","スコープアウト",IF(テーブル1[[#This Row],[列1]]="必要IN","アドオン",IF(テーブル1[[#This Row],[列1]]="OUT","スコープアウト","")))) -> 標準 | Z11: =VLOOKUP($B11,Sheet1!$C$2:$L$315,9,) -> 会計システムアドオン | AA11: =VLOOKUP($B11,Sheet1!$C$2:$L$315,10,) -> 未転記の仕訳を選択後、ボタン押下後に転記後の残高を確認できるポップアップ画面を表示する機能を追加する | AB11: アドオン | AC11: =テーブル1[[#This Row],[要求事項一覧 判定]]=テーブル1[[#This Row],[列2]] -> FALSE
A12: =テーブル1[[#This Row],[対象部門]]&テーブル1[[#This Row],[業務要件回答表からの事前回答案_v1.0.xlsxより]] -> 一般会計全般・決算1.8 | B12: 一般会計全般・決算1.8 | D12: Req008 | E12: 定型の仕訳伝票に関して、配賦用のテンプレートを定義、繰り返し使用できること ※テンプレート項目例：配賦元部門/勘定科目/金額、配賦先部門/勘定科目金額、配賦基準(金額比、割合比等) | F12: 配賦のために定型の仕訳伝票を入力テンプレートとして定義する機能 | G12: 1.8 | H12: サンスター | J12: 一般会計全般・決算 | K12: 事務管理G | L12: 伝票テンプレート機能や科目残高にたいして配賦処理を実行する機能はあるが、伝票毎に配賦条件を設定して配賦計算を行う機能はない。 | M12: 決算チームとしては、この要件はない。 経営計画グループに、配賦の要件があるが、定型の仕訳に対してではなく科目残高に対する配賦の要件と思われる。 →2/7事務管理チームにも確認したが、伝票テンプレート機能があればよく、定型の仕訳伝票に関して、配賦用のテンプレートを定義する要件はなかった。 | O12: FO | Q12: 日次振伝処理 | R12: 不要 | S12: 定期処理仕訳帳で定型の仕訳パターンは登録可能。配賦処理の計算については、配賦ルールを登録してバッチ処理にて計算処理実行が可能(均等/割合/売上高比などの配賦方法が可能) | T12: OUT | X12: =テーブル1[[#This Row],[開発]]&テーブル1[[#This Row],[スコープ]] -> 不要OUT | Y12: =IF(テーブル1[[#This Row],[列1]]="不要IN","標準",IF(テーブル1[[#This Row],[列1]]="不要OUT","スコープアウト",IF(テーブル1[[#This Row],[列1]]="必要IN","アドオン",IF(テーブル1[[#This Row],[列1]]="OUT","スコープアウト","")))) -> スコープアウト | Z12: =VLOOKUP($B12,Sheet1!$C$2:$L$315,9,) -> 会計システム標準機能 | AA12: =VLOOKUP($B12,Sheet1!$C$2:$L$315,10,) -> 一般仕訳帳のテンプレ機能があります。（配賦のためというわけではない） | AB12: 標準 | AC12: =テーブル1[[#This Row],[要求事項一覧 判定]]=テーブル1[[#This Row],[列2]] -> FALSE
A13: =テーブル1[[#This Row],[対象部門]]&テーブル1[[#This Row],[業務要件回答表からの事前回答案_v1.0.xlsxより]] -> 一般会計全般・決算1.9 | B13: 一般会計全般・決算1.9 | C13: ◎ | D13: Req009 | E13: 定型の仕訳伝票に関して、伝票登録時の入力テンプレートを定義し、繰り返し使用できること | F13: 各会計期間で繰り返される定型の仕訳を処理するため、定型の仕訳伝票を入力テンプレートとして定義する機能 | G13: 1.9 | H13: サンスター | J13: 一般会計全般・決算 | K13: 事務管理G | O13: FO | Q13: 日次振伝処理 | R13: 不要 | S13: 定期処理仕訳帳という機能で定期的に作成される定型の伝票を登録することが可能。 | T13: IN | X13: =テーブル1[[#This Row],[開発]]&テーブル1[[#This Row],[スコープ]] -> 不要IN | Y13: =IF(テーブル1[[#This Row],[列1]]="不要IN","標準",IF(テーブル1[[#This Row],[列1]]="不要OUT","スコープアウト",IF(テーブル1[[#This Row],[列1]]="必要IN","アドオン",IF(テーブル1[[#This Row],[列1]]="OUT","スコープアウト","")))) -> 標準 | Z13: =VLOOKUP($B13,Sheet1!$C$2:$L$315,9,) -> 会計システム標準機能 | AA13: =VLOOKUP($B13,Sheet1!$C$2:$L$315,10,) -> 0 | AB13: 標準 | AC13: =テーブル1[[#This Row],[要求事項一覧 判定]]=テーブル1[[#This Row],[列2]] -> TRUE
A14: =テーブル1[[#This Row],[対象部門]]&テーブル1[[#This Row],[業務要件回答表からの事前回答案_v1.0.xlsxより]] -> 一般会計全般・決算2.1 | B14: 一般会計全般・決算2.1 | C14: ◎ | D14: Req010 | E14: 未転記の場合、登録した仕訳伝票を登録者の方から修正することができること | F14: 仕訳明細情報を訂正する機能 | G14: 2.1 | H14: サンスター | J14: 一般会計全般・決算 | K14: 決算G | O14: FO | Q14: 日次振伝処理 | R14: 不要 | S14: 未転記の伝票は登録者が修正可能。 （ワークフロー申請済未承認の場合、「申請取消」をして伝票修正可能） | T14: IN | X14: =テーブル1[[#This Row],[開発]]&テーブル1[[#This Row],[スコープ]] -> 不要IN | Y14: =IF(テーブル1[[#This Row],[列1]]="不要IN","標準",IF(テーブル1[[#This Row],[列1]]="不要OUT","スコープアウト",IF(テーブル1[[#This Row],[列1]]="必要IN","アドオン",IF(テーブル1[[#This Row],[列1]]="OUT","スコープアウト","")))) -> 標準 | Z14: =VLOOKUP($B14,Sheet1!$C$2:$L$315,9,) -> 会計システム標準機能 | AA14: =VLOOKUP($B14,Sheet1!$C$2:$L$315,10,) -> 0 | AB14: 標準 | AC14: =テーブル1[[#This Row],[要求事項一覧 判定]]=テーブル1[[#This Row],[列2]] -> TRUE
A15: =テーブル1[[#This Row],[対象部門]]&テーブル1[[#This Row],[業務要件回答表からの事前回答案_v1.0.xlsxより]] -> 一般会計全般・決算2.2 | B15: 一般会計全般・決算2.2 | C15: ◎ | D15: Req011 | E15: 未転記の場合、登録した仕訳伝票を登録者の方から削除することができること | F15: 仕訳明細情報を削除する機能 | G15: 2.2 | H15: サンスター | J15: 一般会計全般・決算 | K15: 決算G | O15: FO | Q15: 日次振伝処理 | R15: 不要 | S15: 未転記の伝票は登録者が削除可能。 （ワークフロー申請済未承認の場合、「申請取消」をして伝票削除可能） | T15: IN | X15: =テーブル1[[#This Row],[開発]]&テーブル1[[#This Row],[スコープ]] -> 不要IN | Y15: =IF(テーブル1[[#This Row],[列1]]="不要IN","標準",IF(テーブル1[[#This Row],[列1]]="不要OUT","スコープアウト",IF(テーブル1[[#This Row],[列1]]="必要IN","アドオン",IF(テーブル1[[#This Row],[列1]]="OUT","スコープアウト","")))) -> 標準 | Z15: =VLOOKUP($B15,Sheet1!$C$2:$L$315,9,) -> 会計システム標準機能 | AA15: =VLOOKUP($B15,Sheet1!$C$2:$L$315,10,) -> 0 | AB15: 標準 | AC15: =テーブル1[[#This Row],[要求事項一覧 判定]]=テーブル1[[#This Row],[列2]] -> TRUE
A16: =テーブル1[[#This Row],[対象部門]]&テーブル1[[#This Row],[業務要件回答表からの事前回答案_v1.0.xlsxより]] -> 一般会計全般・決算2.3 | B16: 一般会計全般・決算2.3 | C16: ◎ | D16: Req012 | E16: 登録した仕訳伝票を符号の変更（登録された仕訳伝票の金額をプラスからマイナスに変更）できること | F16: 逆仕訳を生成する機能 | G16: 2.3 | H16: サンスター | J16: 一般会計全般・決算 | K16: 決算G | O16: FO | Q16: 日次振伝処理 | R16: 不要 | S16: 「トランザクションの取消」という機能で符号を反転した逆仕訳を作成する機能あり。 | T16: IN | X16: =テーブル1[[#This Row],[開発]]&テーブル1[[#This Row],[スコープ]] -> 不要IN | Y16: =IF(テーブル1[[#This Row],[列1]]="不要IN","標準",IF(テーブル1[[#This Row],[列1]]="不要OUT","スコープアウト",IF(テーブル1[[#This Row],[列1]]="必要IN","アドオン",IF(テーブル1[[#This Row],[列1]]="OUT","スコープアウト","")))) -> 標準 | Z16: =VLOOKUP($B16,Sheet1!$C$2:$L$315,9,) -> 会計システム標準機能 | AA16: =VLOOKUP($B16,Sheet1!$C$2:$L$315,10,) -> 転記済み仕訳を指定し「仕訳全体の取り消し」 | AB16: 標準 | AC16: =テーブル1[[#This Row],[要求事項一覧 判定]]=テーブル1[[#This Row],[列2]] -> TRUE
A17: =テーブル1[[#This Row],[対象部門]]&テーブル1[[#This Row],[業務要件回答表からの事前回答案_v1.0.xlsxより]] -> 一般会計全般・決算3.1 | B17: 一般会計全般・決算3.1 | C17: ◎ | D17: Req013 | E17: 承認者による承認のもと、仕訳伝票を転記できること | F17: 仕訳を転記する機能 | G17: 3.1 | H17: サンスター | J17: 一般会計全般・決算 | K17: 決算G | O17: FO | Q17: 日次振伝処理 | R17: 不要 | S17: 簡易的な1段階承認が可能な機能と、多段階承認や条件分岐を追加できるようなワークフロー機能あり。 | T17: IN | X17: =テーブル1[[#This Row],[開発]]&テーブル1[[#This Row],[スコープ]] -> 不要IN | Y17: =IF(テーブル1[[#This Row],[列1]]="不要IN","標準",IF(テーブル1[[#This Row],[列1]]="不要OUT","スコープアウト",IF(テーブル1[[#This Row],[列1]]="必要IN","アドオン",IF(テーブル1[[#This Row],[列1]]="OUT","スコープアウト","")))) -> 標準 | Z17: =VLOOKUP($B17,Sheet1!$C$2:$L$315,9,) -> 会計システム標準機能 | AA17: =VLOOKUP($B17,Sheet1!$C$2:$L$315,10,) -> 0 | AB17: 標準 | AC17: =テーブル1[[#This Row],[要求事項一覧 判定]]=テーブル1[[#This Row],[列2]] -> TRUE
A18: =テーブル1[[#This Row],[対象部門]]&テーブル1[[#This Row],[業務要件回答表からの事前回答案_v1.0.xlsxより]] -> 一般会計全般・決算3.2 | B18: 一般会計全般・決算3.2 | D18: Req014 | E18: 自動で転記処理を行うために、転記承認を経ずに転記できること | F18: 自動で転記処理を行う機能 | G18: 3.2 | H18: サンスター | J18: 一般会計全般・決算 | K18: 事務管理G | L18: 定期バッチ処理で未転記伝票を転記する機能あり。承認不要な伝票は、承認設定なしの仕訳帳を設定して運用することにより承認なしで転記可能。 ※自動で転記処理を行うのはどのような種類の伝票でしょうか？ | M18: 各種自動転記機能全般のことを指しており 通常の伝票入力のなかで自動転記させる機能のことではない。 支払い処理、消費税の処理（年度末）、減価償却費、リース料など | O18: FO | Q18: 日次振伝処理 | R18: 不要 | S18: 各モジュールの仕訳が必要なプロセス処理では自動仕訳が作成される仕様となっている | T18: IN | X18: =テーブル1[[#This Row],[開発]]&テーブル1[[#This Row],[スコープ]] -> 不要IN | Y18: =IF(テーブル1[[#This Row],[列1]]="不要IN","標準",IF(テーブル1[[#This Row],[列1]]="不要OUT","スコープアウト",IF(テーブル1[[#This Row],[列1]]="必要IN","アドオン",IF(テーブル1[[#This Row],[列1]]="OUT","スコープアウト","")))) -> 標準 | Z18: =VLOOKUP($B18,Sheet1!$C$2:$L$315,9,) -> 会計システム標準機能 | AA18: =VLOOKUP($B18,Sheet1!$C$2:$L$315,10,) -> 特定金額以下であれば、承認不要（転記可能）等は設定できる。 | AB18: 標準 | AC18: =テーブル1[[#This Row],[要求事項一覧 判定]]=テーブル1[[#This Row],[列2]] -> TRUE
A19: =テーブル1[[#This Row],[対象部門]]&テーブル1[[#This Row],[業務要件回答表からの事前回答案_v1.0.xlsxより]] -> 一般会計全般・決算4.1 | B19: 一般会計全般・決算4.1 | C19: ◎ | D19: Req015 | E19: 仕訳作成者が、設定された仕訳の承認要求ができること | F19: 仕訳の承認依頼を行う機能 | G19: 4.1 | H19: サンスター | J19: 一般会計全般・決算 | K19: 決算G | O19: FO | Q19: 日次振伝処理 | R19: 不要 | S19: 承認設定した仕訳帳で入力した場合、仕訳承認要求が可能。ワークフロー機能を使用した場合、メール通知も可能。 | T19: IN | X19: =テーブル1[[#This Row],[開発]]&テーブル1[[#This Row],[スコープ]] -> 不要IN | Y19: =IF(テーブル1[[#This Row],[列1]]="不要IN","標準",IF(テーブル1[[#This Row],[列1]]="不要OUT","スコープアウト",IF(テーブル1[[#This Row],[列1]]="必要IN","アドオン",IF(テーブル1[[#This Row],[列1]]="OUT","スコープアウト","")))) -> 標準 | Z19: =VLOOKUP($B19,Sheet1!$C$2:$L$315,9,) -> 会計システム標準機能 | AA19: =VLOOKUP($B19,Sheet1!$C$2:$L$315,10,) -> 0 | AB19: 標準 | AC19: =テーブル1[[#This Row],[要求事項一覧 判定]]=テーブル1[[#This Row],[列2]] -> TRUE
A20: =テーブル1[[#This Row],[対象部門]]&テーブル1[[#This Row],[業務要件回答表からの事前回答案_v1.0.xlsxより]] -> 一般会計全般・決算4.2 | B20: 一般会計全般・決算4.2 | C20: ◎ | D20: Req016 | E20: 仕訳作成者が、設定された仕訳バッチ一覧から任意の単位で仕訳を一括に承認要求ができること | F20: 一括で仕訳の承認依頼を行う機能 | G20: 4.2 | H20: サンスター | J20: 一般会計全般・決算 | K20: 決算G | L20: 一括承認依頼の機能は無い。承認待ちリストから個別に選択して承認依頼する | M20: 現在SAPで入力したものについて一括承認はしていおらず、1件1件承認申請をしている。 楽楽精算の場合は件数が多いので一括承認機能を利用しているが、SAPは件数が少ないのでこの機能はなくてもよい。 20240326 楽々精算の振伝入力をFOで実施する場合、一括提出は不要だが一括承認が必要となる見込み R/3に代わるDynamicsでは、1件1件の伝票承認で対応可能との認識をした。 | O20: FO | Q20: 日次振伝処理 | R20: 不要 | S20: 一括承認依頼の機能は無い。承認待ちリストから個別に選択して承認依頼する | T20: OUT | X20: =テーブル1[[#This Row],[開発]]&テーブル1[[#This Row],[スコープ]] -> 不要OUT | Y20: =IF(テーブル1[[#This Row],[列1]]="不要IN","標準",IF(テーブル1[[#This Row],[列1]]="不要OUT","スコープアウト",IF(テーブル1[[#This Row],[列1]]="必要IN","アドオン",IF(テーブル1[[#This Row],[列1]]="OUT","スコープアウト","")))) -> スコープアウト | Z20: =VLOOKUP($B20,Sheet1!$C$2:$L$315,9,) -> 会計システムアドオン | AA20: =VLOOKUP($B20,Sheet1!$C$2:$L$315,10,) -> 一括で承認依頼/承認を行う機能を追加する | AB20: アドオン | AC20: =テーブル1[[#This Row],[要求事項一覧 判定]]=テーブル1[[#This Row],[列2]] -> FALSE
A21: =テーブル1[[#This Row],[対象部門]]&テーブル1[[#This Row],[業務要件回答表からの事前回答案_v1.0.xlsxより]] -> 一般会計全般・決算4.3 | B21: 一般会計全般・決算4.3 | C21: ◎ | D21: Req017 | E21: 仕訳一括承認依頼受領時に、任意の仕訳単位に対して一括で承認、否決処理ができること | F21: 一括で仕訳の承認を行う機能 | G21: 4.3 | H21: サンスター | J21: 一般会計全般・決算 | K21: 事務管理G | L21: 一括承認の機能は無い。承認待ちリストから個別に選択して承認する | M21: 現在SAPで入力したものについて一括承認はしていおらず、1件1件承認申請をしている。 楽楽精算の場合は件数が多いので一括承認機能を利用しているが、SAPは件数が少ないのでこの機能はなくてもよい。 R/3に代わるDynamicsでは、1件1件の伝票承認で対応可能との認識をした。 20240326 楽々精算の振伝入力をFOで実施する場合、一括提出は不要だが一括承認が必要となる見込み R/3に代わるDynamicsでは、1件1件の伝票承認で対応可能との認識をした。 | O21: FO | Q21: 日次振伝処理 | R21: 必要 | S21: 一括承認の機能は無い。承認待ちリストから個別に選択して承認する 20240404 楽々精算からFOで代替するケースを想定して一旦開発扱いとする。 | T21: IN | U21: 楽々精算の振伝をFOでやるかどうかにより要不要が決まる。 | V21: 〇 | W21: 振替伝票など、承認対象の伝票が多くなるケースにおいて、本アドオンでどれだけの効果が出るかを検証要 | X21: =テーブル1[[#This Row],[開発]]&テーブル1[[#This Row],[スコープ]] -> 必要IN | Y21: =IF(テーブル1[[#This Row],[列1]]="不要IN","標準",IF(テーブル1[[#This Row],[列1]]="不要OUT","スコープアウト",IF(テーブル1[[#This Row],[列1]]="必要IN","アドオン",IF(テーブル1[[#This Row],[列1]]="OUT","スコープアウト","")))) -> アドオン | Z21: =VLOOKUP($B21,Sheet1!$C$2:$L$315,9,) -> 会計システムアドオン | AA21: =VLOOKUP($B21,Sheet1!$C$2:$L$315,10,) -> 4.3の範囲にて対応。 | AB21: アドオン | AC21: =テーブル1[[#This Row],[要求事項一覧 判定]]=テーブル1[[#This Row],[列2]] -> TRUE
A22: =テーブル1[[#This Row],[対象部門]]&テーブル1[[#This Row],[業務要件回答表からの事前回答案_v1.0.xlsxより]] -> 一般会計全般・決算5.1 | B22: 一般会計全般・決算5.1 | C22: ◎ | D22: Req018 | E22: 仕訳入力者を区分として、仕訳のステータスが未承認または承認依頼未済である仕訳の仕訳明細情報を一覧で、画面照会および帳票出力できること | F22: 承認依頼時に、依頼者別の未承認または承認依頼未済の仕訳明細情報を一覧で出力する機能 | G22: 5.1 | H22: サンスター | J22: 一般会計全般・決算 | K22: 決算G | L22: 一般仕訳帳画面で未転記状態の仕訳帳を一覧表示可能、ワークフローの承認状態も表示可能だが、ヘッダ情報のみ。 帳票では、「未転記の一般仕訳入力」が未転記の仕訳明細を確認できるが承認状態が確認できない。 | M22: 上長が承認したのか、未転記か転記済みかだけがわかればよいので提示いただいている機能だけでもよいと考えている。 | O22: FO | Q22: 日次振伝処理 | R22: 不要 | S22: 一般仕訳帳画面で未転記状態の仕訳帳を一覧表示可能、 | T22: IN | X22: =テーブル1[[#This Row],[開発]]&テーブル1[[#This Row],[スコープ]] -> 不要IN | Y22: =IF(テーブル1[[#This Row],[列1]]="不要IN","標準",IF(テーブル1[[#This Row],[列1]]="不要OUT","スコープアウト",IF(テーブル1[[#This Row],[列1]]="必要IN","アドオン",IF(テーブル1[[#This Row],[列1]]="OUT","スコープアウト","")))) -> 標準 | Z22: =VLOOKUP($B22,Sheet1!$C$2:$L$315,9,) -> 会計システム標準機能 | AA22: =VLOOKUP($B22,Sheet1!$C$2:$L$315,10,) -> 0 | AB22: 標準 | AC22: =テーブル1[[#This Row],[要求事項一覧 判定]]=テーブル1[[#This Row],[列2]] -> TRUE
A23: =テーブル1[[#This Row],[対象部門]]&テーブル1[[#This Row],[業務要件回答表からの事前回答案_v1.0.xlsxより]] -> 一般会計全般・決算5.2 | B23: 一般会計全般・決算5.2 | C23: ◎ | D23: Req019 | E23: 承認依頼が必要な未承認の仕訳を勘定科目別に集計した一覧で、画面照会および帳票出力できること | F23: 承認依頼が必要な仕訳を勘定科目別に集計した一覧を出力する機能 | G23: 5.2 | H23: サンスター | J23: 一般会計全般・決算 | K23: 決算G | L23: 仕訳帳明細を未承認のものに絞って出力することはできるが、科目別に集計されていない。CSV出力後に集計を行う必要あり。 | M23: 転記後の金額がわかればよいので機能としては不要である。 | O23: FO | Q23: 日次振伝処理 | R23: 不要 | S23: 仕訳帳明細を未承認のものに絞って出力することはできるが、科目別に集計されていない。CSV出力後に集計を行う必要あり。 | T23: OUT | X23: =テーブル1[[#This Row],[開発]]&テーブル1[[#This Row],[スコープ]] -> 不要OUT | Y23: =IF(テーブル1[[#This Row],[列1]]="不要IN","標準",IF(テーブル1[[#This Row],[列1]]="不要OUT","スコープアウト",IF(テーブル1[[#This Row],[列1]]="必要IN","アドオン",IF(テーブル1[[#This Row],[列1]]="OUT","スコープアウト","")))) -> スコープアウト | Z23: =VLOOKUP($B23,Sheet1!$C$2:$L$315,9,) -> 会計システムアドオン | AA23: =VLOOKUP($B23,Sheet1!$C$2:$L$315,10,) -> 新規画面として、承認依頼が必要な仕訳を勘定科目別に集計した一覧を出力する画面を作成。帳票に関しては、現時点では標準機能のExcelファイルエクスポート機能を使用予定。要件次第で開発とする。 | AB23: アドオン | AC23: =テーブル1[[#This Row],[要求事項一覧 判定]]=テーブル1[[#This Row],[列2]] -> FALSE
A24: =テーブル1[[#This Row],[対象部門]]&テーブル1[[#This Row],[業務要件回答表からの事前回答案_v1.0.xlsxより]] -> 一般会計全般・決算6.1 | B24: 一般会計全般・決算6.1 | D24: Req020 | E24: 前日、前月末までの借方貸方の累計と残高を集計し、画面照会および帳票出力ができること | F24: 指定時点での科目別残高一覧を出力する機能 | G24: 6.1 | H24: サンスター | J24: 一般会計全般・決算 | K24: 決算G | O24: FO | Q24: 日次振伝処理 | R24: 不要 | S24: 試算表で日付指定して科目残高確認可能。 | T24: IN | X24: =テーブル1[[#This Row],[開発]]&テーブル1[[#This Row],[スコープ]] -> 不要IN | Y24: =IF(テーブル1[[#This Row],[列1]]="不要IN","標準",IF(テーブル1[[#This Row],[列1]]="不要OUT","スコープアウト",IF(テーブル1[[#This Row],[列1]]="必要IN","アドオン",IF(テーブル1[[#This Row],[列1]]="OUT","スコープアウト","")))) -> 標準 | Z24: =VLOOKUP($B24,Sheet1!$C$2:$L$315,9,) -> 会計システム標準機能 | AA24: =VLOOKUP($B24,Sheet1!$C$2:$L$315,10,) -> 0 | AB24: 標準 | AC24: =テーブル1[[#This Row],[要求事項一覧 判定]]=テーブル1[[#This Row],[列2]] -> TRUE
A25: =テーブル1[[#This Row],[対象部門]]&テーブル1[[#This Row],[業務要件回答表からの事前回答案_v1.0.xlsxより]] -> 一般会計全般・決算6.2 | B25: 一般会計全般・決算6.2 | D25: Req021 | E25: 指定された会計期間において発生した任意の勘定科目の残高明細情報を、画面照会および帳票出力できること | F25: 科目別残高明細一覧を出力する機能 | G25: 6.2 | H25: サンスター | J25: 一般会計全般・決算 | K25: 決算G | O25: FO | Q25: 日次振伝処理 | R25: 不要 | S25: 試算表で日付指定して科目残高確認可能。 分析コード明細書で日付指定および合計指定することで帳票出力可能。 | T25: IN | X25: =テーブル1[[#This Row],[開発]]&テーブル1[[#This Row],[スコープ]] -> 不要IN | Y25: =IF(テーブル1[[#This Row],[列1]]="不要IN","標準",IF(テーブル1[[#This Row],[列1]]="不要OUT","スコープアウト",IF(テーブル1[[#This Row],[列1]]="必要IN","アドオン",IF(テーブル1[[#This Row],[列1]]="OUT","スコープアウト","")))) -> 標準 | Z25: =VLOOKUP($B25,Sheet1!$C$2:$L$315,9,) -> 会計システム標準機能 | AA25: =VLOOKUP($B25,Sheet1!$C$2:$L$315,10,) -> 0 | AB25: 標準 | AC25: =テーブル1[[#This Row],[要求事項一覧 判定]]=テーブル1[[#This Row],[列2]] -> TRUE
A26: =テーブル1[[#This Row],[対象部門]]&テーブル1[[#This Row],[業務要件回答表からの事前回答案_v1.0.xlsxより]] -> 一般会計全般・決算6.3 | B26: 一般会計全般・決算6.3 | D26: Req022 | E26: 前期末の残高明細情報と比較できること | F26: 前年同期比で残高の比較照合ができる機能 | G26: 6.3 | H26: サンスター | J26: 一般会計全般・決算 | K26: 決算G | O26: FO | Q26: 月次決算処理 | R26: 必要 | S26: 標準の帳票作成ツールManagementReporterを使って、前年同期比帳票を作成すれば参照可能。 | T26: IN | V26: × | W26: MRでできるのであれば審査対象外 | X26: =テーブル1[[#This Row],[開発]]&テーブル1[[#This Row],[スコープ]] -> 必要IN | Y26: =IF(テーブル1[[#This Row],[列1]]="不要IN","標準",IF(テーブル1[[#This Row],[列1]]="不要OUT","スコープアウト",IF(テーブル1[[#This Row],[列1]]="必要IN","アドオン",IF(テーブル1[[#This Row],[列1]]="OUT","スコープアウト","")))) -> アドオン | Z26: =VLOOKUP($B26,Sheet1!$C$2:$L$315,9,) -> 会計システム標準機能 | AA26: =VLOOKUP($B26,Sheet1!$C$2:$L$315,10,) -> MRで対応 | AB26: 標準 | AC26: =テーブル1[[#This Row],[要求事項一覧 判定]]=テーブル1[[#This Row],[列2]] -> FALSE
A27: =テーブル1[[#This Row],[対象部門]]&テーブル1[[#This Row],[業務要件回答表からの事前回答案_v1.0.xlsxより]] -> 一般会計全般・決算6.4 | B27: 一般会計全般・決算6.4 | D27: Req023 | E27: 特定の会計期間において勘定科目別、貨幣別等で各残高を集計して、画面照会および帳票出力ができること | F27: 特定の会計期間において勘定科目別の残高を指定した一定の条件別に一覧化して集計する機能 | G27: 6.4 | H27: サンスター | J27: 一般会計全般・決算 | K27: 決算G | L27: 外貨建ての入力と通貨別残高参照画面はある。ただし一覧形式での参照機能がほしい場合、アドオンが必要。 標準の帳票作成ツールManagementReporterを使って、ある程度の条件別の帳票が作成可能であるが、制限あり。 ※MRの場合、貨幣別は明細での出力は可能だが残高集計すると邦貨で集計される制限あり ※試算表画面の邦貨での一覧表示から、貨幣別算高画面へ遷移して確認できるが、 科目を個別指定して表示する方式のため該当科目を一覧表示で貨幣別に表示する機能がない。 | M27: 決算では外貨建てで管理しているものはない。外貨は円換算して決算しているので決算チームとしては不要である。 今後は、外貨建て運用する方針。 2024/04/11 試算表の通貨別画面で個別科目ごとに確認することは可能であるが、一覧性がないため帳票を開発するか議論したが、試算表の通貨別画面で個別に確認する運用対応とし開発対象外となった。 | O27: FO | Q27: 月次決算処理 | R27: 不要 | S27: 外貨建ての入力と通貨別残高参照画面はある。ただし一覧形式での参照機能がほしい場合、アドオンが必要。 | T27: IN | U27: 2024/04/11 試算表の通貨別画面で個別科目ごとに確認することは可能であるが、一覧性がないため帳票を開発するか議論したが、試算表の通貨別画面で個別に確認する運用対応とし開発対象外となった。 | X27: =テーブル1[[#This Row],[開発]]&テーブル1[[#This Row],[スコープ]] -> 不要IN | Y27: =IF(テーブル1[[#This Row],[列1]]="不要IN","標準",IF(テーブル1[[#This Row],[列1]]="不要OUT","スコープアウト",IF(テーブル1[[#This Row],[列1]]="必要IN","アドオン",IF(テーブル1[[#This Row],[列1]]="OUT","スコープアウト","")))) -> 標準 | Z27: =VLOOKUP($B27,Sheet1!$C$2:$L$315,9,) -> 会計システム標準機能 | AA27: =VLOOKUP($B27,Sheet1!$C$2:$L$315,10,) -> 0 | AB27: 標準 | AC27: =テーブル1[[#This Row],[要求事項一覧 判定]]=テーブル1[[#This Row],[列2]] -> TRUE
A28: =テーブル1[[#This Row],[対象部門]]&テーブル1[[#This Row],[業務要件回答表からの事前回答案_v1.0.xlsxより]] -> 一般会計全般・決算6.5 | B28: 一般会計全般・決算6.5 | D28: Req024 | E28: 各勘定科目の残高を確認し、残高がマイナスである科目がある場合、該当科目別の残高を通貨・会社毎にリストとして、画面照会および帳票出力ができること | F28: 残高がマイナスである科目を一覧で出力する機能 | G28: 6.5 | H28: サンスター | J28: 一般会計全般・決算 | K28: 決算G | L28: 試算表(科目残高参照機能)で「-1以下」の条件でフィルタすることができるが、 試算表画面では、規定の表示方法として貸方勘定の残高がーで表示されるため、要件を満たせない。 ManagementReporterで貸方科目もプラス残で表示する残高リストを作成して、出力した残高リストでマイナス残の科目を抽出する。 | M28: 現状SAPから出てくる試算表で確認できているので、マイナス分のみの一覧表は不要である。 | O28: FO | Q28: 月次決算処理 | R28: 不要 | S28: 通常の試算表で確認 | T28: OUT | X28: =テーブル1[[#This Row],[開発]]&テーブル1[[#This Row],[スコープ]] -> 不要OUT | Y28: =IF(テーブル1[[#This Row],[列1]]="不要IN","標準",IF(テーブル1[[#This Row],[列1]]="不要OUT","スコープアウト",IF(テーブル1[[#This Row],[列1]]="必要IN","アドオン",IF(テーブル1[[#This Row],[列1]]="OUT","スコープアウト","")))) -> スコープアウト | Z28: =VLOOKUP($B28,Sheet1!$C$2:$L$315,9,) -> 会計システム標準機能 | AA28: =VLOOKUP($B28,Sheet1!$C$2:$L$315,10,) -> 勘定科目一覧画面で、金額欄にマイナス金額のフィルタを使用 | AB28: 標準 | AC28: =テーブル1[[#This Row],[要求事項一覧 判定]]=テーブル1[[#This Row],[列2]] -> FALSE
A29: =テーブル1[[#This Row],[対象部門]]&テーブル1[[#This Row],[業務要件回答表からの事前回答案_v1.0.xlsxより]] -> 一般会計全般・決算6.6 | B29: 一般会計全般・決算6.6 | D29: Req025 | E29: 決算時の通過勘定科目の残高を確認し、残高が0円以外の科目がある場合、該当科目別の残高を通貨・会社毎にリストとして、画面照会および帳票出力ができること | F29: 決算時において0円である必要がある勘定科目(通過勘定科目)に対し未整理の残高が存在する場合、対象の残高情報を一覧で出力する機能 | G29: 6.6 | H29: サンスター | J29: 一般会計全般・決算 | K29: 決算G | M29: 現状SAPから出てくる試算表で確認できているので、特定科目分のみの一覧表は不要である。 会社ごとにしか確認していないので、特別な機能は必要ない。 | O29: FO | Q29: 月次決算処理 | R29: 不要 | S29: 通常の試算表で確認 | T29: OUT | X29: =テーブル1[[#This Row],[開発]]&テーブル1[[#This Row],[スコープ]] -> 不要OUT | Y29: =IF(テーブル1[[#This Row],[列1]]="不要IN","標準",IF(テーブル1[[#This Row],[列1]]="不要OUT","スコープアウト",IF(テーブル1[[#This Row],[列1]]="必要IN","アドオン",IF(テーブル1[[#This Row],[列1]]="OUT","スコープアウト","")))) -> スコープアウト | Z29: =VLOOKUP($B29,Sheet1!$C$2:$L$315,9,) -> 会計システム標準機能 | AA29: =VLOOKUP($B29,Sheet1!$C$2:$L$315,10,) -> 伝票トランザクションにてフィルタしてExcel出力での対応 | AB29: 標準 | AC29: =テーブル1[[#This Row],[要求事項一覧 判定]]=テーブル1[[#This Row],[列2]] -> FALSE
A30: =テーブル1[[#This Row],[対象部門]]&テーブル1[[#This Row],[業務要件回答表からの事前回答案_v1.0.xlsxより]] -> 一般会計全般・決算7.1 | B30: 一般会計全般・決算7.1 | D30: Req026 | E30: 指定された会計期間時点での以下の財務諸表を、全社、部門別で、画面照会および帳票出力できること ・貸借対照表(BS) ・損益計算書(PL累計) ・株主資本等変動計算書(SS) ・注記表 ・キャッシュフロー計算書(CF) ・製造原価報告書 ・労務費及び生産費明細表 ・営業費明細表 ・研究費明細表 | F30: 財務諸表をを全社/各社別に作成・出力する機能(BS/PLについては開示用科目(親科目)と集計元科目(子科目)単位でそれぞれ閲覧できること) | G30: 7.1 | H30: サンスター | J30: 一般会計全般・決算 | K30: 決算G | L30: 標準の帳票作成ツールManagementReportを使って、全社、部門別に帳票作成可能。 ※・注記表 ・キャッシュフロー計算書(CF)は、ロジックしだいでアドオンが必要。 | M30: 製造原価報告書が直接出力されているわけではない。 労務費及び生産費明細表は、SAPから経費実績表の合計数字をExcelに転記している。元データ出力ができればよいと考えている。 SEJはR/3からホストで出てきた製造原価が出てこない。 決算調整の数字はホストに反映されない問題がある。SAPでは製造原価が出せていないため、手作業で数字の調整をしないといけない。 株主資本等変動計算書、注記表、キャッシュフロー計算書は手作業が必要になる想定。 どこまでコストをかけて必要なのか検討が必要。 | O30: FO | Q30: 月次決算処理 | R30: 必要 | S30: 標準の帳票作成ツールManagementReportを使って出力可能な帳票は作成。 株主資本等変動計算書、注記表、キャッシュフロー計算書は手作業が必要。 | T30: IN | V30: × | W30: MRでできるのであれば審査対象外 株主資本等変動計算書、注記表、キャッシュフロー計算書はシステム化対象外 | X30: =テーブル1[[#This Row],[開発]]&テーブル1[[#This Row],[スコープ]] -> 必要IN | Y30: =IF(テーブル1[[#This Row],[列1]]="不要IN","標準",IF(テーブル1[[#This Row],[列1]]="不要OUT","スコープアウト",IF(テーブル1[[#This Row],[列1]]="必要IN","アドオン",IF(テーブル1[[#This Row],[列1]]="OUT","スコープアウト","")))) -> アドオン | Z30: =VLOOKUP($B30,Sheet1!$C$2:$L$315,9,) -> 会計システム標準機能 | AA30: =VLOOKUP($B30,Sheet1!$C$2:$L$315,10,) -> 「注記表」以外につきましては、FO標準機能の財務諸表で対応可能と考えております。ただ、「注記表」については、標準機能のWordテンプレートを使用して、帳票出力を検討しております。ただし、要件次第では、開発が必要となる場合もございます。 | AB30: 標準 | AC30: =テーブル1[[#This Row],[要求事項一覧 判定]]=テーブル1[[#This Row],[列2]] -> FALSE
A31: =テーブル1[[#This Row],[対象部門]]&テーブル1[[#This Row],[業務要件回答表からの事前回答案_v1.0.xlsxより]] -> 一般会計全般・決算7.2 | B31: 一般会計全般・決算7.2 | D31: Req027 | E31: 各財務諸表類の前年度比較ができること | F31: 前年同期比で各財務諸表類の比較照合ができる機能 | G31: 7.2 | H31: サンスター | J31: 一般会計全般・決算 | K31: 決算G | M31: 単年度があればよい、前年度の比較は不要。 | O31: FO | Q31: 月次決算処理 | R31: 不要 | T31: OUT | X31: =テーブル1[[#This Row],[開発]]&テーブル1[[#This Row],[スコープ]] -> 不要OUT | Y31: =IF(テーブル1[[#This Row],[列1]]="不要IN","標準",IF(テーブル1[[#This Row],[列1]]="不要OUT","スコープアウト",IF(テーブル1[[#This Row],[列1]]="必要IN","アドオン",IF(テーブル1[[#This Row],[列1]]="OUT","スコープアウト","")))) -> スコープアウト | Z31: =VLOOKUP($B31,Sheet1!$C$2:$L$315,9,) -> 会計システム標準機能 | AA31: =VLOOKUP($B31,Sheet1!$C$2:$L$315,10,) -> MRで対応 | AB31: 標準 | AC31: =テーブル1[[#This Row],[要求事項一覧 判定]]=テーブル1[[#This Row],[列2]] -> FALSE
A32: =テーブル1[[#This Row],[対象部門]]&テーブル1[[#This Row],[業務要件回答表からの事前回答案_v1.0.xlsxより]] -> 一般会計全般・決算7.3 | B32: 一般会計全般・決算7.3 | D32: Req028 | E32: 年次毎に下記の決算開示書類を作成すること ・計算書類 ・附属明細書 ・決算短信 ・事業報告書 ・勘定明細 | F32: 決算開示書類を作成・出力する機能 | G32: 7.3 | H32: サンスター | J32: 一般会計全般・決算 | K32: 決算G | L32: 決算開示書類向けのローデータを出力することは可能であるが、各表毎の仕訳トランザクションから取得できない情報については、別途追加編集が必要。 | M32: 仕訳トランザクションから取得できない情報については別途検討が必要。 | O32: FO | Q32: 月次決算処理 | R32: 不要 | S32: 決算開示書類向けのローデータを出力して、各表毎の仕訳トランザクションから取得できない情報については、別途追加編集を行う。 | T32: IN | X32: =テーブル1[[#This Row],[開発]]&テーブル1[[#This Row],[スコープ]] -> 不要IN | Y32: =IF(テーブル1[[#This Row],[列1]]="不要IN","標準",IF(テーブル1[[#This Row],[列1]]="不要OUT","スコープアウト",IF(テーブル1[[#This Row],[列1]]="必要IN","アドオン",IF(テーブル1[[#This Row],[列1]]="OUT","スコープアウト","")))) -> 標準 | Z32: =VLOOKUP($B32,Sheet1!$C$2:$L$315,9,) -> 会計システムアドオン | AA32: =VLOOKUP($B32,Sheet1!$C$2:$L$315,10,) -> 下記帳票類の作成 ・計算書類 ・附属明細書 ・決算短信 ・事業報告書 ・勘定明細 | AB32: アドオン | AC32: =テーブル1[[#This Row],[要求事項一覧 判定]]=テーブル1[[#This Row],[列2]] -> FALSE
A33: =テーブル1[[#This Row],[対象部門]]&テーブル1[[#This Row],[業務要件回答表からの事前回答案_v1.0.xlsxより]] -> 一般会計全般・決算7.4 | B33: 一般会計全般・決算7.4 | D33: Req029 | E33: 決算開示書類の計算書類や付属明細書、勘定明細書の前年度比較ができること | F33: 前年同期比で各決算開示書類の比較照合ができる機能 | G33: 7.4 | H33: サンスター | J33: 一般会計全般・決算 | K33: 決算G | L33: 決算開示書類向けのローデータを出力することは可能であるが、各表毎の仕訳トランザクションから取得できない情報については、別途追加編集が必要。 | M33: BSに関しては出力可能、PLは出力ができていない状況。BSはSAPの中で比較することはなく、Excelで各社2期比較のBS/PLを作成している。 決算開示書類も現状、Excelで作成している。 計算書類、出力明細、勘定明細の前年度比較ができることとなっているが、帳票としてはそれぞれの単年度の数字だけでいい。 BS、PLの前年比較ができれば決算開示書類の前年比較はできなくても差し支えないと考えている。 | O33: FO | Q33: 月次決算処理 | R33: 不要 | S33: 決算開示書類向けのローデータを出力し、各表毎の仕訳トランザクションから取得できない情報については、別途追加編集を行う | T33: IN | X33: =テーブル1[[#This Row],[開発]]&テーブル1[[#This Row],[スコープ]] -> 不要IN | Y33: =IF(テーブル1[[#This Row],[列1]]="不要IN","標準",IF(テーブル1[[#This Row],[列1]]="不要OUT","スコープアウト",IF(テーブル1[[#This Row],[列1]]="必要IN","アドオン",IF(テーブル1[[#This Row],[列1]]="OUT","スコープアウト","")))) -> 標準 | Z33: =VLOOKUP($B33,Sheet1!$C$2:$L$315,9,) -> 会計システムアドオン | AA33: =VLOOKUP($B33,Sheet1!$C$2:$L$315,10,) -> 下記帳票類の履歴管理機能 ・計算書類 ・附属明細書 ・決算短信 ・事業報告書 ・勘定明細 | AB33: アドオン | AC33: =テーブル1[[#This Row],[要求事項一覧 判定]]=テーブル1[[#This Row],[列2]] -> FALSE
A34: =テーブル1[[#This Row],[対象部門]]&テーブル1[[#This Row],[業務要件回答表からの事前回答案_v1.0.xlsxより]] -> 一般会計全般・決算7.5 | B34: 一般会計全般・決算7.5 | D34: Req030 | E34: 指定された会計期間時点での以下の帳簿類を、全社、部門別で、画面照会および出力できること。また、これらの帳簿を指定した日にシステムから指定したデータを自動で保存できること。 定期的に静止データとして帳票等に自動保存させたい ・仕訳帳 （仕訳のステータス(未承認、転記済み、エラー)を区分として、仕訳帳が画面照会および帳票出力でき、仕訳一覧から、ドリルダウンして明細情報が確認できること） ・総勘定元帳 （指定された会計期間(月次/年度等)における、仕訳明細情報(借方、貸方、残高)が、勘定科目別、伝票日付別、転記処理日別、仕訳ソース別、仕訳カテゴリー別等に集計された一覧） （指定された会計期間(月次/年度等)における、仕訳明細情報(借方、貸方、残高)が、勘定科目別、伝票日付別、転記処理日別、仕訳ソース別、仕訳カテゴリー別等に集計された一覧） ・補助簿（固定資産台帳を含む） （指定された会計期間(月次/年度等)における、仕訳の明細情報の勘定科目別、伝票日付別、取引先別等の一覧） ・勘定残高表 （指定された会計期間(月次/年度等)における、指定された勘定科目の残高(前期末残高、借方、貸方)が集計された一覧） ・消費税台帳 （指定された会計期間(月次/年度等)における、売上高・仕入高と消費税額がで集計された一覧） | F34: 仕訳帳、総勘定元帳、補助記入帳、補助元帳、勘定残高表、消費税台帳等を出力、また、指定日に応じて自動保存する機能 | G34: 7.5 | H34: サンスター | J34: 一般会計全般・決算 | K34: 決算G | L34: 標準の帳票作成ツールManagementReporterを使って、スケジュールバッチ出力ができるが、MRでは、出力指示や表示内容に制限があるので、各帳票ごとに検討が必要。 固定資産台帳や消費税台帳は、ManagementReportでの出力は不可。 | M34: 決算チームでは、通常の帳票出力機能で問題ない定期的な自動保存などの要件はない。 2/7 事務管理チーム確認 月次で3社のBSとPLを期間指定して手動で保存し、各社の勘定照合を行っている。よって、画面で必要な期間指定にて照会できれば、 自動保存は不要。最低レベルで、手動で出力したものを保管できれば良い。自動でできればなお良い。 過去のデータを使用するなど、自動でマクロを読んで貼り付けすることなども行っているのでExcelに出力できれば良い。 | O34: FO | Q34: 月次決算処理 | R34: 不要 | S34: ManagementReporterで、バッチスケジュール可能なものは自動スケジュール出力。 それ以外の帳票は、手動で出力したものを保管する。 | T34: IN | X34: =テーブル1[[#This Row],[開発]]&テーブル1[[#This Row],[スコープ]] -> 不要IN | Y34: =IF(テーブル1[[#This Row],[列1]]="不要IN","標準",IF(テーブル1[[#This Row],[列1]]="不要OUT","スコープアウト",IF(テーブル1[[#This Row],[列1]]="必要IN","アドオン",IF(テーブル1[[#This Row],[列1]]="OUT","スコープアウト","")))) -> 標準 | Z34: =VLOOKUP($B34,Sheet1!$C$2:$L$315,9,) -> 会計システム標準機能 | AA34: =VLOOKUP($B34,Sheet1!$C$2:$L$315,10,) -> 伝票トランザクションにてフィルタしてExcel出力での対応 | AB34: 標準 | AC34: =テーブル1[[#This Row],[要求事項一覧 判定]]=テーブル1[[#This Row],[列2]] -> TRUE
A35: =テーブル1[[#This Row],[対象部門]]&テーブル1[[#This Row],[業務要件回答表からの事前回答案_v1.0.xlsxより]] -> 一般会計全般・決算7.6 | B35: 一般会計全般・決算7.6 | D35: Req031 | E35: 当日を含め指定した特定の日付に転記された伝票明細表が画面照会および帳票出力できること ※伝票の仕訳情報の一覧 | F35: 当日を含め指定した特定の日付に転記された伝票の明細表を出力する機能 | G35: 7.6 | H35: サンスター | J35: 一般会計全般・決算 | K35: 決算G | O35: FO | Q35: 月次決算処理 | R35: 不要 | S35: 伝票トランザクション(伝票明細確認画面)にてフィルタ指定で伝票の検索および明細出力が可能 | T35: IN | X35: =テーブル1[[#This Row],[開発]]&テーブル1[[#This Row],[スコープ]] -> 不要IN | Y35: =IF(テーブル1[[#This Row],[列1]]="不要IN","標準",IF(テーブル1[[#This Row],[列1]]="不要OUT","スコープアウト",IF(テーブル1[[#This Row],[列1]]="必要IN","アドオン",IF(テーブル1[[#This Row],[列1]]="OUT","スコープアウト","")))) -> 標準 | Z35: =VLOOKUP($B35,Sheet1!$C$2:$L$315,9,) -> 会計システム標準機能 | AA35: =VLOOKUP($B35,Sheet1!$C$2:$L$315,10,) -> 伝票トランザクションにてフィルタしてExcel出力での対応 | AB35: 標準 | AC35: =テーブル1[[#This Row],[要求事項一覧 判定]]=テーブル1[[#This Row],[列2]] -> TRUE
A36: =テーブル1[[#This Row],[対象部門]]&テーブル1[[#This Row],[業務要件回答表からの事前回答案_v1.0.xlsxより]] -> 一般会計全般・決算7.7 | B36: 一般会計全般・決算7.7 | D36: Req032 | E36: 当日を含め指定した特定の日付に転記された伝票集計表が画面照会および帳票出力できること ※伝票の仕訳情報が勘定科目等別に集計された一覧 | F36: 当日を含め指定した特定の日付に転記された伝票の集計表を出力する機能 | G36: 7.7 | H36: サンスター | J36: 一般会計全般・決算 | K36: 決算G | O36: FO | Q36: 月次決算処理 | R36: 不要 | S36: 伝票トランザクション(伝票明細確認画面)のフィルタし結果をExcel出力して科目集計。 または、分析コード明細書で「合計」モードで科目残高を出力 | T36: IN | X36: =テーブル1[[#This Row],[開発]]&テーブル1[[#This Row],[スコープ]] -> 不要IN | Y36: =IF(テーブル1[[#This Row],[列1]]="不要IN","標準",IF(テーブル1[[#This Row],[列1]]="不要OUT","スコープアウト",IF(テーブル1[[#This Row],[列1]]="必要IN","アドオン",IF(テーブル1[[#This Row],[列1]]="OUT","スコープアウト","")))) -> 標準 | Z36: =VLOOKUP($B36,Sheet1!$C$2:$L$315,9,) -> 会計システム標準機能 | AA36: =VLOOKUP($B36,Sheet1!$C$2:$L$315,10,) -> 伝票トランザクションにてフィルタしてExcel出力での対応 | AB36: 標準 | AC36: =テーブル1[[#This Row],[要求事項一覧 判定]]=テーブル1[[#This Row],[列2]] -> TRUE
A37: =テーブル1[[#This Row],[対象部門]]&テーブル1[[#This Row],[業務要件回答表からの事前回答案_v1.0.xlsxより]] -> 一般会計全般・決算7.8 | B37: 一般会計全般・決算7.8 | D37: Req033 | E37: 売上高明細表・仕入高明細表が画面照会および帳票出力できること ※指定された会計期間における、売上仕入対象勘定科目の仕訳明細情報の一覧 | F37: 売上仕入対象勘定の実績から売上高明細表・仕入高明細表を出力する機能 | G37: 7.8 | H37: サンスター | J37: 一般会計全般・決算 | K37: 決算G | O37: FO | Q37: 月次決算処理 | R37: 不要 | S37: 伝票トランザクション(伝票明細確認画面)にてフィルタ指定で売上高明細、仕入高明細の確認が可能。 | T37: IN | X37: =テーブル1[[#This Row],[開発]]&テーブル1[[#This Row],[スコープ]] -> 不要IN | Y37: =IF(テーブル1[[#This Row],[列1]]="不要IN","標準",IF(テーブル1[[#This Row],[列1]]="不要OUT","スコープアウト",IF(テーブル1[[#This Row],[列1]]="必要IN","アドオン",IF(テーブル1[[#This Row],[列1]]="OUT","スコープアウト","")))) -> 標準 | Z37: =VLOOKUP($B37,Sheet1!$C$2:$L$315,9,) -> 会計システム標準機能 | AA37: =VLOOKUP($B37,Sheet1!$C$2:$L$315,10,) -> 伝票トランザクションにてフィルタしてExcel出力での対応 | AB37: 標準 | AC37: =テーブル1[[#This Row],[要求事項一覧 判定]]=テーブル1[[#This Row],[列2]] -> TRUE
A38: =テーブル1[[#This Row],[対象部門]]&テーブル1[[#This Row],[業務要件回答表からの事前回答案_v1.0.xlsxより]] -> 一般会計全般・決算7.9 | B38: 一般会計全般・決算7.9 | D38: Req034 | E38: 売上高集計表、仕入高集計表が画面照会および帳票出力できること ※指定された会計期間における、売上対象勘定科目・仕入対象勘定科目の実績が集計された一覧 | F38: 売上仕入対象勘定の実績から売上高集計表・仕入高集計表を出力する機能 | G38: 7.9 | H38: サンスター | J38: 一般会計全般・決算 | K38: 決算G | O38: FO | Q38: 月次決算処理 | R38: 不要 | S38: 試算表で対象科目をフィルタすることで、売上高集計表・仕入高集計表を出力可能 または、ManagementReportで残高表を作成 | T38: IN | X38: =テーブル1[[#This Row],[開発]]&テーブル1[[#This Row],[スコープ]] -> 不要IN | Y38: =IF(テーブル1[[#This Row],[列1]]="不要IN","標準",IF(テーブル1[[#This Row],[列1]]="不要OUT","スコープアウト",IF(テーブル1[[#This Row],[列1]]="必要IN","アドオン",IF(テーブル1[[#This Row],[列1]]="OUT","スコープアウト","")))) -> 標準 | Z38: =VLOOKUP($B38,Sheet1!$C$2:$L$315,9,) -> 会計システム標準機能 | AA38: =VLOOKUP($B38,Sheet1!$C$2:$L$315,10,) -> 伝票トランザクションにてフィルタしてExcel出力での対応 | AB38: 標準 | AC38: =テーブル1[[#This Row],[要求事項一覧 判定]]=テーブル1[[#This Row],[列2]] -> TRUE
A39: =テーブル1[[#This Row],[対象部門]]&テーブル1[[#This Row],[業務要件回答表からの事前回答案_v1.0.xlsxより]] -> 一般会計全般・決算8.1 | B39: 一般会計全般・決算8.1 | D39: Req035 | E39: 接待交際費集計表が画面照会および帳票出力できること ※指定された会計期間(月次/年度等)における接待交際費の仕訳明細情報が、勘定科目、細目、月別等に集計された一覧 | F39: 接待交際費集計表を出力する機能 | G39: 8.1 | H39: サンスター | J39: 一般会計全般・決算 | K39: 決算G | M39: 楽楽精算で帳票出力しているが、財務分析コードに交際費分類を設定も可か。楽楽精算から補助科目でIF？（武市） | O39: FO | Q39: 税務 | R39: 不要 | S39: 試算表で対象科目をフィルタすることで、科目集計表を出力可能 または、ManagementReportで残高表を作成 | T39: IN | X39: =テーブル1[[#This Row],[開発]]&テーブル1[[#This Row],[スコープ]] -> 不要IN | Y39: =IF(テーブル1[[#This Row],[列1]]="不要IN","標準",IF(テーブル1[[#This Row],[列1]]="不要OUT","スコープアウト",IF(テーブル1[[#This Row],[列1]]="必要IN","アドオン",IF(テーブル1[[#This Row],[列1]]="OUT","スコープアウト","")))) -> 標準 | Z39: =VLOOKUP($B39,Sheet1!$C$2:$L$315,9,) -> 会計システム標準機能 | AA39: =VLOOKUP($B39,Sheet1!$C$2:$L$315,10,) -> 伝票トランザクションにてフィルタしてExcel出力での対応 | AB39: 標準 | AC39: =テーブル1[[#This Row],[要求事項一覧 判定]]=テーブル1[[#This Row],[列2]] -> TRUE
A40: =テーブル1[[#This Row],[対象部門]]&テーブル1[[#This Row],[業務要件回答表からの事前回答案_v1.0.xlsxより]] -> 一般会計全般・決算8.2 | B40: 一般会計全般・決算8.2 | D40: Req036 | E40: 消費税申告書と申告書作成に必要なデータが作成・出力できること | F40: 消費税申告書を作成・出力する機能 | G40: 8.2 | H40: サンスター | J40: 一般会計全般・決算 | K40: 決算G | M40: 現状、税務会計ソフト側で申告書を作成しているので その元データが出力できればよい。 | O40: FO | Q40: 税務 | R40: 不要 | T40: OUT | X40: =テーブル1[[#This Row],[開発]]&テーブル1[[#This Row],[スコープ]] -> 不要OUT | Y40: =IF(テーブル1[[#This Row],[列1]]="不要IN","標準",IF(テーブル1[[#This Row],[列1]]="不要OUT","スコープアウト",IF(テーブル1[[#This Row],[列1]]="必要IN","アドオン",IF(テーブル1[[#This Row],[列1]]="OUT","スコープアウト","")))) -> スコープアウト | Z40: =VLOOKUP($B40,Sheet1!$C$2:$L$315,9,) -> 会計システム標準機能 | AA40: =VLOOKUP($B40,Sheet1!$C$2:$L$315,10,) -> MRで対応 | AB40: 標準 | AC40: =テーブル1[[#This Row],[要求事項一覧 判定]]=テーブル1[[#This Row],[列2]] -> FALSE
...

Sheet Sheet1
D1: 業務内容 | K1: RFP回答
C2: 結合キー | D2: Lv1 | E2: Lv2 | F2: Lv3 | G2: Lv4 | H2: No | I2: 業務概要 | J2: 対応機能 | K2: システム対応可否 | L2: 会計システム標準機能以外の場合、実現方法詳細
A3: 一般会計全般・決算 | B3: =A3&H3 -> 一般会計全般・決算1.1 | C3: 一般会計全般・決算1.1 | D3: 一般会計全般 | E3: 仕訳処理 | F3: 仕訳データ入力 | G3: 仕訳入力 | H3: 1.1 | I3: 画面入力で仕訳伝票を登録できること (勘定科目を変更せず、仕訳の入力項目の修正のための振替伝票も起票可能であること) ⇒()内の記述は、登録ミスした仕訳伝票の訂正伝票の登録方法に関する記述 | J3: 仕訳伝票の登録機能 | K3: 会計システム標準機能
A4: 一般会計全般・決算 | B4: =A4&H4 -> 一般会計全般・決算1.2 | C4: 一般会計全般・決算1.2 | D4: 一般会計全般 | E4: 仕訳処理 | F4: 仕訳データ入力 | G4: 仕訳入力 | H4: 1.2 | I4: 多通貨で仕訳伝票が登録でき、入力通貨金額が報告通貨金額（邦貨）に換算した額も登録できること | J4: 多通貨の仕訳伝票の登録機能 | K4: 会計システム標準機能
A5: 一般会計全般・決算 | B5: =A5&H5 -> 一般会計全般・決算1.3 | C5: 一般会計全般・決算1.3 | D5: 一般会計全般 | E5: 仕訳処理 | F5: 仕訳データ入力 | G5: 仕訳入力 | H5: 1.3 | I5: Excelフォーマット（取引先、取引内容、部門、消費税区分、金額、伝票日付、相手科目等）のアップロード機能で仕訳作成できること ※機能通貨への換算、消費税明細計上(内税/外税)、為替差損益明細計上への対応、および相互通貨バランスチェック、最新データの取得が可能であること | J5: 仕訳アップロード機能で仕訳を作成する機能 | K5: 会計システム標準機能
A6: 一般会計全般・決算 | B6: =A6&H6 -> 一般会計全般・決算1.4 | C6: 一般会計全般・決算1.4 | D6: 一般会計全般 | E6: 仕訳処理 | F6: 仕訳データ入力 | G6: 仕訳入力 | H6: 1.4 | I6: 勘定科目別に入力条件が設定でき、条件外の場合はエラーアラートが表示できること ⇒例えば経費科目であれば経費発生部門(原価センタ)の入力が必須になるなど、勘定科目の種類に応じて入力の必須・任意(入力フィールドの表示・非表示)をコントロールする機能のイメージです。(SAPでは項目ステータスと呼ばれる機能に該当します。) | J6: 勘定科目別に入力条件を指定する機能 | K6: 会計システム標準機能
A7: 一般会計全般・決算 | B7: =A7&H7 -> 一般会計全般・決算1.5 | C7: 一般会計全般・決算1.5 | D7: 一般会計全般 | E7: 仕訳処理 | F7: 仕訳データ入力 | G7: 仕訳入力 | H7: 1.5 | I7: 複数の仕訳をまとめて仕訳アップロード機能で作成することができること | J7: 複数仕訳を同時で起票できる機能 | K7: 会計システム標準機能
A8: 一般会計全般・決算 | B8: =A8&H8 -> 一般会計全般・決算1.6 | C8: 一般会計全般・決算1.6 | D8: 一般会計全般 | E8: 仕訳処理 | F8: 仕訳データ入力 | G8: 仕訳入力 | H8: 1.6 | I8: 転記済みの仕訳をコピーして登録できること | J8: 転記済みの仕訳をコピーして一部内容を修正することで新たな仕訳として登録できる機能 | K8: 会計システム標準機能 | L8: 仕訳帳のテンプレート登録にて対応
A9: 一般会計全般・決算 | B9: =A9&H9 -> 一般会計全般・決算1.7 | C9: 一般会計全般・決算1.7 | D9: 一般会計全般 | E9: 仕訳処理 | F9: 仕訳データ入力 | G9: 仕訳入力 | H9: 1.7 | I9: 転記前に、転記後の残高を事前にシミュレーション表示できること | J9: 登録は済んでいるが、まだ転記されていない仕訳について、転記後の残高を事前に確認できるように、シミュレーション表示できる機能 | K9: 会計システムアドオン | L9: 未転記の仕訳を選択後、ボタン押下後に転記後の残高を確認できるポップアップ画面を表示する機能を追加する
A10: 一般会計全般・決算 | B10: =A10&H10 -> 一般会計全般・決算1.8 | C10: 一般会計全般・決算1.8 | D10: 一般会計全般 | E10: 仕訳処理 | F10: 仕訳データ入力 | G10: 定型仕訳 | H10: 1.8 | I10: 定型の仕訳伝票に関して、配賦用のテンプレートを定義、繰り返し使用できること ※テンプレート項目例：配賦元部門/勘定科目/金額、配賦先部門/勘定科目金額、配賦基準(金額比、割合比等) | J10: 配賦のために定型の仕訳伝票を入力テンプレートとして定義する機能 | K10: 会計システム標準機能 | L10: 一般仕訳帳のテンプレ機能があります。（配賦のためというわけではない）
A11: 一般会計全般・決算 | B11: =A11&H11 -> 一般会計全般・決算1.9 | C11: 一般会計全般・決算1.9 | D11: 一般会計全般 | E11: 仕訳処理 | F11: 仕訳データ入力 | G11: 定型仕訳 | H11: 1.9 | I11: 定型の仕訳伝票に関して、伝票登録時の入力テンプレートを定義し、繰り返し使用できること | J11: 各会計期間で繰り返される定型の仕訳を処理するため、定型の仕訳伝票を入力テンプレートとして定義する機能 | K11: 会計システム標準機能
A12: 一般会計全般・決算 | B12: =A12&H12 -> 一般会計全般・決算2.1 | C12: 一般会計全般・決算2.1 | D12: 一般会計全般 | E12: 仕訳処理 | F12: 仕訳データ修正 | G12: 修正仕訳 | H12: 2.1 | I12: 未転記の場合、登録した仕訳伝票を登録者の方から修正することができること | J12: 仕訳明細情報を訂正する機能 | K12: 会計システム標準機能
A13: 一般会計全般・決算 | B13: =A13&H13 -> 一般会計全般・決算2.2 | C13: 一般会計全般・決算2.2 | D13: 一般会計全般 | E13: 仕訳処理 | F13: 仕訳データ修正 | G13: 修正仕訳 | H13: 2.2 | I13: 未転記の場合、登録した仕訳伝票を登録者の方から削除することができること | J13: 仕訳明細情報を削除する機能 | K13: 会計システム標準機能
A14: 一般会計全般・決算 | B14: =A14&H14 -> 一般会計全般・決算2.3 | C14: 一般会計全般・決算2.3 | D14: 一般会計全般 | E14: 仕訳処理 | F14: 仕訳データ修正 | G14: 逆仕訳 | H14: 2.3 | I14: 登録した仕訳伝票を符号の変更（登録された仕訳伝票の金額をプラスからマイナスに変更）できること | J14: 逆仕訳を生成する機能 | K14: 会計システム標準機能 | L14: 転記済み仕訳を指定し「仕訳全体の取り消し」
A15: 一般会計全般・決算 | B15: =A15&H15 -> 一般会計全般・決算3.1 | C15: 一般会計全般・決算3.1 | D15: 一般会計全般 | E15: 仕訳処理 | F15: 仕訳の転記 | G15: 仕訳の転記 | H15: 3.1 | I15: 承認者による承認のもと、仕訳伝票を転記できること | J15: 仕訳を転記する機能 | K15: 会計システム標準機能
A16: 一般会計全般・決算 | B16: =A16&H16 -> 一般会計全般・決算3.2 | C16: 一般会計全般・決算3.2 | D16: 一般会計全般 | E16: 仕訳処理 | F16: 仕訳の転記 | G16: 仕訳の転記 | H16: 3.2 | I16: 自動で転記処理を行うために、転記承認を経ずに転記できること | J16: 自動で転記処理を行う機能 | K16: 会計システム標準機能 | L16: 特定金額以下であれば、承認不要（転記可能）等は設定できる。
A17: 一般会計全般・決算 | B17: =A17&H17 -> 一般会計全般・決算4.1 | C17: 一般会計全般・決算4.1 | D17: 一般会計全般 | E17: 仕訳処理 | F17: 仕訳の承認 | G17: 仕訳の承認 | H17: 4.1 | I17: 仕訳作成者が、設定された仕訳の承認要求ができること | J17: 仕訳の承認依頼を行う機能 | K17: 会計システム標準機能
A18: 一般会計全般・決算 | B18: =A18&H18 -> 一般会計全般・決算4.2 | C18: 一般会計全般・決算4.2 | D18: 一般会計全般 | E18: 仕訳処理 | H18: 4.2 | I18: 仕訳作成者が、設定された仕訳バッチ一覧から任意の単位で仕訳を一括に承認要求ができること | J18: 一括で仕訳の承認依頼を行う機能 | K18: 会計システムアドオン | L18: 一括で承認依頼/承認を行う機能を追加する
A19: 一般会計全般・決算 | B19: =A19&H19 -> 一般会計全般・決算4.3 | C19: 一般会計全般・決算4.3 | D19: 一般会計全般 | E19: 仕訳処理 | F19: 仕訳の承認 | G19: 仕訳の承認 | H19: 4.3 | I19: 仕訳一括承認依頼受領時に、任意の仕訳単位に対して一括で承認、否決処理ができること | J19: 一括で仕訳の承認を行う機能 | K19: 会計システムアドオン | L19: 4.3の範囲にて対応。
A20: 一般会計全般・決算 | B20: =A20&H20 -> 一般会計全般・決算5.1 | C20: 一般会計全般・決算5.1 | D20: 一般会計全般 | E20: 仕訳処理 | F20: 未転記の仕訳管理 | G20: 未転記の仕訳管理 | H20: 5.1 | I20: 仕訳入力者を区分として、仕訳のステータスが未承認または承認依頼未済である仕訳の仕訳明細情報を一覧で、画面照会および帳票出力できること | J20: 承認依頼時に、依頼者別の未承認または承認依頼未済の仕訳明細情報を一覧で出力する機能 | K20: 会計システム標準機能
A21: 一般会計全般・決算 | B21: =A21&H21 -> 一般会計全般・決算5.2 | C21: 一般会計全般・決算5.2 | D21: 一般会計全般 | E21: 仕訳処理 | F21: 未転記の仕訳管理 | G21: 未転記の仕訳管理 | H21: 5.2 | I21: 承認依頼が必要な未承認の仕訳を勘定科目別に集計した一覧で、画面照会および帳票出力できること | J21: 承認依頼が必要な仕訳を勘定科目別に集計した一覧を出力する機能 | K21: 会計システムアドオン | L21: 新規画面として、承認依頼が必要な仕訳を勘定科目別に集計した一覧を出力する画面を作成。帳票に関しては、現時点では標準機能のExcelファイルエクスポート機能を使用予定。要件次第で開発とする。
A22: 一般会計全般・決算 | B22: =A22&H22 -> 一般会計全般・決算6.1 | C22: 一般会計全般・決算6.1 | D22: 一般会計全般 | E22: 残高確認 | F22: 残高照会 | G22: 帳票・明細出力 | H22: 6.1 | I22: 前日、前月末までの借方貸方の累計と残高を集計し、画面照会および帳票出力ができること | J22: 指定時点での科目別残高一覧を出力する機能 | K22: 会計システム標準機能
A23: 一般会計全般・決算 | B23: =A23&H23 -> 一般会計全般・決算6.2 | C23: 一般会計全般・決算6.2 | D23: 一般会計全般 | E23: 残高確認 | F23: 残高照会 | G23: 帳票・明細出力 | H23: 6.2 | I23: 指定された会計期間において発生した任意の勘定科目の残高明細情報を、画面照会および帳票出力できること | J23: 科目別残高明細一覧を出力する機能 | K23: 会計システム標準機能
A24: 一般会計全般・決算 | B24: =A24&H24 -> 一般会計全般・決算6.3 | C24: 一般会計全般・決算6.3 | D24: 一般会計全般 | E24: 残高確認 | F24: 残高照会 | G24: 帳票・明細出力 | H24: 6.3 | I24: 前期末の残高明細情報と比較できること | J24: 前年同期比で残高の比較照合ができる機能 | K24: 会計システム標準機能 | L24: MRで対応
A25: 一般会計全般・決算 | B25: =A25&H25 -> 一般会計全般・決算6.4 | C25: 一般会計全般・決算6.4 | D25: 一般会計全般 | E25: 残高確認 | F25: 残高照会 | G25: 帳票・明細出力 | H25: 6.4 | I25: 特定の会計期間において勘定科目別、貨幣別等で各残高を集計して、画面照会および帳票出力ができること | J25: 特定の会計期間において勘定科目別の残高を指定した一定の条件別に一覧化して集計する機能 | K25: 会計システム標準機能
A26: 一般会計全般・決算 | B26: =A26&H26 -> 一般会計全般・決算6.5 | C26: 一般会計全般・決算6.5 | D26: 一般会計全般 | E26: 残高確認 | F26: 残高照会 | G26: 赤残チェック | H26: 6.5 | I26: 各勘定科目の残高を確認し、残高がマイナスである科目がある場合、該当科目別の残高を通貨・会社毎にリストとして、画面照会および帳票出力ができること | J26: 残高がマイナスである科目を一覧で出力する機能 | K26: 会計システム標準機能 | L26: 勘定科目一覧画面で、金額欄にマイナス金額のフィルタを使用
A27: 一般会計全般・決算 | B27: =A27&H27 -> 一般会計全般・決算6.6 | C27: 一般会計全般・決算6.6 | D27: 一般会計全般 | E27: 残高確認 | F27: 残高照会 | G27: 赤残チェック | H27: 6.6 | I27: 決算時の通過勘定科目の残高を確認し、残高が0円以外の科目がある場合、該当科目別の残高を通貨・会社毎にリストとして、画面照会および帳票出力ができること | J27: 決算時において0円である必要がある勘定科目(通過勘定科目)に対し未整理の残高が存在する場合、対象の残高情報を一覧で出力する機能 | K27: 会計システム標準機能 | L27: 伝票トランザクションにてフィルタしてExcel出力での対応
A28: 一般会計全般・決算 | B28: =A28&H28 -> 一般会計全般・決算7.1 | C28: 一般会計全般・決算7.1 | D28: 一般会計全般 | E28: レポート・伝票 | F28: 会計・単体決算用 | G28: 財務諸表 | H28: 7.1 | I28: 指定された会計期間時点での以下の財務諸表を、全社、部門別で、画面照会および帳票出力できること ・貸借対照表(BS) ・損益計算書(PL累計) ・株主資本等変動計算書(SS) ・注記表 ・キャッシュフロー計算書(CF) ・製造原価報告書 ・労務費及び生産費明細表 ・営業費明細表 ・研究費明細表 | J28: 財務諸表をを全社/各社別に作成・出力する機能(BS/PLについては開示用科目(親科目)と集計元科目(子科目)単位でそれぞれ閲覧できること) | K28: 会計システム標準機能 | L28: 「注記表」以外につきましては、FO標準機能の財務諸表で対応可能と考えております。ただ、「注記表」については、標準機能のWordテンプレートを使用して、帳票出力を検討しております。ただし、要件次第では、開発が必要となる場合もございます。
A29: 一般会計全般・決算 | B29: =A29&H29 -> 一般会計全般・決算7.2 | C29: 一般会計全般・決算7.2 | D29: 一般会計全般 | E29: レポート・伝票 | F29: 会計・単体決算用 | G29: 財務諸表作成 | H29: 7.2 | I29: 各財務諸表類の前年度比較ができること | J29: 前年同期比で各財務諸表類の比較照合ができる機能 | K29: 会計システム標準機能 | L29: MRで対応
A30: 一般会計全般・決算 | B30: =A30&H30 -> 一般会計全般・決算7.3 | C30: 一般会計全般・決算7.3 | D30: 一般会計全般 | E30: レポート・伝票 | F30: 会計・単体決算用 | G30: 決算開示書類 | H30: 7.3 | I30: 年次毎に下記の決算開示書類を作成すること ・計算書類 ・附属明細書 ・決算短信 ・事業報告書 ・勘定明細 | J30: 決算開示書類を作成・出力する機能 | K30: 会計システムアドオン | L30: 下記帳票類の作成 ・計算書類 ・附属明細書 ・決算短信 ・事業報告書 ・勘定明細
A31: 一般会計全般・決算 | B31: =A31&H31 -> 一般会計全般・決算7.4 | C31: 一般会計全般・決算7.4 | D31: 一般会計全般 | E31: レポート・伝票 | F31: 会計・単体決算用 | G31: 決算開示書類 | H31: 7.4 | I31: 決算開示書類の計算書類や付属明細書、勘定明細書の前年度比較ができること | J31: 前年同期比で各決算開示書類の比較照合ができる機能 | K31: 会計システムアドオン | L31: 下記帳票類の履歴管理機能 ・計算書類 ・附属明細書 ・決算短信 ・事業報告書 ・勘定明細
A32: 一般会計全般・決算 | B32: =A32&H32 -> 一般会計全般・決算7.5 | C32: 一般会計全般・決算7.5 | D32: 一般会計全般 | E32: レポート・伝票 | F32: 会計・単体決算用 | G32: 帳簿 | H32: 7.5 | I32: 指定された会計期間時点での以下の帳簿類を、全社、部門別で、画面照会および出力できること。また、これらの帳簿を指定した日にシステムから指定したデータを自動で保存できること。 ・仕訳帳 （仕訳のステータス(未承認、転記済み、エラー)を区分として、仕訳帳が画面照会および帳票出力でき、仕訳一覧から、ドリルダウンして明細情報が確認できること） ・総勘定元帳 （指定された会計期間(月次/年度等)における、仕訳明細情報(借方、貸方、残高)が、勘定科目別、伝票日付別、転記処理日別、仕訳ソース別、仕訳カテゴリー別等に集計された一覧） （指定された会計期間(月次/年度等)における、仕訳明細情報(借方、貸方、残高)が、勘定科目別、伝票日付別、転記処理日別、仕訳ソース別、仕訳カテゴリー別等に集計された一覧） ・補助簿（固定資産台帳を含む） （指定された会計期間(月次/年度等)における、仕訳の明細情報の勘定科目別、伝票日付別、取引先別等の一覧） ・勘定残高表 （指定された会計期間(月次/年度等)における、指定された勘定科目の残高(前期末残高、借方、貸方)が集計された一覧） ・消費税台帳 （指定された会計期間(月次/年度等)における、売上高・仕入高と消費税額がで集計された一覧） | J32: 仕訳帳、総勘定元帳、補助記入帳、補助元帳、勘定残高表、消費税台帳等を出力、また、指定日に応じて自動保存する機能 | K32: 会計システム標準機能 | L32: 伝票トランザクションにてフィルタしてExcel出力での対応
A33: 一般会計全般・決算 | B33: =A33&H33 -> 一般会計全般・決算7.6 | C33: 一般会計全般・決算7.6 | D33: 一般会計全般 | E33: レポート・伝票 | F33: 会計・単体決算用 | G33: 伝票 | H33: 7.6 | I33: 当日を含め指定した特定の日付に転記された伝票明細表が画面照会および帳票出力できること ※伝票の仕訳情報の一覧 | J33: 当日を含め指定した特定の日付に転記された伝票の明細表を出力する機能 | K33: 会計システム標準機能 | L33: 伝票トランザクションにてフィルタしてExcel出力での対応
A34: 一般会計全般・決算 | B34: =A34&H34 -> 一般会計全般・決算7.7 | C34: 一般会計全般・決算7.7 | D34: 一般会計全般 | E34: レポート・伝票 | F34: 会計・単体決算用 | G34: 伝票 | H34: 7.7 | I34: 当日を含め指定した特定の日付に転記された伝票集計表が画面照会および帳票出力できること ※伝票の仕訳情報が勘定科目等別に集計された一覧 | J34: 当日を含め指定した特定の日付に転記された伝票の集計表を出力する機能 | K34: 会計システム標準機能 | L34: 伝票トランザクションにてフィルタしてExcel出力での対応
A35: 一般会計全般・決算 | B35: =A35&H35 -> 一般会計全般・決算7.8 | C35: 一般会計全般・決算7.8 | D35: 一般会計全般 | E35: レポート・伝票 | F35: 会計・単体決算用 | G35: 売上高/仕入高の明細・集計 | H35: 7.8 | I35: 売上高明細表・仕入高明細表が画面照会および帳票出力できること ※指定された会計期間における、売上仕入対象勘定科目の仕訳明細情報の一覧 | J35: 売上仕入対象勘定の実績から売上高明細表・仕入高明細表を出力する機能 | K35: 会計システム標準機能 | L35: 伝票トランザクションにてフィルタしてExcel出力での対応
A36: 一般会計全般・決算 | B36: =A36&H36 -> 一般会計全般・決算7.9 | C36: 一般会計全般・決算7.9 | D36: 一般会計全般 | E36: レポート・伝票 | F36: 会計・単体決算用 | G36: 売上高/仕入高の明細・集計 | H36: 7.9 | I36: 売上高集計表、仕入高集計表が画面照会および帳票出力できること ※指定された会計期間における、売上対象勘定科目・仕入対象勘定科目の実績が集計された一覧 | J36: 売上仕入対象勘定の実績から売上高集計表・仕入高集計表を出力する機能 | K36: 会計システム標準機能 | L36: 伝票トランザクションにてフィルタしてExcel出力での対応
A37: 一般会計全般・決算 | B37: =A37&H37 -> 一般会計全般・決算8.1 | C37: 一般会計全般・決算8.1 | D37: 一般会計全般 | E37: レポート・伝票 | F37: 税務用 | G37: 接待交際費 | H37: 8.1 | I37: 接待交際費集計表が画面照会および帳票出力できること ※指定された会計期間(月次/年度等)における接待交際費の仕訳明細情報が、勘定科目、細目、月別等に集計された一覧 | J37: 接待交際費集計表を出力する機能 | K37: 会計システム標準機能 | L37: 伝票トランザクションにてフィルタしてExcel出力での対応
... A45: 一般会計全般・決算 | B45: =A45&H45 -> 一般会計全般・決算9.2 | C45: 一般会計全般・決算9.2 | D45: 一般会計全般 | E45: レポート・伝票 | F45: 監査用 | G45: 増減調査＆資料作成 | H45: 9.2 | I45: 監査用に必要な増減調査用の資料を出力できること | J45: 監査用に必要な増減調査用の資料を出力できる機能 | K45: 会計システムアドオン | L45: 新規帳票を開発。
A46: 一般会計全般・決算 | B46: =A46&H46 -> 一般会計全般・決算10.1 | C46: 一般会計全般・決算10.1 | D46: 一般会計全般 | E46: その他 | F46: レート | G46: レート設定 | H46: 10.1 | I46: 月末・期末レートが定義できること | J46: 月末・期末レートを定義する機能 | K46: 会計システム標準機能
A47: 一般会計全般・決算 | B47: =A47&H47 -> 一般会計全般・決算10.2 | C47: 一般会計全般・決算10.2 | D47: 一般会計全般 | E47: その他 | F47: レート | G47: レート設定 | H47: 10.2 | I47: 通貨毎に月末・期末レートを自動設定できること | J47: 指定された通貨の期末レートを自動設定する機能 | K47: 会計システム標準機能
...

Sheet マスタ
B1: 優先度
B2: S | C2: 業務が停止してしまうので必須
B3: A | C3: 運用回避が可能だが、業務負荷が大きいもの
B4: B | C4: 運用回避が可能で、業務負荷がそれほど大きくないもの
B5: C | C5: 便利機能としての要求事項
B7: 対象システム
B8: FO
B9: CRM
B10: その他
B11: -
B13: 開発
B14: 必要
B15: 不要
B17: スコープ
B18: IN
B19: OUT
