Workbook
Name io: [1]マスタ!$B$3:$B$5
Name io: マスタ!$B$3:$B$5
Name LinkType: マスタ!$A$3:$A$9
Name Visivility: マスタ!$G$3:$G$4
Name オブジェクト: マスタ!$I$7:$I$20
Name オブジェクト一覧: [1]マスタ!$I$3:$I$20
Name オブジェクト一覧: マスタ!$I$3:$I$20
Name テーブル種別: [1]マスタ!$H$3:$H$4
Name テーブル種別: マスタ!$H$3:$H$4
Name ヘッダー明細行: マスタ!$K$3:$K$5
Name マスタ: マスタ!$I$3:$I$20
Name 横位置: [1]マスタ!$D$3:$D$6
Name 横位置: マスタ!$D$3:$D$6
Name 作成日: DATE(2000,3,21)
Name 取得元: マスタ!$J$3:$J$7
Name 縦位置: [1]マスタ!$E$3:$E$6
Name 縦位置: マスタ!$E$3:$E$6
Name 書式: [1]マスタ!$C$3:$C$5
Name 書式: マスタ!$C$3:$C$5
Name 折り返して全体を表示する: [1]マスタ!$F$3:$F$4
Name 折り返して全体を表示する: マスタ!$F$3:$F$4

Sheet 表紙
B3: サンスター株式会社 御中
B10: 会計システム刷新プロジェクト（LIBRA）
B14: FO-008_支払方法・支払サイト更新バッチ
AA21: ＜機能ID>_＜画面名＞画面を入力
B22: ="第"&IF(COUNTA(変更履歴!BE5:BG10000)=1,"",INDIRECT("変更履歴!BE"&COUNTA(変更履歴!BE5:BG10000)+4))&"版" -> 第1.7版
B24: =IF(OR(COUNTA(変更履歴!A:E)=2),"",INDIRECT("変更履歴!A"&COUNTA(変更履歴!A:E)+3)) -> 45708
B26: 日本ビジネスシステムズ株式会社
F29: 作成者 | O29: JBS承認者 | V29: 基本設計部確認者
F30: =変更履歴!AV2 -> 45477 | N30: 45484 | V30: 45530
F31: =変更履歴!BB2 -> JBS 秋信 | N31: JBS加藤 | V31: サンスター藤田

Sheet 変更履歴
A1: 設計書 | F1: システム名 | Q1: 機能分類 | W1: 機能ＩＤ | AE1: 機能名称 | AT1: 日付 | BB1: 更新者
F2: Dynamics365 for Finance and Operations | Q2: 債権・債務 | W2: FO-008 | AE2: 支払方法・支払サイト更新バッチ | AT2: 作成 | AV2: =A6 -> 45477 | BB2: =AZ6 -> JBS 秋信
AT3: 更新 | AV3: {=IF(OR(COUNTA(A:E)=2),"",INDIRECT("A"&COUNTA(A:E)+3))} -> 45708 | BB3: {=IF(COUNTA(AZ5:BD100018)=1,"",INDIRECT("AZ"&COUNTA(AZ5:BD100018)+4))} -> JBS秋信
AW4: （表紙同様値）
A5: 変更年月日 | F5: 変更箇所 | T5: 変更内容 | AZ5: 変更者 | BE5: 版数
A6: 45477 | F6: 新規作成 | T6: 新規作成 | AZ6: JBS 秋信 | BE6: 1.0
A7: 45594 | F7: シート「イベント説明」 | T7: シート:イベント説明 1-1-2.汎用パラメータの取得（電子記録債務対象の支払方法を取得） 下記のように修正をお願いします。 ■変更前 [汎用パラメータ.ItemId]＝”ElectronicallyRecorded” ■変更後 [汎用パラメータ.ItemId]＝”ElectronicDebit” | AZ7: JBS井田 | BE7: 1.1
A8: 45594 | F8: シート「補足説明 (汎用パラメータ)」 | T8: シート:補足説明 (汎用パラメータ) 下記のように修正をお願いします。 ■変更前 ElectronicallyRecorded ■変更後 ElectronicDebit | AZ8: JBS井田 | BE8: 1.1
A9: 45601 | F9: シート「補足説明 (処理イメージ)」 | T9: シート：補足説明 (処理イメージ) 処理対象外のデータの支払基準日、期日の値を修正 | AZ9: JBS秋信 | BE9: 1.2
A10: 45611 | F10: シート「イベント説明」 | T10: 処理1-3-1に分岐処理を追加 | AZ10: JBS秋信 | BE10: 1.3
A11: 45646 | F11: シート「画面レイアウト」 | T11: メニューパスを修正 | AZ11: JBS秋信 | BE11: 1.4
A12: 45686 | F12: シート「イベント説明」 | T12: 【IT-NG-005】 1-1-3.仕入先トランザクションの取得 1-3-1.データ取得 ・未処理トランザクションの抽出条件追加 ・金額の取得不備修正（仕入先トランザクションの”金額”ではなく、”残高”を取得） | AZ12: JBS秋信 | BE12: 1.5
A13: 45686 | F13: シート「テーブル出力仕様（支払方法・支払サイト更新ログ_金額参照）」 | T13: 【IT-NG-005】 説明（登録時）の項目：金額 の設定内容を修正 | AZ13: JBS秋信 | BE13: 1.5
A14: 45691 | F14: シート「画面レイアウト」 | T14: 【IT-NG-002】 バックグラウンドで実行 を追加 | AZ14: JBS秋信 | BE14: 1.6
A15: 45691 | F15: シート「イベント説明」 | T15: 【IT-NG-004】 処理1-5にて、期日設定時に支払カレンダーを考慮する旨を追記 | AZ15: JBS秋信 | BE15: 1.6
A16: 45708 | F16: プログラムフロー図 | T16: 「更新に成功したか？」のいいえの場合のメッセージを更新 | AZ16: FPTリン | BE16: 1.7
A17: 45708 | F17: シート「テーブル出力仕様」 シート「イベント説明」 シート「DFD」 シート「テーブル出力仕様（未処理の仕入先トランザクション）」 | T17: シート「テーブル出力仕様」 シート「イベント説明」 ⇒処理1-6-3.未処理の仕入先トランザクションの更新 を追加 シート「DFD」 ⇒未処理の仕入先トランザクションを追加 シート「テーブル出力仕様（未処理の仕入先トランザクション）」 ⇒シート新規作成 | AZ17: JBS秋信 | BE17: 1.7

Sheet 処理概要
A1: 基本設計書 | F1: =変更履歴!F1 -> システム名 | Q1: =変更履歴!Q1 -> 機能分類 | W1: =変更履歴!W1 -> 機能ＩＤ | AE1: =変更履歴!AE1 -> 機能名称 | AT1: =変更履歴!AT1 -> 日付 | BB1: =変更履歴!BB1 -> 更新者
F2: =変更履歴!F2 -> Dynamics365 for Finance and Operations | Q2: =変更履歴!Q2 -> 債権・債務 | W2: =変更履歴!W2 -> FO-008 | AE2: =変更履歴!AE2 -> 支払方法・支払サイト更新バッチ | AT2: =変更履歴!AT2 -> 作成 | AV2: =変更履歴!AV2 -> 45477 | BB2: =変更履歴!BB2 -> JBS 秋信
AT3: =変更履歴!AT3 -> 更新 | AV3: =変更履歴!AV3 -> 45708 | BB3: =変更履歴!BB3 -> JBS秋信
A5: 開発目的
B6: 1. | C6: 支払合計金額に応じて、銀行振込、または期日振込・電子記録債務を判定し、支払処理を行う必要があるため。
C7: ※ | D7: 銀行振込：支払基準日に支払を実施する振込。
D8: 期日振込：支払基準日に支払サイトを加算し、支払を実施する振込。
B9: 2. | C9: 仕入先の支払方法の変更は月2~3件発生するが、変更前に作成された債務データも新しい支払方法で支払を行う必要があるため。
A12: 前提条件
B13: 1. | C13: 基本的に実行は、支払予定の修正後とする。（支払月6日ごろ、手動実行）
B14: 2. | C14: 再実行が必要な場合は、本機能で更新対象となる項目（期日、支払方法・支払サイト更新フラグ、支払サイト）を仕入先トランザクション画面にて手動で修正し、バッチ（本機能）を実行すること。
C15: 支払予定と仕入先の支払方法に変更が発生した場合は、仕入先マスタの支払方法を変更する前にバッチ（本機能）を手動実行し、バッチが終了してから仕入先マスタの支払方法の変更を行うこと。
C16: 例） | E16: 7月計上8月払から適用される仕入先マスタの支払方法の変更は、7月分支払のバッチ（本機能）を実施後に仕入先マスタの支払方法の変更を行う。
B17: 3. | C17: 期日振込/電子記録債務からの支払方法の変更・規定外支払で使用する支払方法「2」は、処理の対象外とする。
A23: 使用タイミング
B24: 1. | C24: 月次
A29: 開発内容
B30: 1. | C30: 仕入先トランザクション（債務データ）の支払方法を仕入先マスタに登録されている支払方法に変更する。
C31: ただし、支払方法「2」が設定されているデータは除外する。
B32: 2. | C32: FO-006（支払方法・支払サイトマスタ画面）に登録されている支払方法の債務データを対象に、
C33: 仕入先ごとの債務データの合計金額に応じて、仕入先トランザクションの更新を行う。
C34: ・振込（銀行振込、期日振込）の場合：仕入先トランザクションの「期日」「支払方法」「支払サイト」の更新を行う。
C35: ・電子記録債務の場合：仕入先トランザクションの「支払方法」「支払サイト」の更新を行う。
B36: ※ | C36: 電子記録債務の場合は、支払手形仕訳帳の振出時にFO-010（支払手形仕訳帳の振出画面）にて「期日」の更新を行う。
A39: 制限事項
B40: 1. | C40: 更新対象の通貨は、JPYとする。
B41: 2.

Sheet テーブル一覧
A1: 基本設計書 | F1: =変更履歴!F1 -> システム名 | Q1: =変更履歴!Q1 -> 機能分類 | W1: =変更履歴!W1 -> 機能ＩＤ | AE1: =変更履歴!AE1 -> 機能名称 | AT1: =変更履歴!AT1 -> 日付 | BB1: =変更履歴!BB1 -> 更新者
F2: =変更履歴!F2 -> Dynamics365 for Finance and Operations | Q2: =変更履歴!Q2 -> 債権・債務 | W2: =変更履歴!W2 -> FO-008 | AE2: =変更履歴!AE2 -> 支払方法・支払サイト更新バッチ | AT2: =変更履歴!AT2 -> 作成 | AV2: =変更履歴!AV2 -> 45477 | BB2: =変更履歴!BB2 -> JBS 秋信
AT3: =変更履歴!AT3 -> 更新 | AV3: =変更履歴!AV3 -> 45708 | BB3: =変更履歴!BB3 -> JBS秋信
A5: No. | C5: 種別 | K5: 論理名 | AC5: 物理名 | AS5: I/O | AU5: 備考
A6: =ROW()-5 -> 1 | C6: テーブル | K6: 仕入先トランザクション | AC6: VendTrans | AS6: I/O
A7: =ROW()-5 -> 2 | C7: テーブル | K7: 支払方法・支払サイト | AC7: SJ_PaymModePaymSiteTable | AS7: I | AU7: アドオン
A8: =ROW()-5 -> 3 | C8: テーブル | K8: 支払方法・支払サイト更新ログ | AC8: SJ_PaymModePaymSiteUpdatedLog | AS8: I/O | AU8: アドオン
A9: =ROW()-5 -> 4 | C9: テーブル | K9: 汎用パラメータ | AC9: SJ_GeneralParameter | AS9: I | AU9: アドオン
A10: =ROW()-5 -> 5 | C10: テーブル | K10: 未処理の仕入先トランザクション | AC10: VendTransOpen | AS10: O
A11: =ROW()-5 -> 6
A12: =ROW()-5 -> 7
A13: =ROW()-5 -> 8
A14: =ROW()-5 -> 9
A15: =ROW()-5 -> 10
A16: =ROW()-5 -> 11
A17: =ROW()-5 -> 12
A18: =ROW()-5 -> 13
A19: =ROW()-5 -> 14
A20: =ROW()-5 -> 15
A21: =ROW()-5 -> 16
A22: =ROW()-5 -> 17
... A38: =ROW()-5 -> 33

Sheet DFD
A1: 基本設計書 | F1: =変更履歴!F1 -> システム名 | Q1: =変更履歴!Q1 -> 機能分類 | W1: =変更履歴!W1 -> 機能ＩＤ | AE1: =変更履歴!AE1 -> 機能名称 | AT1: =変更履歴!AT1 -> 日付 | BB1: =変更履歴!BB1 -> 更新者
F2: =変更履歴!F2 -> Dynamics365 for Finance and Operations | Q2: =変更履歴!Q2 -> 債権・債務 | W2: =変更履歴!W2 -> FO-008 | AE2: =変更履歴!AE2 -> 支払方法・支払サイト更新バッチ | AT2: =変更履歴!AT2 -> 作成 | AV2: =変更履歴!AV2 -> 45477 | BB2: =変更履歴!BB2 -> JBS 秋信
AT3: =変更履歴!AT3 -> 更新 | AV3: =変更履歴!AV3 -> 45708 | BB3: =変更履歴!BB3 -> JBS秋信
A5: イベント | O5: 機能 | AN5: DB
A151: 凡例
A152: 記号
AL156: ※DBが複数ある場合は複数DBをまとめるために使用

Sheet イベント説明
A1: 基本設計書 | F1: =変更履歴!F1 -> システム名 | Q1: =変更履歴!Q1 -> 機能分類 | W1: =変更履歴!W1 -> 機能ＩＤ | AE1: =変更履歴!AE1 -> 機能名称 | AT1: =変更履歴!AT1 -> 日付 | BB1: =変更履歴!BB1 -> 更新者
F2: =変更履歴!F2 -> Dynamics365 for Finance and Operations | Q2: =変更履歴!Q2 -> 債権・債務 | W2: =変更履歴!W2 -> FO-008 | AE2: =変更履歴!AE2 -> 支払方法・支払サイト更新バッチ | AT2: =変更履歴!AT2 -> 作成 | AV2: =変更履歴!AV2 -> 45477 | BB2: =変更履歴!BB2 -> JBS 秋信
AT3: =変更履歴!AT3 -> 更新 | AV3: =変更履歴!AV3 -> 45708 | BB3: =変更履歴!BB3 -> JBS秋信
A5: No. | C5: イベント名 | I5: 処理内容 | AO5: 種別 | AR5: メッセージ | BD5: ID
A6: 1. | C6: OK ボタン押下
J7: 1-1.データ取得（仕入先マスタ参照用）
K9: 1-1-1. | N9: 汎用パラメータの取得（処理対象外の支払方法の取得）
L10: 処理対象外の支払方法の取得する。
L11: （取得に失敗した場合、エラー出力は不要。）
L13: <項目>
M14: [値(Value)]
L15: ＜取得テーブル＞
M16: [汎用パラメータ(SJ_GeneralParameter)]
L17: ＜抽出条件＞
M18: [汎用パラメータ.機能ID(FunctionId)] | Z18: = | AA18: SJ_FunctionIdEnum::FO-008(FO-008)
L19: && | M19: [汎用パラメータ.項目ID(ItemId)] | Z19: = | AA19: ”002”
L20: && | M20: [汎用パラメータ.Key(Key)] | Z20: = | AA20: ”1”
K23: 1-1-2. | N23: 汎用パラメータの取得（電子記録債務対象の支払方法を取得）
L24: 電子記録債務対象の支払方法を取得する。
L25: 取得できなかった場合、メッセージを表示し処理を終了する。 | AO25: 情報ログ | AR25: 汎用パラメータに該当データが存在しません。 | BD25: SJ00224
AO26: Error | AR26: 機能ID 「%1」、項目ID 「%2」、Key 「%3」
L27: <項目> | AR27: ％1：”FO-014” | AT27: ”COMMON”
M28: [値(Value)] | AR28: ％2：”ElectronicDebit”
L29: ＜取得テーブル＞ | AR29: %3："-" | AT29: (空欄)
M30: [汎用パラメータ(SJ_GeneralParameter)]
L31: ＜抽出条件＞
M32: [汎用パラメータ.機能ID(FunctionId)] | Z32: = | AA32: SJ_FunctionIdEnum::COMMON(共通)
L33: && | M33: [汎用パラメータ.項目ID(ItemId)] | Z33: = | AA33: ”ElectronicDebit”
K36: 1-1-3. | N36: 仕入先トランザクションの取得
L37: 仕入先トランザクション(未処理)で、仕入先マスタに登録されている支払方法と異なるデータを取得する。
L38: 一件も取得できなかった場合は、1-3.の処理を実施する。
L40: <項目>
M41: [仕入先トランザクション.支払方法(PaymMode)]
M42: [仕入先トランザクション.仕入先(AccountNum)]
M43: [仕入先トランザクション.支払サイト(SJ_PaymSite)]
M44: [仕入先トランザクション.期日(DueDate)]
M45: [仕入先トランザクション.支払基準日(SJ_PaymtBaseDate)]
M46: [仕入先トランザクション.レコードID(RecId)]
M47: [仕入先.支払方法(PaymMode)]
L48: ＜取得テーブル＞
...

Sheet 画面レイアウト
A1: 基本設計書 | F1: =変更履歴!F1 -> システム名 | Q1: =変更履歴!Q1 -> 機能分類 | W1: =変更履歴!W1 -> 機能ＩＤ | AE1: =変更履歴!AE1 -> 機能名称 | AT1: =変更履歴!AT1 -> 日付 | BB1: =変更履歴!BB1 -> 更新者
F2: =変更履歴!F2 -> Dynamics365 for Finance and Operations | Q2: =変更履歴!Q2 -> 債権・債務 | W2: =変更履歴!W2 -> FO-008 | AE2: =変更履歴!AE2 -> 支払方法・支払サイト更新バッチ | AT2: =変更履歴!AT2 -> 作成 | AV2: =変更履歴!AV2 -> 45477 | BB2: =変更履歴!BB2 -> JBS 秋信
AT3: =変更履歴!AT3 -> 更新 | AV3: =変更履歴!AV3 -> 45708 | BB3: =変更履歴!BB3 -> JBS秋信
A5: パス | I5: [買掛金管理] > [定期処理のタスク] > [支払方法・支払サイト更新]
A6: フォーム名
A8: タブ名
B10: ＜バッチ画面＞

Sheet 画面項目説明
A1: 基本設計書 | F1: =変更履歴!F1 -> システム名 | Q1: =変更履歴!Q1 -> 機能分類 | W1: =変更履歴!W1 -> 機能ＩＤ | AE1: =変更履歴!AE1 -> 機能名称 | AT1: =変更履歴!AT1 -> 日付 | BB1: =変更履歴!BB1 -> 更新者
F2: =変更履歴!F2 -> Dynamics365 for Finance and Operations | Q2: =変更履歴!Q2 -> 債権・債務 | W2: =変更履歴!W2 -> FO-008 | AE2: =変更履歴!AE2 -> 支払方法・支払サイト更新バッチ | AT2: =変更履歴!AT2 -> 作成 | AV2: =変更履歴!AV2 -> 45477 | BB2: =変更履歴!BB2 -> JBS 秋信
AT3: =変更履歴!AT3 -> 更新 | AV3: =変更履歴!AV3 -> 45708 | BB3: =変更履歴!BB3 -> JBS秋信
A5: コントロール | H5: 項目名 | Q5: 種類 | U5: 入力 | W5: 必須 | Y5: 項目説明（概要） | BB5: 備考
A6: タイトル | Q6: 文字列 | U6: × | W6: × | Y6: ＜タイトル＞
Y7: ・Caption：支払方法・支払サイト更新
A9: 支払方法・支払サイト更新
D11: パラメーター
H12: 支払基準日 | Q12: 日付 | U12: 〇 | W12: 〇 | Y12: ＜入力内容＞
Y13: 日付形式：”YYYY/MM/DD”
Y14: ＜初期値＞
Y15: 空欄
H17: 仕入先 | Q17: テキスト | U17: 〇 | W17: × | Y17: ＜入力内容＞ | BB17: 仕入先コードでルックアップ
Y18: 仕入先コードを入力する。
Y19: ※ | Z19: 「,」で複数入力可能とする。
Y20: ※ | Z20: 「..」で範囲指定入力可能とする。
Y21: ＜初期値＞
Y22: 空欄
D24: ボタン
H25: OK | Q25: ボタン | Y25: ＜後処理＞
Y26: 「支払方法・支払サイト更新」画面を閉じる
H28: キャンセル | Q28: ボタン | Y28: ＜後処理＞
Y29: 「支払方法・支払サイト更新」画面を閉じる

Sheet 帳票レイアウト
A1: 基本設計書 | F1: =変更履歴!F1 -> システム名 | Q1: =変更履歴!Q1 -> 機能分類 | W1: =変更履歴!W1 -> 機能ＩＤ | AE1: =変更履歴!AE1 -> 機能名称 | AT1: =変更履歴!AT1 -> 日付 | BB1: =変更履歴!BB1 -> 更新者
F2: =変更履歴!F2 -> Dynamics365 for Finance and Operations | Q2: =変更履歴!Q2 -> 債権・債務 | W2: =変更履歴!W2 -> FO-008 | AE2: =変更履歴!AE2 -> 支払方法・支払サイト更新バッチ | AT2: =変更履歴!AT2 -> 作成 | AV2: =変更履歴!AV2 -> 45477 | BB2: =変更履歴!BB2 -> JBS 秋信
AT3: =変更履歴!AT3 -> 更新 | AV3: =変更履歴!AV3 -> 45708 | BB3: =変更履歴!BB3 -> JBS秋信
A5: レイアウト | AY5: 備考
A6: 帳票タイトル： | AI6: 帳票タイプ：
A7: 用紙サイズ： | L7: 用紙の向き： | X7: 自動サイズ調整： | AI7: フォント：
A8: 余白(cm) | F8: 左： | J8: 右： | N8: 上： | R8: 下： | AI8: テーブルソート設定：

Sheet 帳票出力仕様
A1: 基本設計書 | F1: =変更履歴!F1 -> システム名 | Q1: =変更履歴!Q1 -> 機能分類 | W1: =変更履歴!W1 -> 機能ＩＤ | AE1: =変更履歴!AE1 -> 機能名称 | AT1: =変更履歴!AT1 -> 日付 | BB1: =変更履歴!BB1 -> 更新者
F2: =変更履歴!F2 -> Dynamics365 for Finance and Operations | Q2: =変更履歴!Q2 -> 債権・債務 | W2: =変更履歴!W2 -> FO-008 | AE2: =変更履歴!AE2 -> 支払方法・支払サイト更新バッチ | AT2: =変更履歴!AT2 -> 作成 | AV2: =変更履歴!AV2 -> 45477 | BB2: =変更履歴!BB2 -> JBS 秋信
AT3: =変更履歴!AT3 -> 更新 | AV3: =変更履歴!AV3 -> 45708 | BB3: =変更履歴!BB3 -> JBS秋信
S5: 表示形式 | AB5: 配置
A6: ヘッダー/フッター/明細 | H6: No. | J6: 項目名 | S6: 書式 | V6: フォーマット | AB6: 横位置 | AE6: 縦位置 | AH6: サイズ | AK6: 最大項目長 （項目幅） | AO6: 出力値 | BL6: 備考 | CC6: 取得元テーブル | CO6: 取得元フィールド | DA6: 折り返して全体を 表示する | DG6: TmpTable | DT6: TmpTableフィールド
A8: ① ヘッダー | H8: =ROW()-7 -> 1 | DA8: ー
H9: =ROW()-7 -> 2 | DA9: ー
H10: =ROW()-7 -> 3 | DA10: ー
H11: =ROW()-7 -> 4 | DA11: ー
H12: =ROW()-7 -> 5 | DA12: ー
H13: =ROW()-7 -> 6 | DA13: ー
H14: =ROW()-7 -> 7 | DA14: ー
H15: =ROW()-7 -> 8 | DA15: ー
H16: =ROW()-7 -> 9 | DA16: ー
A17: ② 明細 | H17: =ROW()-7 -> 10 | DA17: ー
A18: （項目名） | H18: =ROW()-7 -> 11 | DA18: ー
H19: =ROW()-7 -> 12 | DA19: ー
H20: =ROW()-7 -> 13 | DA20: ー
H21: =ROW()-7 -> 14 | DA21: ー
H22: =ROW()-7 -> 15 | DA22: ー
H23: =ROW()-7 -> 16 | DA23: ー
H24: =ROW()-7 -> 17 | DA24: ー
H25: =ROW()-7 -> 18 | DA25: ー
H26: =ROW()-7 -> 19 | DA26: ー
H27: =ROW()-7 -> 20 | DA27: ー
H28: =ROW()-7 -> 21 | DA28: ー
H29: =ROW()-7 -> 22 | DA29: ー
H30: =ROW()-7 -> 23 | DA30: ー
A31: ②明細 | H31: =ROW()-7 -> 24 | DA31: ー
A32: （データ） | H32: =ROW()-7 -> 25 | DA32: ー
H33: =ROW()-7 -> 26 | DA33: ー
H34: =ROW()-7 -> 27 | DA34: ー
H35: =ROW()-7 -> 28 | DA35: ー
H36: =ROW()-7 -> 29 | DA36: ー
H37: =ROW()-7 -> 30 | DA37: ー
H38: =ROW()-7 -> 31 | DA38: ー
H39: =ROW()-7 -> 32 | DA39: ー
H40: =ROW()-7 -> 33 | DA40: ー
H41: =ROW()-7 -> 34 | DA41: ー
H42: =ROW()-7 -> 35 | DA42: ー
...

Sheet ファイルレイアウト
A1: 基本設計書 | F1: =変更履歴!F1 -> システム名 | Q1: =変更履歴!Q1 -> 機能分類 | W1: =変更履歴!W1 -> 機能ＩＤ | AE1: =変更履歴!AE1 -> 機能名称 | AT1: =変更履歴!AT1 -> 日付 | BB1: =変更履歴!BB1 -> 更新者
F2: =変更履歴!F2 -> Dynamics365 for Finance and Operations | Q2: =変更履歴!Q2 -> 債権・債務 | W2: =変更履歴!W2 -> FO-008 | AE2: =変更履歴!AE2 -> 支払方法・支払サイト更新バッチ | AT2: =変更履歴!AT2 -> 作成 | AV2: =変更履歴!AV2 -> 45477 | BB2: =変更履歴!BB2 -> JBS 秋信
AT3: =変更履歴!AT3 -> 更新 | AV3: =変更履歴!AV3 -> 45708 | BB3: =変更履歴!BB3 -> JBS秋信
A5: 文字コード： | I5: ファイル名称：
A6: 区切り文字： | I6: 文字列：
A7: 改行コード： | I7: ソート： | AT7: タイトル行：
A8: No. | C8: フィールド名 | Q8: 説明 | AT8: 属性 | AX8: 桁数 | AZ8: 備考
A9: =ROW()-8 -> 1
A10: =ROW()-8 -> 2
A11: =ROW()-8 -> 3
A12: =ROW()-8 -> 4
A13: =ROW()-8 -> 5
A14: =ROW()-8 -> 6
A15: =ROW()-8 -> 7
A16: =ROW()-8 -> 8
A17: =ROW()-8 -> 9
A18: =ROW()-8 -> 10
A19: =ROW()-8 -> 11
A20: =ROW()-8 -> 12
... A38: =ROW()-8 -> 30

Sheet テーブル出力仕様（支払方法・支払サイト更新ログ_仕入先参照）
A1: 基本設計書 | F1: =変更履歴!F1 -> システム名 | Q1: =変更履歴!Q1 -> 機能分類 | W1: =変更履歴!W1 -> 機能ＩＤ | AE1: =変更履歴!AE1 -> 機能名称 | AT1: =変更履歴!AT1 -> 日付 | BB1: =変更履歴!BB1 -> 更新者
F2: =変更履歴!F2 -> Dynamics365 for Finance and Operations | Q2: =変更履歴!Q2 -> 債権・債務 | W2: =変更履歴!W2 -> FO-008 | AE2: =変更履歴!AE2 -> 支払方法・支払サイト更新バッチ | AT2: =変更履歴!AT2 -> 作成 | AV2: =変更履歴!AV2 -> 45477 | BB2: =変更履歴!BB2 -> JBS 秋信
AT3: =変更履歴!AT3 -> 更新 | AV3: =変更履歴!AV3 -> 45708 | BB3: =変更履歴!BB3 -> JBS秋信
A5: テーブル名 | M5: SJ_PaymModePaymSiteUpdatedLog
A6: ラベル | M6: 支払方法・支払サイト更新ログ
A7: 拡張名
A8: No. | C8: 論理名 | M8: 物理名 | W8: 説明 | AZ8: 備考
A9: =ROW()-8 -> 1 | C9: 仕入先 | M9: AccountNum | W9: 1-1-3.で取得した[仕入先トランザクション].[仕入先]を設定
A10: =ROW()-8 -> 2 | C10: 金額 | M10: AmountMST | W10: -
A11: =ROW()-8 -> 3 | C11: 集計金額 | M11: TotalAmount | W11: -
A12: =ROW()-8 -> 4 | C12: 支払方法 | M12: PaymMode | W12: 1-1-3.で取得した[仕入先トランザクション].[支払方法]を設定
A13: =ROW()-8 -> 5 | C13: 支払方法(更新後) | M13: UpdatePayｍMode | W13: 1-1-3.で取得した[仕入先].[支払方法]を設定
A14: =ROW()-8 -> 6 | C14: 支払サイト | M14: PaymSite | W14: -
A15: =ROW()-8 -> 7 | C15: 支払サイト(更新後) | M15: UpdatePaymSite | W15: -
A16: =ROW()-8 -> 8 | C16: 期日 | M16: DueDate | W16: -
A17: =ROW()-8 -> 9 | C17: 期日(更新後) | M17: UpdateDueDate | W17: -
A18: =ROW()-8 -> 10 | C18: 支払基準日 | M18: PaymBaseDate | W18: 1-1-3.で取得した[仕入先トランザクション].[支払基準日]を設定
A19: =ROW()-8 -> 11 | C19: 参照 | M19: VendTransRecId | W19: 1-1-3.で取得した[仕入先トランザクション].[レコードID]を設定
A20: =ROW()-8 -> 12 | C20: 集計ステータス | M20: AggregationStatus | W20: SJ_AggregationStatusEnum::Excluded(対象外) を設定
A21: =ROW()-8 -> 13
A22: =ROW()-8 -> 14
A23: =ROW()-8 -> 15
A24: =ROW()-8 -> 16
A25: =ROW()-8 -> 17
A26: =ROW()-8 -> 18
A27: =ROW()-8 -> 19
A28: =ROW()-8 -> 20
A29: =ROW()-8 -> 21
A30: =ROW()-8 -> 22

Sheet テーブル出力仕様（支払方法・支払サイト更新ログ_金額参照）
A1: 基本設計書 | F1: =変更履歴!F1 -> システム名 | Q1: =変更履歴!Q1 -> 機能分類 | W1: =変更履歴!W1 -> 機能ＩＤ | AE1: =変更履歴!AE1 -> 機能名称 | AT1: =変更履歴!AT1 -> 日付 | BB1: =変更履歴!BB1 -> 更新者
F2: =変更履歴!F2 -> Dynamics365 for Finance and Operations | Q2: =変更履歴!Q2 -> 債権・債務 | W2: =変更履歴!W2 -> FO-008 | AE2: =変更履歴!AE2 -> 支払方法・支払サイト更新バッチ | AT2: =変更履歴!AT2 -> 作成 | AV2: =変更履歴!AV2 -> 45477 | BB2: =変更履歴!BB2 -> JBS 秋信
AT3: =変更履歴!AT3 -> 更新 | AV3: =変更履歴!AV3 -> 45708 | BB3: =変更履歴!BB3 -> JBS秋信
A5: テーブル名 | M5: SJ_PaymModePaymSiteUpdatedLog
A6: ラベル | M6: 支払方法・支払サイト更新ログ
A7: 拡張名
A8: No. | C8: 論理名 | M8: 物理名 | W8: 説明（登録時） | AZ8: 説明（更新時） | CC8: 備考
A9: =ROW()-8 -> 1 | C9: 仕入先 | M9: AccountNum | W9: 1-3-1.で取得した[仕入先トランザクション].[仕入先]を設定 | AZ9: -
A10: =ROW()-8 -> 2 | C10: 金額 | M10: AmountMST | W10: 1-3-1.で取得した[仕入先トランザクション].[金額] +1-3-1.で取得した[仕入先トランザクション].[為替レートの調整金額] -1-3-1.で取得した[仕入先トランザクション].[標準通貨の決済金額]を設定 | AZ10: -
A11: =ROW()-8 -> 3 | C11: 集計金額 | M11: TotalAmount | W11: - | AZ11: 1-4.で取得したSum([支払方法・支払サイト更新ログ].[金額])を設定
A12: =ROW()-8 -> 4 | C12: 支払方法 | M12: PaymMode | W12: 1-3-1.で取得した[仕入先トランザクション].[支払方法]を設定 | AZ12: -
A13: =ROW()-8 -> 5 | C13: 支払方法(更新後) | M13: UpdatePayｍMode | W13: - | AZ13: 振込（銀行振込、期日振込）の場合： 1-5-2. ①で取得した[支払方法・支払サイト.支払方法(更新後)] 電子記録債務の場合： 1-5-1. ①で取得した[支払方法・支払サイト.支払方法(更新後)] 上記以外の場合： 設定なし
A14: =ROW()-8 -> 6 | C14: 支払サイト | M14: PaymSite | W14: 1-3-1.で取得した[仕入先トランザクション].[支払サイト]を設定 | AZ14: -
A15: =ROW()-8 -> 7 | C15: 支払サイト(更新後) | M15: UpdatePaymSite | W15: - | AZ15: 振込（銀行振込、期日振込）の場合： 1-5-2. ①で取得した[支払方法・支払サイト.支払サイト] 電子記録債務の場合： 1-5-1. ①で取得した[支払方法・支払サイト.支払サイト] 上記以外の場合： 設定なし
A16: =ROW()-8 -> 8 | C16: 期日 | M16: DueDate | W16: 1-3-1.で取得した[仕入先トランザクション].[期日]を設定 | AZ16: -
A17: =ROW()-8 -> 9 | C17: 期日(更新後) | M17: UpdateDueDate | W17: - | AZ17: 振込（銀行振込、期日振込）の場合： 処理中の[支払方法・支払サイト更新ログ.支払基準日]と 1-5-2. ①で取得した[支払方法・支払サイト.支払条件]をもとに期日を算出し設定 電子記録債務の場合： 処理中の[支払方法・支払サイト更新ログ.支払基準日]と 1-5-1. ②で取得した[汎用パラメータ.値]（支払条件）をもとに期日を算出し設定 上記以外の場合： 設定なし
A18: =ROW()-8 -> 10 | C18: 支払基準日 | M18: PaymBaseDate | W18: 1-3-1.で取得した[仕入先トランザクション].[支払基準日]を設定 | AZ18: -
A19: =ROW()-8 -> 11 | C19: 参照 | M19: VendTransRecId | W19: 1-3-1.で取得した[仕入先トランザクション].[レコードID]を設定 | AZ19: -
A20: =ROW()-8 -> 12 | C20: 集計ステータス | M20: AggregationStatus | W20: SJ_AggregationStatusEnum::Pre-Aggregation(集計前) を設定 | AZ20: SJ_AggregationStatusEnum::Post-Aggregation(集計済) を設定
A21: =ROW()-8 -> 13
A22: =ROW()-8 -> 14
A23: =ROW()-8 -> 15
A24: =ROW()-8 -> 16
A25: =ROW()-8 -> 17
A26: =ROW()-8 -> 18
A27: =ROW()-8 -> 19
A28: =ROW()-8 -> 20
A29: =ROW()-8 -> 21
A30: =ROW()-8 -> 22
A31: =ROW()-8 -> 23
A32: =ROW()-8 -> 24
A33: =ROW()-8 -> 25

Sheet テーブル出力仕様（仕入先トランザクション）
A1: 基本設計書 | F1: =変更履歴!F1 -> システム名 | Q1: =変更履歴!Q1 -> 機能分類 | W1: =変更履歴!W1 -> 機能ＩＤ | AE1: =変更履歴!AE1 -> 機能名称 | AT1: =変更履歴!AT1 -> 日付 | BB1: =変更履歴!BB1 -> 更新者
F2: =変更履歴!F2 -> Dynamics365 for Finance and Operations | Q2: =変更履歴!Q2 -> 債権・債務 | W2: =変更履歴!W2 -> FO-008 | AE2: =変更履歴!AE2 -> 支払方法・支払サイト更新バッチ | AT2: =変更履歴!AT2 -> 作成 | AV2: =変更履歴!AV2 -> 45477 | BB2: =変更履歴!BB2 -> JBS 秋信
AT3: =変更履歴!AT3 -> 更新 | AV3: =変更履歴!AV3 -> 45708 | BB3: =変更履歴!BB3 -> JBS秋信
A5: テーブル名 | M5: VendTrans
A6: ラベル | M6: 仕入先トランザクション
A7: 拡張名
A8: No. | C8: 論理名 | M8: 物理名 | W8: 説明（仕入先参照時） | AZ8: 説明（金額参照時） | CC8: 備考
A9: =ROW()-8 -> 1 | C9: 支払方法 | M9: PaymMode | W9: 1-1-3.で取得した[仕入先].[支払方法]を設定 | AZ9: 1-6-1.で取得した[支払方法・支払サイト更新ログ.支払方法(更新後)(UpdatePayｍMode)]
A10: =ROW()-8 -> 2 | C10: 支払サイト | M10: SJ_PaymSite | W10: - | AZ10: 1-6-1.で取得した[支払方法・支払サイト更新ログ.支払サイト(更新後)(UpdatePaymSite)]
A11: =ROW()-8 -> 3 | C11: 期日 | M11: DueDate | W11: - | AZ11: 1-6-1.で取得した[支払方法・支払サイト更新ログ.期日(更新後)(UpdateDueDate)]
A12: =ROW()-8 -> 4 | C12: 支払方法・支払サイト更新フラグ | M12: SJ_PaymModePaymSiteUpdatedFlag | W12: - | AZ12: NoYes::Yes
A13: =ROW()-8 -> 5
A14: =ROW()-8 -> 6
A15: =ROW()-8 -> 7
A16: =ROW()-8 -> 8
A17: =ROW()-8 -> 9
A18: =ROW()-8 -> 10
A19: =ROW()-8 -> 11
A20: =ROW()-8 -> 12
A21: =ROW()-8 -> 13
A22: =ROW()-8 -> 14
A23: =ROW()-8 -> 15
A24: =ROW()-8 -> 16
... A34: =ROW()-8 -> 26

Sheet テーブル出力仕様（未処理の仕入先トランザクション）
A1: 基本設計書 | F1: =[1]変更履歴!F1 -> システム名 | Q1: =[1]変更履歴!Q1 -> 機能分類 | W1: =[1]変更履歴!W1 -> 機能ＩＤ | AE1: =[1]変更履歴!AE1 -> 機能名称 | AT1: =[1]変更履歴!AT1 -> 日付 | BB1: =[1]変更履歴!BB1 -> 更新者
F2: =[1]変更履歴!F2 -> Dynamics365 for Finance and Operations | Q2: =[1]変更履歴!Q2 -> 債権・債務 | W2: =[1]変更履歴!W2 -> FO-008 | AE2: =[1]変更履歴!AE2 -> 支払方法・支払サイト更新バッチ | AT2: =[1]変更履歴!AT2 -> 作成 | AV2: =[1]変更履歴!AV2 -> 45477 | BB2: =[1]変更履歴!BB2 -> JBS 秋信
AT3: =[1]変更履歴!AT3 -> 更新 | AV3: =[1]変更履歴!AV3 -> 45708 | BB3: =[1]変更履歴!BB3 -> JBS秋信
A5: テーブル名 | M5: VendTransOpen
A6: ラベル | M6: 未処理の仕入先トランザクション
A7: 拡張名
A8: No. | C8: 論理名 | M8: 物理名 | W8: 説明 | AZ8: 備考
A9: =ROW()-8 -> 1 | C9: 期日 | M9: DueDate | W9: 1-6-1.で取得した[支払方法・支払サイト更新ログ.期日(更新後)(UpdateDueDate)]
A10: =ROW()-8 -> 2
A11: =ROW()-8 -> 3
A12: =ROW()-8 -> 4
A13: =ROW()-8 -> 5
A14: =ROW()-8 -> 6
A15: =ROW()-8 -> 7
A16: =ROW()-8 -> 8
A17: =ROW()-8 -> 9
A18: =ROW()-8 -> 10
A19: =ROW()-8 -> 11
A20: =ROW()-8 -> 12
A21: =ROW()-8 -> 13
... A31: =ROW()-8 -> 23

Sheet 補足説明
A1: 基本設計書 | F1: =変更履歴!F1 -> システム名 | Q1: =変更履歴!Q1 -> 機能分類 | W1: =変更履歴!W1 -> 機能ＩＤ | AE1: =変更履歴!AE1 -> 機能名称 | AT1: =変更履歴!AT1 -> 日付 | BB1: =変更履歴!BB1 -> 更新者
F2: =変更履歴!F2 -> Dynamics365 for Finance and Operations | Q2: =変更履歴!Q2 -> 債権・債務 | W2: =変更履歴!W2 -> FO-008 | AE2: =変更履歴!AE2 -> 支払方法・支払サイト更新バッチ | AT2: =変更履歴!AT2 -> 作成 | AV2: =変更履歴!AV2 -> 45477 | BB2: =変更履歴!BB2 -> JBS 秋信
AT3: =変更履歴!AT3 -> 更新 | AV3: =変更履歴!AV3 -> 45708 | BB3: =変更履歴!BB3 -> JBS秋信
A5: 補足
B7: ＜機能関連図＞

Sheet 補足説明 (汎用パラメータ)
A1: 基本設計書 | F1: =変更履歴!F1 -> システム名 | Q1: =変更履歴!Q1 -> 機能分類 | W1: =変更履歴!W1 -> 機能ＩＤ | AE1: =変更履歴!AE1 -> 機能名称 | AT1: =変更履歴!AT1 -> 日付 | BB1: =変更履歴!BB1 -> 更新者
F2: =変更履歴!F2 -> Dynamics365 for Finance and Operations | Q2: =変更履歴!Q2 -> 債権・債務 | W2: =変更履歴!W2 -> FO-008 | AE2: =変更履歴!AE2 -> 支払方法・支払サイト更新バッチ | AT2: =変更履歴!AT2 -> 作成 | AV2: =変更履歴!AV2 -> 45477 | BB2: =変更履歴!BB2 -> JBS 秋信
AT3: =変更履歴!AT3 -> 更新 | AV3: =変更履歴!AV3 -> 45708 | BB3: =変更履歴!BB3 -> JBS秋信
A5: 補足
B7: ■汎用パラメータについて
C8: 事前に本機能で使用する下記汎用パラメータを設定する。
C10: SSJの場合
C11: 機能ID(FunctionId) | J11: 項目ID(ItemId) | P11: Key(Key) | V11: 値(Value) | AF11: 説明(Description)
C12: COMMON | J12: ElectronicDebit | P12: 1 | V12: 9-1 | AF12: 支払方法：でんさい(三井住友/95)
C13: COMMON | J13: ElectronicDebit | P13: 2 | V13: 8-1 | AF13: 支払方法：でんさい(三井住友/60)
C14: FO-008 | J14: 001 | P14: 1 | V14: PTXX | AF14: 支払条件：【システム利用】非営業日考慮用
C15: FO-008 | J15: 002 | P15: 1 | V15: 2 | AF15: 処理対象外の支払方法
C17: SEJの場合
C18: 機能ID(FunctionId) | J18: 項目ID(ItemId) | P18: Key(Key) | V18: 値(Value) | AF18: 説明(Description)
C19: COMMON | J19: ElectronicDebit | P19: 1 | V19: 9-2 | AF19: 支払方法：電債95(三菱UFJ/95)
C20: COMMON | J20: ElectronicDebit | P20: 2 | V20: 8-2 | AF20: 支払方法：電債(三菱UFJ/60)
C21: FO-008 | J21: 001 | P21: 1 | V21: PTXX | AF21: 支払条件：【システム利用】非営業日考慮用
C22: FO-008 | J22: 002 | P22: 1 | V22: 2 | AF22: 処理対象外の支払方法
C24: SLJの場合
C25: 機能ID(FunctionId) | J25: 項目ID(ItemId) | P25: Key(Key) | V25: 値(Value) | AF25: 説明(Description)
C26: FO-008 | J26: 001 | P26: 1 | V26: PTXX | AF26: 支払条件：【システム利用】非営業日考慮用
C27: FO-008 | J27: 002 | P27: 1 | V27: 2 | AF27: 処理対象外の支払方法

Sheet 補足説明 (支払方法マスタ)
A1: 基本設計書 | F1: =変更履歴!F1 -> システム名 | Q1: =変更履歴!Q1 -> 機能分類 | W1: =変更履歴!W1 -> 機能ＩＤ | AE1: =変更履歴!AE1 -> 機能名称 | AT1: =変更履歴!AT1 -> 日付 | BB1: =変更履歴!BB1 -> 更新者
F2: =変更履歴!F2 -> Dynamics365 for Finance and Operations | Q2: =変更履歴!Q2 -> 債権・債務 | W2: =変更履歴!W2 -> FO-008 | AE2: =変更履歴!AE2 -> 支払方法・支払サイト更新バッチ | AT2: =変更履歴!AT2 -> 作成 | AV2: =変更履歴!AV2 -> 45477 | BB2: =変更履歴!BB2 -> JBS 秋信
AT3: =変更履歴!AT3 -> 更新 | AV3: =変更履歴!AV3 -> 45708 | BB3: =変更履歴!BB3 -> JBS秋信
A5: 補足
C8: ＜SSJ＞

Sheet 補足説明 (処理イメージ)
A1: 基本設計書 | F1: =変更履歴!F1 -> システム名 | Q1: =変更履歴!Q1 -> 機能分類 | W1: =変更履歴!W1 -> 機能ＩＤ | AE1: =変更履歴!AE1 -> 機能名称 | AT1: =変更履歴!AT1 -> 日付 | BB1: =変更履歴!BB1 -> 更新者
F2: =変更履歴!F2 -> Dynamics365 for Finance and Operations | Q2: =変更履歴!Q2 -> 債権・債務 | W2: =変更履歴!W2 -> FO-008 | AE2: =変更履歴!AE2 -> 支払方法・支払サイト更新バッチ | AT2: =変更履歴!AT2 -> 作成 | AV2: =変更履歴!AV2 -> 45477 | BB2: =変更履歴!BB2 -> JBS 秋信
AT3: =変更履歴!AT3 -> 更新 | AV3: =変更履歴!AV3 -> 45708 | BB3: =変更履歴!BB3 -> JBS秋信
A5: 補足
C8: ＜支払方法・支払サイト＞
D9: 支払方法 | K9: 請求金額 | Q9: 支払方法（更新後） | X9: 支払サイト | AC9: 支払条件
D10: 9T | K10: 0 | Q10: T | X10: 0 | AC10: 【システム利用】非営業日考慮用
D11: 9T | K11: 500000 | Q11: 9-1 | X11: 95 | AC11: 【システム使用】サイト95日
D12: TU | K12: 0 | Q12: T | X12: 0 | AC12: 【システム利用】非営業日考慮用
D13: TU | K13: 500000 | Q13: W | X13: 95 | AC13: 【システム使用】サイト95日
D14: 2-1 | K14: 0 | Q14: 2-1 | X14: 0 | AC14: 【システム利用】非営業日考慮用
D16: 支払方法：2 | N16: ⇒期日振込/電子記録債務からの全額振込の変更、規定外の全額振込 に該当（仕入先に設定しない、本機能の更新対象外）
D17: 支払方法：T | N17: ⇒本機能で設定される支払方法（銀行振込、仕入先には設定しない。）
D18: 支払方法：W | N18: ⇒本機能で設定される支払方法（期日振込、仕入先には設定しない。）
D19: 支払方法：2-1 | N19: ⇒仕入先に設定する支払方法
C21: 例１：仕入先の支払方法を6/15に「9T」（電子記録債務（支払サイト：95））⇒「2-1」（全額振込）に変更
D23: 日付 | I23: 支払方法 | P23: 支払基準日 | U23: 期日 | Z23: 支払サイト | AF23: ＜7/6：バッチ実行＞ | AO23: 日付 | AT23: 支払方法 | BA23: 支払基準日 | BF23: 期日 | BK23: 支払サイト
D24: 2024/6/1 | I24: 9T | P24: 2024/7/20 | U24: 2024/7/20 | Z24: 0 | AF24: 処理① 仕入先マスタに登録 | AO24: 2024/6/1 | AT24: 2-1 | BA24: 2024/7/20 | BF24: 2024/7/20 | BK24: 0
D25: 2024/6/1 | I25: 9T | P25: 2024/7/20 | U25: 2024/7/20 | Z25: 0 | AF25: されている支払方法に変更 | AO25: 2024/6/1 | AT25: 2-1 | BA25: 2024/7/20 | BF25: 2024/7/20 | BK25: 0
D26: 2024/6/1 | I26: 2 | P26: 2024/6/20 | U26: 2024/6/20 | Z26: 0 | AO26: 2024/6/1 | AT26: 2 | BA26: 2024/6/20 | BF26: 2024/6/20 | BK26: 0 | BP26: ※対象外
D27: 2024/6/1 | I27: 9T | P27: 2024/7/20 | U27: 2024/7/20 | Z27: 0 | AO27: 2024/6/1 | AT27: 2-1 | BA27: 2024/7/20 | BF27: 2024/7/20 | BK27: 0
D28: 2024/6/15 | I28: 2-1 | P28: 2024/7/20 | U28: 2024/7/20 | Z28: 0 | AO28: 2024/6/15 | AT28: 2-1 | BA28: 2024/7/20 | BF28: 2024/7/20 | BK28: 0
D29: 2024/6/15 | I29: 2-1 | P29: 2024/7/20 | U29: 2024/7/20 | Z29: 0 | AO29: 2024/6/15 | AT29: 2-1 | BA29: 2024/7/20 | BF29: 2024/7/20 | BK29: 0
D30: 2024/6/15 | I30: 2-1 | P30: 2024/7/20 | U30: 2024/7/20 | Z30: 0 | AO30: 2024/6/15 | AT30: 2-1 | BA30: 2024/7/20 | BF30: 2024/7/20 | BK30: 0
P31: ※ | Q31: IFで仕入先マスタの支払条件を見て設定。
Q32: 基本仕入先マスタの支払条件は非営業日を考慮しない末締め翌20日
M34: 日付 | R34: 支払方法 | Y34: 支払基準日 | AD34: 期日 | AI34: 支払サイト
D35: 処理② 金額に応じて | M35: 2024/6/1 | R35: 2-1 | Y35: 2024/7/20 | AD35: 2024/7/22 | AI35: 0
D36: 支払方法、支払サイトを設定 | M36: 2024/6/1 | R36: 2-1 | Y36: 2024/7/20 | AD36: 2024/7/22 | AI36: 0
M37: 2024/6/1 | R37: 2 | Y37: 2024/6/20 | AD37: 2024/6/20 | AI37: 0
M38: 2024/6/1 | R38: 2-1 | Y38: 2024/7/20 | AD38: 2024/7/22 | AI38: 0
M39: 2024/6/15 | R39: 2-1 | Y39: 2024/7/20 | AD39: 2024/7/22 | AI39: 0
M40: 2024/6/15 | R40: 2-1 | Y40: 2024/7/20 | AD40: 2024/7/22 | AI40: 0
M41: 2024/6/15 | R41: 2-1 | Y41: 2024/7/20 | AD41: 2024/7/22 | AI41: 0
AD42: ※ | AE42: 非営業日の計算し設定。
C44: 例２：仕入先の支払方法を6/15に「9T」⇒「TU」（期日振込（支払サイト：95））に変更
D45: ①支払の合計金額が、50万以上の場合
D46: 日付 | I46: 支払方法 | P46: 支払基準日 | U46: 期日 | Z46: 支払サイト | AG46: ＜7/6：バッチ実行＞ | AP46: 日付 | AU46: 支払方法 | BB46: 支払基準日 | BG46: 期日 | BL46: 支払サイト
D47: 2024/6/1 | I47: 9T | P47: 2024/7/20 | U47: 2024/7/20 | Z47: 0 | AG47: 処理① 仕入先マスタに登録 | AP47: 2024/6/1 | AU47: TU | BB47: 2024/7/20 | BG47: 2024/7/20 | BL47: 0
D48: 2024/6/1 | I48: 9T | P48: 2024/7/20 | U48: 2024/7/20 | Z48: 0 | AG48: されている支払方法に変更 | AP48: 2024/6/1 | AU48: TU | BB48: 2024/7/20 | BG48: 2024/7/20 | BL48: 0
...

Sheet 参考_支払基準日の方針
B3: ①支払基準日が考慮されてない場合（すべて20日）
B4: ⇒規定支払については、支払基準日を空欄ですべてもらうことができないか。
B5: ⇒本方針で決定
F6: ※2024/7/20は、土曜
C7: 会計伝票取込 | D7: ⇒ | E7: FO | I7: ⇒ | J7: 更新バッチ | O7: ⇒ | P7: 振出時
C8: 支払方法 | E8: 支払方法 | F8: 支払基準日 | G8: 期日 | H8: サイト | K8: 支払方法 | L8: 支払基準日 | M8: 期日 | N8: サイト | P8: 支払方法 | Q8: 支払基準日 | R8: 期日 | S8: サイト
C9: TU（期日振込、サイト95） | E9: TU（期日振込、サイト95） | F9: 2024/7/20（元は空欄） | G9: 45493 | H9: 0 | J9: 50万未満の場合 | K9: T | L9: 45493 | M9: 45495 | N9: 0
J10: 50万以上の場合 | K10: W | L10: 45493 | M10: 45590 | N10: 95
C11: 8T（でんさい、サイト60） | E11: 8T（でんさい、サイト60） | F11: 2024/7/20（元は空欄） | G11: 45493 | H11: 0 | J11: 50万未満の場合 | K11: T | L11: 45493 | M11: 45495 | N11: 0
J12: 50万以上の場合 | K12: 8-1 | L12: 45493 | M12: 45495 | N12: 60 | P12: 8-1 | Q12: 45493 | R12: 45555 | S12: 60
C13: 2-1 | E13: 2-1 | F13: 2024/7/20（元は空欄） | G13: 45495 | H13: 0 | J13: 対象外
B14: 楽楽精算など | C14: 2 | E14: 2 | F14: 45495 | G14: 45495 | H14: 0 | J14: 対象外
M15: ※電子記録債務の振出用の支払条件を
M16: 汎用パラメータで保持する。
B18: ポイント1 | C18: 更新バッチ：
C19: 支払基準日（単一）でデータの取得を行う。
B20: ポイント2 | C20: 更新バッチ：期日振込以外
C21: 支払基準日から期日（土日考慮有）を計算する必要がある。
C22: ※支払条件は、支払方法・支払サイトマスタから取得
B23: ポイント3 | C23: 更新バッチ：でんさいの場合
C24: 支払基準日から期日（土日考慮有）を計算する必要がある。
C25: ※支払条件は、汎用パラメータから取得
B26: ポイント4 | C26: でんさい振出時：
C27: 支払基準日から期日（土日考慮有）を計算する必要がある。
C28: ※支払条件は、支払方法・支払サイトマスタから取得
B31: ②支払基準日が考慮された場合
F33: ※2024/7/20は、土曜
C34: 会計伝票取込 | D34: ⇒ | E34: FO | I34: ⇒ | J34: 更新バッチ | O34: ⇒ | P34: 振出時
C35: 支払方法 | E35: 支払方法 | F35: 支払基準日 | G35: 期日 | H35: サイト | K35: 支払方法 | L35: 支払基準日 | M35: 期日 | N35: サイト | P35: 支払方法 | Q35: 支払基準日 | R35: 期日 | S35: サイト
C36: TU（期日振込、サイト95） | E36: TU（期日振込、サイト95） | F36: 45495 | G36: 45495 | H36: 0 | J36: 50万未満の場合 | K36: 銀行振込 | L36: 45495 | M36: 45495 | N36: 0
J37: 50万以上の場合 | K37: 期日振込 | L37: 45495 | M37: 45590 | N37: 95
C38: 9T（でんさい、サイト60） | E38: 9T（でんさい、サイト60） | F38: 45495 | G38: 45495 | H38: 0 | J38: 50万未満の場合 | K38: 銀行振込 | L38: 45495 | M38: 45495 | N38: 0
J39: 50万以上の場合 | K39: でんさい60 | L39: 45495 | M39: 45495 | N39: 60 | P39: でんさい60 | Q39: 45495 | R39: 45555 | S39: 60
C40: 銀行振込/三菱U | E40: 銀行振込/三菱U | F40: 45495 | G40: 45495 | H40: 0 | J40: 対象外
C41: 全額銀行振込/三菱U | E41: 全額銀行振込/三菱U | F41: 45495 | G41: 45495 | H41: 0 | J41: 対象外
B43: ポイント1 | C43: 更新バッチ：
C44: 支払基準日（単一）でデータの取得を行う。
B45: ポイント2 | C45: 更新バッチ：期日振込の場合
C46: 汎用パラメータ（20日）を軸にして期日（土日考慮有）を計算する必要がある。
C47: ※支払条件は、支払方法・支払サイトマスタから取得
...

Sheet レビュー指摘事項
A1: 基本設計書 | F1: =変更履歴!F1 -> システム名 | Q1: =変更履歴!Q1 -> 機能分類 | W1: =変更履歴!W1 -> 機能ＩＤ | AE1: =変更履歴!AE1 -> 機能名称 | AT1: =変更履歴!AT1 -> 日付 | BB1: =変更履歴!BB1 -> 更新者
F2: =変更履歴!F2 -> Dynamics365 for Finance and Operations | Q2: =変更履歴!Q2 -> 債権・債務 | W2: =変更履歴!W2 -> FO-008 | AE2: =変更履歴!AE2 -> 支払方法・支払サイト更新バッチ | AT2: =変更履歴!AT2 -> 作成 | AV2: =変更履歴!AV2 -> 45477 | BB2: =変更履歴!BB2 -> JBS 秋信
AT3: =変更履歴!AT3 -> 更新 | AV3: =変更履歴!AV3 -> 45708 | BB3: =変更履歴!BB3 -> JBS秋信
A5: No. | C5: レビュー事項 | Q5: 対応内容 | AF5: 指摘日 | AK5: 指摘者 | AP5: 対応日 | AU5: 対応者 | AZ5: 確認日 | BE5: 確認者
A6: =ROW()-5 -> 1 | C6: シート：処理概要 バッチ更新後の修正に関してのオペレーションを確定する。 | Q6: 2024/8/1の打合せにて、以下内容で決定し修正対応を行いました。 ・仕入先の支払方法の変更に対応するように仕様の変更 ・支払予定の確定後にバッチを実行すること。 バッチ実行後に修正が発生した場合は、手動にて修正対応していただくき、バッチ実行を行うこと。 | AF6: 45489 | AK6: JBS 秋信 | AP6: 45506 | AU6: JBS 秋信 | AZ6: 45523 | BE6: サンスター藤田
A7: =ROW()-5 -> 2 | C7: シート：画面レイアウト 支払基準日に土日に該当する場合、幅を持たせて日付指定できる必要ある | Q7: シート：画面レイアウト、画面項目説明 支払基準日でFromTo指摘できるように修正いたしました。 シート：処理概要 以下前提条件の削除を行いました。 「処理対象は、支払基準日が当月の債務データを対象とする。（先日付で転記されている債務データは対象外）」 ⇒前提条件ではなく、バッチ実行時に支払基準日を指定するため削除いたしました。 | AF7: 45513 | AK7: サンスター 藤田さま | AP7: 45517 | AU7: JBS 秋信 | AZ7: 45523 | BE7: サンスター藤田
A8: =ROW()-5 -> 3 | C8: 仕入先の複数条件指定方法を統一する。 | Q8: シート：画面レイアウト、画面項目説明 複数条件指定の場合は、「,」を使用して設定する方針で統一することになりましたので、修正いたしました。 | AF8: 45524 | AK8: JBS 秋信 | AP8: 45524 | AU8: JBS 秋信 | AZ8: 45530 | BE8: サンスター藤田
A9: =ROW()-5 -> 4 | C9: ①支払基準日を規定払いについては、末締翌20日を固定で設定する方針で決定した。それに伴い、支払基準日を使用する機能の修正を行う。 ②支払方法マスタのコード値を文字列から英数字にする方針に決定した。それに伴い、支払方法を使用する機能の修正を行う。 ※2024/09/17の債務チームの定例会で説明済 | Q9: ① シート：イベント説明 処理内容（支払基準日の条件）の修正 シート：画面レイアウト・画面項目説明 項目：「支払基準日 From」「支払基準日 To」削除 項目：「支払基準日」追加 ② シート：処理概要 前提条件（除外対象）の修正 シート：イベント説明,DFD 処理内容（除外対象）の修正、除外対象の支払方法を汎用パラメータから取得するように変更 シート：補足説明（汎用パラメータ） 支払方法マスタの最新化 シート：補足説明（支払方法マスタ） 支払方法マスタの最新化 シート：補足説明（処理イメージ） 支払方法マスタの最新化 シート：参考_支払基準日の方針 支払方法マスタの最新化 | AF9: 45553 | AK9: JBS 秋信 | AP9: 45561 | AU9: JBS 秋信 | AZ9: 45568 | BE9: サンスター藤田
A10: =ROW()-5 -> 5
A11: =ROW()-5 -> 6
A12: =ROW()-5 -> 7
A13: =ROW()-5 -> 8
A14: =ROW()-5 -> 9
A15: =ROW()-5 -> 10
A16: =ROW()-5 -> 11
A17: =ROW()-5 -> 12
A18: =ROW()-5 -> 13
A19: =ROW()-5 -> 14
A20: =ROW()-5 -> 15
A21: =ROW()-5 -> 16
... A40: =ROW()-5 -> 35

Sheet オブジェクト一覧
A1: 詳細設計書 | F1: システム名 | Q1: 機能分類 | W1: 機能ＩＤ | AE1: 機能名称 | AT1: 日付 | BB1: 更新者
F2: Dynamics365 for Finance and Operations | Q2: 債権・債務 | W2: FO-008 | AE2: 支払方法・支払サイト更新バッチ | AT2: 作成 | AV2: 45477 | BB2: JBS 秋信
AT3: 更新 | AV3: 45601 | BB3: JBS秋信
A5: No. | C5: オブジェクト名 | S5: 属性 | AA5: 概要 | BD5: 備考
A6: =ROW()-5 -> 1 | C6: SJ_BatchPaymUpdate | S6: Menu Items(Action) | AA6: 買掛金メニューでBatchPaymUpdateメニューを作成する
A7: =ROW()-5 -> 2 | C7: SJ_BatchPaymUpdateContract | S7: Class | AA7: BatchPaymUpdateのgets/setsを定義する。
A8: =ROW()-5 -> 3 | C8: SJ_BatchPaymUpdateController | S8: Class | AA8: SJ_BatchPaymUpdateServiceクラスを実行するクラス
A9: =ROW()-5 -> 4 | C9: SJ_BatchPaymUpdateService | S9: Class | AA9: BatchPaymentUpdateを実行するクラス
A10: =ROW()-5 -> 5 | C10: SJ_BatchPaymUpdateUIBuilder | S10: Class | AA10: ダイアログ制御を変更するクラス
A11: =ROW()-5 -> 6 | C11: SJ_BatchPaymUpdateqQuery | S11: Queries | AA11: SJ_BatchPaymUpdateUIBuilderで複数の値ルークアップを実行するクラス
A12: =ROW()-5 -> 7 | C12: AccountsPayable.SJ_Extension | S12: Menus | AA12: 買掛金メニューを拡張し、BatchPaymentUpdate実行用ボタンを作成する。
A13: =ROW()-5 -> 8 | C13: SJ_PaymModePaymSiteUpdatedLog | S13: Table | AA13: BatchPaymentUpdateのログを格納するテーブル
A14: =ROW()-5 -> 9 | C14: SJ_HelperClass | S14: Class | AA14: refreshCaller メソッドを使用してレコードから通話フォームを更新します | BD14: refreshCaller()
A15: =ROW()-5 -> 10 | C15: SJ_AggregationStatusEnum | S15: EDT | AA15: SJ_PaymModePaymSiteUpdatedLog フィールドの EDT
A16: =ROW()-5 -> 11 | C16: SJ_PaymBaseDate | S16: EDT | AA16: SJ_PaymModePaymSiteUpdatedLog フィールドの EDT
A17: =ROW()-5 -> 12 | C17: SJ_UpdateDueDate | S17: EDT | AA17: SJ_PaymModePaymSiteUpdatedLog フィールドの EDT
A18: =ROW()-5 -> 13 | C18: SJ_VendTransRecId | S18: EDT | AA18: SJ_PaymModePaymSiteUpdatedLog フィールドの EDT
A19: =ROW()-5 -> 14 | C19: SJ_UpdatePaymSite | S19: EDT | AA19: SJ_PaymModePaymSiteUpdatedLog フィールドの EDT
A20: =ROW()-5 -> 15 | C20: SJ_TotalAmount | S20: EDT | AA20: SJ_PaymModePaymSiteUpdatedLog フィールドの EDT
A21: =ROW()-5 -> 16 | C21: SJ_UpdatePaymMode | S21: EDT | AA21: SJ_PaymModePaymSiteUpdatedLog フィールドの EDT
A22: =ROW()-5 -> 17
A23: =ROW()-5 -> 18
A24: =ROW()-5 -> 19
A25: =ROW()-5 -> 20
A26: =ROW()-5 -> 21
A27: =ROW()-5 -> 22
A28: =ROW()-5 -> 23
A29: =ROW()-5 -> 24
A30: =ROW()-5 -> 25
A31: =ROW()-5 -> 26
A32: =ROW()-5 -> 27
A33: =ROW()-5 -> 28
... A38: =ROW()-5 -> 33

Sheet プログラムフロー図
A1: 詳細設計書 | F1: =変更履歴!F1 -> システム名 | Q1: =変更履歴!Q1 -> 機能分類 | W1: =変更履歴!W1 -> 機能ＩＤ | AE1: =変更履歴!AE1 -> 機能名称 | AT1: =変更履歴!AT1 -> 日付 | BB1: =変更履歴!BB1 -> 更新者
F2: =変更履歴!F2 -> Dynamics365 for Finance and Operations | Q2: =変更履歴!Q2 -> 債権・債務 | W2: =変更履歴!W2 -> FO-008 | AE2: =変更履歴!AE2 -> 支払方法・支払サイト更新バッチ | AT2: =変更履歴!AT2 -> 作成 | AV2: =変更履歴!AV2 -> 45477 | BB2: =変更履歴!BB2 -> JBS 秋信
AT3: =変更履歴!AT3 -> 更新 | AV3: =変更履歴!AV3 -> 45708 | BB3: =変更履歴!BB3 -> JBS秋信
A5: プログラムフロー図
A27: 凡例
A28: 記号

Sheet マスタ
A2: LinkType | B2: IO | C2: 書式 | D2: 横位置 | E2: 縦位置 | F2: 折り返して全体を表示する | G2: 表示/非表示 Visivility | H2: テーブル種別 | I2: オブジェクト | J2: 取得元 | K2: ヘッダー/明細行
A3: Passive | B3: I/O | C3: テキスト | D3: 標準 | E3: 標準 | F3: 〇 | G3: 表示 | H3: テーブル | I3: Class | J3: 必須 | K3: ヘッダー
A4: Delayed | B4: I | C4: 日付 | D4: 中央詰 | E4: 中央詰 | F4: ー | G4: 非表示 | H4: ビュー | I4: Form Class | J4: 顧客マスタ | K4: 明細行
A5: Active | B5: O | C5: 数値 | D5: 左詰 | E5: 上詰 | I5: Table Class | J5: 製品マスタ | K5: ヘッダー/明細行
A6: Inner | D6: 右詰 | E6: 下詰 | I6: Macro | J6: ユーザ入力
A7: Outer | I7: Enum | J7: 自動入力
A8: Exsits | I8: EDT
A9: Not Exsits | I9: Queries
I10: Data Entities
I11: Maps
I12: Forms
I13: Menus
I14: Menu Items(Display)
I15: Menu Items(Output)
I16: Menu Items(Action)
I17: Repoters
I18: Security Roles
I19: Security Duties
I20: Security Policies
